{"series": [{"name": "data", "columns": ["time", "data", "symbol"], "values": [[1528683682759, "{\"table\": \"orderBookL2\", \"action\": \"update\", \"data\": [{\"id\": 8799322350, \"side\": \"Sell\", \"size\": 615194}], \"symbol\": \"XBTUSD\", \"timestamp\": \"2018-06-11 02:21:22.756214Z\"}", "XBTUSD"], [1528683683711, "{\"table\": \"orderBookL2\", \"action\": \"update\", \"data\": [{\"id\": 8799320050, \"side\": \"Sell\", \"size\": 19837}, {\"id\": 8799321450, \"side\": \"Sell\", \"size\": 1800}], \"symbol\": \"XBTUSD\", \"timestamp\": \"2018-06-11 02:21:23.708322Z\"}", "XBTUSD"], [1528683686351, "{\"table\": \"orderBookL2\", \"action\": \"update\", \"data\": [{\"id\": 8799322400, \"side\": \"Buy\", \"size\": 1746090}, {\"id\": 8799322450, \"side\": \"Buy\", \"size\": 70604}], \"symbol\": \"XBTUSD\", \"timestamp\": \"2018-06-11 02:21:26.347897Z\"}", "XBTUSD"], [1528683688009, "{\"table\": \"orderBookL2\", \"action\": \"update\", \"data\": [{\"id\": 8799322350, \"side\": \"Sell\", \"size\": 1023419}], \"symbol\": \"XBTUSD\", \"timestamp\": \"2018-06-11 02:21:28.005414Z\"}", "XBTUSD"], [1528683689615, "{\"table\": \"orderBookL2\", \"action\": \"update\", \"data\": [{\"id\": 8799322000, \"side\": \"Sell\", \"size\": 497627}, {\"id\": 8799322350, \"side\": \"Sell\", \"size\": 316408}], \"symbol\": \"XBTUSD\", \"timestamp\": \"2018-06-11 02:21:29.610410Z\"}", "XBTUSD"], [1528683694426, "{\"table\": \"orderBookL2\", \"action\": \"update\", \"data\": [{\"id\": 8799322400, \"side\": \"Buy\", \"size\": 1362911}], \"symbol\": \"XBTUSD\", \"timestamp\": \"2018-06-11 02:21:34.413045Z\"}", "XBTUSD"], [1528683694791, "{\"table\": \"orderBookL2\", \"action\": \"update\", \"data\": [{\"id\": 8799322100, \"side\": \"Sell\", \"size\": 742}], \"symbol\": \"XBTUSD\", \"timestamp\": \"2018-06-11 02:21:34.788868Z\"}", "XBTUSD"], [1528683696388, "{\"table\": \"orderBookL2\", \"action\": \"update\", \"data\": [{\"id\": 8799322350, \"side\": \"Buy\", \"size\": 1177220}], \"symbol\": \"XBTUSD\", \"timestamp\": \"2018-06-11 02:21:36.385196Z\"}", "XBTUSD"], [1528683698911, "{\"table\": \"trade\", \"action\": \"insert\", \"data\": [{\"timestamp\": \"2018-06-11T02:21:37.409Z\", \"side\": \"Buy\", \"size\": 5876, \"price\": 6777, \"tickDirection\": \"PlusTick\", \"trdMatchID\": \"ef08ec2c-142e-ad6e-b4e0-4ccee77c9a9b\", \"grossValue\": 86706256, \"homeNotional\": 0.86706256, \"foreignNotional\": 5876}, {\"timestamp\": \"2018-06-11T02:21:37.409Z\", \"side\": \"Buy\", \"size\": 2000, \"price\": 6777, \"tickDirection\": \"ZeroPlusTick\", \"trdMatchID\": \"e76f89e6-7e44-f7f5-1cfa-5a548fe3aac3\", \"grossValue\": 29512000, \"homeNotional\": 0.29512, \"foreignNotional\": 2000}, {\"timestamp\": \"2018-06-11T02:21:37.409Z\", \"side\": \"Buy\", \"size\": 25, \"price\": 6777, \"tickDirection\": \"ZeroPlusTick\", \"trdMatchID\": \"617b4f10-d052-c78e-e3e2-d288ae0fac8e\", \"grossValue\": 368900, \"homeNotional\": 0.003689, \"foreignNotional\": 25}], \"symbol\": \"XBTUSD\", \"timestamp\": \"2018-06-11 02:21:38.901480Z\"}", "XBTUSD"], [1528683699257, "{\"table\": \"orderBookL2\", \"action\": \"update\", \"data\": [{\"id\": 8799320200, \"side\": \"Sell\", \"size\": 1058248}, {\"id\": 8799321700, \"side\": \"Sell\", \"size\": 517}, {\"id\": 8799322900, \"side\": \"Buy\", \"size\": 31068}, {\"id\": 8799325900, \"side\": \"Buy\", \"size\": 217483}], \"symbol\": \"XBTUSD\", \"timestamp\": \"2018-06-11 02:21:39.250819Z\"}", "XBTUSD"], [1528683699581, "{\"table\": \"orderBookL2\", \"action\": \"update\", \"data\": [{\"id\": 8799322500, \"side\": \"Buy\", \"size\": 132907}, {\"id\": 8799324500, \"side\": \"Buy\", \"size\": 121408}], \"symbol\": \"XBTUSD\", \"timestamp\": \"2018-06-11 02:21:39.578614Z\"}", "XBTUSD"], [1528683700143, "{\"table\": \"orderBookL2\", \"action\": \"update\", \"data\": [{\"id\": 8799322150, \"side\": \"Buy\", \"size\": 688836}, {\"id\": 8799322300, \"side\": \"Buy\", \"size\": 425070}], \"symbol\": \"XBTUSD\", \"timestamp\": \"2018-06-11 02:21:40.140242Z\"}", "XBTUSD"], [1528683701420, "{\"table\": \"orderBookL2\", \"action\": \"update\", \"data\": [{\"id\": 8799322050, \"side\": \"Buy\", \"size\": 629702}, {\"id\": 8799322100, \"side\": \"Buy\", \"size\": 151668}], \"symbol\": \"XBTUSD\", \"timestamp\": \"2018-06-11 02:21:41.416067Z\"}", "XBTUSD"], [1528683703903, "{\"table\": \"orderBookL2\", \"action\": \"update\", \"data\": [{\"id\": 8799322400, \"side\": \"Buy\", \"size\": 442727}, {\"id\": 8799322450, \"side\": \"Buy\", \"size\": 68982}, {\"id\": 8799322500, \"side\": \"Buy\", \"size\": 132600}], \"symbol\": \"XBTUSD\", \"timestamp\": \"2018-06-11 02:21:43.899885Z\"}", "XBTUSD"], [1528683704088, "{\"table\": \"orderBookL2\", \"action\": \"update\", \"data\": [{\"id\": 8799325400, \"side\": \"Buy\", \"size\": 73078}], \"symbol\": \"XBTUSD\", \"timestamp\": \"2018-06-11 02:21:44.085862Z\"}", "XBTUSD"], [1528683704815, "{\"table\": \"orderBookL2\", \"action\": \"update\", \"data\": [{\"id\": 8799321350, \"side\": \"Sell\", \"size\": 2100}], \"symbol\": \"XBTUSD\", \"timestamp\": \"2018-06-11 02:21:44.809345Z\"}", "XBTUSD"], [1528683709159, "{\"table\": \"orderBookL2\", \"action\": \"update\", \"data\": [{\"id\": 8799321300, \"side\": \"Sell\", \"size\": 22182}], \"symbol\": \"XBTUSD\", \"timestamp\": \"2018-06-11 02:21:49.154848Z\"}", "XBTUSD"], [1528683709479, "{\"table\": \"orderBookL2\", \"action\": \"update\", \"data\": [{\"id\": 8799321500, \"side\": \"Sell\", \"size\": 6745}, {\"id\": 8799321550, \"side\": \"Sell\", \"size\": 2143}], \"symbol\": \"XBTUSD\", \"timestamp\": \"2018-06-11 02:21:49.472312Z\"}", "XBTUSD"], [1528683710882, "{\"table\": \"orderBookL2\", \"action\": \"update\", \"data\": [{\"id\": 8799320900, \"side\": \"Sell\", \"size\": 147664}, {\"id\": 8799321150, \"side\": \"Sell\", \"size\": 17078}, {\"id\": 8799322450, \"side\": \"Buy\", \"size\": 16888}, {\"id\": 8799322550, \"side\": \"Buy\", \"size\": 1284}], \"symbol\": \"XBTUSD\", \"timestamp\": \"2018-06-11 02:21:50.878346Z\"}", "XBTUSD"], [1528683713436, "{\"table\": \"orderBookL2\", \"action\": \"update\", \"data\": [{\"id\": 8799322000, \"side\": \"Sell\", \"size\": 183544}], \"symbol\": \"XBTUSD\", \"timestamp\": \"2018-06-11 02:21:53.431665Z\"}", "XBTUSD"], [1528683715597, "{\"table\": \"orderBookL2\", \"action\": \"update\", \"data\": [{\"id\": 8799321200, \"side\": \"Sell\", \"size\": 72158}, {\"id\": 8799321300, \"side\": \"Sell\", \"size\": 18182}], \"symbol\": \"XBTUSD\", \"timestamp\": \"2018-06-11 02:21:55.594656Z\"}", "XBTUSD"], [1528683717382, "{\"table\": \"orderBookL2\", \"action\": \"update\", \"data\": [{\"id\": 8799320850, \"side\": \"Sell\", \"size\": 75400}], \"symbol\": \"XBTUSD\", \"timestamp\": \"2018-06-11 02:21:57.378655Z\"}", "XBTUSD"], [1528683722651, "{\"table\": \"orderBookL2\", \"action\": \"update\", \"data\": [{\"id\": 8799321500, \"side\": \"Sell\", \"size\": 10371}, {\"id\": 8799321550, \"side\": \"Sell\", \"size\": 34544}], \"symbol\": \"XBTUSD\", \"timestamp\": \"2018-06-11 02:22:02.648381Z\"}", "XBTUSD"], [1528683725254, "{\"table\": \"orderBookL2\", \"action\": \"update\", \"data\": [{\"id\": 8799324950, \"side\": \"Buy\", \"size\": 93513}, {\"id\": 8799325000, \"side\": \"Buy\", \"size\": 162679}], \"symbol\": \"XBTUSD\", \"timestamp\": \"2018-06-11 02:22:05.250715Z\"}", "XBTUSD"], [1528683727949, "{\"table\": \"orderBookL2\", \"action\": \"update\", \"data\": [{\"id\": 8799322300, \"side\": \"Buy\", \"size\": 130910}], \"symbol\": \"XBTUSD\", \"timestamp\": \"2018-06-11 02:22:07.943463Z\"}", "XBTUSD"], [1528683730414, "{\"table\": \"orderBookL2\", \"action\": \"update\", \"data\": [{\"id\": 8799321200, \"side\": \"Sell\", \"size\": 98508}, {\"id\": 8799321300, \"side\": \"Sell\", \"size\": 14464}], \"symbol\": \"XBTUSD\", \"timestamp\": \"2018-06-11 02:22:10.407817Z\"}", "XBTUSD"], [1528683733073, "{\"table\": \"orderBookL2\", \"action\": \"update\", \"data\": [{\"id\": 8799321600, \"side\": \"Sell\", \"size\": 29740}], \"symbol\": \"XBTUSD\", \"timestamp\": \"2018-06-11 02:22:13.069680Z\"}", "XBTUSD"], [1528683737185, "{\"table\": \"orderBookL2\", \"action\": \"update\", \"data\": [{\"id\": 8799322450, \"side\": \"Buy\", \"size\": 2988}, {\"id\": 8799322600, \"side\": \"Buy\", \"size\": 69871}], \"symbol\": \"XBTUSD\", \"timestamp\": \"2018-06-11 02:22:17.179426Z\"}", "XBTUSD"], [1528683739422, "{\"table\": \"orderBookL2\", \"action\": \"update\", \"data\": [{\"id\": 8799320400, \"side\": \"Sell\", \"size\": 135439}, {\"id\": 8799321500, \"side\": \"Sell\", \"size\": 579197}, {\"id\": 8799322300, \"side\": \"Buy\", \"size\": 81510}, {\"id\": 8799324300, \"side\": \"Buy\", \"size\": 40828}], \"symbol\": \"XBTUSD\", \"timestamp\": \"2018-06-11 02:22:19.418553Z\"}", "XBTUSD"], [1528683739700, "{\"table\": \"orderBookL2\", \"action\": \"update\", \"data\": [{\"id\": 8799320550, \"side\": \"Sell\", \"size\": 258934}], \"symbol\": \"XBTUSD\", \"timestamp\": \"2018-06-11 02:22:19.692352Z\"}", "XBTUSD"], [1528683739917, "{\"table\": \"orderBookL2\", \"action\": \"update\", \"data\": [{\"id\": 8799322850, \"side\": \"Buy\", \"size\": 29938}], \"symbol\": \"XBTUSD\", \"timestamp\": \"2018-06-11 02:22:19.911888Z\"}", "XBTUSD"], [1528683741933, "{\"table\": \"orderBookL2\", \"action\": \"update\", \"data\": [{\"id\": 8799322600, \"side\": \"Buy\", \"size\": 81619}], \"symbol\": \"XBTUSD\", \"timestamp\": \"2018-06-11 02:22:21.929769Z\"}", "XBTUSD"], [1528683743918, "{\"table\": \"trade\", \"action\": \"insert\", \"data\": [{\"timestamp\": \"2018-06-11T02:22:22.309Z\", \"side\": \"Buy\", \"size\": 3091, \"price\": 6780.5, \"tickDirection\": \"ZeroPlusTick\", \"trdMatchID\": \"61d1ec94-9327-9751-72c9-f1ba7e2adf6a\", \"grossValue\": 45586068, \"homeNotional\": 0.45586068, \"foreignNotional\": 3091}, {\"timestamp\": \"2018-06-11T02:22:22.309Z\", \"side\": \"Buy\", \"size\": 21909, \"price\": 6780.5, \"tickDirection\": \"ZeroPlusTick\", \"trdMatchID\": \"b4f2ebae-eb1b-ac2a-193e-38a37b450a8a\", \"grossValue\": 323113932, \"homeNotional\": 3.23113932, \"foreignNotional\": 21909}], \"symbol\": \"XBTUSD\", \"timestamp\": \"2018-06-11 02:22:23.914384Z\"}", "XBTUSD"], [1528683744376, "{\"table\": \"orderBookL2\", \"action\": \"update\", \"data\": [{\"id\": 8799321950, \"side\": \"Sell\", \"size\": 325394}], \"symbol\": \"XBTUSD\", \"timestamp\": \"2018-06-11 02:22:24.373388Z\"}", "XBTUSD"], [1528683747582, "{\"table\": \"quote\", \"action\": \"insert\", \"data\": [{\"timestamp\": \"2018-06-11T02:22:25.056Z\", \"bidSize\": 816417, \"bidPrice\": 6780, \"askPrice\": 6780.5, \"askSize\": 339487}], \"symbol\": \"XBTUSD\", \"timestamp\": \"2018-06-11 02:22:27.577853Z\"}", "XBTUSD"], [1528683747948, "{\"table\": \"orderBookL2\", \"action\": \"update\", \"data\": [{\"id\": 8799322050, \"side\": \"Buy\", \"size\": 209177}, {\"id\": 8799332000, \"side\": \"Buy\", \"size\": 680892}], \"symbol\": \"XBTUSD\", \"timestamp\": \"2018-06-11 02:22:27.945302Z\"}", "XBTUSD"], [1528683751151, "{\"table\": \"orderBookL2\", \"action\": \"delete\", \"data\": [{\"id\": 8799309250, \"side\": \"Sell\"}], \"symbol\": \"XBTUSD\", \"timestamp\": \"2018-06-11 02:22:31.144286Z\"}", "XBTUSD"], [1528683752749, "{\"table\": \"orderBookL2\", \"action\": \"update\", \"data\": [{\"id\": 8799322000, \"side\": \"Buy\", \"size\": 770074}], \"symbol\": \"XBTUSD\", \"timestamp\": \"2018-06-11 02:22:32.745033Z\"}", "XBTUSD"], [1528683756385, "{\"table\": \"orderBookL2\", \"action\": \"update\", \"data\": [{\"id\": 8799321850, \"side\": \"Sell\", \"size\": 11162}, {\"id\": 8799322050, \"side\": \"Buy\", \"size\": 105502}], \"symbol\": \"XBTUSD\", \"timestamp\": \"2018-06-11 02:22:36.378919Z\"}", "XBTUSD"], [1528683758898, "{\"table\": \"orderBookL2\", \"action\": \"update\", \"data\": [{\"id\": 8799322000, \"side\": \"Buy\", \"size\": 1027476}], \"symbol\": \"XBTUSD\", \"timestamp\": \"2018-06-11 02:22:38.894561Z\"}", "XBTUSD"], [1528683760063, "{\"table\": \"orderBookL2\", \"action\": \"update\", \"data\": [{\"id\": 8799320250, \"side\": \"Sell\", \"size\": 17219}, {\"id\": 8799321350, \"side\": \"Sell\", \"size\": 17385}], \"symbol\": \"XBTUSD\", \"timestamp\": \"2018-06-11 02:22:40.059269Z\"}", "XBTUSD"], [1528683763916, "{\"table\": \"orderBookL2\", \"action\": \"update\", \"data\": [{\"id\": 8799322300, \"side\": \"Buy\", \"size\": 129787}, {\"id\": 8799322400, \"side\": \"Buy\", \"size\": 331281}], \"symbol\": \"XBTUSD\", \"timestamp\": \"2018-06-11 02:22:43.913838Z\"}", "XBTUSD"], [1528683764681, "{\"table\": \"orderBookL2\", \"action\": \"update\", \"data\": [{\"id\": 8799321650, \"side\": \"Sell\", \"size\": 6450}], \"symbol\": \"XBTUSD\", \"timestamp\": \"2018-06-11 02:22:44.678276Z\"}", "XBTUSD"], [1528683767214, "{\"table\": \"orderBookL2\", \"action\": \"update\", \"data\": [{\"id\": 8799321550, \"side\": \"Sell\", \"size\": 72502}], \"symbol\": \"XBTUSD\", \"timestamp\": \"2018-06-11 02:22:47.205818Z\"}", "XBTUSD"], [1528683769156, "{\"table\": \"orderBookL2\", \"action\": \"update\", \"data\": [{\"id\": 8799321950, \"side\": \"Buy\", \"size\": 152291}, {\"id\": 8799322000, \"side\": \"Buy\", \"size\": 1185725}], \"symbol\": \"XBTUSD\", \"timestamp\": \"2018-06-11 02:22:49.153225Z\"}", "XBTUSD"], [1528683769579, "{\"table\": \"orderBookL2\", \"action\": \"update\", \"data\": [{\"id\": 8799320550, \"side\": \"Sell\", \"size\": 264462}, {\"id\": 8799320700, \"side\": \"Sell\", \"size\": 206969}, {\"id\": 8799320900, \"side\": \"Sell\", \"size\": 22750}, {\"id\": 8799321050, \"side\": \"Sell\", \"size\": 11631}, {\"id\": 8799321300, \"side\": \"Sell\", \"size\": 1728}, {\"id\": 8799321400, \"side\": \"Sell\", \"size\": 153675}, {\"id\": 8799323150, \"side\": \"Buy\", \"size\": 1412}, {\"id\": 8799323250, \"side\": \"Buy\", \"size\": 1756}], \"symbol\": \"XBTUSD\", \"timestamp\": \"2018-06-11 02:22:49.576057Z\"}", "XBTUSD"], [1528683770248, "{\"table\": \"orderBookL2\", \"action\": \"update\", \"data\": [{\"id\": 8799321600, \"side\": \"Buy\", \"size\": 271086}, {\"id\": 8799321950, \"side\": \"Buy\", \"size\": 584123}], \"symbol\": \"XBTUSD\", \"timestamp\": \"2018-06-11 02:22:50.246058Z\"}", "XBTUSD"], [1528683770849, "{\"table\": \"orderBookL2\", \"action\": \"update\", \"data\": [{\"id\": 8799321650, \"side\": \"Buy\", \"size\": 28821}, {\"id\": 8799321750, \"side\": \"Buy\", \"size\": 109961}, {\"id\": 8799321850, \"side\": \"Buy\", \"size\": 26129}], \"symbol\": \"XBTUSD\", \"timestamp\": \"2018-06-11 02:22:50.846167Z\"}", "XBTUSD"], [1528683771465, "{\"table\": \"orderBookL2\", \"action\": \"update\", \"data\": [{\"id\": 8799321650, \"side\": \"Buy\", \"size\": 41989}], \"symbol\": \"XBTUSD\", \"timestamp\": \"2018-06-11 02:22:51.462623Z\"}", "XBTUSD"], [1528683772135, "{\"table\": \"orderBookL2\", \"action\": \"update\", \"data\": [{\"id\": 8799321900, \"side\": \"Buy\", \"size\": 147529}], \"symbol\": \"XBTUSD\", \"timestamp\": \"2018-06-11 02:22:52.132445Z\"}", "XBTUSD"], [1528683773173, "{\"table\": \"orderBookL2\", \"action\": \"update\", \"data\": [{\"id\": 8799321550, \"side\": \"Sell\", \"size\": 965068}], \"symbol\": \"XBTUSD\", \"timestamp\": \"2018-06-11 02:22:53.170685Z\"}", "XBTUSD"], [1528683774469, "{\"table\": \"orderBookL2\", \"action\": \"update\", \"data\": [{\"id\": 8799321950, \"side\": \"Buy\", \"size\": 34868}], \"symbol\": \"XBTUSD\", \"timestamp\": \"2018-06-11 02:22:54.466842Z\"}", "XBTUSD"], [1528683777872, "{\"table\": \"orderBookL2\", \"action\": \"update\", \"data\": [{\"id\": 8799335000, \"side\": \"Buy\", \"size\": 804178}], \"symbol\": \"XBTUSD\", \"timestamp\": \"2018-06-11 02:22:57.869064Z\"}", "XBTUSD"], [1528683778938, "{\"table\": \"orderBookL2\", \"action\": \"update\", \"data\": [{\"id\": 8799321200, \"side\": \"Sell\", \"size\": 22890}, {\"id\": 8799321350, \"side\": \"Sell\", \"size\": 20300}], \"symbol\": \"XBTUSD\", \"timestamp\": \"2018-06-11 02:22:58.934894Z\"}", "XBTUSD"], [1528683779982, "{\"table\": \"orderBookL2\", \"action\": \"update\", \"data\": [{\"id\": 8799321300, \"side\": \"Sell\", \"size\": 25864}, {\"id\": 8799321350, \"side\": \"Sell\", \"size\": 28300}], \"symbol\": \"XBTUSD\", \"timestamp\": \"2018-06-11 02:22:59.979785Z\"}", "XBTUSD"], [1528683784917, "{\"table\": \"orderBookL2\", \"action\": \"update\", \"data\": [{\"id\": 8799320550, \"side\": \"Sell\", \"size\": 45362}, {\"id\": 8799320600, \"side\": \"Sell\", \"size\": 194797}], \"symbol\": \"XBTUSD\", \"timestamp\": \"2018-06-11 02:23:04.905251Z\"}", "XBTUSD"], [1528683785253, "{\"table\": \"orderBookL2\", \"action\": \"update\", \"data\": [{\"id\": 8799321700, \"side\": \"Buy\", \"size\": 1463}, {\"id\": 8799321750, \"side\": \"Buy\", \"size\": 797}], \"symbol\": \"XBTUSD\", \"timestamp\": \"2018-06-11 02:23:05.246705Z\"}", "XBTUSD"], [1528683787926, "{\"table\": \"orderBookL2\", \"action\": \"update\", \"data\": [{\"id\": 8799321300, \"side\": \"Sell\", \"size\": 82264}, {\"id\": 8799321400, \"side\": \"Sell\", \"size\": 134212}], \"symbol\": \"XBTUSD\", \"timestamp\": \"2018-06-11 02:23:07.924044Z\"}", "XBTUSD"], [1528683789246, "{\"table\": \"trade\", \"action\": \"insert\", \"data\": [{\"timestamp\": \"2018-06-11T02:23:09.143Z\", \"side\": \"Sell\", \"size\": 1700, \"price\": 6784, \"tickDirection\": \"ZeroMinusTick\", \"trdMatchID\": \"365fab56-5b8a-6614-9638-baeee0d8cb95\", \"grossValue\": 25059700, \"homeNotional\": 0.250597, \"foreignNotional\": 1700}], \"symbol\": \"XBTUSD\", \"timestamp\": \"2018-06-11 02:23:09.233757Z\"}", "XBTUSD"], [1528683790896, "{\"table\": \"orderBookL2\", \"action\": \"update\", \"data\": [{\"id\": 8799321650, \"side\": \"Buy\", \"size\": 355}], \"symbol\": \"XBTUSD\", \"timestamp\": \"2018-06-11 02:23:10.891044Z\"}", "XBTUSD"], [1528683794384, "{\"table\": \"orderBookL2\", \"action\": \"insert\", \"data\": [{\"id\": 8799321850, \"side\": \"Buy\", \"size\": 4000, \"price\": 6781.5}, {\"id\": 8799321900, \"side\": \"Buy\", \"size\": 8000, \"price\": 6781}, {\"id\": 8799321950, \"side\": \"Buy\", \"size\": 4000, \"price\": 6780.5}], \"symbol\": \"XBTUSD\", \"timestamp\": \"2018-06-11 02:23:14.381586Z\"}", "XBTUSD"], [1528683794923, "{\"table\": \"orderBookL2\", \"action\": \"update\", \"data\": [{\"id\": 8799322300, \"side\": \"Buy\", \"size\": 152293}], \"symbol\": \"XBTUSD\", \"timestamp\": \"2018-06-11 02:23:14.920507Z\"}", "XBTUSD"], [1528683795191, "{\"table\": \"orderBookL2\", \"action\": \"update\", \"data\": [{\"id\": 8799321600, \"side\": \"Sell\", \"size\": 1283673}], \"symbol\": \"XBTUSD\", \"timestamp\": \"2018-06-11 02:23:15.184400Z\"}", "XBTUSD"], [1528683795377, "{\"table\": \"orderBookL2\", \"action\": \"update\", \"data\": [{\"id\": 8799321600, \"side\": \"Sell\", \"size\": 804881}, {\"id\": 8799321800, \"side\": \"Sell\", \"size\": 179308}], \"symbol\": \"XBTUSD\", \"timestamp\": \"2018-06-11 02:23:15.375069Z\"}", "XBTUSD"], [1528683798430, "{\"table\": \"orderBookL2\", \"action\": \"update\", \"data\": [{\"id\": 8799323950, \"side\": \"Buy\", \"size\": 255649}, {\"id\": 8799324050, \"side\": \"Buy\", \"size\": 228374}], \"symbol\": \"XBTUSD\", \"timestamp\": \"2018-06-11 02:23:18.425283Z\"}", "XBTUSD"], [1528683799089, "{\"table\": \"orderBookL2\", \"action\": \"update\", \"data\": [{\"id\": 8799321800, \"side\": \"Sell\", \"size\": 120623}, {\"id\": 8799322100, \"side\": \"Buy\", \"size\": 110912}], \"symbol\": \"XBTUSD\", \"timestamp\": \"2018-06-11 02:23:19.086295Z\"}", "XBTUSD"], [1528683799305, "{\"table\": \"orderBookL2\", \"action\": \"update\", \"data\": [{\"id\": 8799372000, \"side\": \"Buy\", \"size\": 120607}, {\"id\": 8799373400, \"side\": \"Buy\", \"size\": 214017}], \"symbol\": \"XBTUSD\", \"timestamp\": \"2018-06-11 02:23:19.302548Z\"}", "XBTUSD"], [1528683799525, "{\"table\": \"orderBookL2\", \"action\": \"update\", \"data\": [{\"id\": 8799321950, \"side\": \"Sell\", \"size\": 737899}], \"symbol\": \"XBTUSD\", \"timestamp\": \"2018-06-11 02:23:19.522216Z\"}", "XBTUSD"], [1528683799735, "{\"table\": \"orderBookL2\", \"action\": \"update\", \"data\": [{\"id\": 8799323950, \"side\": \"Buy\", \"size\": 255649}, {\"id\": 8799324050, \"side\": \"Buy\", \"size\": 228374}], \"symbol\": \"XBTUSD\", \"timestamp\": \"2018-06-11 02:23:19.732748Z\"}", "XBTUSD"], [1528683802938, "{\"table\": \"orderBookL2\", \"action\": \"update\", \"data\": [{\"id\": 8799322500, \"side\": \"Buy\", \"size\": 18132}], \"symbol\": \"XBTUSD\", \"timestamp\": \"2018-06-11 02:23:22.935805Z\"}", "XBTUSD"], [1528683803882, "{\"table\": \"orderBookL2\", \"action\": \"update\", \"data\": [{\"id\": 8799321950, \"side\": \"Sell\", \"size\": 1118529}], \"symbol\": \"XBTUSD\", \"timestamp\": \"2018-06-11 02:23:23.876982Z\"}", "XBTUSD"], [1528683804462, "{\"table\": \"orderBookL2\", \"action\": \"update\", \"data\": [{\"id\": 8799321950, \"side\": \"Sell\", \"size\": 1102147}], \"symbol\": \"XBTUSD\", \"timestamp\": \"2018-06-11 02:23:24.456322Z\"}", "XBTUSD"], [1528683807487, "{\"table\": \"orderBookL2\", \"action\": \"update\", \"data\": [{\"id\": 8799322250, \"side\": \"Buy\", \"size\": 54006}], \"symbol\": \"XBTUSD\", \"timestamp\": \"2018-06-11 02:23:27.472334Z\"}", "XBTUSD"], [1528683808903, "{\"table\": \"orderBookL2\", \"action\": \"update\", \"data\": [{\"id\": 8799322250, \"side\": \"Buy\", \"size\": 47320}], \"symbol\": \"XBTUSD\", \"timestamp\": \"2018-06-11 02:23:28.900916Z\"}", "XBTUSD"], [1528683812111, "{\"table\": \"orderBookL2\", \"action\": \"update\", \"data\": [{\"id\": 8799316000, \"side\": \"Sell\", \"size\": 667983}, {\"id\": 8799324800, \"side\": \"Buy\", \"size\": 166048}, {\"id\": 8799326500, \"side\": \"Buy\", \"size\": 244969}], \"symbol\": \"XBTUSD\", \"timestamp\": \"2018-06-11 02:23:32.101569Z\"}", "XBTUSD"], [1528683814803, "{\"table\": \"orderBookL2\", \"action\": \"update\", \"data\": [{\"id\": 8799323900, \"side\": \"Buy\", \"size\": 127970}, {\"id\": 8799324100, \"side\": \"Buy\", \"size\": 26474}], \"symbol\": \"XBTUSD\", \"timestamp\": \"2018-06-11 02:23:34.800773Z\"}", "XBTUSD"], [1528683816481, "{\"table\": \"orderBookL2\", \"action\": \"update\", \"data\": [{\"id\": 8799322000, \"side\": \"Buy\", \"size\": 630426}, {\"id\": 8799322050, \"side\": \"Buy\", \"size\": 62937}], \"symbol\": \"XBTUSD\", \"timestamp\": \"2018-06-11 02:23:36.476850Z\"}", "XBTUSD"], [1528683818931, "{\"table\": \"orderBookL2\", \"action\": \"update\", \"data\": [{\"id\": 8799321950, \"side\": \"Sell\", \"size\": 930677}], \"symbol\": \"XBTUSD\", \"timestamp\": \"2018-06-11 02:23:38.927732Z\"}", "XBTUSD"], [1528683821482, "{\"table\": \"orderBookL2\", \"action\": \"update\", \"data\": [{\"id\": 8799321150, \"side\": \"Sell\", \"size\": 5220}, {\"id\": 8799321250, \"side\": \"Sell\", \"size\": 30812}, {\"id\": 8799322000, \"side\": \"Buy\", \"size\": 797076}, {\"id\": 8799322100, \"side\": \"Buy\", \"size\": 60678}], \"symbol\": \"XBTUSD\", \"timestamp\": \"2018-06-11 02:23:41.479657Z\"}", "XBTUSD"], [1528683823961, "{\"table\": \"orderBookL2\", \"action\": \"update\", \"data\": [{\"id\": 8799321950, \"side\": \"Sell\", \"size\": 482537}], \"symbol\": \"XBTUSD\", \"timestamp\": \"2018-06-11 02:23:43.958572Z\"}", "XBTUSD"], [1528683824248, "{\"table\": \"orderBookL2\", \"action\": \"update\", \"data\": [{\"id\": 8799322000, \"side\": \"Sell\", \"size\": 1192439}], \"symbol\": \"XBTUSD\", \"timestamp\": \"2018-06-11 02:23:44.245333Z\"}", "XBTUSD"], [1528683826351, "{\"table\": \"orderBookL2\", \"action\": \"update\", \"data\": [{\"id\": 8799322250, \"side\": \"Buy\", \"size\": 43045}], \"symbol\": \"XBTUSD\", \"timestamp\": \"2018-06-11 02:23:46.347906Z\"}", "XBTUSD"], [1528683829154, "{\"table\": \"orderBookL2\", \"action\": \"update\", \"data\": [{\"id\": 8799321150, \"side\": \"Sell\", \"size\": 5220}, {\"id\": 8799321500, \"side\": \"Sell\", \"size\": 667467}], \"symbol\": \"XBTUSD\", \"timestamp\": \"2018-06-11 02:23:49.151794Z\"}", "XBTUSD"], [1528683829739, "{\"table\": \"orderBookL2\", \"action\": \"update\", \"data\": [{\"id\": 8799320950, \"side\": \"Sell\", \"size\": 25067}, {\"id\": 8799321100, \"side\": \"Sell\", \"size\": 261033}, {\"id\": 8799322850, \"side\": \"Buy\", \"size\": 40671}, {\"id\": 8799323000, \"side\": \"Buy\", \"size\": 97748}], \"symbol\": \"XBTUSD\", \"timestamp\": \"2018-06-11 02:23:49.736404Z\"}", "XBTUSD"], [1528683833911, "{\"table\": \"orderBookL2\", \"action\": \"update\", \"data\": [{\"id\": 8799322100, \"side\": \"Buy\", \"size\": 67019}], \"symbol\": \"XBTUSD\", \"timestamp\": \"2018-06-11 02:23:53.907452Z\"}", "XBTUSD"], [1528683836284, "{\"table\": \"orderBookL2\", \"action\": \"update\", \"data\": [{\"id\": 8799324750, \"side\": \"Buy\", \"size\": 52140}, {\"id\": 8799324800, \"side\": \"Buy\", \"size\": 157291}], \"symbol\": \"XBTUSD\", \"timestamp\": \"2018-06-11 02:23:56.278233Z\"}", "XBTUSD"], [1528683838842, "{\"table\": \"trade\", \"action\": \"insert\", \"data\": [{\"timestamp\": \"2018-06-11T02:23:58.139Z\", \"side\": \"Buy\", \"size\": 230, \"price\": 6780, \"tickDirection\": \"PlusTick\", \"trdMatchID\": \"86d1011d-7c5d-4bd6-4c58-1f256d799922\", \"grossValue\": 3392270, \"homeNotional\": 0.0339227, \"foreignNotional\": 230}], \"symbol\": \"XBTUSD\", \"timestamp\": \"2018-06-11 02:23:58.837895Z\"}", "XBTUSD"], [1528683842011, "{\"table\": \"orderBookL2\", \"action\": \"delete\", \"data\": [{\"id\": 8799932200, \"side\": \"Buy\"}], \"symbol\": \"XBTUSD\", \"timestamp\": \"2018-06-11 02:24:02.006869Z\"}", "XBTUSD"], [1528683843792, "{\"table\": \"orderBookL2\", \"action\": \"update\", \"data\": [{\"id\": 8799322000, \"side\": \"Sell\", \"size\": 1472104}, {\"id\": 8799324300, \"side\": \"Buy\", \"size\": 71460}], \"symbol\": \"XBTUSD\", \"timestamp\": \"2018-06-11 02:24:03.789532Z\"}", "XBTUSD"], [1528683844662, "{\"table\": \"orderBookL2\", \"action\": \"update\", \"data\": [{\"id\": 8799323050, \"side\": \"Buy\", \"size\": 27415}], \"symbol\": \"XBTUSD\", \"timestamp\": \"2018-06-11 02:24:04.656330Z\"}", "XBTUSD"], [1528683847852, "{\"table\": \"orderBookL2\", \"action\": \"update\", \"data\": [{\"id\": 8799321950, \"side\": \"Sell\", \"size\": 955}], \"symbol\": \"XBTUSD\", \"timestamp\": \"2018-06-11 02:24:07.848309Z\"}", "XBTUSD"], [1528683849539, "{\"table\": \"orderBookL2\", \"action\": \"update\", \"data\": [{\"id\": 8799321650, \"side\": \"Sell\", \"size\": 9186}, {\"id\": 8799321950, \"side\": \"Sell\", \"size\": 155}], \"symbol\": \"XBTUSD\", \"timestamp\": \"2018-06-11 02:24:09.534640Z\"}", "XBTUSD"], [1528683853851, "{\"table\": \"orderBookL2\", \"action\": \"update\", \"data\": [{\"id\": 8799315000, \"side\": \"Sell\", \"size\": 869757}], \"symbol\": \"XBTUSD\", \"timestamp\": \"2018-06-11 02:24:13.846732Z\"}", "XBTUSD"], [1528683854306, "{\"table\": \"orderBookL2\", \"action\": \"update\", \"data\": [{\"id\": 8799321750, \"side\": \"Sell\", \"size\": 196}], \"symbol\": \"XBTUSD\", \"timestamp\": \"2018-06-11 02:24:14.303266Z\"}", "XBTUSD"], [1528683856713, "{\"table\": \"orderBookL2\", \"action\": \"update\", \"data\": [{\"id\": 8799322150, \"side\": \"Buy\", \"size\": 18603}], \"symbol\": \"XBTUSD\", \"timestamp\": \"2018-06-11 02:24:16.705476Z\"}", "XBTUSD"], [1528683859522, "{\"table\": \"orderBookL2\", \"action\": \"update\", \"data\": [{\"id\": 8799321900, \"side\": \"Sell\", \"size\": 31093}, {\"id\": 8799322100, \"side\": \"Buy\", \"size\": 123993}], \"symbol\": \"XBTUSD\", \"timestamp\": \"2018-06-11 02:24:19.519706Z\"}", "XBTUSD"], [1528683860659, "{\"table\": \"orderBookL2\", \"action\": \"update\", \"data\": [{\"id\": 8799316200, \"side\": \"Sell\", \"size\": 95917}], \"symbol\": \"XBTUSD\", \"timestamp\": \"2018-06-11 02:24:20.654485Z\"}", "XBTUSD"], [1528683861996, "{\"table\": \"orderBookL2\", \"action\": \"update\", \"data\": [{\"id\": 8799321950, \"side\": \"Buy\", \"size\": 1020293}], \"symbol\": \"XBTUSD\", \"timestamp\": \"2018-06-11 02:24:21.993543Z\"}", "XBTUSD"], [1528683862721, "{\"table\": \"orderBookL2\", \"action\": \"update\", \"data\": [{\"id\": 8799321950, \"side\": \"Buy\", \"size\": 1099245}, {\"id\": 8799322150, \"side\": \"Buy\", \"size\": 4624}], \"symbol\": \"XBTUSD\", \"timestamp\": \"2018-06-11 02:24:22.718820Z\"}", "XBTUSD"], [1528683864355, "{\"table\": \"orderBookL2\", \"action\": \"update\", \"data\": [{\"id\": 8799317250, \"side\": \"Sell\", \"size\": 38037}], \"symbol\": \"XBTUSD\", \"timestamp\": \"2018-06-11 02:24:24.348152Z\"}", "XBTUSD"], [1528683865187, "{\"table\": \"quote\", \"action\": \"insert\", \"data\": [{\"timestamp\": \"2018-06-11T02:24:24.143Z\", \"bidSize\": 1099111, \"bidPrice\": 6780.5, \"askPrice\": 6781, \"askSize\": 9321}, {\"timestamp\": \"2018-06-11T02:24:24.401Z\", \"bidSize\": 1098908, \"bidPrice\": 6780.5, \"askPrice\": 6781, \"askSize\": 9321}, {\"timestamp\": \"2018-06-11T02:24:24.501Z\", \"bidSize\": 1098908, \"bidPrice\": 6780.5, \"askPrice\": 6781, \"askSize\": 10388}, {\"timestamp\": \"2018-06-11T02:24:24.536Z\", \"bidSize\": 1098908, \"bidPrice\": 6780.5, \"askPrice\": 6781, \"askSize\": 10188}, {\"timestamp\": \"2018-06-11T02:24:24.568Z\", \"bidSize\": 9812, \"bidPrice\": 6781, \"askPrice\": 6781.5, \"askSize\": 17738}, {\"timestamp\": \"2018-06-11T02:24:24.582Z\", \"bidSize\": 16312, \"bidPrice\": 6781, \"askPrice\": 6781.5, \"askSize\": 17738}, {\"timestamp\": \"2018-06-11T02:24:24.589Z\", \"bidSize\": 21312, \"bidPrice\": 6781, \"askPrice\": 6781.5, \"askSize\": 17738}, {\"timestamp\": \"2018-06-11T02:24:24.594Z\", \"bidSize\": 24312, \"bidPrice\": 6781, \"askPrice\": 6781.5, \"askSize\": 17738}, {\"timestamp\": \"2018-06-11T02:24:24.599Z\", \"bidSize\": 29312, \"bidPrice\": 6781, \"askPrice\": 6781.5, \"askSize\": 17738}, {\"timestamp\": \"2018-06-11T02:24:24.631Z\", \"bidSize\": 29812, \"bidPrice\": 6781, \"askPrice\": 6781.5, \"askSize\": 17738}, {\"timestamp\": \"2018-06-11T02:24:24.641Z\", \"bidSize\": 66128, \"bidPrice\": 6781, \"askPrice\": 6781.5, \"askSize\": 17738}, {\"timestamp\": \"2018-06-11T02:24:24.645Z\", \"bidSize\": 147230, \"bidPrice\": 6781, \"askPrice\": 6781.5, \"askSize\": 17738}, {\"timestamp\": \"2018-06-11T02:24:24.649Z\", \"bidSize\": 217230, \"bidPrice\": 6781, \"askPrice\": 6781.5, \"askSize\": 17738}, {\"timestamp\": \"2018-06-11T02:24:24.655Z\", \"bidSize\": 217230, \"bidPrice\": 6781, \"askPrice\": 6781.5, \"askSize\": 17763}, {\"timestamp\": \"2018-06-11T02:24:24.661Z\", \"bidSize\": 287230, \"bidPrice\": 6781, \"askPrice\": 6781.5, \"askSize\": 17763}, {\"timestamp\": \"2018-06-11T02:24:24.668Z\", \"bidSize\": 303875, \"bidPrice\": 6781, \"askPrice\": 6781.5, \"askSize\": 17763}, {\"timestamp\": \"2018-06-11T02:24:24.674Z\", \"bidSize\": 373875, \"bidPrice\": 6781, \"askPrice\": 6781.5, \"askSize\": 17763}, {\"timestamp\": \"2018-06-11T02:24:24.686Z\", \"bidSize\": 533873, \"bidPrice\": 6781, \"askPrice\": 6781.5, \"askSize\": 17763}, {\"timestamp\": \"2018-06-11T02:24:24.697Z\", \"bidSize\": 633873, \"bidPrice\": 6781, \"askPrice\": 6781.5, \"askSize\": 17763}, {\"timestamp\": \"2018-06-11T02:24:24.706Z\", \"bidSize\": 639873, \"bidPrice\": 6781, \"askPrice\": 6781.5, \"askSize\": 17763}, {\"timestamp\": \"2018-06-11T02:24:24.714Z\", \"bidSize\": 639883, \"bidPrice\": 6781, \"askPrice\": 6781.5, \"askSize\": 17763}, {\"timestamp\": \"2018-06-11T02:24:24.732Z\", \"bidSize\": 652786, \"bidPrice\": 6781, \"askPrice\": 6781.5, \"askSize\": 17763}, {\"timestamp\": \"2018-06-11T02:24:24.748Z\", \"bidSize\": 656231, \"bidPrice\": 6781, \"askPrice\": 6781.5, \"askSize\": 17763}, {\"timestamp\": \"2018-06-11T02:24:24.760Z\", \"bidSize\": 662231, \"bidPrice\": 6781, \"askPrice\": 6781.5, \"askSize\": 17763}, {\"timestamp\": \"2018-06-11T02:24:24.764Z\", \"bidSize\": 682841, \"bidPrice\": 6781, \"askPrice\": 6781.5, \"askSize\": 17763}, {\"timestamp\": \"2018-06-11T02:24:24.776Z\", \"bidSize\": 710823, \"bidPrice\": 6781, \"askPrice\": 6781.5, \"askSize\": 17763}, {\"timestamp\": \"2018-06-11T02:24:24.791Z\", \"bidSize\": 713006, \"bidPrice\": 6781, \"askPrice\": 6781.5, \"askSize\": 17763}, {\"timestamp\": \"2018-06-11T02:24:24.806Z\", \"bidSize\": 713206, \"bidPrice\": 6781, \"askPrice\": 6781.5, \"askSize\": 17763}, {\"timestamp\": \"2018-06-11T02:24:24.817Z\", \"bidSize\": 713355, \"bidPrice\": 6781, \"askPrice\": 6781.5, \"askSize\": 17763}, {\"timestamp\": \"2018-06-11T02:24:24.825Z\", \"bidSize\": 713356, \"bidPrice\": 6781, \"askPrice\": 6781.5, \"askSize\": 17763}, {\"timestamp\": \"2018-06-11T02:24:24.829Z\", \"bidSize\": 714356, \"bidPrice\": 6781, \"askPrice\": 6781.5, \"askSize\": 17763}, {\"timestamp\": \"2018-06-11T02:24:24.835Z\", \"bidSize\": 724601, \"bidPrice\": 6781, \"askPrice\": 6781.5, \"askSize\": 17763}, {\"timestamp\": \"2018-06-11T02:24:24.847Z\", \"bidSize\": 726601, \"bidPrice\": 6781, \"askPrice\": 6781.5, \"askSize\": 17763}, {\"timestamp\": \"2018-06-11T02:24:24.851Z\", \"bidSize\": 726626, \"bidPrice\": 6781, \"askPrice\": 6781.5, \"askSize\": 17763}, {\"timestamp\": \"2018-06-11T02:24:24.856Z\", \"bidSize\": 730308, \"bidPrice\": 6781, \"askPrice\": 6781.5, \"askSize\": 17763}, {\"timestamp\": \"2018-06-11T02:24:24.872Z\", \"bidSize\": 730808, \"bidPrice\": 6781, \"askPrice\": 6781.5, \"askSize\": 17763}, {\"timestamp\": \"2018-06-11T02:24:24.878Z\", \"bidSize\": 742155, \"bidPrice\": 6781, \"askPrice\": 6781.5, \"askSize\": 17763}, {\"timestamp\": \"2018-06-11T02:24:24.893Z\", \"bidSize\": 802155, \"bidPrice\": 6781, \"askPrice\": 6781.5, \"askSize\": 17763}, {\"timestamp\": \"2018-06-11T02:24:24.898Z\", \"bidSize\": 808155, \"bidPrice\": 6781, \"askPrice\": 6781.5, \"askSize\": 17763}, {\"timestamp\": \"2018-06-11T02:24:24.911Z\", \"bidSize\": 828596, \"bidPrice\": 6781, \"askPrice\": 6781.5, \"askSize\": 17763}, {\"timestamp\": \"2018-06-11T02:24:24.933Z\", \"bidSize\": 843596, \"bidPrice\": 6781, \"askPrice\": 6781.5, \"askSize\": 17763}, {\"timestamp\": \"2018-06-11T02:24:24.936Z\", \"bidSize\": 843617, \"bidPrice\": 6781, \"askPrice\": 6781.5, \"askSize\": 17763}, {\"timestamp\": \"2018-06-11T02:24:24.947Z\", \"bidSize\": 863617, \"bidPrice\": 6781, \"askPrice\": 6781.5, \"askSize\": 17763}, {\"timestamp\": \"2018-06-11T02:24:24.949Z\", \"bidSize\": 865946, \"bidPrice\": 6781, \"askPrice\": 6781.5, \"askSize\": 17763}, {\"timestamp\": \"2018-06-11T02:24:25.003Z\", \"bidSize\": 865936, \"bidPrice\": 6781, \"askPrice\": 6781.5, \"askSize\": 17763}, {\"timestamp\": \"2018-06-11T02:24:25.006Z\", \"bidSize\": 866130, \"bidPrice\": 6781, \"askPrice\": 6781.5, \"askSize\": 17763}, {\"timestamp\": \"2018-06-11T02:24:25.008Z\", \"bidSize\": 871912, \"bidPrice\": 6781, \"askPrice\": 6781.5, \"askSize\": 925}, {\"timestamp\": \"2018-06-11T02:24:25.029Z\", \"bidSize\": 886912, \"bidPrice\": 6781, \"askPrice\": 6781.5, \"askSize\": 925}], \"symbol\": \"XBTUSD\", \"timestamp\": \"2018-06-11 02:24:25.173974Z\"}", "XBTUSD"], [1528683866774, "{\"table\": \"orderBookL2\", \"action\": \"update\", \"data\": [{\"id\": 8799321300, \"side\": \"Sell\", \"size\": 9714}, {\"id\": 8799321350, \"side\": \"Sell\", \"size\": 29320}], \"symbol\": \"XBTUSD\", \"timestamp\": \"2018-06-11 02:24:26.768312Z\"}", "XBTUSD"], [1528683868712, "{\"table\": \"orderBookL2\", \"action\": \"update\", \"data\": [{\"id\": 8799321100, \"side\": \"Sell\", \"size\": 270155}, {\"id\": 8799321150, \"side\": \"Sell\", \"size\": 120400}, {\"id\": 8799321900, \"side\": \"Buy\", \"size\": 1002274}, {\"id\": 8799322000, \"side\": \"Buy\", \"size\": 177703}], \"symbol\": \"XBTUSD\", \"timestamp\": \"2018-06-11 02:24:28.709755Z\"}", "XBTUSD"], [1528683870138, "{\"table\": \"orderBookL2\", \"action\": \"update\", \"data\": [{\"id\": 8799321750, \"side\": \"Buy\", \"size\": 942854}], \"symbol\": \"XBTUSD\", \"timestamp\": \"2018-06-11 02:24:30.135570Z\"}", "XBTUSD"], [1528683874568, "{\"table\": \"orderBookL2\", \"action\": \"insert\", \"data\": [{\"id\": 8799932200, \"side\": \"Buy\", \"size\": 3, \"price\": 678}], \"symbol\": \"XBTUSD\", \"timestamp\": \"2018-06-11 02:24:34.563074Z\"}", "XBTUSD"], [1528683874702, "{\"table\": \"orderBookL2\", \"action\": \"delete\", \"data\": [{\"id\": 8799371750, \"side\": \"Buy\"}], \"symbol\": \"XBTUSD\", \"timestamp\": \"2018-06-11 02:24:34.699467Z\"}", "XBTUSD"], [1528683874866, "{\"table\": \"orderBookL2\", \"action\": \"delete\", \"data\": [{\"id\": 8793216900, \"side\": \"Sell\"}], \"symbol\": \"XBTUSD\", \"timestamp\": \"2018-06-11 02:24:34.863774Z\"}", "XBTUSD"], [1528683875239, "{\"table\": \"orderBookL2\", \"action\": \"update\", \"data\": [{\"id\": 8799320700, \"side\": \"Sell\", \"size\": 223345}, {\"id\": 8799320950, \"side\": \"Sell\", \"size\": 12980}, {\"id\": 8799322600, \"side\": \"Buy\", \"size\": 89696}, {\"id\": 8799322850, \"side\": \"Buy\", \"size\": 69393}], \"symbol\": \"XBTUSD\", \"timestamp\": \"2018-06-11 02:24:35.235395Z\"}", "XBTUSD"], [1528683877365, "{\"table\": \"orderBookL2\", \"action\": \"update\", \"data\": [{\"id\": 8799322050, \"side\": \"Buy\", \"size\": 148495}, {\"id\": 8799322100, \"side\": \"Buy\", \"size\": 69293}], \"symbol\": \"XBTUSD\", \"timestamp\": \"2018-06-11 02:24:37.359422Z\"}", "XBTUSD"], [1528683879057, "{\"table\": \"orderBookL2\", \"action\": \"update\", \"data\": [{\"id\": 8799321650, \"side\": \"Sell\", \"size\": 596102}, {\"id\": 8799323950, \"side\": \"Buy\", \"size\": 555649}], \"symbol\": \"XBTUSD\", \"timestamp\": \"2018-06-11 02:24:39.047620Z\"}", "XBTUSD"], [1528683882511, "{\"table\": \"orderBookL2\", \"action\": \"update\", \"data\": [{\"id\": 8799321250, \"side\": \"Sell\", \"size\": 16834}, {\"id\": 8799321400, \"side\": \"Sell\", \"size\": 129506}, {\"id\": 8799322200, \"side\": \"Buy\", \"size\": 76425}, {\"id\": 8799322250, \"side\": \"Buy\", \"size\": 51623}], \"symbol\": \"XBTUSD\", \"timestamp\": \"2018-06-11 02:24:42.500976Z\"}", "XBTUSD"], [1528683884272, "{\"table\": \"quote\", \"action\": \"insert\", \"data\": [{\"timestamp\": \"2018-06-11T02:24:43.252Z\", \"bidSize\": 548962, \"bidPrice\": 6783, \"askPrice\": 6783.5, \"askSize\": 1215146}, {\"timestamp\": \"2018-06-11T02:24:43.296Z\", \"bidSize\": 554962, \"bidPrice\": 6783, \"askPrice\": 6783.5, \"askSize\": 1215146}, {\"timestamp\": \"2018-06-11T02:24:43.370Z\", \"bidSize\": 556962, \"bidPrice\": 6783, \"askPrice\": 6783.5, \"askSize\": 1215146}, {\"timestamp\": \"2018-06-11T02:24:43.388Z\", \"bidSize\": 556962, \"bidPrice\": 6783, \"askPrice\": 6783.5, \"askSize\": 1285146}, {\"timestamp\": \"2018-06-11T02:24:43.517Z\", \"bidSize\": 562962, \"bidPrice\": 6783, \"askPrice\": 6783.5, \"askSize\": 1285146}, {\"timestamp\": \"2018-06-11T02:24:43.527Z\", \"bidSize\": 568962, \"bidPrice\": 6783, \"askPrice\": 6783.5, \"askSize\": 1285146}, {\"timestamp\": \"2018-06-11T02:24:43.543Z\", \"bidSize\": 574962, \"bidPrice\": 6783, \"askPrice\": 6783.5, \"askSize\": 1285146}, {\"timestamp\": \"2018-06-11T02:24:43.750Z\", \"bidSize\": 579962, \"bidPrice\": 6783, \"askPrice\": 6783.5, \"askSize\": 1285146}, {\"timestamp\": \"2018-06-11T02:24:43.788Z\", \"bidSize\": 579962, \"bidPrice\": 6783, \"askPrice\": 6783.5, \"askSize\": 1285147}, {\"timestamp\": \"2018-06-11T02:24:43.860Z\", \"bidSize\": 579963, \"bidPrice\": 6783, \"askPrice\": 6783.5, \"askSize\": 1285147}, {\"timestamp\": \"2018-06-11T02:24:43.981Z\", \"bidSize\": 578963, \"bidPrice\": 6783, \"askPrice\": 6783.5, \"askSize\": 1285147}], \"symbol\": \"XBTUSD\", \"timestamp\": \"2018-06-11 02:24:44.267121Z\"}", "XBTUSD"], [1528683886786, "{\"table\": \"orderBookL2\", \"action\": \"delete\", \"data\": [{\"id\": 8793216400, \"side\": \"Sell\"}], \"symbol\": \"XBTUSD\", \"timestamp\": \"2018-06-11 02:24:46.780235Z\"}", "XBTUSD"], [1528683887836, "{\"table\": \"orderBookL2\", \"action\": \"update\", \"data\": [{\"id\": 8799321650, \"side\": \"Sell\", \"size\": 1076130}, {\"id\": 8799321700, \"side\": \"Sell\", \"size\": 344619}], \"symbol\": \"XBTUSD\", \"timestamp\": \"2018-06-11 02:24:47.833537Z\"}", "XBTUSD"], [1528683889578, "{\"table\": \"orderBookL2\", \"action\": \"update\", \"data\": [{\"id\": 8799321750, \"side\": \"Buy\", \"size\": 156813}], \"symbol\": \"XBTUSD\", \"timestamp\": \"2018-06-11 02:24:49.575188Z\"}", "XBTUSD"], [1528683893773, "{\"table\": \"orderBookL2\", \"action\": \"update\", \"data\": [{\"id\": 8799276750, \"side\": \"Sell\", \"size\": 483656}, {\"id\": 8799277300, \"side\": \"Sell\", \"size\": 38466}, {\"id\": 8799304100, \"side\": \"Sell\", \"size\": 360200}, {\"id\": 8799319400, \"side\": \"Sell\", \"size\": 593254}, {\"id\": 8799319500, \"side\": \"Sell\", \"size\": 86297}, {\"id\": 8799333350, \"side\": \"Buy\", \"size\": 578349}, {\"id\": 8799341550, \"side\": \"Buy\", \"size\": 555127}, {\"id\": 8799341600, \"side\": \"Buy\", \"size\": 152430}, {\"id\": 8799355250, \"side\": \"Buy\", \"size\": 552927}, {\"id\": 8799355300, \"side\": \"Buy\", \"size\": 8545}], \"symbol\": \"XBTUSD\", \"timestamp\": \"2018-06-11 02:24:53.766781Z\"}", "XBTUSD"], [1528683895533, "{\"table\": \"orderBookL2\", \"action\": \"update\", \"data\": [{\"id\": 8799321700, \"side\": \"Sell\", \"size\": 1763930}], \"symbol\": \"XBTUSD\", \"timestamp\": \"2018-06-11 02:24:55.527298Z\"}", "XBTUSD"], [1528683897871, "{\"table\": \"orderBookL2\", \"action\": \"update\", \"data\": [{\"id\": 8799321700, \"side\": \"Sell\", \"size\": 1834571}], \"symbol\": \"XBTUSD\", \"timestamp\": \"2018-06-11 02:24:57.868527Z\"}", "XBTUSD"], [1528683903068, "{\"table\": \"orderBookL2\", \"action\": \"update\", \"data\": [{\"id\": 8799321850, \"side\": \"Buy\", \"size\": 8274}, {\"id\": 8799321950, \"side\": \"Buy\", \"size\": 3106}], \"symbol\": \"XBTUSD\", \"timestamp\": \"2018-06-11 02:25:03.064452Z\"}", "XBTUSD"], [1528683903746, "{\"table\": \"orderBookL2\", \"action\": \"update\", \"data\": [{\"id\": 8799307950, \"side\": \"Sell\", \"size\": 110000}, {\"id\": 8799314700, \"side\": \"Sell\", \"size\": 90923}, {\"id\": 8799328300, \"side\": \"Buy\", \"size\": 78013}], \"symbol\": \"XBTUSD\", \"timestamp\": \"2018-06-11 02:25:03.741577Z\"}", "XBTUSD"], [1528683907910, "{\"table\": \"orderBookL2\", \"action\": \"update\", \"data\": [{\"id\": 8799321300, \"side\": \"Sell\", \"size\": 33791}, {\"id\": 8799321350, \"side\": \"Sell\", \"size\": 19614}], \"symbol\": \"XBTUSD\", \"timestamp\": \"2018-06-11 02:25:07.905895Z\"}", "XBTUSD"], [1528683911404, "{\"table\": \"orderBookL2\", \"action\": \"update\", \"data\": [{\"id\": 8799322250, \"side\": \"Buy\", \"size\": 107156}], \"symbol\": \"XBTUSD\", \"timestamp\": \"2018-06-11 02:25:11.400790Z\"}", "XBTUSD"], [1528683916319, "{\"table\": \"orderBookL2\", \"action\": \"update\", \"data\": [{\"id\": 8799321850, \"side\": \"Buy\", \"size\": 69173}], \"symbol\": \"XBTUSD\", \"timestamp\": \"2018-06-11 02:25:16.311162Z\"}", "XBTUSD"], [1528683919131, "{\"table\": \"orderBookL2\", \"action\": \"update\", \"data\": [{\"id\": 8799320850, \"side\": \"Sell\", \"size\": 55400}], \"symbol\": \"XBTUSD\", \"timestamp\": \"2018-06-11 02:25:19.128106Z\"}", "XBTUSD"], [1528683923686, "{\"table\": \"orderBookL2\", \"action\": \"update\", \"data\": [{\"id\": 8799314400, \"side\": \"Sell\", \"size\": 52857}], \"symbol\": \"XBTUSD\", \"timestamp\": \"2018-06-11 02:25:23.681240Z\"}", "XBTUSD"], [1528683923910, "{\"table\": \"orderBookL2\", \"action\": \"insert\", \"data\": [{\"id\": 8799932200, \"side\": \"Buy\", \"size\": 3, \"price\": 678}], \"symbol\": \"XBTUSD\", \"timestamp\": \"2018-06-11 02:25:23.907025Z\"}", "XBTUSD"], [1528683926861, "{\"table\": \"orderBookL2\", \"action\": \"update\", \"data\": [{\"id\": 8799322550, \"side\": \"Buy\", \"size\": 54170}], \"symbol\": \"XBTUSD\", \"timestamp\": \"2018-06-11 02:25:26.855851Z\"}", "XBTUSD"], [1528683929073, "{\"table\": \"orderBookL2\", \"action\": \"update\", \"data\": [{\"id\": 8799324100, \"side\": \"Buy\", \"size\": 26918}, {\"id\": 8799324200, \"side\": \"Buy\", \"size\": 262966}], \"symbol\": \"XBTUSD\", \"timestamp\": \"2018-06-11 02:25:29.069707Z\"}", "XBTUSD"], [1528683935038, "{\"table\": \"orderBookL2\", \"action\": \"update\", \"data\": [{\"id\": 8799321700, \"side\": \"Sell\", \"size\": 2076546}, {\"id\": 8799322000, \"side\": \"Sell\", \"size\": 407499}], \"symbol\": \"XBTUSD\", \"timestamp\": \"2018-06-11 02:25:35.034393Z\"}", "XBTUSD"], [1528683935256, "{\"table\": \"orderBookL2\", \"action\": \"update\", \"data\": [{\"id\": 8799321700, \"side\": \"Sell\", \"size\": 1249621}, {\"id\": 8799321750, \"side\": \"Sell\", \"size\": 526863}], \"symbol\": \"XBTUSD\", \"timestamp\": \"2018-06-11 02:25:35.253327Z\"}", "XBTUSD"], [1528683935597, "{\"table\": \"orderBookL2\", \"action\": \"update\", \"data\": [{\"id\": 8799322000, \"side\": \"Sell\", \"size\": 1182480}], \"symbol\": \"XBTUSD\", \"timestamp\": \"2018-06-11 02:25:35.591796Z\"}", "XBTUSD"], [1528683936357, "{\"table\": \"orderBookL2\", \"action\": \"update\", \"data\": [{\"id\": 8799321700, \"side\": \"Sell\", \"size\": 1209601}, {\"id\": 8799321800, \"side\": \"Sell\", \"size\": 73518}, {\"id\": 8799322350, \"side\": \"Buy\", \"size\": 540117}, {\"id\": 8799322450, \"side\": \"Buy\", \"size\": 39608}], \"symbol\": \"XBTUSD\", \"timestamp\": \"2018-06-11 02:25:36.348250Z\"}", "XBTUSD"], [1528683938880, "{\"table\": \"orderBookL2\", \"action\": \"update\", \"data\": [{\"id\": 8799321900, \"side\": \"Sell\", \"size\": 108132}, {\"id\": 8799322100, \"side\": \"Buy\", \"size\": 9309}], \"symbol\": \"XBTUSD\", \"timestamp\": \"2018-06-11 02:25:38.876811Z\"}", "XBTUSD"], [1528683939130, "{\"table\": \"orderBookL2\", \"action\": \"update\", \"data\": [{\"id\": 8799310650, \"side\": \"Sell\", \"size\": 6500}, {\"id\": 8799312650, \"side\": \"Sell\", \"size\": 14124}, {\"id\": 8799313650, \"side\": \"Sell\", \"size\": 4240}, {\"id\": 8799315650, \"side\": \"Sell\", \"size\": 704521}, {\"id\": 8799316650, \"side\": \"Sell\", \"size\": 1150}, {\"id\": 8799318650, \"side\": \"Sell\", \"size\": 80300}, {\"id\": 8799319650, \"side\": \"Sell\", \"size\": 2729}, {\"id\": 8799321650, \"side\": \"Sell\", \"size\": 54505}, {\"id\": 8799322900, \"side\": \"Buy\", \"size\": 1119}, {\"id\": 8799324900, \"side\": \"Buy\", \"size\": 87578}, {\"id\": 8799325900, \"side\": \"Buy\", \"size\": 206454}, {\"id\": 8799327900, \"side\": \"Buy\", \"size\": 107189}], \"symbol\": \"XBTUSD\", \"timestamp\": \"2018-06-11 02:25:39.127646Z\"}", "XBTUSD"], [1528683942671, "{\"table\": \"orderBookL2\", \"action\": \"update\", \"data\": [{\"id\": 8799319500, \"side\": \"Sell\", \"size\": 577009}, {\"id\": 8799319550, \"side\": \"Sell\", \"size\": 37900}, {\"id\": 8799321700, \"side\": \"Sell\", \"size\": 391071}, {\"id\": 8799321800, \"side\": \"Sell\", \"size\": 56636}], \"symbol\": \"XBTUSD\", \"timestamp\": \"2018-06-11 02:25:42.656291Z\"}", "XBTUSD"], [1528683944380, "{\"table\": \"orderBookL2\", \"action\": \"update\", \"data\": [{\"id\": 8799323850, \"side\": \"Buy\", \"size\": 7912}, {\"id\": 8799323900, \"side\": \"Buy\", \"size\": 11674}], \"symbol\": \"XBTUSD\", \"timestamp\": \"2018-06-11 02:25:44.376967Z\"}", "XBTUSD"], [1528683944889, "{\"table\": \"trade\", \"action\": \"insert\", \"data\": [{\"timestamp\": \"2018-06-11T02:25:44.705Z\", \"side\": \"Buy\", \"size\": 100000, \"price\": 6779, \"tickDirection\": \"ZeroMinusTick\", \"trdMatchID\": \"cf2c30b1-48a6-ec10-ceb2-c0140b624c8c\", \"grossValue\": 1475100000, \"homeNotional\": 14.751, \"foreignNotional\": 100000}], \"symbol\": \"XBTUSD\", \"timestamp\": \"2018-06-11 02:25:44.886081Z\"}", "XBTUSD"], [1528683945979, "{\"table\": \"orderBookL2\", \"action\": \"update\", \"data\": [{\"id\": 8799324250, \"side\": \"Buy\", \"size\": 337960}], \"symbol\": \"XBTUSD\", \"timestamp\": \"2018-06-11 02:25:45.974475Z\"}", "XBTUSD"], [1528683948056, "{\"table\": \"orderBookL2\", \"action\": \"delete\", \"data\": [{\"id\": 8793217000, \"side\": \"Sell\"}], \"symbol\": \"XBTUSD\", \"timestamp\": \"2018-06-11 02:25:48.051790Z\"}", "XBTUSD"], [1528683949397, "{\"table\": \"orderBookL2\", \"action\": \"update\", \"data\": [{\"id\": 8799324150, \"side\": \"Buy\", \"size\": 109925}, {\"id\": 8799324300, \"side\": \"Buy\", \"size\": 71460}], \"symbol\": \"XBTUSD\", \"timestamp\": \"2018-06-11 02:25:49.394566Z\"}", "XBTUSD"], [1528683951205, "{\"table\": \"trade\", \"action\": \"insert\", \"data\": [{\"timestamp\": \"2018-06-11T02:25:51.145Z\", \"side\": \"Sell\", \"size\": 1, \"price\": 6778.5, \"tickDirection\": \"ZeroMinusTick\", \"trdMatchID\": \"8ab9f7b3-cbcf-afec-65a4-4be9a2364665\", \"grossValue\": 14753, \"homeNotional\": 0.00014753, \"foreignNotional\": 1}], \"symbol\": \"XBTUSD\", \"timestamp\": \"2018-06-11 02:25:51.202795Z\"}", "XBTUSD"], [1528683952994, "{\"table\": \"orderBookL2\", \"action\": \"update\", \"data\": [{\"id\": 8799322150, \"side\": \"Buy\", \"size\": 642196}], \"symbol\": \"XBTUSD\", \"timestamp\": \"2018-06-11 02:25:52.990397Z\"}", "XBTUSD"], [1528683954974, "{\"table\": \"orderBookL2\", \"action\": \"update\", \"data\": [{\"id\": 8799322150, \"side\": \"Buy\", \"size\": 735181}], \"symbol\": \"XBTUSD\", \"timestamp\": \"2018-06-11 02:25:54.968636Z\"}", "XBTUSD"], [1528683957813, "{\"table\": \"orderBookL2\", \"action\": \"update\", \"data\": [{\"id\": 8799322000, \"side\": \"Sell\", \"size\": 782174}, {\"id\": 8799322200, \"side\": \"Buy\", \"size\": 73806}], \"symbol\": \"XBTUSD\", \"timestamp\": \"2018-06-11 02:25:57.807718Z\"}", "XBTUSD"], [1528683959907, "{\"table\": \"orderBookL2\", \"action\": \"update\", \"data\": [{\"id\": 8799322100, \"side\": \"Sell\", \"size\": 1145824}], \"symbol\": \"XBTUSD\", \"timestamp\": \"2018-06-11 02:25:59.903517Z\"}", "XBTUSD"], [1528683965192, "{\"table\": \"orderBookL2\", \"action\": \"insert\", \"data\": [{\"id\": 8799932300, \"side\": \"Buy\", \"size\": 3, \"price\": 677}], \"symbol\": \"XBTUSD\", \"timestamp\": \"2018-06-11 02:26:05.188819Z\"}", "XBTUSD"], [1528683967795, "{\"table\": \"orderBookL2\", \"action\": \"update\", \"data\": [{\"id\": 8799322050, \"side\": \"Sell\", \"size\": 97083}, {\"id\": 8799322250, \"side\": \"Buy\", \"size\": 37322}], \"symbol\": \"XBTUSD\", \"timestamp\": \"2018-06-11 02:26:07.790578Z\"}", "XBTUSD"], [1528683968763, "{\"table\": \"orderBookL2\", \"action\": \"update\", \"data\": [{\"id\": 8799322600, \"side\": \"Buy\", \"size\": 65068}], \"symbol\": \"XBTUSD\", \"timestamp\": \"2018-06-11 02:26:08.758790Z\"}", "XBTUSD"], [1528683970748, "{\"table\": \"orderBookL2\", \"action\": \"update\", \"data\": [{\"id\": 8799321450, \"side\": \"Sell\", \"size\": 27300}, {\"id\": 8799321700, \"side\": \"Sell\", \"size\": 106525}, {\"id\": 8799322150, \"side\": \"Buy\", \"size\": 1446385}, {\"id\": 8799322400, \"side\": \"Buy\", \"size\": 321151}], \"symbol\": \"XBTUSD\", \"timestamp\": \"2018-06-11 02:26:10.744399Z\"}", "XBTUSD"], [1528683973525, "{\"table\": \"orderBookL2\", \"action\": \"update\", \"data\": [{\"id\": 8799322100, \"side\": \"Sell\", \"size\": 1513659}], \"symbol\": \"XBTUSD\", \"timestamp\": \"2018-06-11 02:26:13.519327Z\"}", "XBTUSD"], [1528683976590, "{\"table\": \"orderBookL2\", \"action\": \"update\", \"data\": [{\"id\": 8799322100, \"side\": \"Sell\", \"size\": 1670452}, {\"id\": 8799324050, \"side\": \"Buy\", \"size\": 454927}], \"symbol\": \"XBTUSD\", \"timestamp\": \"2018-06-11 02:26:16.584075Z\"}", "XBTUSD"], [1528683979217, "{\"table\": \"orderBookL2\", \"action\": \"update\", \"data\": [{\"id\": 8799322250, \"side\": \"Buy\", \"size\": 35322}, {\"id\": 8799322450, \"side\": \"Buy\", \"size\": 42674}], \"symbol\": \"XBTUSD\", \"timestamp\": \"2018-06-11 02:26:19.213518Z\"}", "XBTUSD"], [1528683983010, "{\"table\": \"orderBookL2\", \"action\": \"update\", \"data\": [{\"id\": 8799301500, \"side\": \"Sell\", \"size\": 134610}, {\"id\": 8799301800, \"side\": \"Sell\", \"size\": 3890}, {\"id\": 8799308300, \"side\": \"Sell\", \"size\": 23848}, {\"id\": 8799309650, \"side\": \"Sell\", \"size\": 1409}, {\"id\": 8799311700, \"side\": \"Sell\", \"size\": 61425}, {\"id\": 8799312800, \"side\": \"Sell\", \"size\": 16230}, {\"id\": 8799315100, \"side\": \"Sell\", \"size\": 299977}, {\"id\": 8799315400, \"side\": \"Sell\", \"size\": 137242}, {\"id\": 8799335150, \"side\": \"Buy\", \"size\": 2241}, {\"id\": 8799335600, \"side\": \"Buy\", \"size\": 17890}, {\"id\": 8799338700, \"side\": \"Buy\", \"size\": 21268}, {\"id\": 8799339000, \"side\": \"Buy\", \"size\": 522280}, {\"id\": 8799342100, \"side\": \"Buy\", \"size\": 9171}, {\"id\": 8799342400, \"side\": \"Buy\", \"size\": 1872}], \"symbol\": \"XBTUSD\", \"timestamp\": \"2018-06-11 02:26:22.998656Z\"}", "XBTUSD"], [1528683986828, "{\"table\": \"orderBookL2\", \"action\": \"update\", \"data\": [{\"id\": 8799322150, \"side\": \"Buy\", \"size\": 1120245}], \"symbol\": \"XBTUSD\", \"timestamp\": \"2018-06-11 02:26:26.824144Z\"}", "XBTUSD"], [1528683990954, "{\"table\": \"orderBookL2\", \"action\": \"update\", \"data\": [{\"id\": 8799320450, \"side\": \"Sell\", \"size\": 77520}, {\"id\": 8799320500, \"side\": \"Sell\", \"size\": 124441}], \"symbol\": \"XBTUSD\", \"timestamp\": \"2018-06-11 02:26:30.949265Z\"}", "XBTUSD"], [1528683993520, "{\"table\": \"trade\", \"action\": \"insert\", \"data\": [{\"timestamp\": \"2018-06-11T02:26:33.495Z\", \"side\": \"Buy\", \"size\": 75, \"price\": 6779, \"tickDirection\": \"PlusTick\", \"trdMatchID\": \"fff32cb3-4637-289d-e4ac-7a5a6e6eb114\", \"grossValue\": 1106325, \"homeNotional\": 0.01106325, \"foreignNotional\": 75}], \"symbol\": \"XBTUSD\", \"timestamp\": \"2018-06-11 02:26:33.517864Z\"}", "XBTUSD"], [1528683998796, "{\"table\": \"orderBookL2\", \"action\": \"update\", \"data\": [{\"id\": 8799322100, \"side\": \"Sell\", \"size\": 1812232}], \"symbol\": \"XBTUSD\", \"timestamp\": \"2018-06-11 02:26:38.790765Z\"}", "XBTUSD"], [1528684001227, "{\"table\": \"orderBookL2\", \"action\": \"update\", \"data\": [{\"id\": 8799322150, \"side\": \"Buy\", \"size\": 1358195}], \"symbol\": \"XBTUSD\", \"timestamp\": \"2018-06-11 02:26:41.221090Z\"}", "XBTUSD"], [1528684006308, "{\"table\": \"orderBookL2\", \"action\": \"update\", \"data\": [{\"id\": 8799315100, \"side\": \"Sell\", \"size\": 300077}], \"symbol\": \"XBTUSD\", \"timestamp\": \"2018-06-11 02:26:46.303309Z\"}", "XBTUSD"], [1528684009566, "{\"table\": \"orderBookL2\", \"action\": \"update\", \"data\": [{\"id\": 8799321800, \"side\": \"Sell\", \"size\": 8190}], \"symbol\": \"XBTUSD\", \"timestamp\": \"2018-06-11 02:26:49.562502Z\"}", "XBTUSD"], [1528684012710, "{\"table\": \"trade\", \"action\": \"insert\", \"data\": [{\"timestamp\": \"2018-06-11T02:26:52.673Z\", \"side\": \"Sell\", \"size\": 16, \"price\": 6778.5, \"tickDirection\": \"MinusTick\", \"trdMatchID\": \"5cf9eb58-dd3c-e5f3-8db7-150bc7fa32e5\", \"grossValue\": 236048, \"homeNotional\": 0.00236048, \"foreignNotional\": 16}], \"symbol\": \"XBTUSD\", \"timestamp\": \"2018-06-11 02:26:52.703432Z\"}", "XBTUSD"], [1528684016284, "{\"table\": \"orderBookL2\", \"action\": \"update\", \"data\": [{\"id\": 8799320950, \"side\": \"Sell\", \"size\": 12660}, {\"id\": 8799321200, \"side\": \"Sell\", \"size\": 20540}, {\"id\": 8799322200, \"side\": \"Buy\", \"size\": 120393}, {\"id\": 8799322700, \"side\": \"Buy\", \"size\": 25243}], \"symbol\": \"XBTUSD\", \"timestamp\": \"2018-06-11 02:26:56.278567Z\"}", "XBTUSD"], [1528684018928, "{\"table\": \"orderBookL2\", \"action\": \"update\", \"data\": [{\"id\": 8799320850, \"side\": \"Sell\", \"size\": 81400}, {\"id\": 8799320950, \"side\": \"Sell\", \"size\": 12760}], \"symbol\": \"XBTUSD\", \"timestamp\": \"2018-06-11 02:26:58.924921Z\"}", "XBTUSD"], [1528684019776, "{\"table\": \"orderBookL2\", \"action\": \"update\", \"data\": [{\"id\": 8799322050, \"side\": \"Sell\", \"size\": 178800}, {\"id\": 8799322250, \"side\": \"Buy\", \"size\": 41201}], \"symbol\": \"XBTUSD\", \"timestamp\": \"2018-06-11 02:26:59.772073Z\"}", "XBTUSD"], [1528684023527, "{\"table\": \"orderBookL2\", \"action\": \"update\", \"data\": [{\"id\": 8799321450, \"side\": \"Sell\", \"size\": 31320}, {\"id\": 8799321500, \"side\": \"Sell\", \"size\": 1018196}], \"symbol\": \"XBTUSD\", \"timestamp\": \"2018-06-11 02:27:03.524200Z\"}", "XBTUSD"], [1528684024593, "{\"table\": \"orderBookL2\", \"action\": \"update\", \"data\": [{\"id\": 8799322100, \"side\": \"Sell\", \"size\": 541125}], \"symbol\": \"XBTUSD\", \"timestamp\": \"2018-06-11 02:27:04.589965Z\"}", "XBTUSD"], [1528684029029, "{\"table\": \"orderBookL2\", \"action\": \"update\", \"data\": [{\"id\": 8799323800, \"side\": \"Buy\", \"size\": 339355}, {\"id\": 8799324000, \"side\": \"Buy\", \"size\": 376741}], \"symbol\": \"XBTUSD\", \"timestamp\": \"2018-06-11 02:27:09.019784Z\"}", "XBTUSD"], [1528684029294, "{\"table\": \"orderBookL2\", \"action\": \"update\", \"data\": [{\"id\": 8799321300, \"side\": \"Sell\", \"size\": 8987}, {\"id\": 8799321450, \"side\": \"Sell\", \"size\": 31587}], \"symbol\": \"XBTUSD\", \"timestamp\": \"2018-06-11 02:27:09.292024Z\"}", "XBTUSD"], [1528684031318, "{\"table\": \"orderBookL2\", \"action\": \"update\", \"data\": [{\"id\": 8799322300, \"side\": \"Buy\", \"size\": 132302}], \"symbol\": \"XBTUSD\", \"timestamp\": \"2018-06-11 02:27:11.312406Z\"}", "XBTUSD"], [1528684034105, "{\"table\": \"orderBookL2\", \"action\": \"update\", \"data\": [{\"id\": 8799323200, \"side\": \"Buy\", \"size\": 73723}], \"symbol\": \"XBTUSD\", \"timestamp\": \"2018-06-11 02:27:14.100983Z\"}", "XBTUSD"], [1528684034457, "{\"table\": \"orderBookL2\", \"action\": \"update\", \"data\": [{\"id\": 8799322050, \"side\": \"Buy\", \"size\": 649348}], \"symbol\": \"XBTUSD\", \"timestamp\": \"2018-06-11 02:27:14.454389Z\"}", "XBTUSD"], [1528684036255, "{\"table\": \"orderBookL2\", \"action\": \"update\", \"data\": [{\"id\": 8799322300, \"side\": \"Buy\", \"size\": 183902}], \"symbol\": \"XBTUSD\", \"timestamp\": \"2018-06-11 02:27:16.250994Z\"}", "XBTUSD"], [1528684038938, "{\"table\": \"orderBookL2\", \"action\": \"update\", \"data\": [{\"id\": 8799324100, \"side\": \"Buy\", \"size\": 11296}], \"symbol\": \"XBTUSD\", \"timestamp\": \"2018-06-11 02:27:18.934973Z\"}", "XBTUSD"], [1528684039351, "{\"table\": \"trade\", \"action\": \"insert\", \"data\": [{\"timestamp\": \"2018-06-11T02:27:18.945Z\", \"side\": \"Buy\", \"size\": 3000, \"price\": 6780, \"tickDirection\": \"ZeroPlusTick\", \"trdMatchID\": \"de495af2-0c0c-a131-0a20-bf736fc25605\", \"grossValue\": 44247000, \"homeNotional\": 0.44247, \"foreignNotional\": 3000}], \"symbol\": \"XBTUSD\", \"timestamp\": \"2018-06-11 02:27:19.346448Z\"}", "XBTUSD"], [1528684041399, "{\"table\": \"orderBookL2\", \"action\": \"update\", \"data\": [{\"id\": 8799321950, \"side\": \"Buy\", \"size\": 769381}], \"symbol\": \"XBTUSD\", \"timestamp\": \"2018-06-11 02:27:21.393604Z\"}", "XBTUSD"], [1528684042897, "{\"table\": \"orderBookL2\", \"action\": \"update\", \"data\": [{\"id\": 8799321950, \"side\": \"Buy\", \"size\": 901862}], \"symbol\": \"XBTUSD\", \"timestamp\": \"2018-06-11 02:27:22.891851Z\"}", "XBTUSD"], [1528684043039, "{\"table\": \"orderBookL2\", \"action\": \"update\", \"data\": [{\"id\": 8799372500, \"side\": \"Buy\", \"size\": 122}], \"symbol\": \"XBTUSD\", \"timestamp\": \"2018-06-11 02:27:23.036793Z\"}", "XBTUSD"], [1528684043555, "{\"table\": \"orderBookL2\", \"action\": \"update\", \"data\": [{\"id\": 8799321950, \"side\": \"Buy\", \"size\": 420366}], \"symbol\": \"XBTUSD\", \"timestamp\": \"2018-06-11 02:27:23.552745Z\"}", "XBTUSD"], [1528684044248, "{\"table\": \"orderBookL2\", \"action\": \"update\", \"data\": [{\"id\": 8799321950, \"side\": \"Buy\", \"size\": 396620}], \"symbol\": \"XBTUSD\", \"timestamp\": \"2018-06-11 02:27:24.246218Z\"}", "XBTUSD"], [1528684045080, "{\"table\": \"trade\", \"action\": \"insert\", \"data\": [{\"timestamp\": \"2018-06-11T02:27:24.822Z\", \"side\": \"Sell\", \"size\": 2000, \"price\": 6784.5, \"tickDirection\": \"ZeroMinusTick\", \"trdMatchID\": \"7c5ad179-b457-8eea-1ab9-f558360ccdd0\", \"grossValue\": 29478000, \"homeNotional\": 0.29478, \"foreignNotional\": 2000}], \"symbol\": \"XBTUSD\", \"timestamp\": \"2018-06-11 02:27:25.076658Z\"}", "XBTUSD"], [1528684048924, "{\"table\": \"orderBookL2\", \"action\": \"update\", \"data\": [{\"id\": 8799321250, \"side\": \"Sell\", \"size\": 24520}, {\"id\": 8799321450, \"side\": \"Sell\", \"size\": 21694}, {\"id\": 8799321750, \"side\": \"Buy\", \"size\": 39619}, {\"id\": 8799321800, \"side\": \"Buy\", \"size\": 64854}], \"symbol\": \"XBTUSD\", \"timestamp\": \"2018-06-11 02:27:28.920265Z\"}", "XBTUSD"], [1528684049865, "{\"table\": \"orderBookL2\", \"action\": \"update\", \"data\": [{\"id\": 8799322900, \"side\": \"Buy\", \"size\": 14760}, {\"id\": 8799323300, \"side\": \"Buy\", \"size\": 275794}], \"symbol\": \"XBTUSD\", \"timestamp\": \"2018-06-11 02:27:29.858424Z\"}", "XBTUSD"], [1528684054307, "{\"table\": \"orderBookL2\", \"action\": \"update\", \"data\": [{\"id\": 8799321550, \"side\": \"Buy\", \"size\": 971546}], \"symbol\": \"XBTUSD\", \"timestamp\": \"2018-06-11 02:27:34.302565Z\"}", "XBTUSD"], [1528684054672, "{\"table\": \"orderBookL2\", \"action\": \"update\", \"data\": [{\"id\": 8799321500, \"side\": \"Sell\", \"size\": 942302}], \"symbol\": \"XBTUSD\", \"timestamp\": \"2018-06-11 02:27:34.669415Z\"}", "XBTUSD"], [1528684056922, "{\"table\": \"orderBookL2\", \"action\": \"update\", \"data\": [{\"id\": 8799321550, \"side\": \"Buy\", \"size\": 1037203}], \"symbol\": \"XBTUSD\", \"timestamp\": \"2018-06-11 02:27:36.916523Z\"}", "XBTUSD"], [1528684059236, "{\"table\": \"orderBookL2\", \"action\": \"update\", \"data\": [{\"id\": 8799321550, \"side\": \"Buy\", \"size\": 1157876}], \"symbol\": \"XBTUSD\", \"timestamp\": \"2018-06-11 02:27:39.228388Z\"}", "XBTUSD"], [1528684062263, "{\"table\": \"orderBookL2\", \"action\": \"update\", \"data\": [{\"id\": 8799321700, \"side\": \"Buy\", \"size\": 28222}], \"symbol\": \"XBTUSD\", \"timestamp\": \"2018-06-11 02:27:42.253371Z\"}", "XBTUSD"], [1528684064097, "{\"table\": \"orderBookL2\", \"action\": \"update\", \"data\": [{\"id\": 8799321500, \"side\": \"Buy\", \"size\": 660631}], \"symbol\": \"XBTUSD\", \"timestamp\": \"2018-06-11 02:27:44.094827Z\"}", "XBTUSD"], [1528684064715, "{\"table\": \"orderBookL2\", \"action\": \"update\", \"data\": [{\"id\": 8799321450, \"side\": \"Buy\", \"size\": 491353}], \"symbol\": \"XBTUSD\", \"timestamp\": \"2018-06-11 02:27:44.712933Z\"}", "XBTUSD"], [1528684065521, "{\"table\": \"orderBookL2\", \"action\": \"update\", \"data\": [{\"id\": 8799321650, \"side\": \"Buy\", \"size\": 59996}], \"symbol\": \"XBTUSD\", \"timestamp\": \"2018-06-11 02:27:45.517389Z\"}", "XBTUSD"], [1528684066796, "{\"table\": \"orderBookL2\", \"action\": \"update\", \"data\": [{\"id\": 8799321400, \"side\": \"Buy\", \"size\": 428057}], \"symbol\": \"XBTUSD\", \"timestamp\": \"2018-06-11 02:27:46.793670Z\"}", "XBTUSD"], [1528684067487, "{\"table\": \"orderBookL2\", \"action\": \"update\", \"data\": [{\"id\": 8799321200, \"side\": \"Buy\", \"size\": 32188}, {\"id\": 8799321250, \"side\": \"Buy\", \"size\": 49075}, {\"id\": 8799321350, \"side\": \"Buy\", \"size\": 71099}], \"symbol\": \"XBTUSD\", \"timestamp\": \"2018-06-11 02:27:47.481270Z\"}", "XBTUSD"], [1528684068218, "{\"table\": \"orderBookL2\", \"action\": \"update\", \"data\": [{\"id\": 8799321350, \"side\": \"Buy\", \"size\": 132053}], \"symbol\": \"XBTUSD\", \"timestamp\": \"2018-06-11 02:27:48.213782Z\"}", "XBTUSD"], [1528684068904, "{\"table\": \"orderBookL2\", \"action\": \"update\", \"data\": [{\"id\": 8799321250, \"side\": \"Buy\", \"size\": 36986}, {\"id\": 8799321400, \"side\": \"Buy\", \"size\": 179528}], \"symbol\": \"XBTUSD\", \"timestamp\": \"2018-06-11 02:27:48.901748Z\"}", "XBTUSD"], [1528684071394, "{\"table\": \"orderBookL2\", \"action\": \"update\", \"data\": [{\"id\": 8799320650, \"side\": \"Sell\", \"size\": 18612}, {\"id\": 8799321100, \"side\": \"Sell\", \"size\": 343649}], \"symbol\": \"XBTUSD\", \"timestamp\": \"2018-06-11 02:27:51.391434Z\"}", "XBTUSD"], [1528684073924, "{\"table\": \"orderBookL2\", \"action\": \"update\", \"data\": [{\"id\": 8799321050, \"side\": \"Sell\", \"size\": 6341}], \"symbol\": \"XBTUSD\", \"timestamp\": \"2018-06-11 02:27:53.921093Z\"}", "XBTUSD"], [1528684074323, "{\"table\": \"orderBookL2\", \"action\": \"update\", \"data\": [{\"id\": 8799321100, \"side\": \"Sell\", \"size\": 105567}], \"symbol\": \"XBTUSD\", \"timestamp\": \"2018-06-11 02:27:54.320433Z\"}", "XBTUSD"], [1528684077545, "{\"table\": \"orderBookL2\", \"action\": \"update\", \"data\": [{\"id\": 8799319600, \"side\": \"Sell\", \"size\": 115079}], \"symbol\": \"XBTUSD\", \"timestamp\": \"2018-06-11 02:27:57.542438Z\"}", "XBTUSD"], [1528684078976, "{\"table\": \"orderBookL2\", \"action\": \"update\", \"data\": [{\"id\": 8799321100, \"side\": \"Buy\", \"size\": 185940}], \"symbol\": \"XBTUSD\", \"timestamp\": \"2018-06-11 02:27:58.973009Z\"}", "XBTUSD"], [1528684079455, "{\"table\": \"orderBookL2\", \"action\": \"update\", \"data\": [{\"id\": 8799320850, \"side\": \"Buy\", \"size\": 88231}, {\"id\": 8799320950, \"side\": \"Buy\", \"size\": 92755}], \"symbol\": \"XBTUSD\", \"timestamp\": \"2018-06-11 02:27:59.452305Z\"}", "XBTUSD"], [1528684079816, "{\"table\": \"orderBookL2\", \"action\": \"update\", \"data\": [{\"id\": 8799320950, \"side\": \"Buy\", \"size\": 570945}, {\"id\": 8799321000, \"side\": \"Buy\", \"size\": 418858}], \"symbol\": \"XBTUSD\", \"timestamp\": \"2018-06-11 02:27:59.813834Z\"}", "XBTUSD"], [1528684080188, "{\"table\": \"orderBookL2\", \"action\": \"insert\", \"data\": [{\"id\": 8799320550, \"side\": \"Buy\", \"size\": 3000, \"price\": 6794.5}], \"symbol\": \"XBTUSD\", \"timestamp\": \"2018-06-11 02:28:00.183717Z\"}", "XBTUSD"], [1528684080671, "{\"table\": \"orderBookL2\", \"action\": \"update\", \"data\": [{\"id\": 8799320850, \"side\": \"Buy\", \"size\": 153039}, {\"id\": 8799321050, \"side\": \"Buy\", \"size\": 305456}], \"symbol\": \"XBTUSD\", \"timestamp\": \"2018-06-11 02:28:00.669022Z\"}", "XBTUSD"], [1528684084662, "{\"table\": \"orderBookL2\", \"action\": \"update\", \"data\": [{\"id\": 8799323050, \"side\": \"Buy\", \"size\": 1507}], \"symbol\": \"XBTUSD\", \"timestamp\": \"2018-06-11 02:28:04.655153Z\"}", "XBTUSD"], [1528684085011, "{\"table\": \"orderBookL2\", \"action\": \"update\", \"data\": [{\"id\": 8799316450, \"side\": \"Sell\", \"size\": 23430}, {\"id\": 8799317250, \"side\": \"Sell\", \"size\": 71260}, {\"id\": 8799318050, \"side\": \"Sell\", \"size\": 182065}, {\"id\": 8799318850, \"side\": \"Sell\", \"size\": 6968}, {\"id\": 8799319650, \"side\": \"Sell\", \"size\": 22867}, {\"id\": 8799320700, \"side\": \"Buy\", \"size\": 95442}, {\"id\": 8799322300, \"side\": \"Buy\", \"size\": 122644}, {\"id\": 8799322450, \"side\": \"Buy\", \"size\": 22670}, {\"id\": 8799323100, \"side\": \"Buy\", \"size\": 9192}, {\"id\": 8799323850, \"side\": \"Buy\", \"size\": 5754}, {\"id\": 8799323950, \"side\": \"Buy\", \"size\": 2699}, {\"id\": 8799324650, \"side\": \"Buy\", \"size\": 24800}, {\"id\": 8799324750, \"side\": \"Buy\", \"size\": 6287}, {\"id\": 8799325500, \"side\": \"Buy\", \"size\": 110735}, {\"id\": 8799326300, \"side\": \"Buy\", \"size\": 33050}], \"symbol\": \"XBTUSD\", \"timestamp\": \"2018-06-11 02:28:05.007041Z\"}", "XBTUSD"], [1528684085452, "{\"table\": \"orderBookL2\", \"action\": \"update\", \"data\": [{\"id\": 8799318300, \"side\": \"Sell\", \"size\": 240299}, {\"id\": 8799319000, \"side\": \"Sell\", \"size\": 411269}, {\"id\": 8799319550, \"side\": \"Sell\", \"size\": 12700}, {\"id\": 8799319650, \"side\": \"Sell\", \"size\": 4923}, {\"id\": 8799320850, \"side\": \"Buy\", \"size\": 124932}, {\"id\": 8799321500, \"side\": \"Buy\", \"size\": 166666}, {\"id\": 8799321700, \"side\": \"Buy\", \"size\": 5170}, {\"id\": 8799322200, \"side\": \"Buy\", \"size\": 81248}, {\"id\": 8799322750, \"side\": \"Buy\", \"size\": 18000}, {\"id\": 8799322850, \"side\": \"Buy\", \"size\": 150417}, {\"id\": 8799323250, \"side\": \"Buy\", \"size\": 500}], \"symbol\": \"XBTUSD\", \"timestamp\": \"2018-06-11 02:28:05.449767Z\"}", "XBTUSD"], [1528684087691, "{\"table\": \"orderBookL2\", \"action\": \"update\", \"data\": [{\"id\": 8799312000, \"side\": \"Sell\", \"size\": 222690}], \"symbol\": \"XBTUSD\", \"timestamp\": \"2018-06-11 02:28:07.688677Z\"}", "XBTUSD"], [1528684089540, "{\"table\": \"orderBookL2\", \"action\": \"update\", \"data\": [{\"id\": 8799320550, \"side\": \"Buy\", \"size\": 120860}, {\"id\": 8799320650, \"side\": \"Buy\", \"size\": 266863}], \"symbol\": \"XBTUSD\", \"timestamp\": \"2018-06-11 02:28:09.536512Z\"}", "XBTUSD"], [1528684090012, "{\"table\": \"trade\", \"action\": \"insert\", \"data\": [{\"timestamp\": \"2018-06-11T02:28:08.158Z\", \"side\": \"Buy\", \"size\": 345, \"price\": 6810, \"tickDirection\": \"ZeroPlusTick\", \"trdMatchID\": \"853e9ba2-7b0e-a849-9c39-a211baacff84\", \"grossValue\": 5065980, \"homeNotional\": 0.0506598, \"foreignNotional\": 345}, {\"timestamp\": \"2018-06-11T02:28:08.158Z\", \"side\": \"Buy\", \"size\": 1000, \"price\": 6810, \"tickDirection\": \"ZeroPlusTick\", \"trdMatchID\": \"f2e58906-1037-3709-28d4-3fbb9f4b0942\", \"grossValue\": 14684000, \"homeNotional\": 0.14684, \"foreignNotional\": 1000}, {\"timestamp\": \"2018-06-11T02:28:08.158Z\", \"side\": \"Buy\", \"size\": 10000, \"price\": 6810, \"tickDirection\": \"ZeroPlusTick\", \"trdMatchID\": \"f555518f-55ef-797d-2b20-79d72c1168b7\", \"grossValue\": 146840000, \"homeNotional\": 1.4684, \"foreignNotional\": 10000}, {\"timestamp\": \"2018-06-11T02:28:08.158Z\", \"side\": \"Buy\", \"size\": 2000, \"price\": 6810, \"tickDirection\": \"ZeroPlusTick\", \"trdMatchID\": \"966e3433-9797-caa7-8fc7-bc8e52a0c2a9\", \"grossValue\": 29368000, \"homeNotional\": 0.29368, \"foreignNotional\": 2000}, {\"timestamp\": \"2018-06-11T02:28:08.158Z\", \"side\": \"Buy\", \"size\": 16655, \"price\": 6810, \"tickDirection\": \"ZeroPlusTick\", \"trdMatchID\": \"6fbc1611-b868-c9c1-413d-1495130784d2\", \"grossValue\": 244562020, \"homeNotional\": 2.4456202, \"foreignNotional\": 16655}], \"symbol\": \"XBTUSD\", \"timestamp\": \"2018-06-11 02:28:09.998076Z\"}", "XBTUSD"], [1528684090444, "{\"table\": \"orderBookL2\", \"action\": \"update\", \"data\": [{\"id\": 8799321100, \"side\": \"Buy\", \"size\": 192076}, {\"id\": 8799321600, \"side\": \"Buy\", \"size\": 59394}], \"symbol\": \"XBTUSD\", \"timestamp\": \"2018-06-11 02:28:10.441452Z\"}", "XBTUSD"], [1528684091500, "{\"table\": \"orderBookL2\", \"action\": \"update\", \"data\": [{\"id\": 8799318900, \"side\": \"Sell\", \"size\": 41895}], \"symbol\": \"XBTUSD\", \"timestamp\": \"2018-06-11 02:28:11.493321Z\"}", "XBTUSD"], [1528684094141, "{\"table\": \"orderBookL2\", \"action\": \"update\", \"data\": [{\"id\": 8799320450, \"side\": \"Buy\", \"size\": 21366}, {\"id\": 8799321000, \"side\": \"Buy\", \"size\": 113540}], \"symbol\": \"XBTUSD\", \"timestamp\": \"2018-06-11 02:28:14.137955Z\"}", "XBTUSD"], [1528684094653, "{\"table\": \"orderBookL2\", \"action\": \"update\", \"data\": [{\"id\": 8799317950, \"side\": \"Sell\", \"size\": 599025}], \"symbol\": \"XBTUSD\", \"timestamp\": \"2018-06-11 02:28:14.650116Z\"}", "XBTUSD"], [1528684094937, "{\"table\": \"orderBookL2\", \"action\": \"update\", \"data\": [{\"id\": 8799320700, \"side\": \"Buy\", \"size\": 100056}], \"symbol\": \"XBTUSD\", \"timestamp\": \"2018-06-11 02:28:14.934286Z\"}", "XBTUSD"], [1528684097883, "{\"table\": \"orderBookL2\", \"action\": \"update\", \"data\": [{\"id\": 8799321700, \"side\": \"Buy\", \"size\": 113130}], \"symbol\": \"XBTUSD\", \"timestamp\": \"2018-06-11 02:28:17.877465Z\"}", "XBTUSD"], [1528684099273, "{\"table\": \"orderBookL2\", \"action\": \"update\", \"data\": [{\"id\": 8799318850, \"side\": \"Buy\", \"size\": 264162}], \"symbol\": \"XBTUSD\", \"timestamp\": \"2018-06-11 02:28:19.270464Z\"}", "XBTUSD"], [1528684099626, "{\"table\": \"orderBookL2\", \"action\": \"update\", \"data\": [{\"id\": 8799319800, \"side\": \"Buy\", \"size\": 10176}], \"symbol\": \"XBTUSD\", \"timestamp\": \"2018-06-11 02:28:19.623309Z\"}", "XBTUSD"], [1528684099978, "{\"table\": \"orderBookL2\", \"action\": \"update\", \"data\": [{\"id\": 8799273100, \"side\": \"Sell\", \"size\": 2000}, {\"id\": 8799304850, \"side\": \"Sell\", \"size\": 471805}, {\"id\": 8799313650, \"side\": \"Sell\", \"size\": 4240}, {\"id\": 8799315850, \"side\": \"Sell\", \"size\": 675425}, {\"id\": 8799327150, \"side\": \"Buy\", \"size\": 730328}, {\"id\": 8799327200, \"side\": \"Buy\", \"size\": 73987}, {\"id\": 8799335400, \"side\": \"Buy\", \"size\": 462647}, {\"id\": 8799335500, \"side\": \"Buy\", \"size\": 38820}, {\"id\": 8799349150, \"side\": \"Buy\", \"size\": 459688}, {\"id\": 8799349350, \"side\": \"Buy\", \"size\": 156000}], \"symbol\": \"XBTUSD\", \"timestamp\": \"2018-06-11 02:28:19.975749Z\"}", "XBTUSD"], [1528684100278, "{\"table\": \"orderBookL2\", \"action\": \"update\", \"data\": [{\"id\": 8799323600, \"side\": \"Buy\", \"size\": 57309}], \"symbol\": \"XBTUSD\", \"timestamp\": \"2018-06-11 02:28:20.275909Z\"}", "XBTUSD"], [1528684104272, "{\"table\": \"orderBookL2\", \"action\": \"update\", \"data\": [{\"id\": 8799320050, \"side\": \"Buy\", \"size\": 52532}, {\"id\": 8799320150, \"side\": \"Buy\", \"size\": 6600}], \"symbol\": \"XBTUSD\", \"timestamp\": \"2018-06-11 02:28:24.269066Z\"}", "XBTUSD"], [1528684104555, "{\"table\": \"orderBookL2\", \"action\": \"update\", \"data\": [{\"id\": 8799318300, \"side\": \"Sell\", \"size\": 58127}, {\"id\": 8799318400, \"side\": \"Sell\", \"size\": 10570}], \"symbol\": \"XBTUSD\", \"timestamp\": \"2018-06-11 02:28:24.549209Z\"}", "XBTUSD"], [1528684104981, "{\"table\": \"orderBookL2\", \"action\": \"update\", \"data\": [{\"id\": 8799320050, \"side\": \"Buy\", \"size\": 113795}], \"symbol\": \"XBTUSD\", \"timestamp\": \"2018-06-11 02:28:24.975723Z\"}", "XBTUSD"], [1528684105508, "{\"table\": \"orderBookL2\", \"action\": \"update\", \"data\": [{\"id\": 8799318950, \"side\": \"Buy\", \"size\": 11864}], \"symbol\": \"XBTUSD\", \"timestamp\": \"2018-06-11 02:28:25.506023Z\"}", "XBTUSD"], [1528684109090, "{\"table\": \"quote\", \"action\": \"insert\", \"data\": [{\"timestamp\": \"2018-06-11T02:28:25.860Z\", \"bidSize\": 52300, \"bidPrice\": 6812, \"askPrice\": 6812.5, \"askSize\": 2880771}, {\"timestamp\": \"2018-06-11T02:28:25.860Z\", \"bidSize\": 52300, \"bidPrice\": 6812, \"askPrice\": 6812.5, \"askSize\": 2705771}, {\"timestamp\": \"2018-06-11T02:28:25.925Z\", \"bidSize\": 52300, \"bidPrice\": 6812, \"askPrice\": 6812.5, \"askSize\": 2671471}, {\"timestamp\": \"2018-06-11T02:28:25.987Z\", \"bidSize\": 52300, \"bidPrice\": 6812, \"askPrice\": 6812.5, \"askSize\": 2668471}, {\"timestamp\": \"2018-06-11T02:28:26.016Z\", \"bidSize\": 52300, \"bidPrice\": 6812, \"askPrice\": 6812.5, \"askSize\": 2748471}, {\"timestamp\": \"2018-06-11T02:28:26.020Z\", \"bidSize\": 26500, \"bidPrice\": 6809, \"askPrice\": 6809.5, \"askSize\": 913801}], \"symbol\": \"XBTUSD\", \"timestamp\": \"2018-06-11 02:28:29.082246Z\"}", "XBTUSD"], [1528684109446, "{\"table\": \"orderBookL2\", \"action\": \"update\", \"data\": [{\"id\": 8799318850, \"side\": \"Sell\", \"size\": 231111}], \"symbol\": \"XBTUSD\", \"timestamp\": \"2018-06-11 02:28:29.441818Z\"}", "XBTUSD"], [1528684109821, "{\"table\": \"orderBookL2\", \"action\": \"update\", \"data\": [{\"id\": 8799319050, \"side\": \"Sell\", \"size\": 834071}], \"symbol\": \"XBTUSD\", \"timestamp\": \"2018-06-11 02:28:29.818785Z\"}", "XBTUSD"], [1528684110145, "{\"table\": \"orderBookL2\", \"action\": \"update\", \"data\": [{\"id\": 8799319500, \"side\": \"Buy\", \"size\": 3100}, {\"id\": 8799324700, \"side\": \"Buy\", \"size\": 106495}], \"symbol\": \"XBTUSD\", \"timestamp\": \"2018-06-11 02:28:30.138894Z\"}", "XBTUSD"], [1528684115062, "{\"table\": \"orderBookL2\", \"action\": \"insert\", \"data\": [{\"id\": 8799319200, \"side\": \"Sell\", \"size\": 20000, \"price\": 6808}], \"symbol\": \"XBTUSD\", \"timestamp\": \"2018-06-11 02:28:35.058381Z\"}", "XBTUSD"], [1528684115439, "{\"table\": \"orderBookL2\", \"action\": \"update\", \"data\": [{\"id\": 8799320400, \"side\": \"Buy\", \"size\": 543}], \"symbol\": \"XBTUSD\", \"timestamp\": \"2018-06-11 02:28:35.435534Z\"}", "XBTUSD"], [1528684115945, "{\"table\": \"orderBookL2\", \"action\": \"update\", \"data\": [{\"id\": 8799325250, \"side\": \"Buy\", \"size\": 15816}], \"symbol\": \"XBTUSD\", \"timestamp\": \"2018-06-11 02:28:35.942650Z\"}", "XBTUSD"], [1528684117528, "{\"table\": \"orderBookL2\", \"action\": \"insert\", \"data\": [{\"id\": 8799316850, \"side\": \"Sell\", \"size\": 485326, \"price\": 6831.5}], \"symbol\": \"XBTUSD\", \"timestamp\": \"2018-06-11 02:28:37.525951Z\"}", "XBTUSD"], [1528684118933, "{\"table\": \"trade\", \"action\": \"insert\", \"data\": [{\"timestamp\": \"2018-06-11T02:28:37.001Z\", \"side\": \"Buy\", \"size\": 1, \"price\": 6802.5, \"tickDirection\": \"ZeroPlusTick\", \"trdMatchID\": \"b54bc06a-ff2a-5601-7b3e-7e283f346f7c\", \"grossValue\": 14700, \"homeNotional\": 0.000147, \"foreignNotional\": 1}], \"symbol\": \"XBTUSD\", \"timestamp\": \"2018-06-11 02:28:38.929645Z\"}", "XBTUSD"], [1528684119276, "{\"table\": \"orderBookL2\", \"action\": \"update\", \"data\": [{\"id\": 8799321000, \"side\": \"Buy\", \"size\": 160945}, {\"id\": 8799322000, \"side\": \"Buy\", \"size\": 53150}], \"symbol\": \"XBTUSD\", \"timestamp\": \"2018-06-11 02:28:39.266647Z\"}", "XBTUSD"], [1528684119599, "{\"table\": \"orderBookL2\", \"action\": \"update\", \"data\": [{\"id\": 8799324000, \"side\": \"Buy\", \"size\": 366898}], \"symbol\": \"XBTUSD\", \"timestamp\": \"2018-06-11 02:28:39.596249Z\"}", "XBTUSD"], [1528684120048, "{\"table\": \"orderBookL2\", \"action\": \"update\", \"data\": [{\"id\": 8799320500, \"side\": \"Buy\", \"size\": 7771}, {\"id\": 8799320700, \"side\": \"Buy\", \"size\": 22904}], \"symbol\": \"XBTUSD\", \"timestamp\": \"2018-06-11 02:28:40.045920Z\"}", "XBTUSD"], [1528684123795, "{\"table\": \"orderBookL2\", \"action\": \"update\", \"data\": [{\"id\": 8799320800, \"side\": \"Buy\", \"size\": 58121}], \"symbol\": \"XBTUSD\", \"timestamp\": \"2018-06-11 02:28:43.792165Z\"}", "XBTUSD"], [1528684124100, "{\"table\": \"orderBookL2\", \"action\": \"update\", \"data\": [{\"id\": 8799320450, \"side\": \"Buy\", \"size\": 1471241}], \"symbol\": \"XBTUSD\", \"timestamp\": \"2018-06-11 02:28:44.093689Z\"}", "XBTUSD"], [1528684124474, "{\"table\": \"orderBookL2\", \"action\": \"update\", \"data\": [{\"id\": 8799320550, \"side\": \"Buy\", \"size\": 3430}], \"symbol\": \"XBTUSD\", \"timestamp\": \"2018-06-11 02:28:44.468435Z\"}", "XBTUSD"], [1528684124833, "{\"table\": \"orderBookL2\", \"action\": \"update\", \"data\": [{\"id\": 8799316500, \"side\": \"Sell\", \"size\": 17125}, {\"id\": 8799318600, \"side\": \"Sell\", \"size\": 402106}, {\"id\": 8799320300, \"side\": \"Buy\", \"size\": 214115}, {\"id\": 8799324300, \"side\": \"Buy\", \"size\": 25828}], \"symbol\": \"XBTUSD\", \"timestamp\": \"2018-06-11 02:28:44.830465Z\"}", "XBTUSD"], [1528684125311, "{\"table\": \"orderBookL2\", \"action\": \"update\", \"data\": [{\"id\": 8799309350, \"side\": \"Sell\", \"size\": 49200}, {\"id\": 8799309600, \"side\": \"Sell\", \"size\": 56200}, {\"id\": 8799309850, \"side\": \"Sell\", \"size\": 78824}, {\"id\": 8799310100, \"side\": \"Sell\", \"size\": 281002}, {\"id\": 8799310350, \"side\": \"Sell\", \"size\": 61820}, {\"id\": 8799310600, \"side\": \"Sell\", \"size\": 120762}, {\"id\": 8799310850, \"side\": \"Sell\", \"size\": 51652}, {\"id\": 8799311100, \"side\": \"Sell\", \"size\": 169400}, {\"id\": 8799311350, \"side\": \"Sell\", \"size\": 52840}, {\"id\": 8799317800, \"side\": \"Sell\", \"size\": 2118376}, {\"id\": 8799318000, \"side\": \"Sell\", \"size\": 867715}, {\"id\": 8799318200, \"side\": \"Sell\", \"size\": 172055}, {\"id\": 8799320050, \"side\": \"Buy\", \"size\": 130671}], \"symbol\": \"XBTUSD\", \"timestamp\": \"2018-06-11 02:28:45.307436Z\"}", "XBTUSD"], [1528684129098, "{\"table\": \"orderBookL2\", \"action\": \"update\", \"data\": [{\"id\": 8799319750, \"side\": \"Sell\", \"size\": 36900}], \"symbol\": \"XBTUSD\", \"timestamp\": \"2018-06-11 02:28:49.095635Z\"}", "XBTUSD"], [1528684129494, "{\"table\": \"orderBookL2\", \"action\": \"update\", \"data\": [{\"id\": 8799328700, \"side\": \"Buy\", \"size\": 10910}, {\"id\": 8799333000, \"side\": \"Buy\", \"size\": 738200}], \"symbol\": \"XBTUSD\", \"timestamp\": \"2018-06-11 02:28:49.491490Z\"}", "XBTUSD"], [1528684129860, "{\"table\": \"orderBookL2\", \"action\": \"update\", \"data\": [{\"id\": 8799320050, \"side\": \"Buy\", \"size\": 978830}], \"symbol\": \"XBTUSD\", \"timestamp\": \"2018-06-11 02:28:49.854691Z\"}", "XBTUSD"], [1528684130356, "{\"table\": \"orderBookL2\", \"action\": \"update\", \"data\": [{\"id\": 8799320200, \"side\": \"Buy\", \"size\": 51350}], \"symbol\": \"XBTUSD\", \"timestamp\": \"2018-06-11 02:28:50.353336Z\"}", "XBTUSD"], [1528684133828, "{\"table\": \"orderBookL2\", \"action\": \"update\", \"data\": [{\"id\": 8799319500, \"side\": \"Sell\", \"size\": 34134}], \"symbol\": \"XBTUSD\", \"timestamp\": \"2018-06-11 02:28:53.825204Z\"}", "XBTUSD"], [1528684134204, "{\"table\": \"orderBookL2\", \"action\": \"update\", \"data\": [{\"id\": 8799319950, \"side\": \"Buy\", \"size\": 107840}, {\"id\": 8799370700, \"side\": \"Buy\", \"size\": 33100}], \"symbol\": \"XBTUSD\", \"timestamp\": \"2018-06-11 02:28:54.199831Z\"}", "XBTUSD"], [1528684134524, "{\"table\": \"orderBookL2\", \"action\": \"update\", \"data\": [{\"id\": 8799318350, \"side\": \"Sell\", \"size\": 40600}], \"symbol\": \"XBTUSD\", \"timestamp\": \"2018-06-11 02:28:54.519395Z\"}", "XBTUSD"], [1528684134798, "{\"table\": \"orderBookL2\", \"action\": \"update\", \"data\": [{\"id\": 8799319250, \"side\": \"Sell\", \"size\": 18800}], \"symbol\": \"XBTUSD\", \"timestamp\": \"2018-06-11 02:28:54.795598Z\"}", "XBTUSD"], [1528684136336, "{\"table\": \"orderBookL2\", \"action\": \"update\", \"data\": [{\"id\": 8799320450, \"side\": \"Buy\", \"size\": 1428619}], \"symbol\": \"XBTUSD\", \"timestamp\": \"2018-06-11 02:28:56.334142Z\"}", "XBTUSD"], [1528684138832, "{\"table\": \"trade\", \"action\": \"insert\", \"data\": [{\"timestamp\": \"2018-06-11T02:28:56.703Z\", \"side\": \"Buy\", \"size\": 550, \"price\": 6803, \"tickDirection\": \"PlusTick\", \"trdMatchID\": \"e79cb031-7556-717d-a82d-601f3f4c2325\", \"grossValue\": 8084450, \"homeNotional\": 0.0808445, \"foreignNotional\": 550}], \"symbol\": \"XBTUSD\", \"timestamp\": \"2018-06-11 02:28:58.829478Z\"}", "XBTUSD"], [1528684139309, "{\"table\": \"orderBookL2\", \"action\": \"update\", \"data\": [{\"id\": 8799320650, \"side\": \"Buy\", \"size\": 159080}, {\"id\": 8799320800, \"side\": \"Buy\", \"size\": 61871}], \"symbol\": \"XBTUSD\", \"timestamp\": \"2018-06-11 02:28:59.304324Z\"}", "XBTUSD"], [1528684142314, "{\"table\": \"orderBookL2\", \"action\": \"update\", \"data\": [{\"id\": 8799313550, \"side\": \"Sell\", \"size\": 3980}, {\"id\": 8799322300, \"side\": \"Buy\", \"size\": 47310}, {\"id\": 8799324000, \"side\": \"Buy\", \"size\": 367923}], \"symbol\": \"XBTUSD\", \"timestamp\": \"2018-06-11 02:29:02.309153Z\"}", "XBTUSD"], [1528684144809, "{\"table\": \"orderBookL2\", \"action\": \"update\", \"data\": [{\"id\": 8799319350, \"side\": \"Sell\", \"size\": 4484}], \"symbol\": \"XBTUSD\", \"timestamp\": \"2018-06-11 02:29:04.806260Z\"}", "XBTUSD"], [1528684145267, "{\"table\": \"orderBookL2\", \"action\": \"update\", \"data\": [{\"id\": 8799319750, \"side\": \"Buy\", \"size\": 1265423}], \"symbol\": \"XBTUSD\", \"timestamp\": \"2018-06-11 02:29:05.262600Z\"}", "XBTUSD"], [1528684148101, "{\"table\": \"orderBookL2\", \"action\": \"update\", \"data\": [{\"id\": 8799319400, \"side\": \"Sell\", \"size\": 7154}, {\"id\": 8799319500, \"side\": \"Sell\", \"size\": 35135}, {\"id\": 8799320250, \"side\": \"Buy\", \"size\": 3311}, {\"id\": 8799320350, \"side\": \"Buy\", \"size\": 1024272}], \"symbol\": \"XBTUSD\", \"timestamp\": \"2018-06-11 02:29:08.096011Z\"}", "XBTUSD"], [1528684148383, "{\"table\": \"orderBookL2\", \"action\": \"update\", \"data\": [{\"id\": 8799321350, \"side\": \"Buy\", \"size\": 175215}, {\"id\": 8799321450, \"side\": \"Buy\", \"size\": 3362}], \"symbol\": \"XBTUSD\", \"timestamp\": \"2018-06-11 02:29:08.380184Z\"}", "XBTUSD"], [1528684148579, "{\"table\": \"orderBookL2\", \"action\": \"update\", \"data\": [{\"id\": 8799319650, \"side\": \"Buy\", \"size\": 631085}], \"symbol\": \"XBTUSD\", \"timestamp\": \"2018-06-11 02:29:08.576348Z\"}", "XBTUSD"], [1528684149274, "{\"table\": \"orderBookL2\", \"action\": \"update\", \"data\": [{\"id\": 8799319650, \"side\": \"Buy\", \"size\": 283308}], \"symbol\": \"XBTUSD\", \"timestamp\": \"2018-06-11 02:29:09.271567Z\"}", "XBTUSD"], [1528684150029, "{\"table\": \"orderBookL2\", \"action\": \"update\", \"data\": [{\"id\": 8799320000, \"side\": \"Buy\", \"size\": 184064}, {\"id\": 8799322800, \"side\": \"Buy\", \"size\": 73633}], \"symbol\": \"XBTUSD\", \"timestamp\": \"2018-06-11 02:29:10.026644Z\"}", "XBTUSD"], [1528684153980, "{\"table\": \"orderBookL2\", \"action\": \"update\", \"data\": [{\"id\": 8799319600, \"side\": \"Sell\", \"size\": 944943}], \"symbol\": \"XBTUSD\", \"timestamp\": \"2018-06-11 02:29:13.973076Z\"}", "XBTUSD"], [1528684154373, "{\"table\": \"orderBookL2\", \"action\": \"update\", \"data\": [{\"id\": 8799321550, \"side\": \"Buy\", \"size\": 10764}], \"symbol\": \"XBTUSD\", \"timestamp\": \"2018-06-11 02:29:14.370789Z\"}", "XBTUSD"], [1528684154801, "{\"table\": \"orderBookL2\", \"action\": \"update\", \"data\": [{\"id\": 8799319200, \"side\": \"Sell\", \"size\": 218296}, {\"id\": 8799320050, \"side\": \"Buy\", \"size\": 674030}], \"symbol\": \"XBTUSD\", \"timestamp\": \"2018-06-11 02:29:14.798559Z\"}", "XBTUSD"], [1528684155914, "{\"table\": \"orderBookL2\", \"action\": \"update\", \"data\": [{\"id\": 8799316400, \"side\": \"Sell\", \"size\": 117754}], \"symbol\": \"XBTUSD\", \"timestamp\": \"2018-06-11 02:29:15.912015Z\"}", "XBTUSD"], [1528684157691, "{\"table\": \"orderBookL2\", \"action\": \"insert\", \"data\": [{\"id\": 8799523750, \"side\": \"Buy\", \"size\": 20, \"price\": 4762.5}], \"symbol\": \"XBTUSD\", \"timestamp\": \"2018-06-11 02:29:17.678080Z\"}", "XBTUSD"], [1528684159076, "{\"table\": \"orderBookL2\", \"action\": \"update\", \"data\": [{\"id\": 8799320600, \"side\": \"Buy\", \"size\": 192330}, {\"id\": 8799320700, \"side\": \"Buy\", \"size\": 24472}], \"symbol\": \"XBTUSD\", \"timestamp\": \"2018-06-11 02:29:19.072386Z\"}", "XBTUSD"], [1528684160355, "{\"table\": \"orderBookL2\", \"action\": \"update\", \"data\": [{\"id\": 8799321850, \"side\": \"Buy\", \"size\": 111373}, {\"id\": 8799321950, \"side\": \"Buy\", \"size\": 80669}], \"symbol\": \"XBTUSD\", \"timestamp\": \"2018-06-11 02:29:20.352523Z\"}", "XBTUSD"], [1528684161679, "{\"table\": \"orderBookL2\", \"action\": \"update\", \"data\": [{\"id\": 8799320100, \"side\": \"Buy\", \"size\": 421341}], \"symbol\": \"XBTUSD\", \"timestamp\": \"2018-06-11 02:29:21.674614Z\"}", "XBTUSD"], [1528684163484, "{\"table\": \"orderBookL2\", \"action\": \"update\", \"data\": [{\"id\": 8799322000, \"side\": \"Buy\", \"size\": 77284}], \"symbol\": \"XBTUSD\", \"timestamp\": \"2018-06-11 02:29:23.479902Z\"}", "XBTUSD"], [1528684165569, "{\"table\": \"orderBookL2\", \"action\": \"update\", \"data\": [{\"id\": 8799313050, \"side\": \"Sell\", \"size\": 13794}], \"symbol\": \"XBTUSD\", \"timestamp\": \"2018-06-11 02:29:25.561724Z\"}", "XBTUSD"], [1528684167361, "{\"table\": \"orderBookL2\", \"action\": \"update\", \"data\": [{\"id\": 8799251000, \"side\": \"Sell\", \"size\": 76920}, {\"id\": 8799305300, \"side\": \"Sell\", \"size\": 40607}], \"symbol\": \"XBTUSD\", \"timestamp\": \"2018-06-11 02:29:27.355822Z\"}", "XBTUSD"], [1528684169246, "{\"table\": \"orderBookL2\", \"action\": \"update\", \"data\": [{\"id\": 8799319650, \"side\": \"Buy\", \"size\": 479158}], \"symbol\": \"XBTUSD\", \"timestamp\": \"2018-06-11 02:29:29.240342Z\"}", "XBTUSD"], [1528684171783, "{\"table\": \"orderBookL2\", \"action\": \"update\", \"data\": [{\"id\": 8799319650, \"side\": \"Sell\", \"size\": 310424}], \"symbol\": \"XBTUSD\", \"timestamp\": \"2018-06-11 02:29:31.778174Z\"}", "XBTUSD"], [1528684172227, "{\"table\": \"orderBookL2\", \"action\": \"update\", \"data\": [{\"id\": 8799319650, \"side\": \"Sell\", \"size\": 575525}, {\"id\": 8799321450, \"side\": \"Buy\", \"size\": 433755}], \"symbol\": \"XBTUSD\", \"timestamp\": \"2018-06-11 02:29:32.224369Z\"}", "XBTUSD"], [1528684173186, "{\"table\": \"orderBookL2\", \"action\": \"update\", \"data\": [{\"id\": 8799319650, \"side\": \"Sell\", \"size\": 855312}], \"symbol\": \"XBTUSD\", \"timestamp\": \"2018-06-11 02:29:33.178033Z\"}", "XBTUSD"], [1528684174646, "{\"table\": \"orderBookL2\", \"action\": \"update\", \"data\": [{\"id\": 8799319650, \"side\": \"Sell\", \"size\": 652695}], \"symbol\": \"XBTUSD\", \"timestamp\": \"2018-06-11 02:29:34.644076Z\"}", "XBTUSD"], [1528684178787, "{\"table\": \"orderBookL2\", \"action\": \"update\", \"data\": [{\"id\": 8799318000, \"side\": \"Sell\", \"size\": 856711}], \"symbol\": \"XBTUSD\", \"timestamp\": \"2018-06-11 02:29:38.783772Z\"}", "XBTUSD"], [1528684179107, "{\"table\": \"orderBookL2\", \"action\": \"update\", \"data\": [{\"id\": 8799319700, \"side\": \"Buy\", \"size\": 1330225}], \"symbol\": \"XBTUSD\", \"timestamp\": \"2018-06-11 02:29:39.103985Z\"}", "XBTUSD"], [1528684181266, "{\"table\": \"orderBookL2\", \"action\": \"update\", \"data\": [{\"id\": 8799317100, \"side\": \"Sell\", \"size\": 15254}, {\"id\": 8799318700, \"side\": \"Sell\", \"size\": 7219}], \"symbol\": \"XBTUSD\", \"timestamp\": \"2018-06-11 02:29:41.258518Z\"}", "XBTUSD"], [1528684183726, "{\"table\": \"orderBookL2\", \"action\": \"update\", \"data\": [{\"id\": 8799319700, \"side\": \"Buy\", \"size\": 1294788}], \"symbol\": \"XBTUSD\", \"timestamp\": \"2018-06-11 02:29:43.720078Z\"}", "XBTUSD"], [1528684184053, "{\"table\": \"orderBookL2\", \"action\": \"update\", \"data\": [{\"id\": 8799319500, \"side\": \"Sell\", \"size\": 283434}, {\"id\": 8799319550, \"side\": \"Sell\", \"size\": 107000}, {\"id\": 8799319950, \"side\": \"Buy\", \"size\": 10292}, {\"id\": 8799320000, \"side\": \"Buy\", \"size\": 177179}], \"symbol\": \"XBTUSD\", \"timestamp\": \"2018-06-11 02:29:44.049547Z\"}", "XBTUSD"], [1528684188574, "{\"table\": \"orderBookL2\", \"action\": \"update\", \"data\": [{\"id\": 8799319650, \"side\": \"Sell\", \"size\": 764159}], \"symbol\": \"XBTUSD\", \"timestamp\": \"2018-06-11 02:29:48.570776Z\"}", "XBTUSD"], [1528684189192, "{\"table\": \"orderBookL2\", \"action\": \"update\", \"data\": [{\"id\": 8799320950, \"side\": \"Buy\", \"size\": 100749}, {\"id\": 8799321550, \"side\": \"Buy\", \"size\": 46092}], \"symbol\": \"XBTUSD\", \"timestamp\": \"2018-06-11 02:29:49.189267Z\"}", "XBTUSD"], [1528684189413, "{\"table\": \"orderBookL2\", \"action\": \"update\", \"data\": [{\"id\": 8799319700, \"side\": \"Sell\", \"size\": 1226528}], \"symbol\": \"XBTUSD\", \"timestamp\": \"2018-06-11 02:29:49.410530Z\"}", "XBTUSD"], [1528684189786, "{\"table\": \"orderBookL2\", \"action\": \"update\", \"data\": [{\"id\": 8799931900, \"side\": \"Buy\", \"size\": 104}], \"symbol\": \"XBTUSD\", \"timestamp\": \"2018-06-11 02:29:49.782241Z\"}", "XBTUSD"], [1528684190159, "{\"table\": \"orderBookL2\", \"action\": \"update\", \"data\": [{\"id\": 8799319800, \"side\": \"Sell\", \"size\": 204410}, {\"id\": 8799319850, \"side\": \"Sell\", \"size\": 243225}], \"symbol\": \"XBTUSD\", \"timestamp\": \"2018-06-11 02:29:50.151855Z\"}", "XBTUSD"], [1528684193750, "{\"table\": \"orderBookL2\", \"action\": \"update\", \"data\": [{\"id\": 8799319650, \"side\": \"Sell\", \"size\": 342038}, {\"id\": 8799319700, \"side\": \"Sell\", \"size\": 269695}], \"symbol\": \"XBTUSD\", \"timestamp\": \"2018-06-11 02:29:53.748076Z\"}", "XBTUSD"], [1528684193973, "{\"table\": \"orderBookL2\", \"action\": \"update\", \"data\": [{\"id\": 8799320150, \"side\": \"Buy\", \"size\": 211623}], \"symbol\": \"XBTUSD\", \"timestamp\": \"2018-06-11 02:29:53.969651Z\"}", "XBTUSD"], [1528684194183, "{\"table\": \"orderBookL2\", \"action\": \"update\", \"data\": [{\"id\": 8799319100, \"side\": \"Sell\", \"size\": 207359}, {\"id\": 8799319300, \"side\": \"Sell\", \"size\": 51953}, {\"id\": 8799319500, \"side\": \"Sell\", \"size\": 101834}, {\"id\": 8799370000, \"side\": \"Buy\", \"size\": 753291}, {\"id\": 8799370200, \"side\": \"Buy\", \"size\": 48200}, {\"id\": 8799370300, \"side\": \"Buy\", \"size\": 48200}, {\"id\": 8799370500, \"side\": \"Buy\", \"size\": 48200}], \"symbol\": \"XBTUSD\", \"timestamp\": \"2018-06-11 02:29:54.180917Z\"}", "XBTUSD"], [1528684195897, "{\"table\": \"orderBookL2\", \"action\": \"update\", \"data\": [{\"id\": 8799320000, \"side\": \"Buy\", \"size\": 3335}], \"symbol\": \"XBTUSD\", \"timestamp\": \"2018-06-11 02:29:55.893657Z\"}", "XBTUSD"], [1528684198674, "{\"table\": \"orderBookL2\", \"action\": \"update\", \"data\": [{\"id\": 8799320100, \"side\": \"Sell\", \"size\": 133000}], \"symbol\": \"XBTUSD\", \"timestamp\": \"2018-06-11 02:29:58.670337Z\"}", "XBTUSD"], [1528684198886, "{\"table\": \"quote\", \"action\": \"insert\", \"data\": [{\"timestamp\": \"2018-06-11T02:29:55.933Z\", \"bidSize\": 26816, \"bidPrice\": 6799.5, \"askPrice\": 6800.5, \"askSize\": 1318777}, {\"timestamp\": \"2018-06-11T02:29:55.951Z\", \"bidSize\": 26816, \"bidPrice\": 6799.5, \"askPrice\": 6800.5, \"askSize\": 1319185}, {\"timestamp\": \"2018-06-11T02:29:55.968Z\", \"bidSize\": 26816, \"bidPrice\": 6799.5, \"askPrice\": 6800, \"askSize\": 18646}, {\"timestamp\": \"2018-06-11T02:29:56.030Z\", \"bidSize\": 26816, \"bidPrice\": 6799.5, \"askPrice\": 6800, \"askSize\": 301561}, {\"timestamp\": \"2018-06-11T02:29:56.056Z\", \"bidSize\": 26816, \"bidPrice\": 6799.5, \"askPrice\": 6800, \"askSize\": 301861}, {\"timestamp\": \"2018-06-11T02:29:56.066Z\", \"bidSize\": 18627, \"bidPrice\": 6799.5, \"askPrice\": 6800, \"askSize\": 301861}, {\"timestamp\": \"2018-06-11T02:29:56.074Z\", \"bidSize\": 18627, \"bidPrice\": 6799.5, \"askPrice\": 6800, \"askSize\": 302461}, {\"timestamp\": \"2018-06-11T02:29:56.074Z\", \"bidSize\": 18627, \"bidPrice\": 6799.5, \"askPrice\": 6800, \"askSize\": 305967}, {\"timestamp\": \"2018-06-11T02:29:56.074Z\", \"bidSize\": 18627, \"bidPrice\": 6799.5, \"askPrice\": 6800, \"askSize\": 306724}, {\"timestamp\": \"2018-06-11T02:29:56.074Z\", \"bidSize\": 18627, \"bidPrice\": 6799.5, \"askPrice\": 6800, \"askSize\": 316869}, {\"timestamp\": \"2018-06-11T02:29:56.074Z\", \"bidSize\": 18627, \"bidPrice\": 6799.5, \"askPrice\": 6800, \"askSize\": 322893}, {\"timestamp\": \"2018-06-11T02:29:56.090Z\", \"bidSize\": 18627, \"bidPrice\": 6799.5, \"askPrice\": 6800, \"askSize\": 382893}, {\"timestamp\": \"2018-06-11T02:29:56.141Z\", \"bidSize\": 285402, \"bidPrice\": 6798.5, \"askPrice\": 6800, \"askSize\": 382893}, {\"timestamp\": \"2018-06-11T02:29:56.158Z\", \"bidSize\": 285402, \"bidPrice\": 6798.5, \"askPrice\": 6800, \"askSize\": 386893}, {\"timestamp\": \"2018-06-11T02:29:56.160Z\", \"bidSize\": 285202, \"bidPrice\": 6798.5, \"askPrice\": 6800, \"askSize\": 386893}, {\"timestamp\": \"2018-06-11T02:29:56.171Z\", \"bidSize\": 285202, \"bidPrice\": 6798.5, \"askPrice\": 6799.5, \"askSize\": 200}, {\"timestamp\": \"2018-06-11T02:29:56.177Z\", \"bidSize\": 285202, \"bidPrice\": 6798.5, \"askPrice\": 6799.5, \"askSize\": 3200}, {\"timestamp\": \"2018-06-11T02:29:56.181Z\", \"bidSize\": 285202, \"bidPrice\": 6798.5, \"askPrice\": 6799.5, \"askSize\": 9700}, {\"timestamp\": \"2018-06-11T02:29:56.184Z\", \"bidSize\": 285202, \"bidPrice\": 6798.5, \"askPrice\": 6799.5, \"askSize\": 14700}, {\"timestamp\": \"2018-06-11T02:29:56.205Z\", \"bidSize\": 285202, \"bidPrice\": 6798.5, \"askPrice\": 6799.5, \"askSize\": 15200}, {\"timestamp\": \"2018-06-11T02:29:56.287Z\", \"bidSize\": 285202, \"bidPrice\": 6798.5, \"askPrice\": 6800, \"askSize\": 450487}, {\"timestamp\": \"2018-06-11T02:29:56.372Z\", \"bidSize\": 285202, \"bidPrice\": 6798.5, \"askPrice\": 6800, \"askSize\": 450387}, {\"timestamp\": \"2018-06-11T02:29:56.385Z\", \"bidSize\": 285202, \"bidPrice\": 6798.5, \"askPrice\": 6800, \"askSize\": 472388}, {\"timestamp\": \"2018-06-11T02:29:56.392Z\", \"bidSize\": 285227, \"bidPrice\": 6798.5, \"askPrice\": 6800, \"askSize\": 472388}, {\"timestamp\": \"2018-06-11T02:29:56.397Z\", \"bidSize\": 285227, \"bidPrice\": 6798.5, \"askPrice\": 6799.5, \"askSize\": 5000}, {\"timestamp\": \"2018-06-11T02:29:56.416Z\", \"bidSize\": 285227, \"bidPrice\": 6798.5, \"askPrice\": 6799, \"askSize\": 50000}, {\"timestamp\": \"2018-06-11T02:29:56.427Z\", \"bidSize\": 285227, \"bidPrice\": 6798.5, \"askPrice\": 6799, \"askSize\": 90000}, {\"timestamp\": \"2018-06-11T02:29:56.431Z\", \"bidSize\": 285227, \"bidPrice\": 6798.5, \"askPrice\": 6799, \"askSize\": 130000}, {\"timestamp\": \"2018-06-11T02:29:56.437Z\", \"bidSize\": 285227, \"bidPrice\": 6798.5, \"askPrice\": 6799, \"askSize\": 133000}, {\"timestamp\": \"2018-06-11T02:29:56.449Z\", \"bidSize\": 285227, \"bidPrice\": 6798.5, \"askPrice\": 6799, \"askSize\": 139500}, {\"timestamp\": \"2018-06-11T02:29:56.452Z\", \"bidSize\": 285227, \"bidPrice\": 6798.5, \"askPrice\": 6799, \"askSize\": 159500}, {\"timestamp\": \"2018-06-11T02:29:56.482Z\", \"bidSize\": 285227, \"bidPrice\": 6798.5, \"askPrice\": 6799, \"askSize\": 160000}, {\"timestamp\": \"2018-06-11T02:29:56.518Z\", \"bidSize\": 285227, \"bidPrice\": 6798.5, \"askPrice\": 6799, \"askSize\": 160025}], \"symbol\": \"XBTUSD\", \"timestamp\": \"2018-06-11 02:29:58.879335Z\"}", "XBTUSD"], [1528684199150, "{\"table\": \"orderBookL2\", \"action\": \"update\", \"data\": [{\"id\": 8799320100, \"side\": \"Sell\", \"size\": 697154}], \"symbol\": \"XBTUSD\", \"timestamp\": \"2018-06-11 02:29:59.142144Z\"}", "XBTUSD"], [1528684199491, "{\"table\": \"orderBookL2\", \"action\": \"update\", \"data\": [{\"id\": 8799320150, \"side\": \"Buy\", \"size\": 758309}], \"symbol\": \"XBTUSD\", \"timestamp\": \"2018-06-11 02:29:59.487398Z\"}", "XBTUSD"], [1528684202220, "{\"table\": \"orderBookL2\", \"action\": \"update\", \"data\": [{\"id\": 8799320250, \"side\": \"Buy\", \"size\": 1681}], \"symbol\": \"XBTUSD\", \"timestamp\": \"2018-06-11 02:30:02.218047Z\"}", "XBTUSD"], [1528684204767, "{\"table\": \"orderBookL2\", \"action\": \"update\", \"data\": [{\"id\": 8799320150, \"side\": \"Buy\", \"size\": 178281}], \"symbol\": \"XBTUSD\", \"timestamp\": \"2018-06-11 02:30:04.760627Z\"}", "XBTUSD"], [1528684205171, "{\"table\": \"trade\", \"action\": \"insert\", \"data\": [{\"timestamp\": \"2018-06-11T02:30:04.571Z\", \"side\": \"Sell\", \"size\": 2000, \"price\": 6798.5, \"tickDirection\": \"MinusTick\", \"trdMatchID\": \"5cdd50b7-3158-854f-1c32-f5d4f9685855\", \"grossValue\": 29418000, \"homeNotional\": 0.29418, \"foreignNotional\": 2000}], \"symbol\": \"XBTUSD\", \"timestamp\": \"2018-06-11 02:30:05.162026Z\"}", "XBTUSD"], [1528684209060, "{\"table\": \"orderBookL2\", \"action\": \"update\", \"data\": [{\"id\": 8799320100, \"side\": \"Sell\", \"size\": 1226850}], \"symbol\": \"XBTUSD\", \"timestamp\": \"2018-06-11 02:30:09.057346Z\"}", "XBTUSD"], [1528684209346, "{\"table\": \"orderBookL2\", \"action\": \"update\", \"data\": [{\"id\": 8799319900, \"side\": \"Sell\", \"size\": 132550}, {\"id\": 8799319950, \"side\": \"Sell\", \"size\": 179000}, {\"id\": 8799320000, \"side\": \"Sell\", \"size\": 869275}, {\"id\": 8799320050, \"side\": \"Sell\", \"size\": 203019}, {\"id\": 8799320100, \"side\": \"Sell\", \"size\": 1256605}], \"symbol\": \"XBTUSD\", \"timestamp\": \"2018-06-11 02:30:09.344043Z\"}", "XBTUSD"], [1528684211409, "{\"table\": \"orderBookL2\", \"action\": \"update\", \"data\": [{\"id\": 8799320150, \"side\": \"Buy\", \"size\": 141851}], \"symbol\": \"XBTUSD\", \"timestamp\": \"2018-06-11 02:30:11.403308Z\"}", "XBTUSD"], [1528684213917, "{\"table\": \"orderBookL2\", \"action\": \"update\", \"data\": [{\"id\": 8799323350, \"side\": \"Buy\", \"size\": 1561}], \"symbol\": \"XBTUSD\", \"timestamp\": \"2018-06-11 02:30:13.913401Z\"}", "XBTUSD"], [1528684214567, "{\"table\": \"orderBookL2\", \"action\": \"update\", \"data\": [{\"id\": 8799320100, \"side\": \"Sell\", \"size\": 1100011}, {\"id\": 8799320150, \"side\": \"Sell\", \"size\": 491751}], \"symbol\": \"XBTUSD\", \"timestamp\": \"2018-06-11 02:30:14.547611Z\"}", "XBTUSD"], [1528684216372, "{\"table\": \"orderBookL2\", \"action\": \"update\", \"data\": [{\"id\": 8799318200, \"side\": \"Sell\", \"size\": 169909}], \"symbol\": \"XBTUSD\", \"timestamp\": \"2018-06-11 02:30:16.369736Z\"}", "XBTUSD"], [1528684219064, "{\"table\": \"orderBookL2\", \"action\": \"update\", \"data\": [{\"id\": 8799320150, \"side\": \"Sell\", \"size\": 1483831}], \"symbol\": \"XBTUSD\", \"timestamp\": \"2018-06-11 02:30:19.061435Z\"}", "XBTUSD"], [1528684219552, "{\"table\": \"orderBookL2\", \"action\": \"update\", \"data\": [{\"id\": 8799320800, \"side\": \"Buy\", \"size\": 88020}], \"symbol\": \"XBTUSD\", \"timestamp\": \"2018-06-11 02:30:19.549712Z\"}", "XBTUSD"], [1528684221964, "{\"table\": \"orderBookL2\", \"action\": \"update\", \"data\": [{\"id\": 8799320100, \"side\": \"Sell\", \"size\": 277085}], \"symbol\": \"XBTUSD\", \"timestamp\": \"2018-06-11 02:30:21.956983Z\"}", "XBTUSD"], [1528684224007, "{\"table\": \"orderBookL2\", \"action\": \"update\", \"data\": [{\"id\": 8799321700, \"side\": \"Buy\", \"size\": 346454}, {\"id\": 8799321750, \"side\": \"Buy\", \"size\": 337370}], \"symbol\": \"XBTUSD\", \"timestamp\": \"2018-06-11 02:30:24.004101Z\"}", "XBTUSD"], [1528684226442, "{\"table\": \"orderBookL2\", \"action\": \"delete\", \"data\": [{\"id\": 8799320200, \"side\": \"Buy\"}], \"symbol\": \"XBTUSD\", \"timestamp\": \"2018-06-11 02:30:26.437097Z\"}", "XBTUSD"], [1528684228840, "{\"table\": \"orderBookL2\", \"action\": \"insert\", \"data\": [{\"id\": 8799932100, \"side\": \"Buy\", \"size\": 3, \"price\": 679}], \"symbol\": \"XBTUSD\", \"timestamp\": \"2018-06-11 02:30:28.837217Z\"}", "XBTUSD"], [1528684229157, "{\"table\": \"trade\", \"action\": \"insert\", \"data\": [{\"timestamp\": \"2018-06-11T02:30:28.499Z\", \"side\": \"Sell\", \"size\": 20000, \"price\": 6797.5, \"tickDirection\": \"MinusTick\", \"trdMatchID\": \"7d547123-3eac-8898-94de-c6238e354162\", \"grossValue\": 294220000, \"homeNotional\": 2.9422, \"foreignNotional\": 20000}], \"symbol\": \"XBTUSD\", \"timestamp\": \"2018-06-11 02:30:29.153730Z\"}", "XBTUSD"], [1528684231499, "{\"table\": \"orderBookL2\", \"action\": \"update\", \"data\": [{\"id\": 8799322150, \"side\": \"Buy\", \"size\": 199502}, {\"id\": 8799322350, \"side\": \"Buy\", \"size\": 5243}], \"symbol\": \"XBTUSD\", \"timestamp\": \"2018-06-11 02:30:31.495513Z\"}", "XBTUSD"], [1528684232587, "{\"table\": \"orderBookL2\", \"action\": \"update\", \"data\": [{\"id\": 8799320300, \"side\": \"Buy\", \"size\": 1624}], \"symbol\": \"XBTUSD\", \"timestamp\": \"2018-06-11 02:30:32.583255Z\"}", "XBTUSD"], [1528684234349, "{\"table\": \"orderBookL2\", \"action\": \"update\", \"data\": [{\"id\": 8799321450, \"side\": \"Buy\", \"size\": 19962}, {\"id\": 8799321500, \"side\": \"Buy\", \"size\": 10744}], \"symbol\": \"XBTUSD\", \"timestamp\": \"2018-06-11 02:30:34.339531Z\"}", "XBTUSD"], [1528684237730, "{\"table\": \"orderBookL2\", \"action\": \"update\", \"data\": [{\"id\": 8799320200, \"side\": \"Sell\", \"size\": 2580556}, {\"id\": 8799322250, \"side\": \"Buy\", \"size\": 15310}], \"symbol\": \"XBTUSD\", \"timestamp\": \"2018-06-11 02:30:37.720454Z\"}", "XBTUSD"], [1528684238912, "{\"table\": \"orderBookL2\", \"action\": \"update\", \"data\": [{\"id\": 8799320200, \"side\": \"Sell\", \"size\": 2194162}, {\"id\": 8799320250, \"side\": \"Sell\", \"size\": 886803}], \"symbol\": \"XBTUSD\", \"timestamp\": \"2018-06-11 02:30:38.908386Z\"}", "XBTUSD"], [1528684239587, "{\"table\": \"orderBookL2\", \"action\": \"update\", \"data\": [{\"id\": 8799319100, \"side\": \"Sell\", \"size\": 522320}, {\"id\": 8799319250, \"side\": \"Sell\", \"size\": 287041}], \"symbol\": \"XBTUSD\", \"timestamp\": \"2018-06-11 02:30:39.584794Z\"}", "XBTUSD"], [1528684240243, "{\"table\": \"orderBookL2\", \"action\": \"update\", \"data\": [{\"id\": 8799320200, \"side\": \"Sell\", \"size\": 1246387}, {\"id\": 8799320250, \"side\": \"Sell\", \"size\": 867743}], \"symbol\": \"XBTUSD\", \"timestamp\": \"2018-06-11 02:30:40.239701Z\"}", "XBTUSD"], [1528684241021, "{\"table\": \"orderBookL2\", \"action\": \"update\", \"data\": [{\"id\": 8799320650, \"side\": \"Buy\", \"size\": 141972}, {\"id\": 8799320750, \"side\": \"Buy\", \"size\": 11718}, {\"id\": 8799321200, \"side\": \"Buy\", \"size\": 401268}, {\"id\": 8799321350, \"side\": \"Buy\", \"size\": 835222}, {\"id\": 8799321800, \"side\": \"Buy\", \"size\": 132840}, {\"id\": 8799321950, \"side\": \"Buy\", \"size\": 104742}, {\"id\": 8799322400, \"side\": \"Buy\", \"size\": 173393}, {\"id\": 8799322550, \"side\": \"Buy\", \"size\": 10737}], \"symbol\": \"XBTUSD\", \"timestamp\": \"2018-06-11 02:30:41.017865Z\"}", "XBTUSD"], [1528684242939, "{\"table\": \"orderBookL2\", \"action\": \"update\", \"data\": [{\"id\": 8799311300, \"side\": \"Sell\", \"size\": 121251}, {\"id\": 8799312050, \"side\": \"Sell\", \"size\": 16660}, {\"id\": 8799314300, \"side\": \"Sell\", \"size\": 217170}, {\"id\": 8799315050, \"side\": \"Sell\", \"size\": 35868}, {\"id\": 8799317300, \"side\": \"Sell\", \"size\": 41268}, {\"id\": 8799318050, \"side\": \"Sell\", \"size\": 52425}, {\"id\": 8799320300, \"side\": \"Sell\", \"size\": 1851932}, {\"id\": 8799321750, \"side\": \"Buy\", \"size\": 304706}, {\"id\": 8799323750, \"side\": \"Buy\", \"size\": 33014}, {\"id\": 8799324750, \"side\": \"Buy\", \"size\": 42027}, {\"id\": 8799326750, \"side\": \"Buy\", \"size\": 69349}], \"symbol\": \"XBTUSD\", \"timestamp\": \"2018-06-11 02:30:42.936327Z\"}", "XBTUSD"], [1528684244376, "{\"table\": \"orderBookL2\", \"action\": \"update\", \"data\": [{\"id\": 8798825100, \"side\": \"Sell\", \"size\": 30000}], \"symbol\": \"XBTUSD\", \"timestamp\": \"2018-06-11 02:30:44.373467Z\"}", "XBTUSD"], [1528684248970, "{\"table\": \"orderBookL2\", \"action\": \"update\", \"data\": [{\"id\": 8799320700, \"side\": \"Buy\", \"size\": 11871}, {\"id\": 8799320800, \"side\": \"Buy\", \"size\": 52416}], \"symbol\": \"XBTUSD\", \"timestamp\": \"2018-06-11 02:30:48.964701Z\"}", "XBTUSD"], [1528684250095, "{\"table\": \"orderBookL2\", \"action\": \"update\", \"data\": [{\"id\": 8799320300, \"side\": \"Sell\", \"size\": 1750369}], \"symbol\": \"XBTUSD\", \"timestamp\": \"2018-06-11 02:30:50.092234Z\"}", "XBTUSD"], [1528684250395, "{\"table\": \"orderBookL2\", \"action\": \"update\", \"data\": [{\"id\": 8799319700, \"side\": \"Sell\", \"size\": 17630}], \"symbol\": \"XBTUSD\", \"timestamp\": \"2018-06-11 02:30:50.378987Z\"}", "XBTUSD"], [1528684251303, "{\"table\": \"orderBookL2\", \"action\": \"update\", \"data\": [{\"id\": 8799320500, \"side\": \"Sell\", \"size\": 182617}], \"symbol\": \"XBTUSD\", \"timestamp\": \"2018-06-11 02:30:51.300566Z\"}", "XBTUSD"], [1528684253842, "{\"table\": \"orderBookL2\", \"action\": \"update\", \"data\": [{\"id\": 8799320350, \"side\": \"Sell\", \"size\": 854345}, {\"id\": 8799320450, \"side\": \"Sell\", \"size\": 232731}], \"symbol\": \"XBTUSD\", \"timestamp\": \"2018-06-11 02:30:53.834787Z\"}", "XBTUSD"], [1528684253998, "{\"table\": \"orderBookL2\", \"action\": \"update\", \"data\": [{\"id\": 8799320400, \"side\": \"Sell\", \"size\": 475560}, {\"id\": 8799320550, \"side\": \"Sell\", \"size\": 685731}], \"symbol\": \"XBTUSD\", \"timestamp\": \"2018-06-11 02:30:53.995334Z\"}", "XBTUSD"], [1528684254177, "{\"table\": \"orderBookL2\", \"action\": \"update\", \"data\": [{\"id\": 8799320550, \"side\": \"Sell\", \"size\": 1145804}, {\"id\": 8799320600, \"side\": \"Sell\", \"size\": 302707}], \"symbol\": \"XBTUSD\", \"timestamp\": \"2018-06-11 02:30:54.173330Z\"}", "XBTUSD"], [1528684254350, "{\"table\": \"orderBookL2\", \"action\": \"update\", \"data\": [{\"id\": 8799320400, \"side\": \"Sell\", \"size\": 179488}, {\"id\": 8799320450, \"side\": \"Sell\", \"size\": 230573}], \"symbol\": \"XBTUSD\", \"timestamp\": \"2018-06-11 02:30:54.347801Z\"}", "XBTUSD"], [1528684254663, "{\"table\": \"orderBookL2\", \"action\": \"update\", \"data\": [{\"id\": 8799320850, \"side\": \"Buy\", \"size\": 421}], \"symbol\": \"XBTUSD\", \"timestamp\": \"2018-06-11 02:30:54.659097Z\"}", "XBTUSD"], [1528684255337, "{\"table\": \"orderBookL2\", \"action\": \"update\", \"data\": [{\"id\": 8799320400, \"side\": \"Sell\", \"size\": 155507}], \"symbol\": \"XBTUSD\", \"timestamp\": \"2018-06-11 02:30:55.334942Z\"}", "XBTUSD"], [1528684258783, "{\"table\": \"orderBookL2\", \"action\": \"update\", \"data\": [{\"id\": 8799319900, \"side\": \"Sell\", \"size\": 50715}, {\"id\": 8799320600, \"side\": \"Sell\", \"size\": 1389435}, {\"id\": 8799370650, \"side\": \"Buy\", \"size\": 17}, {\"id\": 8799370700, \"side\": \"Buy\", \"size\": 44100}], \"symbol\": \"XBTUSD\", \"timestamp\": \"2018-06-11 02:30:58.780567Z\"}", "XBTUSD"], [1528684259130, "{\"table\": \"orderBookL2\", \"action\": \"update\", \"data\": [{\"id\": 8799320600, \"side\": \"Sell\", \"size\": 1257402}], \"symbol\": \"XBTUSD\", \"timestamp\": \"2018-06-11 02:30:59.127107Z\"}", "XBTUSD"], [1528684259303, "{\"table\": \"orderBookL2\", \"action\": \"update\", \"data\": [{\"id\": 8799320600, \"side\": \"Sell\", \"size\": 785237}, {\"id\": 8799320750, \"side\": \"Sell\", \"size\": 309948}, {\"id\": 8799321200, \"side\": \"Buy\", \"size\": 32229}, {\"id\": 8799321250, \"side\": \"Buy\", \"size\": 33300}], \"symbol\": \"XBTUSD\", \"timestamp\": \"2018-06-11 02:30:59.299586Z\"}", "XBTUSD"], [1528684260359, "{\"table\": \"orderBookL2\", \"action\": \"update\", \"data\": [{\"id\": 8799320600, \"side\": \"Sell\", \"size\": 771556}], \"symbol\": \"XBTUSD\", \"timestamp\": \"2018-06-11 02:31:00.355364Z\"}", "XBTUSD"], [1528684263231, "{\"table\": \"orderBookL2\", \"action\": \"update\", \"data\": [{\"id\": 8799285600, \"side\": \"Sell\", \"size\": 111777}, {\"id\": 8799304700, \"side\": \"Sell\", \"size\": 3825}, {\"id\": 8799306200, \"side\": \"Sell\", \"size\": 1061464}, {\"id\": 8799315800, \"side\": \"Sell\", \"size\": 75532}, {\"id\": 8799316350, \"side\": \"Sell\", \"size\": 511797}, {\"id\": 8799326050, \"side\": \"Buy\", \"size\": 51900}, {\"id\": 8799326550, \"side\": \"Buy\", \"size\": 1087218}, {\"id\": 8799332400, \"side\": \"Buy\", \"size\": 9219}, {\"id\": 8799333800, \"side\": \"Buy\", \"size\": 472512}, {\"id\": 8799343050, \"side\": \"Buy\", \"size\": 50}, {\"id\": 8799345850, \"side\": \"Buy\", \"size\": 529474}], \"symbol\": \"XBTUSD\", \"timestamp\": \"2018-06-11 02:31:03.228221Z\"}", "XBTUSD"], [1528684265985, "{\"table\": \"orderBookL2\", \"action\": \"update\", \"data\": [{\"id\": 8799321500, \"side\": \"Buy\", \"size\": 47853}], \"symbol\": \"XBTUSD\", \"timestamp\": \"2018-06-11 02:31:05.977666Z\"}", "XBTUSD"], [1528684266358, "{\"table\": \"orderBookL2\", \"action\": \"update\", \"data\": [{\"id\": 8799320600, \"side\": \"Sell\", \"size\": 595295}, {\"id\": 8799322100, \"side\": \"Buy\", \"size\": 237205}], \"symbol\": \"XBTUSD\", \"timestamp\": \"2018-06-11 02:31:06.351553Z\"}", "XBTUSD"], [1528684268642, "{\"table\": \"orderBookL2\", \"action\": \"update\", \"data\": [{\"id\": 8799320750, \"side\": \"Sell\", \"size\": 772257}], \"symbol\": \"XBTUSD\", \"timestamp\": \"2018-06-11 02:31:08.633977Z\"}", "XBTUSD"], [1528684269012, "{\"table\": \"orderBookL2\", \"action\": \"update\", \"data\": [{\"id\": 8799330350, \"side\": \"Buy\", \"size\": 50}, {\"id\": 8799330750, \"side\": \"Buy\", \"size\": 33574}], \"symbol\": \"XBTUSD\", \"timestamp\": \"2018-06-11 02:31:09.009061Z\"}", "XBTUSD"], [1528684271935, "{\"table\": \"orderBookL2\", \"action\": \"update\", \"data\": [{\"id\": 8799320700, \"side\": \"Sell\", \"size\": 76726}, {\"id\": 8799320900, \"side\": \"Buy\", \"size\": 126602}], \"symbol\": \"XBTUSD\", \"timestamp\": \"2018-06-11 02:31:11.931403Z\"}", "XBTUSD"], [1528684273058, "{\"table\": \"orderBookL2\", \"action\": \"update\", \"data\": [{\"id\": 8799320800, \"side\": \"Buy\", \"size\": 1605608}], \"symbol\": \"XBTUSD\", \"timestamp\": \"2018-06-11 02:31:13.054421Z\"}", "XBTUSD"], [1528684273869, "{\"table\": \"orderBookL2\", \"action\": \"update\", \"data\": [{\"id\": 8799320950, \"side\": \"Buy\", \"size\": 1022362}, {\"id\": 8799321000, \"side\": \"Buy\", \"size\": 781889}], \"symbol\": \"XBTUSD\", \"timestamp\": \"2018-06-11 02:31:13.865597Z\"}", "XBTUSD"], [1528684274604, "{\"table\": \"orderBookL2\", \"action\": \"update\", \"data\": [{\"id\": 8799320700, \"side\": \"Buy\", \"size\": 1242039}], \"symbol\": \"XBTUSD\", \"timestamp\": \"2018-06-11 02:31:14.601278Z\"}", "XBTUSD"], [1528684275259, "{\"table\": \"orderBookL2\", \"action\": \"update\", \"data\": [{\"id\": 8799320650, \"side\": \"Buy\", \"size\": 1532523}], \"symbol\": \"XBTUSD\", \"timestamp\": \"2018-06-11 02:31:15.255295Z\"}", "XBTUSD"], [1528684278897, "{\"table\": \"orderBookL2\", \"action\": \"update\", \"data\": [{\"id\": 8799320750, \"side\": \"Buy\", \"size\": 267959}], \"symbol\": \"XBTUSD\", \"timestamp\": \"2018-06-11 02:31:18.890753Z\"}", "XBTUSD"], [1528684279228, "{\"table\": \"orderBookL2\", \"action\": \"update\", \"data\": [{\"id\": 8799318750, \"side\": \"Sell\", \"size\": 103566}], \"symbol\": \"XBTUSD\", \"timestamp\": \"2018-06-11 02:31:19.226028Z\"}", "XBTUSD"], [1528684279440, "{\"table\": \"orderBookL2\", \"action\": \"update\", \"data\": [{\"id\": 8799371250, \"side\": \"Buy\", \"size\": 190}], \"symbol\": \"XBTUSD\", \"timestamp\": \"2018-06-11 02:31:19.437815Z\"}", "XBTUSD"], [1528684280219, "{\"table\": \"orderBookL2\", \"action\": \"update\", \"data\": [{\"id\": 8799321300, \"side\": \"Buy\", \"size\": 369935}, {\"id\": 8799321350, \"side\": \"Buy\", \"size\": 61014}], \"symbol\": \"XBTUSD\", \"timestamp\": \"2018-06-11 02:31:20.213306Z\"}", "XBTUSD"], [1528684281788, "{\"table\": \"orderBookL2\", \"action\": \"delete\", \"data\": [{\"id\": 8798915600, \"side\": \"Sell\"}], \"symbol\": \"XBTUSD\", \"timestamp\": \"2018-06-11 02:31:21.785956Z\"}", "XBTUSD"], [1528684283657, "{\"table\": \"orderBookL2\", \"action\": \"update\", \"data\": [{\"id\": 8799318550, \"side\": \"Sell\", \"size\": 15300}], \"symbol\": \"XBTUSD\", \"timestamp\": \"2018-06-11 02:31:23.651427Z\"}", "XBTUSD"], [1528684286389, "{\"table\": \"orderBookL2\", \"action\": \"update\", \"data\": [{\"id\": 8799318800, \"side\": \"Sell\", \"size\": 51764}], \"symbol\": \"XBTUSD\", \"timestamp\": \"2018-06-11 02:31:26.384859Z\"}", "XBTUSD"], [1528684288920, "{\"table\": \"orderBookL2\", \"action\": \"update\", \"data\": [{\"id\": 8799318450, \"side\": \"Sell\", \"size\": 236071}, {\"id\": 8799318550, \"side\": \"Sell\", \"size\": 15000}], \"symbol\": \"XBTUSD\", \"timestamp\": \"2018-06-11 02:31:28.917259Z\"}", "XBTUSD"], [1528684290060, "{\"table\": \"orderBookL2\", \"action\": \"update\", \"data\": [{\"id\": 8799320550, \"side\": \"Sell\", \"size\": 433707}], \"symbol\": \"XBTUSD\", \"timestamp\": \"2018-06-11 02:31:30.057700Z\"}", "XBTUSD"], [1528684292373, "{\"table\": \"orderBookL2\", \"action\": \"update\", \"data\": [{\"id\": 8799320250, \"side\": \"Sell\", \"size\": 35512}, {\"id\": 8799320300, \"side\": \"Sell\", \"size\": 75852}], \"symbol\": \"XBTUSD\", \"timestamp\": \"2018-06-11 02:31:32.368259Z\"}", "XBTUSD"], [1528684294475, "{\"table\": \"orderBookL2\", \"action\": \"update\", \"data\": [{\"id\": 8799317950, \"side\": \"Sell\", \"size\": 639085}, {\"id\": 8799318400, \"side\": \"Sell\", \"size\": 167554}], \"symbol\": \"XBTUSD\", \"timestamp\": \"2018-06-11 02:31:34.468777Z\"}", "XBTUSD"], [1528684297906, "{\"table\": \"orderBookL2\", \"action\": \"update\", \"data\": [{\"id\": 8799320600, \"side\": \"Buy\", \"size\": 1050677}], \"symbol\": \"XBTUSD\", \"timestamp\": \"2018-06-11 02:31:37.900336Z\"}", "XBTUSD"], [1528684299111, "{\"table\": \"orderBookL2\", \"action\": \"update\", \"data\": [{\"id\": 8799322000, \"side\": \"Buy\", \"size\": 415606}], \"symbol\": \"XBTUSD\", \"timestamp\": \"2018-06-11 02:31:39.108208Z\"}", "XBTUSD"], [1528684301256, "{\"table\": \"orderBookL2\", \"action\": \"delete\", \"data\": [{\"id\": 8799932000, \"side\": \"Buy\"}], \"symbol\": \"XBTUSD\", \"timestamp\": \"2018-06-11 02:31:41.250927Z\"}", "XBTUSD"], [1528684303735, "{\"table\": \"orderBookL2\", \"action\": \"update\", \"data\": [{\"id\": 8799320600, \"side\": \"Buy\", \"size\": 693820}], \"symbol\": \"XBTUSD\", \"timestamp\": \"2018-06-11 02:31:43.733011Z\"}", "XBTUSD"], [1528684303982, "{\"table\": \"orderBookL2\", \"action\": \"update\", \"data\": [{\"id\": 8799319050, \"side\": \"Sell\", \"size\": 18795}, {\"id\": 8799319700, \"side\": \"Sell\", \"size\": 54655}], \"symbol\": \"XBTUSD\", \"timestamp\": \"2018-06-11 02:31:43.978465Z\"}", "XBTUSD"], [1528684304838, "{\"table\": \"orderBookL2\", \"action\": \"update\", \"data\": [{\"id\": 8799320550, \"side\": \"Buy\", \"size\": 1492107}], \"symbol\": \"XBTUSD\", \"timestamp\": \"2018-06-11 02:31:44.833180Z\"}", "XBTUSD"], [1528684308845, "{\"table\": \"orderBookL2\", \"action\": \"update\", \"data\": [{\"id\": 8799313800, \"side\": \"Sell\", \"size\": 68798}], \"symbol\": \"XBTUSD\", \"timestamp\": \"2018-06-11 02:31:48.841416Z\"}", "XBTUSD"], [1528684309187, "{\"table\": \"orderBookL2\", \"action\": \"update\", \"data\": [{\"id\": 8799320600, \"side\": \"Buy\", \"size\": 724123}], \"symbol\": \"XBTUSD\", \"timestamp\": \"2018-06-11 02:31:49.184048Z\"}", "XBTUSD"], [1528684309435, "{\"table\": \"orderBookL2\", \"action\": \"update\", \"data\": [{\"id\": 8799320500, \"side\": \"Buy\", \"size\": 578252}, {\"id\": 8799320550, \"side\": \"Buy\", \"size\": 847205}], \"symbol\": \"XBTUSD\", \"timestamp\": \"2018-06-11 02:31:49.427033Z\"}", "XBTUSD"], [1528684310076, "{\"table\": \"trade\", \"action\": \"insert\", \"data\": [{\"timestamp\": \"2018-06-11T02:31:49.942Z\", \"side\": \"Buy\", \"size\": 1000, \"price\": 6796.5, \"tickDirection\": \"ZeroPlusTick\", \"trdMatchID\": \"58275ba2-5a97-dec7-eef2-a335f1279a20\", \"grossValue\": 14713000, \"homeNotional\": 0.14713, \"foreignNotional\": 1000}], \"symbol\": \"XBTUSD\", \"timestamp\": \"2018-06-11 02:31:50.071056Z\"}", "XBTUSD"], [1528684313758, "{\"table\": \"orderBookL2\", \"action\": \"update\", \"data\": [{\"id\": 8799320400, \"side\": \"Buy\", \"size\": 764402}], \"symbol\": \"XBTUSD\", \"timestamp\": \"2018-06-11 02:31:53.755594Z\"}", "XBTUSD"], [1528684314040, "{\"table\": \"orderBookL2\", \"action\": \"update\", \"data\": [{\"id\": 8799322000, \"side\": \"Buy\", \"size\": 410384}, {\"id\": 8799322100, \"side\": \"Buy\", \"size\": 93466}], \"symbol\": \"XBTUSD\", \"timestamp\": \"2018-06-11 02:31:54.037512Z\"}", "XBTUSD"], [1528684314722, "{\"table\": \"orderBookL2\", \"action\": \"update\", \"data\": [{\"id\": 8799319650, \"side\": \"Sell\", \"size\": 7500}], \"symbol\": \"XBTUSD\", \"timestamp\": \"2018-06-11 02:31:54.715154Z\"}", "XBTUSD"], [1528684317872, "{\"table\": \"orderBookL2\", \"action\": \"update\", \"data\": [{\"id\": 8799320350, \"side\": \"Buy\", \"size\": 300575}], \"symbol\": \"XBTUSD\", \"timestamp\": \"2018-06-11 02:31:57.869272Z\"}", "XBTUSD"], [1528684318829, "{\"table\": \"orderBookL2\", \"action\": \"update\", \"data\": [{\"id\": 8799320450, \"side\": \"Buy\", \"size\": 190341}], \"symbol\": \"XBTUSD\", \"timestamp\": \"2018-06-11 02:31:58.826166Z\"}", "XBTUSD"], [1528684319071, "{\"table\": \"orderBookL2\", \"action\": \"update\", \"data\": [{\"id\": 8799320250, \"side\": \"Sell\", \"size\": 1212}], \"symbol\": \"XBTUSD\", \"timestamp\": \"2018-06-11 02:31:59.068852Z\"}", "XBTUSD"], [1528684322599, "{\"table\": \"orderBookL2\", \"action\": \"update\", \"data\": [{\"id\": 8799320300, \"side\": \"Buy\", \"size\": 367012}], \"symbol\": \"XBTUSD\", \"timestamp\": \"2018-06-11 02:32:02.593704Z\"}", "XBTUSD"], [1528684324925, "{\"table\": \"orderBookL2\", \"action\": \"update\", \"data\": [{\"id\": 8799319500, \"side\": \"Sell\", \"size\": 68159}], \"symbol\": \"XBTUSD\", \"timestamp\": \"2018-06-11 02:32:04.917489Z\"}", "XBTUSD"], [1528684325193, "{\"table\": \"orderBookL2\", \"action\": \"update\", \"data\": [{\"id\": 8799309300, \"side\": \"Sell\", \"size\": 36567}, {\"id\": 8799312250, \"side\": \"Sell\", \"size\": 27400}, {\"id\": 8799312300, \"side\": \"Sell\", \"size\": 70548}, {\"id\": 8799315250, \"side\": \"Sell\", \"size\": 227436}, {\"id\": 8799315300, \"side\": \"Sell\", \"size\": 6405}, {\"id\": 8799318250, \"side\": \"Sell\", \"size\": 245363}, {\"id\": 8799318300, \"side\": \"Sell\", \"size\": 23191}], \"symbol\": \"XBTUSD\", \"timestamp\": \"2018-06-11 02:32:05.189896Z\"}", "XBTUSD"], [1528684325530, "{\"table\": \"orderBookL2\", \"action\": \"update\", \"data\": [{\"id\": 8799320250, \"side\": \"Buy\", \"size\": 318461}], \"symbol\": \"XBTUSD\", \"timestamp\": \"2018-06-11 02:32:05.525983Z\"}", "XBTUSD"], [1528684327199, "{\"table\": \"orderBookL2\", \"action\": \"update\", \"data\": [{\"id\": 8799320800, \"side\": \"Buy\", \"size\": 1746019}, {\"id\": 8799321200, \"side\": \"Buy\", \"size\": 24592}, {\"id\": 8799321800, \"side\": \"Buy\", \"size\": 91660}, {\"id\": 8799322200, \"side\": \"Buy\", \"size\": 84512}], \"symbol\": \"XBTUSD\", \"timestamp\": \"2018-06-11 02:32:07.195395Z\"}", "XBTUSD"], [1528684329056, "{\"table\": \"orderBookL2\", \"action\": \"update\", \"data\": [{\"id\": 8799273550, \"side\": \"Sell\", \"size\": 478240}, {\"id\": 8799274750, \"side\": \"Sell\", \"size\": 1200}, {\"id\": 8799299600, \"side\": \"Sell\", \"size\": 5555}, {\"id\": 8799313700, \"side\": \"Sell\", \"size\": 492345}, {\"id\": 8799313950, \"side\": \"Sell\", \"size\": 2300}, {\"id\": 8799325300, \"side\": \"Buy\", \"size\": 30837}, {\"id\": 8799325400, \"side\": \"Buy\", \"size\": 1177095}, {\"id\": 8799330450, \"side\": \"Buy\", \"size\": 50500}, {\"id\": 8799330700, \"side\": \"Buy\", \"size\": 504830}, {\"id\": 8799339100, \"side\": \"Buy\", \"size\": 8930}, {\"id\": 8799339650, \"side\": \"Buy\", \"size\": 567273}], \"symbol\": \"XBTUSD\", \"timestamp\": \"2018-06-11 02:32:09.053405Z\"}", "XBTUSD"], [1528684329258, "{\"table\": \"orderBookL2\", \"action\": \"update\", \"data\": [{\"id\": 8799320350, \"side\": \"Buy\", \"size\": 669422}, {\"id\": 8799320400, \"side\": \"Buy\", \"size\": 149007}], \"symbol\": \"XBTUSD\", \"timestamp\": \"2018-06-11 02:32:09.254888Z\"}", "XBTUSD"], [1528684329582, "{\"table\": \"orderBookL2\", \"action\": \"update\", \"data\": [{\"id\": 8799270100, \"side\": \"Sell\", \"size\": 139998}, {\"id\": 8799270200, \"side\": \"Sell\", \"size\": 224870}, {\"id\": 8799320100, \"side\": \"Sell\", \"size\": 13533}, {\"id\": 8799320200, \"side\": \"Sell\", \"size\": 320735}, {\"id\": 8799320250, \"side\": \"Buy\", \"size\": 751354}, {\"id\": 8799320500, \"side\": \"Buy\", \"size\": 177091}, {\"id\": 8799370250, \"side\": \"Buy\", \"size\": 8000}, {\"id\": 8799370450, \"side\": \"Buy\", \"size\": 375}], \"symbol\": \"XBTUSD\", \"timestamp\": \"2018-06-11 02:32:09.578965Z\"}", "XBTUSD"], [1528684332820, "{\"table\": \"orderBookL2\", \"action\": \"update\", \"data\": [{\"id\": 8799320250, \"side\": \"Buy\", \"size\": 779110}], \"symbol\": \"XBTUSD\", \"timestamp\": \"2018-06-11 02:32:12.815283Z\"}", "XBTUSD"], [1528684334571, "{\"table\": \"orderBookL2\", \"action\": \"update\", \"data\": [{\"id\": 8799273550, \"side\": \"Sell\", \"size\": 10}, {\"id\": 8799298500, \"side\": \"Sell\", \"size\": 516807}, {\"id\": 8799313550, \"side\": \"Sell\", \"size\": 476826}, {\"id\": 8799313700, \"side\": \"Sell\", \"size\": 14115}, {\"id\": 8799325400, \"side\": \"Buy\", \"size\": 99980}, {\"id\": 8799325500, \"side\": \"Buy\", \"size\": 1079250}, {\"id\": 8799330700, \"side\": \"Buy\", \"size\": 12247}, {\"id\": 8799331000, \"side\": \"Buy\", \"size\": 689423}, {\"id\": 8799339650, \"side\": \"Buy\", \"size\": 74690}, {\"id\": 8799340150, \"side\": \"Buy\", \"size\": 491252}], \"symbol\": \"XBTUSD\", \"timestamp\": \"2018-06-11 02:32:14.565795Z\"}", "XBTUSD"], [1528684337872, "{\"table\": \"orderBookL2\", \"action\": \"update\", \"data\": [{\"id\": 8799319700, \"side\": \"Sell\", \"size\": 54171}], \"symbol\": \"XBTUSD\", \"timestamp\": \"2018-06-11 02:32:17.869411Z\"}", "XBTUSD"], [1528684339394, "{\"table\": \"orderBookL2\", \"action\": \"update\", \"data\": [{\"id\": 8799321150, \"side\": \"Buy\", \"size\": 300056}], \"symbol\": \"XBTUSD\", \"timestamp\": \"2018-06-11 02:32:19.390110Z\"}", "XBTUSD"], [1528684341555, "{\"table\": \"orderBookL2\", \"action\": \"update\", \"data\": [{\"id\": 8799320200, \"side\": \"Sell\", \"size\": 327255}], \"symbol\": \"XBTUSD\", \"timestamp\": \"2018-06-11 02:32:21.550518Z\"}", "XBTUSD"], [1528684344223, "{\"table\": \"orderBookL2\", \"action\": \"update\", \"data\": [{\"id\": 8799311000, \"side\": \"Sell\", \"size\": 300348}], \"symbol\": \"XBTUSD\", \"timestamp\": \"2018-06-11 02:32:24.217922Z\"}", "XBTUSD"], [1528684347148, "{\"table\": \"orderBookL2\", \"action\": \"update\", \"data\": [{\"id\": 8799318850, \"side\": \"Sell\", \"size\": 25876}, {\"id\": 8799319050, \"side\": \"Sell\", \"size\": 21506}], \"symbol\": \"XBTUSD\", \"timestamp\": \"2018-06-11 02:32:27.143814Z\"}", "XBTUSD"], [1528684349083, "{\"table\": \"orderBookL2\", \"action\": \"insert\", \"data\": [{\"id\": 8799932100, \"side\": \"Buy\", \"size\": 3, \"price\": 679}], \"symbol\": \"XBTUSD\", \"timestamp\": \"2018-06-11 02:32:29.078310Z\"}", "XBTUSD"], [1528684349548, "{\"table\": \"orderBookL2\", \"action\": \"update\", \"data\": [{\"id\": 8799319600, \"side\": \"Sell\", \"size\": 434841}, {\"id\": 8799321150, \"side\": \"Buy\", \"size\": 32380}], \"symbol\": \"XBTUSD\", \"timestamp\": \"2018-06-11 02:32:29.544045Z\"}", "XBTUSD"], [1528684352952, "{\"table\": \"orderBookL2\", \"action\": \"update\", \"data\": [{\"id\": 8799321950, \"side\": \"Buy\", \"size\": 198169}], \"symbol\": \"XBTUSD\", \"timestamp\": \"2018-06-11 02:32:32.948215Z\"}", "XBTUSD"], [1528684353319, "{\"table\": \"orderBookL2\", \"action\": \"update\", \"data\": [{\"id\": 8799319650, \"side\": \"Sell\", \"size\": 29720}], \"symbol\": \"XBTUSD\", \"timestamp\": \"2018-06-11 02:32:33.317059Z\"}", "XBTUSD"], [1528684354640, "{\"table\": \"orderBookL2\", \"action\": \"update\", \"data\": [{\"id\": 8799320100, \"side\": \"Sell\", \"size\": 2906}], \"symbol\": \"XBTUSD\", \"timestamp\": \"2018-06-11 02:32:34.637564Z\"}", "XBTUSD"], [1528684355708, "{\"table\": \"orderBookL2\", \"action\": \"update\", \"data\": [{\"id\": 8799320200, \"side\": \"Buy\", \"size\": 834907}], \"symbol\": \"XBTUSD\", \"timestamp\": \"2018-06-11 02:32:35.705625Z\"}", "XBTUSD"], [1528684356363, "{\"table\": \"orderBookL2\", \"action\": \"update\", \"data\": [{\"id\": 8799320150, \"side\": \"Buy\", \"size\": 256087}, {\"id\": 8799320200, \"side\": \"Buy\", \"size\": 427911}], \"symbol\": \"XBTUSD\", \"timestamp\": \"2018-06-11 02:32:36.355323Z\"}", "XBTUSD"], [1528684356971, "{\"table\": \"orderBookL2\", \"action\": \"update\", \"data\": [{\"id\": 8799320100, \"side\": \"Buy\", \"size\": 443921}], \"symbol\": \"XBTUSD\", \"timestamp\": \"2018-06-11 02:32:36.968252Z\"}", "XBTUSD"], [1528684357660, "{\"table\": \"orderBookL2\", \"action\": \"update\", \"data\": [{\"id\": 8799319150, \"side\": \"Sell\", \"size\": 40510}, {\"id\": 8799319250, \"side\": \"Sell\", \"size\": 850}], \"symbol\": \"XBTUSD\", \"timestamp\": \"2018-06-11 02:32:37.657929Z\"}", "XBTUSD"], [1528684358325, "{\"table\": \"orderBookL2\", \"action\": \"update\", \"data\": [{\"id\": 8799319900, \"side\": \"Buy\", \"size\": 103969}, {\"id\": 8799320000, \"side\": \"Buy\", \"size\": 85866}], \"symbol\": \"XBTUSD\", \"timestamp\": \"2018-06-11 02:32:38.321409Z\"}", "XBTUSD"], [1528684359023, "{\"table\": \"orderBookL2\", \"action\": \"update\", \"data\": [{\"id\": 8799317900, \"side\": \"Sell\", \"size\": 94924}], \"symbol\": \"XBTUSD\", \"timestamp\": \"2018-06-11 02:32:39.020634Z\"}", "XBTUSD"], [1528684359745, "{\"table\": \"orderBookL2\", \"action\": \"update\", \"data\": [{\"id\": 8799320100, \"side\": \"Buy\", \"size\": 360140}], \"symbol\": \"XBTUSD\", \"timestamp\": \"2018-06-11 02:32:39.742339Z\"}", "XBTUSD"], [1528684361293, "{\"table\": \"orderBookL2\", \"action\": \"update\", \"data\": [{\"id\": 8799322950, \"side\": \"Buy\", \"size\": 24690}], \"symbol\": \"XBTUSD\", \"timestamp\": \"2018-06-11 02:32:41.290569Z\"}", "XBTUSD"], [1528684363803, "{\"table\": \"orderBookL2\", \"action\": \"update\", \"data\": [{\"id\": 8799319450, \"side\": \"Sell\", \"size\": 29971}, {\"id\": 8799319550, \"side\": \"Sell\", \"size\": 2910}], \"symbol\": \"XBTUSD\", \"timestamp\": \"2018-06-11 02:32:43.800987Z\"}", "XBTUSD"], [1528684364090, "{\"table\": \"orderBookL2\", \"action\": \"update\", \"data\": [{\"id\": 8799321000, \"side\": \"Buy\", \"size\": 251082}, {\"id\": 8799321100, \"side\": \"Buy\", \"size\": 9274}], \"symbol\": \"XBTUSD\", \"timestamp\": \"2018-06-11 02:32:44.086883Z\"}", "XBTUSD"], [1528684364922, "{\"table\": \"orderBookL2\", \"action\": \"update\", \"data\": [{\"id\": 8799319600, \"side\": \"Sell\", \"size\": 1120960}, {\"id\": 8799321300, \"side\": \"Buy\", \"size\": 356203}], \"symbol\": \"XBTUSD\", \"timestamp\": \"2018-06-11 02:32:44.919241Z\"}", "XBTUSD"], [1528684366547, "{\"table\": \"orderBookL2\", \"action\": \"update\", \"data\": [{\"id\": 8799319800, \"side\": \"Buy\", \"size\": 1859}], \"symbol\": \"XBTUSD\", \"timestamp\": \"2018-06-11 02:32:46.537116Z\"}", "XBTUSD"], [1528684368431, "{\"table\": \"orderBookL2\", \"action\": \"update\", \"data\": [{\"id\": 8799317800, \"side\": \"Sell\", \"size\": 2139093}, {\"id\": 8799318700, \"side\": \"Sell\", \"size\": 18175}], \"symbol\": \"XBTUSD\", \"timestamp\": \"2018-06-11 02:32:48.423875Z\"}", "XBTUSD"], [1528684371272, "{\"table\": \"orderBookL2\", \"action\": \"update\", \"data\": [{\"id\": 8799320000, \"side\": \"Buy\", \"size\": 11928}], \"symbol\": \"XBTUSD\", \"timestamp\": \"2018-06-11 02:32:51.264989Z\"}", "XBTUSD"], [1528684373924, "{\"table\": \"orderBookL2\", \"action\": \"update\", \"data\": [{\"id\": 8799319600, \"side\": \"Sell\", \"size\": 1373487}, {\"id\": 8799319900, \"side\": \"Buy\", \"size\": 4050}], \"symbol\": \"XBTUSD\", \"timestamp\": \"2018-06-11 02:32:53.916966Z\"}", "XBTUSD"], [1528684374659, "{\"table\": \"orderBookL2\", \"action\": \"update\", \"data\": [{\"id\": 8799320050, \"side\": \"Buy\", \"size\": 230723}, {\"id\": 8799320550, \"side\": \"Buy\", \"size\": 9654}], \"symbol\": \"XBTUSD\", \"timestamp\": \"2018-06-11 02:32:54.655302Z\"}", "XBTUSD"], [1528684377783, "{\"table\": \"orderBookL2\", \"action\": \"update\", \"data\": [{\"id\": 8799319850, \"side\": \"Buy\", \"size\": 67100}, {\"id\": 8799320550, \"side\": \"Buy\", \"size\": 8567}], \"symbol\": \"XBTUSD\", \"timestamp\": \"2018-06-11 02:32:57.779830Z\"}", "XBTUSD"], [1528684378993, "{\"table\": \"orderBookL2\", \"action\": \"update\", \"data\": [{\"id\": 8799319600, \"side\": \"Sell\", \"size\": 67855}], \"symbol\": \"XBTUSD\", \"timestamp\": \"2018-06-11 02:32:58.990534Z\"}", "XBTUSD"], [1528684379276, "{\"table\": \"orderBookL2\", \"action\": \"update\", \"data\": [{\"id\": 8799319500, \"side\": \"Sell\", \"size\": 80809}], \"symbol\": \"XBTUSD\", \"timestamp\": \"2018-06-11 02:32:59.273414Z\"}", "XBTUSD"], [1528684379820, "{\"table\": \"orderBookL2\", \"action\": \"update\", \"data\": [{\"id\": 8799320300, \"side\": \"Buy\", \"size\": 1812}], \"symbol\": \"XBTUSD\", \"timestamp\": \"2018-06-11 02:32:59.818052Z\"}", "XBTUSD"], [1528684382561, "{\"table\": \"orderBookL2\", \"action\": \"update\", \"data\": [{\"id\": 8799319400, \"side\": \"Buy\", \"size\": 202630}], \"symbol\": \"XBTUSD\", \"timestamp\": \"2018-06-11 02:33:02.558196Z\"}", "XBTUSD"], [1528684384799, "{\"table\": \"orderBookL2\", \"action\": \"update\", \"data\": [{\"id\": 8799322200, \"side\": \"Buy\", \"size\": 63973}], \"symbol\": \"XBTUSD\", \"timestamp\": \"2018-06-11 02:33:04.796083Z\"}", "XBTUSD"], [1528684385161, "{\"table\": \"orderBookL2\", \"action\": \"update\", \"data\": [{\"id\": 8799319800, \"side\": \"Buy\", \"size\": 1324}], \"symbol\": \"XBTUSD\", \"timestamp\": \"2018-06-11 02:33:05.157722Z\"}", "XBTUSD"], [1528684387290, "{\"table\": \"trade\", \"action\": \"insert\", \"data\": [{\"timestamp\": \"2018-06-11T02:33:06.349Z\", \"side\": \"Buy\", \"size\": 5000, \"price\": 6806.5, \"tickDirection\": \"ZeroPlusTick\", \"trdMatchID\": \"16efa8a8-19d9-1ef1-7aef-7124c06d5d0a\", \"grossValue\": 73460000, \"homeNotional\": 0.7346, \"foreignNotional\": 5000}], \"symbol\": \"XBTUSD\", \"timestamp\": \"2018-06-11 02:33:07.285198Z\"}", "XBTUSD"], [1528684389141, "{\"table\": \"orderBookL2\", \"action\": \"update\", \"data\": [{\"id\": 8799319050, \"side\": \"Sell\", \"size\": 12298}], \"symbol\": \"XBTUSD\", \"timestamp\": \"2018-06-11 02:33:09.134194Z\"}", "XBTUSD"], [1528684389354, "{\"table\": \"orderBookL2\", \"action\": \"update\", \"data\": [{\"id\": 8799319150, \"side\": \"Buy\", \"size\": 227203}, {\"id\": 8799319300, \"side\": \"Buy\", \"size\": 228827}, {\"id\": 8799319350, \"side\": \"Buy\", \"size\": 127256}], \"symbol\": \"XBTUSD\", \"timestamp\": \"2018-06-11 02:33:09.351458Z\"}", "XBTUSD"], [1528684389644, "{\"table\": \"orderBookL2\", \"action\": \"update\", \"data\": [{\"id\": 8799319450, \"side\": \"Buy\", \"size\": 337144}], \"symbol\": \"XBTUSD\", \"timestamp\": \"2018-06-11 02:33:09.641231Z\"}", "XBTUSD"], [1528684390778, "{\"table\": \"orderBookL2\", \"action\": \"update\", \"data\": [{\"id\": 8799318000, \"side\": \"Sell\", \"size\": 1153549}], \"symbol\": \"XBTUSD\", \"timestamp\": \"2018-06-11 02:33:10.775538Z\"}", "XBTUSD"], [1528684391465, "{\"table\": \"orderBookL2\", \"action\": \"update\", \"data\": [{\"id\": 8799319850, \"side\": \"Buy\", \"size\": 51605}, {\"id\": 8799320050, \"side\": \"Buy\", \"size\": 121675}], \"symbol\": \"XBTUSD\", \"timestamp\": \"2018-06-11 02:33:11.462935Z\"}", "XBTUSD"], [1528684392224, "{\"table\": \"orderBookL2\", \"action\": \"update\", \"data\": [{\"id\": 8799319250, \"side\": \"Buy\", \"size\": 6148}], \"symbol\": \"XBTUSD\", \"timestamp\": \"2018-06-11 02:33:12.221798Z\"}", "XBTUSD"], [1528684393098, "{\"table\": \"orderBookL2\", \"action\": \"update\", \"data\": [{\"id\": 8799318450, \"side\": \"Sell\", \"size\": 18400}], \"symbol\": \"XBTUSD\", \"timestamp\": \"2018-06-11 02:33:13.095468Z\"}", "XBTUSD"], [1528684394083, "{\"table\": \"orderBookL2\", \"action\": \"update\", \"data\": [{\"id\": 8799319200, \"side\": \"Buy\", \"size\": 24354}], \"symbol\": \"XBTUSD\", \"timestamp\": \"2018-06-11 02:33:14.080194Z\"}", "XBTUSD"], [1528684396355, "{\"table\": \"orderBookL2\", \"action\": \"update\", \"data\": [{\"id\": 8799319600, \"side\": \"Buy\", \"size\": 1884}], \"symbol\": \"XBTUSD\", \"timestamp\": \"2018-06-11 02:33:16.351613Z\"}", "XBTUSD"], [1528684397878, "{\"table\": \"orderBookL2\", \"action\": \"update\", \"data\": [{\"id\": 8799318350, \"side\": \"Sell\", \"size\": 2200}], \"symbol\": \"XBTUSD\", \"timestamp\": \"2018-06-11 02:33:17.874701Z\"}", "XBTUSD"], [1528684398082, "{\"table\": \"orderBookL2\", \"action\": \"update\", \"data\": [{\"id\": 8799319050, \"side\": \"Buy\", \"size\": 643098}], \"symbol\": \"XBTUSD\", \"timestamp\": \"2018-06-11 02:33:18.077711Z\"}", "XBTUSD"], [1528684399054, "{\"table\": \"orderBookL2\", \"action\": \"update\", \"data\": [{\"id\": 8799318700, \"side\": \"Sell\", \"size\": 26649}], \"symbol\": \"XBTUSD\", \"timestamp\": \"2018-06-11 02:33:19.049643Z\"}", "XBTUSD"], [1528684401489, "{\"table\": \"orderBookL2\", \"action\": \"update\", \"data\": [{\"id\": 8799319300, \"side\": \"Buy\", \"size\": 116488}], \"symbol\": \"XBTUSD\", \"timestamp\": \"2018-06-11 02:33:21.486218Z\"}", "XBTUSD"], [1528684403958, "{\"table\": \"orderBookL2\", \"action\": \"update\", \"data\": [{\"id\": 8799312200, \"side\": \"Sell\", \"size\": 577802}], \"symbol\": \"XBTUSD\", \"timestamp\": \"2018-06-11 02:33:23.954724Z\"}", "XBTUSD"], [1528684404488, "{\"table\": \"orderBookL2\", \"action\": \"update\", \"data\": [{\"id\": 8799319000, \"side\": \"Sell\", \"size\": 280331}], \"symbol\": \"XBTUSD\", \"timestamp\": \"2018-06-11 02:33:24.486044Z\"}", "XBTUSD"], [1528684407631, "{\"table\": \"orderBookL2\", \"action\": \"update\", \"data\": [{\"id\": 8799319000, \"side\": \"Sell\", \"size\": 660220}], \"symbol\": \"XBTUSD\", \"timestamp\": \"2018-06-11 02:33:27.620528Z\"}", "XBTUSD"], [1528684408986, "{\"table\": \"orderBookL2\", \"action\": \"update\", \"data\": [{\"id\": 8799325050, \"side\": \"Buy\", \"size\": 55296}], \"symbol\": \"XBTUSD\", \"timestamp\": \"2018-06-11 02:33:28.982723Z\"}", "XBTUSD"], [1528684410082, "{\"table\": \"orderBookL2\", \"action\": \"update\", \"data\": [{\"id\": 8799319050, \"side\": \"Buy\", \"size\": 592118}], \"symbol\": \"XBTUSD\", \"timestamp\": \"2018-06-11 02:33:30.079991Z\"}", "XBTUSD"], [1528684414468, "{\"table\": \"orderBookL2\", \"action\": \"update\", \"data\": [{\"id\": 8799319000, \"side\": \"Sell\", \"size\": 410866}, {\"id\": 8799320650, \"side\": \"Buy\", \"size\": 326630}], \"symbol\": \"XBTUSD\", \"timestamp\": \"2018-06-11 02:33:34.462674Z\"}", "XBTUSD"], [1528684414914, "{\"table\": \"orderBookL2\", \"action\": \"update\", \"data\": [{\"id\": 8799318450, \"side\": \"Sell\", \"size\": 19772}], \"symbol\": \"XBTUSD\", \"timestamp\": \"2018-06-11 02:33:34.911363Z\"}", "XBTUSD"], [1528684416404, "{\"table\": \"orderBookL2\", \"action\": \"update\", \"data\": [{\"id\": 8799318500, \"side\": \"Sell\", \"size\": 52284}, {\"id\": 8799318600, \"side\": \"Sell\", \"size\": 34352}, {\"id\": 8799319400, \"side\": \"Buy\", \"size\": 164311}, {\"id\": 8799319500, \"side\": \"Buy\", \"size\": 10086}], \"symbol\": \"XBTUSD\", \"timestamp\": \"2018-06-11 02:33:36.401590Z\"}", "XBTUSD"], [1528684418153, "{\"table\": \"orderBookL2\", \"action\": \"update\", \"data\": [{\"id\": 8799319050, \"side\": \"Buy\", \"size\": 968082}], \"symbol\": \"XBTUSD\", \"timestamp\": \"2018-06-11 02:33:38.147985Z\"}", "XBTUSD"], [1528684419054, "{\"table\": \"orderBookL2\", \"action\": \"update\", \"data\": [{\"id\": 8799318300, \"side\": \"Sell\", \"size\": 45621}], \"symbol\": \"XBTUSD\", \"timestamp\": \"2018-06-11 02:33:39.051857Z\"}", "XBTUSD"], [1528684421523, "{\"table\": \"trade\", \"action\": \"insert\", \"data\": [{\"timestamp\": \"2018-06-11T02:33:41.208Z\", \"side\": \"Sell\", \"size\": 5000, \"price\": 6810, \"tickDirection\": \"MinusTick\", \"trdMatchID\": \"660ee27d-e378-53dc-e4dc-0d5573809eae\", \"grossValue\": 73420000, \"homeNotional\": 0.7342, \"foreignNotional\": 5000}], \"symbol\": \"XBTUSD\", \"timestamp\": \"2018-06-11 02:33:41.518239Z\"}", "XBTUSD"], [1528684423945, "{\"table\": \"orderBookL2\", \"action\": \"update\", \"data\": [{\"id\": 8799318150, \"side\": \"Sell\", \"size\": 7913}, {\"id\": 8799320350, \"side\": \"Buy\", \"size\": 6816}], \"symbol\": \"XBTUSD\", \"timestamp\": \"2018-06-11 02:33:43.942662Z\"}", "XBTUSD"], [1528684424692, "{\"table\": \"orderBookL2\", \"action\": \"update\", \"data\": [{\"id\": 8799320950, \"side\": \"Buy\", \"size\": 57070}, {\"id\": 8799321050, \"side\": \"Buy\", \"size\": 50200}], \"symbol\": \"XBTUSD\", \"timestamp\": \"2018-06-11 02:33:44.686668Z\"}", "XBTUSD"], [1528684427367, "{\"table\": \"orderBookL2\", \"action\": \"update\", \"data\": [{\"id\": 8799318900, \"side\": \"Buy\", \"size\": 20000}, {\"id\": 8799318950, \"side\": \"Buy\", \"size\": 20000}], \"symbol\": \"XBTUSD\", \"timestamp\": \"2018-06-11 02:33:47.364176Z\"}", "XBTUSD"], [1528684428912, "{\"table\": \"orderBookL2\", \"action\": \"update\", \"data\": [{\"id\": 8799319250, \"side\": \"Buy\", \"size\": 46250}, {\"id\": 8799319300, \"side\": \"Buy\", \"size\": 57662}], \"symbol\": \"XBTUSD\", \"timestamp\": \"2018-06-11 02:33:48.906861Z\"}", "XBTUSD"], [1528684429130, "{\"table\": \"orderBookL2\", \"action\": \"update\", \"data\": [{\"id\": 8799319000, \"side\": \"Sell\", \"size\": 124368}], \"symbol\": \"XBTUSD\", \"timestamp\": \"2018-06-11 02:33:49.128176Z\"}", "XBTUSD"], [1528684429396, "{\"table\": \"orderBookL2\", \"action\": \"update\", \"data\": [{\"id\": 8799320150, \"side\": \"Buy\", \"size\": 13787}], \"symbol\": \"XBTUSD\", \"timestamp\": \"2018-06-11 02:33:49.391599Z\"}", "XBTUSD"], [1528684429822, "{\"table\": \"orderBookL2\", \"action\": \"update\", \"data\": [{\"id\": 8799319050, \"side\": \"Sell\", \"size\": 428595}], \"symbol\": \"XBTUSD\", \"timestamp\": \"2018-06-11 02:33:49.819450Z\"}", "XBTUSD"], [1528684431489, "{\"table\": \"orderBookL2\", \"action\": \"update\", \"data\": [{\"id\": 8799324200, \"side\": \"Buy\", \"size\": 41966}, {\"id\": 8799324750, \"side\": \"Buy\", \"size\": 2027}], \"symbol\": \"XBTUSD\", \"timestamp\": \"2018-06-11 02:33:51.484862Z\"}", "XBTUSD"], [1528684434018, "{\"table\": \"orderBookL2\", \"action\": \"update\", \"data\": [{\"id\": 8799317400, \"side\": \"Sell\", \"size\": 88028}], \"symbol\": \"XBTUSD\", \"timestamp\": \"2018-06-11 02:33:54.014056Z\"}", "XBTUSD"], [1528684434371, "{\"table\": \"orderBookL2\", \"action\": \"update\", \"data\": [{\"id\": 8799319400, \"side\": \"Buy\", \"size\": 19933}], \"symbol\": \"XBTUSD\", \"timestamp\": \"2018-06-11 02:33:54.369098Z\"}", "XBTUSD"], [1528684434606, "{\"table\": \"orderBookL2\", \"action\": \"update\", \"data\": [{\"id\": 8799318500, \"side\": \"Sell\", \"size\": 25039}], \"symbol\": \"XBTUSD\", \"timestamp\": \"2018-06-11 02:33:54.602268Z\"}", "XBTUSD"], [1528684434867, "{\"table\": \"orderBookL2\", \"action\": \"update\", \"data\": [{\"id\": 8799319300, \"side\": \"Sell\", \"size\": 548114}], \"symbol\": \"XBTUSD\", \"timestamp\": \"2018-06-11 02:33:54.861330Z\"}", "XBTUSD"], [1528684436298, "{\"table\": \"orderBookL2\", \"action\": \"update\", \"data\": [{\"id\": 8799319350, \"side\": \"Sell\", \"size\": 612210}, {\"id\": 8799319400, \"side\": \"Sell\", \"size\": 851763}], \"symbol\": \"XBTUSD\", \"timestamp\": \"2018-06-11 02:33:56.295643Z\"}", "XBTUSD"], [1528684438848, "{\"table\": \"orderBookL2\", \"action\": \"update\", \"data\": [{\"id\": 8799360000, \"side\": \"Buy\", \"size\": 401469}], \"symbol\": \"XBTUSD\", \"timestamp\": \"2018-06-11 02:33:58.845402Z\"}", "XBTUSD"], [1528684439114, "{\"table\": \"orderBookL2\", \"action\": \"update\", \"data\": [{\"id\": 8799319400, \"side\": \"Sell\", \"size\": 1315696}, {\"id\": 8799319450, \"side\": \"Sell\", \"size\": 621523}], \"symbol\": \"XBTUSD\", \"timestamp\": \"2018-06-11 02:33:59.111562Z\"}", "XBTUSD"], [1528684439261, "{\"table\": \"orderBookL2\", \"action\": \"update\", \"data\": [{\"id\": 8799319600, \"side\": \"Sell\", \"size\": 1012046}], \"symbol\": \"XBTUSD\", \"timestamp\": \"2018-06-11 02:33:59.246845Z\"}", "XBTUSD"], [1528684439472, "{\"table\": \"orderBookL2\", \"action\": \"update\", \"data\": [{\"id\": 8799317800, \"side\": \"Sell\", \"size\": 2081856}], \"symbol\": \"XBTUSD\", \"timestamp\": \"2018-06-11 02:33:59.466508Z\"}", "XBTUSD"], [1528684439897, "{\"table\": \"orderBookL2\", \"action\": \"delete\", \"data\": [{\"id\": 8799370500, \"side\": \"Buy\"}], \"symbol\": \"XBTUSD\", \"timestamp\": \"2018-06-11 02:33:59.893877Z\"}", "XBTUSD"], [1528684442453, "{\"table\": \"orderBookL2\", \"action\": \"update\", \"data\": [{\"id\": 8799307100, \"side\": \"Sell\", \"size\": 175708}], \"symbol\": \"XBTUSD\", \"timestamp\": \"2018-06-11 02:34:02.450148Z\"}", "XBTUSD"], [1528684444699, "{\"table\": \"orderBookL2\", \"action\": \"update\", \"data\": [{\"id\": 8799319950, \"side\": \"Sell\", \"size\": 1269877}], \"symbol\": \"XBTUSD\", \"timestamp\": \"2018-06-11 02:34:04.694187Z\"}", "XBTUSD"], [1528684445000, "{\"table\": \"orderBookL2\", \"action\": \"update\", \"data\": [{\"id\": 8799319400, \"side\": \"Sell\", \"size\": 151419}], \"symbol\": \"XBTUSD\", \"timestamp\": \"2018-06-11 02:34:04.997413Z\"}", "XBTUSD"], [1528684445310, "{\"table\": \"orderBookL2\", \"action\": \"update\", \"data\": [{\"id\": 8799322900, \"side\": \"Buy\", \"size\": 16619}], \"symbol\": \"XBTUSD\", \"timestamp\": \"2018-06-11 02:34:05.305389Z\"}", "XBTUSD"], [1528684446418, "{\"table\": \"orderBookL2\", \"action\": \"update\", \"data\": [{\"id\": 8799321200, \"side\": \"Buy\", \"size\": 121036}, {\"id\": 8799321550, \"side\": \"Buy\", \"size\": 270083}], \"symbol\": \"XBTUSD\", \"timestamp\": \"2018-06-11 02:34:06.411086Z\"}", "XBTUSD"], [1528684448977, "{\"table\": \"orderBookL2\", \"action\": \"update\", \"data\": [{\"id\": 8799320000, \"side\": \"Buy\", \"size\": 71054}], \"symbol\": \"XBTUSD\", \"timestamp\": \"2018-06-11 02:34:08.972091Z\"}", "XBTUSD"], [1528684449214, "{\"table\": \"orderBookL2\", \"action\": \"update\", \"data\": [{\"id\": 8799319650, \"side\": \"Sell\", \"size\": 220650}], \"symbol\": \"XBTUSD\", \"timestamp\": \"2018-06-11 02:34:09.208074Z\"}", "XBTUSD"], [1528684449592, "{\"table\": \"orderBookL2\", \"action\": \"update\", \"data\": [{\"id\": 8799317200, \"side\": \"Sell\", \"size\": 76024}, {\"id\": 8799318700, \"side\": \"Sell\", \"size\": 1534}], \"symbol\": \"XBTUSD\", \"timestamp\": \"2018-06-11 02:34:09.587991Z\"}", "XBTUSD"], [1528684451970, "{\"table\": \"orderBookL2\", \"action\": \"update\", \"data\": [{\"id\": 8799320050, \"side\": \"Buy\", \"size\": 8220}], \"symbol\": \"XBTUSD\", \"timestamp\": \"2018-06-11 02:34:11.967585Z\"}", "XBTUSD"], [1528684453985, "{\"table\": \"orderBookL2\", \"action\": \"update\", \"data\": [{\"id\": 8799319950, \"side\": \"Sell\", \"size\": 1567557}], \"symbol\": \"XBTUSD\", \"timestamp\": \"2018-06-11 02:34:13.982363Z\"}", "XBTUSD"], [1528684456415, "{\"table\": \"orderBookL2\", \"action\": \"update\", \"data\": [{\"id\": 8799318500, \"side\": \"Sell\", \"size\": 24934}], \"symbol\": \"XBTUSD\", \"timestamp\": \"2018-06-11 02:34:16.412183Z\"}", "XBTUSD"], [1528684459323, "{\"table\": \"orderBookL2\", \"action\": \"update\", \"data\": [{\"id\": 8799319950, \"side\": \"Sell\", \"size\": 1586614}, {\"id\": 8799320000, \"side\": \"Sell\", \"size\": 245884}], \"symbol\": \"XBTUSD\", \"timestamp\": \"2018-06-11 02:34:19.320118Z\"}", "XBTUSD"], [1528684459573, "{\"table\": \"orderBookL2\", \"action\": \"update\", \"data\": [{\"id\": 8799320500, \"side\": \"Buy\", \"size\": 64915}, {\"id\": 8799320600, \"side\": \"Buy\", \"size\": 66012}], \"symbol\": \"XBTUSD\", \"timestamp\": \"2018-06-11 02:34:19.568879Z\"}", "XBTUSD"], [1528684459859, "{\"table\": \"orderBookL2\", \"action\": \"update\", \"data\": [{\"id\": 8799319950, \"side\": \"Sell\", \"size\": 703764}, {\"id\": 8799322250, \"side\": \"Buy\", \"size\": 74580}], \"symbol\": \"XBTUSD\", \"timestamp\": \"2018-06-11 02:34:19.857140Z\"}", "XBTUSD"], [1528684462639, "{\"table\": \"orderBookL2\", \"action\": \"update\", \"data\": [{\"id\": 8799320850, \"side\": \"Buy\", \"size\": 60600}], \"symbol\": \"XBTUSD\", \"timestamp\": \"2018-06-11 02:34:22.633942Z\"}", "XBTUSD"], [1528684463957, "{\"table\": \"orderBookL2\", \"action\": \"update\", \"data\": [{\"id\": 8799319800, \"side\": \"Sell\", \"size\": 140}], \"symbol\": \"XBTUSD\", \"timestamp\": \"2018-06-11 02:34:23.954936Z\"}", "XBTUSD"], [1528684464146, "{\"table\": \"orderBookL2\", \"action\": \"update\", \"data\": [{\"id\": 8799320050, \"side\": \"Sell\", \"size\": 1185243}, {\"id\": 8799320150, \"side\": \"Sell\", \"size\": 921533}], \"symbol\": \"XBTUSD\", \"timestamp\": \"2018-06-11 02:34:24.141900Z\"}", "XBTUSD"], [1528684464305, "{\"table\": \"orderBookL2\", \"action\": \"delete\", \"data\": [{\"id\": 8799370300, \"side\": \"Buy\"}], \"symbol\": \"XBTUSD\", \"timestamp\": \"2018-06-11 02:34:24.302894Z\"}", "XBTUSD"], [1528684464579, "{\"table\": \"orderBookL2\", \"action\": \"update\", \"data\": [{\"id\": 8799320150, \"side\": \"Sell\", \"size\": 518322}, {\"id\": 8799320200, \"side\": \"Sell\", \"size\": 1118457}], \"symbol\": \"XBTUSD\", \"timestamp\": \"2018-06-11 02:34:24.574675Z\"}", "XBTUSD"], [1528684465857, "{\"table\": \"orderBookL2\", \"action\": \"update\", \"data\": [{\"id\": 8799321500, \"side\": \"Buy\", \"size\": 9290}], \"symbol\": \"XBTUSD\", \"timestamp\": \"2018-06-11 02:34:25.852458Z\"}", "XBTUSD"], [1528684468793, "{\"table\": \"orderBookL2\", \"action\": \"update\", \"data\": [{\"id\": 8799317850, \"side\": \"Sell\", \"size\": 332172}, {\"id\": 8799319700, \"side\": \"Sell\", \"size\": 8600}], \"symbol\": \"XBTUSD\", \"timestamp\": \"2018-06-11 02:34:28.789184Z\"}", "XBTUSD"], [1528684469023, "{\"table\": \"orderBookL2\", \"action\": \"update\", \"data\": [{\"id\": 8799318000, \"side\": \"Sell\", \"size\": 910694}], \"symbol\": \"XBTUSD\", \"timestamp\": \"2018-06-11 02:34:29.016670Z\"}", "XBTUSD"], [1528684471930, "{\"table\": \"orderBookL2\", \"action\": \"update\", \"data\": [{\"id\": 8799319550, \"side\": \"Sell\", \"size\": 8275}], \"symbol\": \"XBTUSD\", \"timestamp\": \"2018-06-11 02:34:31.927052Z\"}", "XBTUSD"], [1528684474805, "{\"table\": \"quote\", \"action\": \"insert\", \"data\": [{\"timestamp\": \"2018-06-11T02:34:31.701Z\", \"bidSize\": 392578, \"bidPrice\": 6797.5, \"askPrice\": 6798, \"askSize\": 1503829}, {\"timestamp\": \"2018-06-11T02:34:31.704Z\", \"bidSize\": 392557, \"bidPrice\": 6797.5, \"askPrice\": 6798, \"askSize\": 1503829}, {\"timestamp\": \"2018-06-11T02:34:31.741Z\", \"bidSize\": 392557, \"bidPrice\": 6797.5, \"askPrice\": 6798, \"askSize\": 1503729}, {\"timestamp\": \"2018-06-11T02:34:31.752Z\", \"bidSize\": 392557, \"bidPrice\": 6797.5, \"askPrice\": 6798, \"askSize\": 1504129}, {\"timestamp\": \"2018-06-11T02:34:31.776Z\", \"bidSize\": 322557, \"bidPrice\": 6797.5, \"askPrice\": 6798, \"askSize\": 1504129}, {\"timestamp\": \"2018-06-11T02:34:31.807Z\", \"bidSize\": 322557, \"bidPrice\": 6797.5, \"askPrice\": 6798, \"askSize\": 1614129}, {\"timestamp\": \"2018-06-11T02:34:31.814Z\", \"bidSize\": 322557, \"bidPrice\": 6797.5, \"askPrice\": 6798, \"askSize\": 1614229}, {\"timestamp\": \"2018-06-11T02:34:31.867Z\", \"bidSize\": 322557, \"bidPrice\": 6797.5, \"askPrice\": 6798, \"askSize\": 1580159}, {\"timestamp\": \"2018-06-11T02:34:31.986Z\", \"bidSize\": 322557, \"bidPrice\": 6797.5, \"askPrice\": 6798, \"askSize\": 1590159}, {\"timestamp\": \"2018-06-11T02:34:32.298Z\", \"bidSize\": 356627, \"bidPrice\": 6797.5, \"askPrice\": 6798, \"askSize\": 1590159}, {\"timestamp\": \"2018-06-11T02:34:32.346Z\", \"bidSize\": 355627, \"bidPrice\": 6797.5, \"askPrice\": 6798, \"askSize\": 1590159}, {\"timestamp\": \"2018-06-11T02:34:32.546Z\", \"bidSize\": 355628, \"bidPrice\": 6797.5, \"askPrice\": 6798, \"askSize\": 1590159}, {\"timestamp\": \"2018-06-11T02:34:32.766Z\", \"bidSize\": 355628, \"bidPrice\": 6797.5, \"askPrice\": 6798, \"askSize\": 1589759}, {\"timestamp\": \"2018-06-11T02:34:32.787Z\", \"bidSize\": 354628, \"bidPrice\": 6797.5, \"askPrice\": 6798, \"askSize\": 1589759}, {\"timestamp\": \"2018-06-11T02:34:32.797Z\", \"bidSize\": 354588, \"bidPrice\": 6797.5, \"askPrice\": 6798, \"askSize\": 1589759}, {\"timestamp\": \"2018-06-11T02:34:32.868Z\", \"bidSize\": 354588, \"bidPrice\": 6797.5, \"askPrice\": 6798, \"askSize\": 1584759}], \"symbol\": \"XBTUSD\", \"timestamp\": \"2018-06-11 02:34:34.801142Z\"}", "XBTUSD"], [1528684476803, "{\"table\": \"orderBookL2\", \"action\": \"update\", \"data\": [{\"id\": 8799320200, \"side\": \"Sell\", \"size\": 1538836}], \"symbol\": \"XBTUSD\", \"timestamp\": \"2018-06-11 02:34:36.797689Z\"}", "XBTUSD"], [1528684479035, "{\"table\": \"orderBookL2\", \"action\": \"update\", \"data\": [{\"id\": 8799320250, \"side\": \"Buy\", \"size\": 420737}], \"symbol\": \"XBTUSD\", \"timestamp\": \"2018-06-11 02:34:39.031691Z\"}", "XBTUSD"], [1528684481430, "{\"table\": \"orderBookL2\", \"action\": \"update\", \"data\": [{\"id\": 8799319800, \"side\": \"Sell\", \"size\": 17140}, {\"id\": 8799319850, \"side\": \"Sell\", \"size\": 11405}], \"symbol\": \"XBTUSD\", \"timestamp\": \"2018-06-11 02:34:41.427387Z\"}", "XBTUSD"], [1528684483932, "{\"table\": \"orderBookL2\", \"action\": \"update\", \"data\": [{\"id\": 8799320500, \"side\": \"Buy\", \"size\": 89751}], \"symbol\": \"XBTUSD\", \"timestamp\": \"2018-06-11 02:34:43.929351Z\"}", "XBTUSD"], [1528684487611, "{\"table\": \"orderBookL2\", \"action\": \"update\", \"data\": [{\"id\": 8799320250, \"side\": \"Buy\", \"size\": 116495}], \"symbol\": \"XBTUSD\", \"timestamp\": \"2018-06-11 02:34:47.606796Z\"}", "XBTUSD"], [1528684489425, "{\"table\": \"quote\", \"action\": \"insert\", \"data\": [{\"timestamp\": \"2018-06-11T02:34:48.309Z\", \"bidSize\": 16497, \"bidPrice\": 6797.5, \"askPrice\": 6798, \"askSize\": 1705819}, {\"timestamp\": \"2018-06-11T02:34:48.340Z\", \"bidSize\": 15497, \"bidPrice\": 6797.5, \"askPrice\": 6798, \"askSize\": 1705819}, {\"timestamp\": \"2018-06-11T02:34:48.373Z\", \"bidSize\": 10497, \"bidPrice\": 6797.5, \"askPrice\": 6798, \"askSize\": 1705819}, {\"timestamp\": \"2018-06-11T02:34:48.944Z\", \"bidSize\": 7097, \"bidPrice\": 6797.5, \"askPrice\": 6798, \"askSize\": 1705819}, {\"timestamp\": \"2018-06-11T02:34:49.063Z\", \"bidSize\": 7097, \"bidPrice\": 6797.5, \"askPrice\": 6798, \"askSize\": 1705820}], \"symbol\": \"XBTUSD\", \"timestamp\": \"2018-06-11 02:34:49.419535Z\"}", "XBTUSD"], [1528684491534, "{\"table\": \"orderBookL2\", \"action\": \"update\", \"data\": [{\"id\": 8799320250, \"side\": \"Sell\", \"size\": 507211}], \"symbol\": \"XBTUSD\", \"timestamp\": \"2018-06-11 02:34:51.531116Z\"}", "XBTUSD"], [1528684493845, "{\"table\": \"orderBookL2\", \"action\": \"update\", \"data\": [{\"id\": 8799320300, \"side\": \"Sell\", \"size\": 541355}], \"symbol\": \"XBTUSD\", \"timestamp\": \"2018-06-11 02:34:53.842932Z\"}", "XBTUSD"], [1528684494039, "{\"table\": \"orderBookL2\", \"action\": \"update\", \"data\": [{\"id\": 8799320250, \"side\": \"Sell\", \"size\": 383900}], \"symbol\": \"XBTUSD\", \"timestamp\": \"2018-06-11 02:34:54.037068Z\"}", "XBTUSD"], [1528684494370, "{\"table\": \"orderBookL2\", \"action\": \"insert\", \"data\": [{\"id\": 8799932100, \"side\": \"Buy\", \"size\": 3, \"price\": 679}], \"symbol\": \"XBTUSD\", \"timestamp\": \"2018-06-11 02:34:54.365440Z\"}", "XBTUSD"], [1528684494675, "{\"table\": \"orderBookL2\", \"action\": \"update\", \"data\": [{\"id\": 8799320350, \"side\": \"Sell\", \"size\": 639168}], \"symbol\": \"XBTUSD\", \"timestamp\": \"2018-06-11 02:34:54.672290Z\"}", "XBTUSD"], [1528684495178, "{\"table\": \"orderBookL2\", \"action\": \"update\", \"data\": [{\"id\": 8799320300, \"side\": \"Sell\", \"size\": 259762}, {\"id\": 8799320350, \"side\": \"Sell\", \"size\": 437744}, {\"id\": 8799320400, \"side\": \"Sell\", \"size\": 282698}, {\"id\": 8799320450, \"side\": \"Sell\", \"size\": 83125}, {\"id\": 8799320500, \"side\": \"Sell\", \"size\": 33444}], \"symbol\": \"XBTUSD\", \"timestamp\": \"2018-06-11 02:34:55.175376Z\"}", "XBTUSD"], [1528684498489, "{\"table\": \"orderBookL2\", \"action\": \"update\", \"data\": [{\"id\": 8799320350, \"side\": \"Sell\", \"size\": 330837}], \"symbol\": \"XBTUSD\", \"timestamp\": \"2018-06-11 02:34:58.485716Z\"}", "XBTUSD"], [1528684498952, "{\"table\": \"orderBookL2\", \"action\": \"delete\", \"data\": [{\"id\": 8799932000, \"side\": \"Buy\"}], \"symbol\": \"XBTUSD\", \"timestamp\": \"2018-06-11 02:34:58.947353Z\"}", "XBTUSD"], [1528684499218, "{\"table\": \"orderBookL2\", \"action\": \"update\", \"data\": [{\"id\": 8799320900, \"side\": \"Buy\", \"size\": 171012}], \"symbol\": \"XBTUSD\", \"timestamp\": \"2018-06-11 02:34:59.215266Z\"}", "XBTUSD"], [1528684499971, "{\"table\": \"orderBookL2\", \"action\": \"update\", \"data\": [{\"id\": 8799320800, \"side\": \"Sell\", \"size\": 1244151}], \"symbol\": \"XBTUSD\", \"timestamp\": \"2018-06-11 02:34:59.968269Z\"}", "XBTUSD"], [1528684504701, "{\"table\": \"quote\", \"action\": \"insert\", \"data\": [{\"timestamp\": \"2018-06-11T02:35:01.490Z\", \"bidSize\": 163316, \"bidPrice\": 6791.5, \"askPrice\": 6792, \"askSize\": 1354152}], \"symbol\": \"XBTUSD\", \"timestamp\": \"2018-06-11 02:35:04.697870Z\"}", "XBTUSD"], [1528684505012, "{\"table\": \"orderBookL2\", \"action\": \"update\", \"data\": [{\"id\": 8799320700, \"side\": \"Sell\", \"size\": 29506}], \"symbol\": \"XBTUSD\", \"timestamp\": \"2018-06-11 02:35:05.008859Z\"}", "XBTUSD"], [1528684506758, "{\"table\": \"orderBookL2\", \"action\": \"update\", \"data\": [{\"id\": 8799312800, \"side\": \"Sell\", \"size\": 59836}, {\"id\": 8799312900, \"side\": \"Sell\", \"size\": 33802}], \"symbol\": \"XBTUSD\", \"timestamp\": \"2018-06-11 02:35:06.754162Z\"}", "XBTUSD"], [1528684509285, "{\"table\": \"orderBookL2\", \"action\": \"update\", \"data\": [{\"id\": 8799319900, \"side\": \"Sell\", \"size\": 29}], \"symbol\": \"XBTUSD\", \"timestamp\": \"2018-06-11 02:35:09.282319Z\"}", "XBTUSD"], [1528684509642, "{\"table\": \"orderBookL2\", \"action\": \"update\", \"data\": [{\"id\": 8799320350, \"side\": \"Sell\", \"size\": 113266}, {\"id\": 8799320800, \"side\": \"Sell\", \"size\": 801748}], \"symbol\": \"XBTUSD\", \"timestamp\": \"2018-06-11 02:35:09.640067Z\"}", "XBTUSD"], [1528684512419, "{\"table\": \"orderBookL2\", \"action\": \"update\", \"data\": [{\"id\": 8799320250, \"side\": \"Sell\", \"size\": 49439}, {\"id\": 8799320400, \"side\": \"Sell\", \"size\": 150759}], \"symbol\": \"XBTUSD\", \"timestamp\": \"2018-06-11 02:35:12.417066Z\"}", "XBTUSD"], [1528684514196, "{\"table\": \"orderBookL2\", \"action\": \"update\", \"data\": [{\"id\": 8799320850, \"side\": \"Sell\", \"size\": 1765063}, {\"id\": 8799323300, \"side\": \"Buy\", \"size\": 371804}], \"symbol\": \"XBTUSD\", \"timestamp\": \"2018-06-11 02:35:14.193446Z\"}", "XBTUSD"], [1528684514530, "{\"table\": \"orderBookL2\", \"action\": \"update\", \"data\": [{\"id\": 8799320850, \"side\": \"Sell\", \"size\": 1198766}, {\"id\": 8799320900, \"side\": \"Sell\", \"size\": 954559}], \"symbol\": \"XBTUSD\", \"timestamp\": \"2018-06-11 02:35:14.527508Z\"}", "XBTUSD"], [1528684516336, "{\"table\": \"orderBookL2\", \"action\": \"update\", \"data\": [{\"id\": 8799320700, \"side\": \"Sell\", \"size\": 36381}, {\"id\": 8799320750, \"side\": \"Sell\", \"size\": 8010}, {\"id\": 8799321050, \"side\": \"Buy\", \"size\": 6200}, {\"id\": 8799321100, \"side\": \"Buy\", \"size\": 30240}], \"symbol\": \"XBTUSD\", \"timestamp\": \"2018-06-11 02:35:16.332080Z\"}", "XBTUSD"], [1528684519064, "{\"table\": \"orderBookL2\", \"action\": \"insert\", \"data\": [{\"id\": 8793201900, \"side\": \"Sell\", \"size\": 204, \"price\": 67981}], \"symbol\": \"XBTUSD\", \"timestamp\": \"2018-06-11 02:35:19.060656Z\"}", "XBTUSD"], [1528684519708, "{\"table\": \"orderBookL2\", \"action\": \"update\", \"data\": [{\"id\": 8799320850, \"side\": \"Sell\", \"size\": 497852}], \"symbol\": \"XBTUSD\", \"timestamp\": \"2018-06-11 02:35:19.705381Z\"}", "XBTUSD"], [1528684523845, "{\"table\": \"orderBookL2\", \"action\": \"update\", \"data\": [{\"id\": 8799320950, \"side\": \"Sell\", \"size\": 327627}], \"symbol\": \"XBTUSD\", \"timestamp\": \"2018-06-11 02:35:23.842295Z\"}", "XBTUSD"], [1528684524059, "{\"table\": \"orderBookL2\", \"action\": \"update\", \"data\": [{\"id\": 8799321000, \"side\": \"Buy\", \"size\": 362650}], \"symbol\": \"XBTUSD\", \"timestamp\": \"2018-06-11 02:35:24.056828Z\"}", "XBTUSD"], [1528684524528, "{\"table\": \"orderBookL2\", \"action\": \"update\", \"data\": [{\"id\": 8799321000, \"side\": \"Buy\", \"size\": 159987}], \"symbol\": \"XBTUSD\", \"timestamp\": \"2018-06-11 02:35:24.524475Z\"}", "XBTUSD"], [1528684528722, "{\"table\": \"orderBookL2\", \"action\": \"update\", \"data\": [{\"id\": 8799320500, \"side\": \"Sell\", \"size\": 35256}], \"symbol\": \"XBTUSD\", \"timestamp\": \"2018-06-11 02:35:28.712338Z\"}", "XBTUSD"], [1528684529629, "{\"table\": \"orderBookL2\", \"action\": \"update\", \"data\": [{\"id\": 8799320950, \"side\": \"Sell\", \"size\": 1691723}], \"symbol\": \"XBTUSD\", \"timestamp\": \"2018-06-11 02:35:29.626293Z\"}", "XBTUSD"], [1528684534553, "{\"table\": \"orderBookL2\", \"action\": \"insert\", \"data\": [{\"id\": 8799269900, \"side\": \"Sell\", \"size\": 355378, \"price\": 7301}, {\"id\": 8799354050, \"side\": \"Buy\", \"size\": 425197, \"price\": 6459.5}], \"symbol\": \"XBTUSD\", \"timestamp\": \"2018-06-11 02:35:34.550795Z\"}", "XBTUSD"], [1528684536993, "{\"table\": \"orderBookL2\", \"action\": \"insert\", \"data\": [{\"id\": 8799932100, \"side\": \"Buy\", \"size\": 3, \"price\": 679}], \"symbol\": \"XBTUSD\", \"timestamp\": \"2018-06-11 02:35:36.989492Z\"}", "XBTUSD"], [1528684537860, "{\"table\": \"orderBookL2\", \"action\": \"update\", \"data\": [{\"id\": 8799346400, \"side\": \"Buy\", \"size\": 19069}], \"symbol\": \"XBTUSD\", \"timestamp\": \"2018-06-11 02:35:37.857855Z\"}", "XBTUSD"], [1528684538480, "{\"table\": \"orderBookL2\", \"action\": \"update\", \"data\": [{\"id\": 8799321400, \"side\": \"Buy\", \"size\": 14521}, {\"id\": 8799323400, \"side\": \"Buy\", \"size\": 338456}], \"symbol\": \"XBTUSD\", \"timestamp\": \"2018-06-11 02:35:38.471461Z\"}", "XBTUSD"], [1528684539709, "{\"table\": \"orderBookL2\", \"action\": \"update\", \"data\": [{\"id\": 8799318000, \"side\": \"Sell\", \"size\": 928913}], \"symbol\": \"XBTUSD\", \"timestamp\": \"2018-06-11 02:35:39.702258Z\"}", "XBTUSD"], [1528684543949, "{\"table\": \"orderBookL2\", \"action\": \"update\", \"data\": [{\"id\": 8799347400, \"side\": \"Buy\", \"size\": 14520}], \"symbol\": \"XBTUSD\", \"timestamp\": \"2018-06-11 02:35:43.945958Z\"}", "XBTUSD"], [1528684544882, "{\"table\": \"orderBookL2\", \"action\": \"insert\", \"data\": [{\"id\": 8799272150, \"side\": \"Sell\", \"size\": 20213, \"price\": 7278.5}], \"symbol\": \"XBTUSD\", \"timestamp\": \"2018-06-11 02:35:44.878203Z\"}", "XBTUSD"], [1528684549092, "{\"table\": \"orderBookL2\", \"action\": \"update\", \"data\": [{\"id\": 8799323350, \"side\": \"Buy\", \"size\": 5500}], \"symbol\": \"XBTUSD\", \"timestamp\": \"2018-06-11 02:35:49.087335Z\"}", "XBTUSD"], [1528684551354, "{\"table\": \"orderBookL2\", \"action\": \"update\", \"data\": [{\"id\": 8799321000, \"side\": \"Sell\", \"size\": 1629820}], \"symbol\": \"XBTUSD\", \"timestamp\": \"2018-06-11 02:35:51.351799Z\"}", "XBTUSD"], [1528684553855, "{\"table\": \"orderBookL2\", \"action\": \"delete\", \"data\": [{\"id\": 8798909800, \"side\": \"Sell\"}], \"symbol\": \"XBTUSD\", \"timestamp\": \"2018-06-11 02:35:53.852564Z\"}", "XBTUSD"], [1528684554146, "{\"table\": \"trade\", \"action\": \"insert\", \"data\": [{\"timestamp\": \"2018-06-11T02:35:53.742Z\", \"side\": \"Sell\", \"size\": 5007, \"price\": 6789.5, \"tickDirection\": \"MinusTick\", \"trdMatchID\": \"e82f3caa-c496-63ab-68c2-a25be8592016\", \"grossValue\": 73748103, \"homeNotional\": 0.73748103, \"foreignNotional\": 5007}], \"symbol\": \"XBTUSD\", \"timestamp\": \"2018-06-11 02:35:54.141797Z\"}", "XBTUSD"], [1528684554874, "{\"table\": \"orderBookL2\", \"action\": \"update\", \"data\": [{\"id\": 8799321250, \"side\": \"Buy\", \"size\": 15040}, {\"id\": 8799321300, \"side\": \"Buy\", \"size\": 186512}], \"symbol\": \"XBTUSD\", \"timestamp\": \"2018-06-11 02:35:54.871307Z\"}", "XBTUSD"], [1528684558624, "{\"table\": \"orderBookL2\", \"action\": \"update\", \"data\": [{\"id\": 8799321000, \"side\": \"Buy\", \"size\": 1379778}, {\"id\": 8799321050, \"side\": \"Buy\", \"size\": 602907}], \"symbol\": \"XBTUSD\", \"timestamp\": \"2018-06-11 02:35:58.620961Z\"}", "XBTUSD"], [1528684558902, "{\"table\": \"orderBookL2\", \"action\": \"update\", \"data\": [{\"id\": 8799318950, \"side\": \"Sell\", \"size\": 330}], \"symbol\": \"XBTUSD\", \"timestamp\": \"2018-06-11 02:35:58.899664Z\"}", "XBTUSD"], [1528684562383, "{\"table\": \"orderBookL2\", \"action\": \"update\", \"data\": [{\"id\": 8799321750, \"side\": \"Buy\", \"size\": 64507}], \"symbol\": \"XBTUSD\", \"timestamp\": \"2018-06-11 02:36:02.378443Z\"}", "XBTUSD"], [1528684565050, "{\"table\": \"orderBookL2\", \"action\": \"update\", \"data\": [{\"id\": 8799318400, \"side\": \"Sell\", \"size\": 197669}, {\"id\": 8799320100, \"side\": \"Sell\", \"size\": 1050}, {\"id\": 8799321600, \"side\": \"Buy\", \"size\": 25570}, {\"id\": 8799324800, \"side\": \"Buy\", \"size\": 17551}], \"symbol\": \"XBTUSD\", \"timestamp\": \"2018-06-11 02:36:05.046947Z\"}", "XBTUSD"], [1528684565246, "{\"table\": \"orderBookL2\", \"action\": \"update\", \"data\": [{\"id\": 8799320750, \"side\": \"Sell\", \"size\": 12310}, {\"id\": 8799320800, \"side\": \"Sell\", \"size\": 18665}], \"symbol\": \"XBTUSD\", \"timestamp\": \"2018-06-11 02:36:05.244164Z\"}", "XBTUSD"], [1528684567290, "{\"table\": \"orderBookL2\", \"action\": \"update\", \"data\": [{\"id\": 8799321000, \"side\": \"Buy\", \"size\": 1322041}], \"symbol\": \"XBTUSD\", \"timestamp\": \"2018-06-11 02:36:07.286093Z\"}", "XBTUSD"], [1528684569116, "{\"table\": \"orderBookL2\", \"action\": \"update\", \"data\": [{\"id\": 8799320500, \"side\": \"Sell\", \"size\": 75258}, {\"id\": 8799320550, \"side\": \"Sell\", \"size\": 200}, {\"id\": 8799321000, \"side\": \"Buy\", \"size\": 1345421}, {\"id\": 8799321050, \"side\": \"Buy\", \"size\": 689466}], \"symbol\": \"XBTUSD\", \"timestamp\": \"2018-06-11 02:36:09.113683Z\"}", "XBTUSD"], [1528684569534, "{\"table\": \"orderBookL2\", \"action\": \"update\", \"data\": [{\"id\": 8799320500, \"side\": \"Sell\", \"size\": 95258}, {\"id\": 8799321000, \"side\": \"Buy\", \"size\": 1306036}], \"symbol\": \"XBTUSD\", \"timestamp\": \"2018-06-11 02:36:09.528371Z\"}", "XBTUSD"], [1528684573777, "{\"table\": \"orderBookL2\", \"action\": \"update\", \"data\": [{\"id\": 8799320300, \"side\": \"Sell\", \"size\": 25950}], \"symbol\": \"XBTUSD\", \"timestamp\": \"2018-06-11 02:36:13.774237Z\"}", "XBTUSD"], [1528684574056, "{\"table\": \"orderBookL2\", \"action\": \"update\", \"data\": [{\"id\": 8799320500, \"side\": \"Sell\", \"size\": 93158}, {\"id\": 8799322000, \"side\": \"Buy\", \"size\": 514775}], \"symbol\": \"XBTUSD\", \"timestamp\": \"2018-06-11 02:36:14.053753Z\"}", "XBTUSD"], [1528684577619, "{\"table\": \"orderBookL2\", \"action\": \"delete\", \"data\": [{\"id\": 8799932100, \"side\": \"Buy\"}], \"symbol\": \"XBTUSD\", \"timestamp\": \"2018-06-11 02:36:17.614932Z\"}", "XBTUSD"], [1528684579265, "{\"table\": \"orderBookL2\", \"action\": \"update\", \"data\": [{\"id\": 8799320950, \"side\": \"Buy\", \"size\": 1167190}], \"symbol\": \"XBTUSD\", \"timestamp\": \"2018-06-11 02:36:19.262737Z\"}", "XBTUSD"], [1528684579598, "{\"table\": \"orderBookL2\", \"action\": \"update\", \"data\": [{\"id\": 8799321000, \"side\": \"Buy\", \"size\": 694706}], \"symbol\": \"XBTUSD\", \"timestamp\": \"2018-06-11 02:36:19.595670Z\"}", "XBTUSD"], [1528684581455, "{\"table\": \"orderBookL2\", \"action\": \"update\", \"data\": [{\"id\": 8799320250, \"side\": \"Sell\", \"size\": 2054}], \"symbol\": \"XBTUSD\", \"timestamp\": \"2018-06-11 02:36:21.451451Z\"}", "XBTUSD"]]}]}