{"series": [{"name": "data", "columns": ["time", "data", "symbol"], "values": [[1528681093838, "{\"table\": \"orderBookL2\", \"action\": \"delete\", \"data\": [{\"id\": 8798865000, \"side\": \"Sell\"}], \"symbol\": \"XBTUSD\", \"timestamp\": \"2018-06-11 01:38:13.834795Z\"}", "XBTUSD"], [1528681094066, "{\"table\": \"orderBookL2\", \"action\": \"update\", \"data\": [{\"id\": 8799327300, \"side\": \"Buy\", \"size\": 605146}], \"symbol\": \"XBTUSD\", \"timestamp\": \"2018-06-11 01:38:14.060906Z\"}", "XBTUSD"], [1528681094242, "{\"table\": \"orderBookL2\", \"action\": \"update\", \"data\": [{\"id\": 8799327700, \"side\": \"Buy\", \"size\": 46251}, {\"id\": 8799328450, \"side\": \"Buy\", \"size\": 2623}], \"symbol\": \"XBTUSD\", \"timestamp\": \"2018-06-11 01:38:14.238462Z\"}", "XBTUSD"], [1528681094679, "{\"table\": \"orderBookL2\", \"action\": \"update\", \"data\": [{\"id\": 8799327150, \"side\": \"Buy\", \"size\": 813372}, {\"id\": 8799327200, \"side\": \"Buy\", \"size\": 664337}], \"symbol\": \"XBTUSD\", \"timestamp\": \"2018-06-11 01:38:14.676224Z\"}", "XBTUSD"], [1528681095510, "{\"table\": \"orderBookL2\", \"action\": \"update\", \"data\": [{\"id\": 8799326800, \"side\": \"Sell\", \"size\": 27077}], \"symbol\": \"XBTUSD\", \"timestamp\": \"2018-06-11 01:38:15.506530Z\"}", "XBTUSD"], [1528681096611, "{\"table\": \"orderBookL2\", \"action\": \"update\", \"data\": [{\"id\": 8799326250, \"side\": \"Sell\", \"size\": 103843}, {\"id\": 8799327800, \"side\": \"Buy\", \"size\": 244742}], \"symbol\": \"XBTUSD\", \"timestamp\": \"2018-06-11 01:38:16.606374Z\"}", "XBTUSD"], [1528681097678, "{\"table\": \"orderBookL2\", \"action\": \"update\", \"data\": [{\"id\": 8799327100, \"side\": \"Buy\", \"size\": 305442}], \"symbol\": \"XBTUSD\", \"timestamp\": \"2018-06-11 01:38:17.674332Z\"}", "XBTUSD"], [1528681098647, "{\"table\": \"orderBookL2\", \"action\": \"update\", \"data\": [{\"id\": 8799326550, \"side\": \"Sell\", \"size\": 9472}], \"symbol\": \"XBTUSD\", \"timestamp\": \"2018-06-11 01:38:18.643257Z\"}", "XBTUSD"], [1528681099329, "{\"table\": \"orderBookL2\", \"action\": \"update\", \"data\": [{\"id\": 8799327100, \"side\": \"Buy\", \"size\": 677526}], \"symbol\": \"XBTUSD\", \"timestamp\": \"2018-06-11 01:38:19.325721Z\"}", "XBTUSD"], [1528681101378, "{\"table\": \"orderBookL2\", \"action\": \"update\", \"data\": [{\"id\": 8799327000, \"side\": \"Sell\", \"size\": 264559}], \"symbol\": \"XBTUSD\", \"timestamp\": \"2018-06-11 01:38:21.375118Z\"}", "XBTUSD"], [1528681103900, "{\"table\": \"orderBookL2\", \"action\": \"update\", \"data\": [{\"id\": 8799328150, \"side\": \"Buy\", \"size\": 53370}, {\"id\": 8799328200, \"side\": \"Buy\", \"size\": 47382}], \"symbol\": \"XBTUSD\", \"timestamp\": \"2018-06-11 01:38:23.897798Z\"}", "XBTUSD"], [1528681105177, "{\"table\": \"orderBookL2\", \"action\": \"update\", \"data\": [{\"id\": 8799326950, \"side\": \"Sell\", \"size\": 1052}], \"symbol\": \"XBTUSD\", \"timestamp\": \"2018-06-11 01:38:25.170886Z\"}", "XBTUSD"], [1528681107678, "{\"table\": \"orderBookL2\", \"action\": \"update\", \"data\": [{\"id\": 8799326550, \"side\": \"Sell\", \"size\": 3195}, {\"id\": 8799328100, \"side\": \"Buy\", \"size\": 170182}], \"symbol\": \"XBTUSD\", \"timestamp\": \"2018-06-11 01:38:27.675394Z\"}", "XBTUSD"], [1528681111226, "{\"table\": \"orderBookL2\", \"action\": \"update\", \"data\": [{\"id\": 8799326600, \"side\": \"Sell\", \"size\": 277962}], \"symbol\": \"XBTUSD\", \"timestamp\": \"2018-06-11 01:38:31.223189Z\"}", "XBTUSD"], [1528681114677, "{\"table\": \"orderBookL2\", \"action\": \"update\", \"data\": [{\"id\": 8799328000, \"side\": \"Buy\", \"size\": 155862}, {\"id\": 8799328050, \"side\": \"Buy\", \"size\": 462413}], \"symbol\": \"XBTUSD\", \"timestamp\": \"2018-06-11 01:38:34.672223Z\"}", "XBTUSD"], [1528681117507, "{\"table\": \"orderBookL2\", \"action\": \"update\", \"data\": [{\"id\": 8799327050, \"side\": \"Buy\", \"size\": 1602343}], \"symbol\": \"XBTUSD\", \"timestamp\": \"2018-06-11 01:38:37.499872Z\"}", "XBTUSD"], [1528681119966, "{\"table\": \"orderBookL2\", \"action\": \"update\", \"data\": [{\"id\": 8799326800, \"side\": \"Sell\", \"size\": 25350}], \"symbol\": \"XBTUSD\", \"timestamp\": \"2018-06-11 01:38:39.963954Z\"}", "XBTUSD"], [1528681124261, "{\"table\": \"orderBookL2\", \"action\": \"update\", \"data\": [{\"id\": 8799326600, \"side\": \"Sell\", \"size\": 284962}, {\"id\": 8799326650, \"side\": \"Sell\", \"size\": 24494}, {\"id\": 8799327050, \"side\": \"Buy\", \"size\": 1583793}, {\"id\": 8799327100, \"side\": \"Buy\", \"size\": 366223}], \"symbol\": \"XBTUSD\", \"timestamp\": \"2018-06-11 01:38:44.254372Z\"}", "XBTUSD"], [1528681129134, "{\"table\": \"orderBookL2\", \"action\": \"update\", \"data\": [{\"id\": 8799326900, \"side\": \"Sell\", \"size\": 8174}, {\"id\": 8799327100, \"side\": \"Buy\", \"size\": 415025}], \"symbol\": \"XBTUSD\", \"timestamp\": \"2018-06-11 01:38:49.130322Z\"}", "XBTUSD"], [1528681129345, "{\"table\": \"orderBookL2\", \"action\": \"update\", \"data\": [{\"id\": 8799327000, \"side\": \"Buy\", \"size\": 1505574}, {\"id\": 8799327050, \"side\": \"Buy\", \"size\": 981905}], \"symbol\": \"XBTUSD\", \"timestamp\": \"2018-06-11 01:38:49.342829Z\"}", "XBTUSD"], [1528681129954, "{\"table\": \"orderBookL2\", \"action\": \"update\", \"data\": [{\"id\": 8799327050, \"side\": \"Buy\", \"size\": 663973}], \"symbol\": \"XBTUSD\", \"timestamp\": \"2018-06-11 01:38:49.950669Z\"}", "XBTUSD"], [1528681133773, "{\"table\": \"orderBookL2\", \"action\": \"update\", \"data\": [{\"id\": 8799326400, \"side\": \"Sell\", \"size\": 39542}, {\"id\": 8799326500, \"side\": \"Sell\", \"size\": 128303}, {\"id\": 8799326550, \"side\": \"Sell\", \"size\": 12277}, {\"id\": 8799327600, \"side\": \"Buy\", \"size\": 9811}], \"symbol\": \"XBTUSD\", \"timestamp\": \"2018-06-11 01:38:53.767473Z\"}", "XBTUSD"], [1528681136060, "{\"table\": \"orderBookL2\", \"action\": \"update\", \"data\": [{\"id\": 8799327050, \"side\": \"Buy\", \"size\": 660736}], \"symbol\": \"XBTUSD\", \"timestamp\": \"2018-06-11 01:38:56.054411Z\"}", "XBTUSD"], [1528681139056, "{\"table\": \"orderBookL2\", \"action\": \"update\", \"data\": [{\"id\": 8799327950, \"side\": \"Buy\", \"size\": 549690}], \"symbol\": \"XBTUSD\", \"timestamp\": \"2018-06-11 01:38:59.051320Z\"}", "XBTUSD"], [1528681143548, "{\"table\": \"orderBookL2\", \"action\": \"update\", \"data\": [{\"id\": 8799326300, \"side\": \"Sell\", \"size\": 355654}, {\"id\": 8799327800, \"side\": \"Buy\", \"size\": 410812}], \"symbol\": \"XBTUSD\", \"timestamp\": \"2018-06-11 01:39:03.544980Z\"}", "XBTUSD"], [1528681146604, "{\"table\": \"orderBookL2\", \"action\": \"update\", \"data\": [{\"id\": 8799327050, \"side\": \"Buy\", \"size\": 654313}], \"symbol\": \"XBTUSD\", \"timestamp\": \"2018-06-11 01:39:06.601200Z\"}", "XBTUSD"], [1528681149699, "{\"table\": \"orderBookL2\", \"action\": \"update\", \"data\": [{\"id\": 8799326500, \"side\": \"Sell\", \"size\": 104745}, {\"id\": 8799326550, \"side\": \"Sell\", \"size\": 11272}], \"symbol\": \"XBTUSD\", \"timestamp\": \"2018-06-11 01:39:09.695787Z\"}", "XBTUSD"], [1528681153195, "{\"table\": \"orderBookL2\", \"action\": \"update\", \"data\": [{\"id\": 8799325550, \"side\": \"Sell\", \"size\": 276483}, {\"id\": 8799328450, \"side\": \"Buy\", \"size\": 284534}], \"symbol\": \"XBTUSD\", \"timestamp\": \"2018-06-11 01:39:13.188861Z\"}", "XBTUSD"], [1528681155416, "{\"table\": \"orderBookL2\", \"action\": \"insert\", \"data\": [{\"id\": 8799932600, \"side\": \"Buy\", \"size\": 3, \"price\": 674}], \"symbol\": \"XBTUSD\", \"timestamp\": \"2018-06-11 01:39:15.413220Z\"}", "XBTUSD"], [1528681157488, "{\"table\": \"trade\", \"action\": \"insert\", \"data\": [{\"timestamp\": \"2018-06-11T01:39:17.456Z\", \"side\": \"Sell\", \"size\": 5000, \"price\": 6730, \"tickDirection\": \"MinusTick\", \"trdMatchID\": \"fc46c3fc-9b33-caa9-ef95-6fd2dc424e1f\", \"grossValue\": 74295000, \"homeNotional\": 0.74295, \"foreignNotional\": 5000}], \"symbol\": \"XBTUSD\", \"timestamp\": \"2018-06-11 01:39:17.485701Z\"}", "XBTUSD"], [1528681158838, "{\"table\": \"orderBookL2\", \"action\": \"insert\", \"data\": [{\"id\": 8799326950, \"side\": \"Buy\", \"size\": 25263, \"price\": 6730.5}], \"symbol\": \"XBTUSD\", \"timestamp\": \"2018-06-11 01:39:18.835738Z\"}", "XBTUSD"], [1528681159521, "{\"table\": \"orderBookL2\", \"action\": \"update\", \"data\": [{\"id\": 8799326950, \"side\": \"Buy\", \"size\": 1614521}, {\"id\": 8799327000, \"side\": \"Buy\", \"size\": 1133621}], \"symbol\": \"XBTUSD\", \"timestamp\": \"2018-06-11 01:39:19.518839Z\"}", "XBTUSD"], [1528681160578, "{\"table\": \"orderBookL2\", \"action\": \"update\", \"data\": [{\"id\": 8799326500, \"side\": \"Sell\", \"size\": 103946}, {\"id\": 8799327000, \"side\": \"Buy\", \"size\": 806077}], \"symbol\": \"XBTUSD\", \"timestamp\": \"2018-06-11 01:39:20.574055Z\"}", "XBTUSD"], [1528681162699, "{\"table\": \"orderBookL2\", \"action\": \"update\", \"data\": [{\"id\": 8799326750, \"side\": \"Sell\", \"size\": 4760}], \"symbol\": \"XBTUSD\", \"timestamp\": \"2018-06-11 01:39:22.694266Z\"}", "XBTUSD"], [1528681164079, "{\"table\": \"orderBookL2\", \"action\": \"update\", \"data\": [{\"id\": 8799326900, \"side\": \"Buy\", \"size\": 741028}, {\"id\": 8799326950, \"side\": \"Buy\", \"size\": 1411441}], \"symbol\": \"XBTUSD\", \"timestamp\": \"2018-06-11 01:39:24.075491Z\"}", "XBTUSD"], [1528681164872, "{\"table\": \"orderBookL2\", \"action\": \"update\", \"data\": [{\"id\": 8799326900, \"side\": \"Buy\", \"size\": 1354360}, {\"id\": 8799326950, \"side\": \"Buy\", \"size\": 597459}], \"symbol\": \"XBTUSD\", \"timestamp\": \"2018-06-11 01:39:24.869983Z\"}", "XBTUSD"], [1528681165533, "{\"table\": \"trade\", \"action\": \"insert\", \"data\": [{\"timestamp\": \"2018-06-11T01:39:25.448Z\", \"side\": \"Buy\", \"size\": 90, \"price\": 6732, \"tickDirection\": \"PlusTick\", \"trdMatchID\": \"cb290898-949e-7461-ba11-578eae91a888\", \"grossValue\": 1336860, \"homeNotional\": 0.0133686, \"foreignNotional\": 90}, {\"timestamp\": \"2018-06-11T01:39:25.448Z\", \"side\": \"Buy\", \"size\": 25, \"price\": 6732, \"tickDirection\": \"ZeroPlusTick\", \"trdMatchID\": \"3e1f33dd-63df-01b7-84e9-301c9a4eecf6\", \"grossValue\": 371350, \"homeNotional\": 0.0037135, \"foreignNotional\": 25}, {\"timestamp\": \"2018-06-11T01:39:25.448Z\", \"side\": \"Buy\", \"size\": 25, \"price\": 6732, \"tickDirection\": \"ZeroPlusTick\", \"trdMatchID\": \"43ecb216-863c-4cfa-c4ce-f975df455200\", \"grossValue\": 371350, \"homeNotional\": 0.0037135, \"foreignNotional\": 25}, {\"timestamp\": \"2018-06-11T01:39:25.448Z\", \"side\": \"Buy\", \"size\": 25, \"price\": 6732, \"tickDirection\": \"ZeroPlusTick\", \"trdMatchID\": \"7a082f84-5115-75a7-a4d1-8dc91a614b59\", \"grossValue\": 371350, \"homeNotional\": 0.0037135, \"foreignNotional\": 25}, {\"timestamp\": \"2018-06-11T01:39:25.448Z\", \"side\": \"Buy\", \"size\": 140, \"price\": 6732, \"tickDirection\": \"ZeroPlusTick\", \"trdMatchID\": \"b4ad7541-eb9a-5cdb-25db-a8dd1cc4a5e5\", \"grossValue\": 2079560, \"homeNotional\": 0.0207956, \"foreignNotional\": 140}, {\"timestamp\": \"2018-06-11T01:39:25.448Z\", \"side\": \"Buy\", \"size\": 500, \"price\": 6732, \"tickDirection\": \"ZeroPlusTick\", \"trdMatchID\": \"f02cb67d-dde0-3171-67bf-0344f23715d5\", \"grossValue\": 7427000, \"homeNotional\": 0.07427, \"foreignNotional\": 500}, {\"timestamp\": \"2018-06-11T01:39:25.448Z\", \"side\": \"Buy\", \"size\": 195, \"price\": 6732, \"tickDirection\": \"ZeroPlusTick\", \"trdMatchID\": \"32dcfa5b-fd8a-bdd1-8ad9-678a4cdd8f2a\", \"grossValue\": 2896530, \"homeNotional\": 0.0289653, \"foreignNotional\": 195}], \"symbol\": \"XBTUSD\", \"timestamp\": \"2018-06-11 01:39:25.530191Z\"}", "XBTUSD"], [1528681166580, "{\"table\": \"orderBookL2\", \"action\": \"update\", \"data\": [{\"id\": 8799326900, \"side\": \"Buy\", \"size\": 429585}], \"symbol\": \"XBTUSD\", \"timestamp\": \"2018-06-11 01:39:26.575279Z\"}", "XBTUSD"], [1528681168147, "{\"table\": \"orderBookL2\", \"action\": \"update\", \"data\": [{\"id\": 8799320700, \"side\": \"Sell\", \"size\": 365}], \"symbol\": \"XBTUSD\", \"timestamp\": \"2018-06-11 01:39:28.141763Z\"}", "XBTUSD"], [1528681171161, "{\"table\": \"orderBookL2\", \"action\": \"update\", \"data\": [{\"id\": 8799320700, \"side\": \"Sell\", \"size\": 12645}], \"symbol\": \"XBTUSD\", \"timestamp\": \"2018-06-11 01:39:31.155934Z\"}", "XBTUSD"], [1528681171814, "{\"table\": \"orderBookL2\", \"action\": \"update\", \"data\": [{\"id\": 8799319700, \"side\": \"Sell\", \"size\": 2517}], \"symbol\": \"XBTUSD\", \"timestamp\": \"2018-06-11 01:39:31.812277Z\"}", "XBTUSD"], [1528681172520, "{\"table\": \"orderBookL2\", \"action\": \"update\", \"data\": [{\"id\": 8799326900, \"side\": \"Buy\", \"size\": 188158}], \"symbol\": \"XBTUSD\", \"timestamp\": \"2018-06-11 01:39:32.517100Z\"}", "XBTUSD"], [1528681173214, "{\"table\": \"quote\", \"action\": \"insert\", \"data\": [{\"timestamp\": \"2018-06-11T01:39:31.966Z\", \"bidSize\": 1871291, \"bidPrice\": 6732, \"askPrice\": 6732.5, \"askSize\": 18860}, {\"timestamp\": \"2018-06-11T01:39:31.970Z\", \"bidSize\": 1871291, \"bidPrice\": 6732, \"askPrice\": 6732.5, \"askSize\": 8860}, {\"timestamp\": \"2018-06-11T01:39:31.996Z\", \"bidSize\": 1871291, \"bidPrice\": 6732, \"askPrice\": 6732.5, \"askSize\": 8862}, {\"timestamp\": \"2018-06-11T01:39:32.002Z\", \"bidSize\": 39036, \"bidPrice\": 6732.5, \"askPrice\": 6733, \"askSize\": 242122}, {\"timestamp\": \"2018-06-11T01:39:32.027Z\", \"bidSize\": 39036, \"bidPrice\": 6732.5, \"askPrice\": 6733, \"askSize\": 242222}, {\"timestamp\": \"2018-06-11T01:39:32.052Z\", \"bidSize\": 39036, \"bidPrice\": 6732.5, \"askPrice\": 6733, \"askSize\": 237222}, {\"timestamp\": \"2018-06-11T01:39:32.064Z\", \"bidSize\": 39062, \"bidPrice\": 6732.5, \"askPrice\": 6733, \"askSize\": 237222}, {\"timestamp\": \"2018-06-11T01:39:32.073Z\", \"bidSize\": 59062, \"bidPrice\": 6732.5, \"askPrice\": 6733, \"askSize\": 237222}, {\"timestamp\": \"2018-06-11T01:39:32.073Z\", \"bidSize\": 119062, \"bidPrice\": 6732.5, \"askPrice\": 6733, \"askSize\": 237222}, {\"timestamp\": \"2018-06-11T01:39:32.073Z\", \"bidSize\": 179062, \"bidPrice\": 6732.5, \"askPrice\": 6733, \"askSize\": 237222}, {\"timestamp\": \"2018-06-11T01:39:32.091Z\", \"bidSize\": 179186, \"bidPrice\": 6732.5, \"askPrice\": 6733, \"askSize\": 237222}, {\"timestamp\": \"2018-06-11T01:39:32.105Z\", \"bidSize\": 184186, \"bidPrice\": 6732.5, \"askPrice\": 6733, \"askSize\": 237222}, {\"timestamp\": \"2018-06-11T01:39:32.131Z\", \"bidSize\": 187186, \"bidPrice\": 6732.5, \"askPrice\": 6733, \"askSize\": 237222}, {\"timestamp\": \"2018-06-11T01:39:32.142Z\", \"bidSize\": 227186, \"bidPrice\": 6732.5, \"askPrice\": 6733, \"askSize\": 237222}, {\"timestamp\": \"2018-06-11T01:39:32.146Z\", \"bidSize\": 247186, \"bidPrice\": 6732.5, \"askPrice\": 6733, \"askSize\": 237222}, {\"timestamp\": \"2018-06-11T01:39:32.156Z\", \"bidSize\": 407184, \"bidPrice\": 6732.5, \"askPrice\": 6733, \"askSize\": 237222}, {\"timestamp\": \"2018-06-11T01:39:32.166Z\", \"bidSize\": 413684, \"bidPrice\": 6732.5, \"askPrice\": 6733, \"askSize\": 237222}, {\"timestamp\": \"2018-06-11T01:39:32.169Z\", \"bidSize\": 421684, \"bidPrice\": 6732.5, \"askPrice\": 6733, \"askSize\": 237222}, {\"timestamp\": \"2018-06-11T01:39:32.182Z\", \"bidSize\": 462820, \"bidPrice\": 6732.5, \"askPrice\": 6733, \"askSize\": 237222}, {\"timestamp\": \"2018-06-11T01:39:32.208Z\", \"bidSize\": 482820, \"bidPrice\": 6732.5, \"askPrice\": 6733, \"askSize\": 237222}, {\"timestamp\": \"2018-06-11T01:39:32.212Z\", \"bidSize\": 443784, \"bidPrice\": 6732.5, \"askPrice\": 6733, \"askSize\": 237222}, {\"timestamp\": \"2018-06-11T01:39:32.219Z\", \"bidSize\": 448784, \"bidPrice\": 6732.5, \"askPrice\": 6733, \"askSize\": 237222}, {\"timestamp\": \"2018-06-11T01:39:32.231Z\", \"bidSize\": 449284, \"bidPrice\": 6732.5, \"askPrice\": 6733, \"askSize\": 237222}, {\"timestamp\": \"2018-06-11T01:39:32.248Z\", \"bidSize\": 519284, \"bidPrice\": 6732.5, \"askPrice\": 6733, \"askSize\": 237222}, {\"timestamp\": \"2018-06-11T01:39:32.251Z\", \"bidSize\": 589284, \"bidPrice\": 6732.5, \"askPrice\": 6733, \"askSize\": 237222}, {\"timestamp\": \"2018-06-11T01:39:32.274Z\", \"bidSize\": 595284, \"bidPrice\": 6732.5, \"askPrice\": 6733, \"askSize\": 237222}, {\"timestamp\": \"2018-06-11T01:39:32.274Z\", \"bidSize\": 603284, \"bidPrice\": 6732.5, \"askPrice\": 6733, \"askSize\": 237222}, {\"timestamp\": \"2018-06-11T01:39:32.282Z\", \"bidSize\": 619105, \"bidPrice\": 6732.5, \"askPrice\": 6733, \"askSize\": 237222}, {\"timestamp\": \"2018-06-11T01:39:32.284Z\", \"bidSize\": 619105, \"bidPrice\": 6732.5, \"askPrice\": 6733, \"askSize\": 237247}, {\"timestamp\": \"2018-06-11T01:39:32.292Z\", \"bidSize\": 622525, \"bidPrice\": 6732.5, \"askPrice\": 6733, \"askSize\": 237247}, {\"timestamp\": \"2018-06-11T01:39:32.313Z\", \"bidSize\": 652525, \"bidPrice\": 6732.5, \"askPrice\": 6733, \"askSize\": 237247}, {\"timestamp\": \"2018-06-11T01:39:32.316Z\", \"bidSize\": 680280, \"bidPrice\": 6732.5, \"askPrice\": 6733, \"askSize\": 237247}, {\"timestamp\": \"2018-06-11T01:39:32.338Z\", \"bidSize\": 680280, \"bidPrice\": 6732.5, \"askPrice\": 6733, \"askSize\": 257247}, {\"timestamp\": \"2018-06-11T01:39:32.340Z\", \"bidSize\": 750280, \"bidPrice\": 6732.5, \"askPrice\": 6733, \"askSize\": 257247}, {\"timestamp\": \"2018-06-11T01:39:32.362Z\", \"bidSize\": 752303, \"bidPrice\": 6732.5, \"askPrice\": 6733, \"askSize\": 257247}, {\"timestamp\": \"2018-06-11T01:39:32.364Z\", \"bidSize\": 772303, \"bidPrice\": 6732.5, \"askPrice\": 6733, \"askSize\": 257247}, {\"timestamp\": \"2018-06-11T01:39:32.368Z\", \"bidSize\": 780303, \"bidPrice\": 6732.5, \"askPrice\": 6733, \"askSize\": 257247}, {\"timestamp\": \"2018-06-11T01:39:32.368Z\", \"bidSize\": 786362, \"bidPrice\": 6732.5, \"askPrice\": 6733, \"askSize\": 257247}, {\"timestamp\": \"2018-06-11T01:39:32.375Z\", \"bidSize\": 803370, \"bidPrice\": 6732.5, \"askPrice\": 6733, \"askSize\": 257247}, {\"timestamp\": \"2018-06-11T01:39:32.378Z\", \"bidSize\": 963368, \"bidPrice\": 6732.5, \"askPrice\": 6733, \"askSize\": 257247}, {\"timestamp\": \"2018-06-11T01:39:32.389Z\", \"bidSize\": 803370, \"bidPrice\": 6732.5, \"askPrice\": 6733, \"askSize\": 257247}, {\"timestamp\": \"2018-06-11T01:39:32.392Z\", \"bidSize\": 843370, \"bidPrice\": 6732.5, \"askPrice\": 6733, \"askSize\": 257247}, {\"timestamp\": \"2018-06-11T01:39:32.397Z\", \"bidSize\": 913370, \"bidPrice\": 6732.5, \"askPrice\": 6733, \"askSize\": 257247}, {\"timestamp\": \"2018-06-11T01:39:32.406Z\", \"bidSize\": 924579, \"bidPrice\": 6732.5, \"askPrice\": 6733, \"askSize\": 257247}, {\"timestamp\": \"2018-06-11T01:39:32.428Z\", \"bidSize\": 944938, \"bidPrice\": 6732.5, \"askPrice\": 6733, \"askSize\": 257247}, {\"timestamp\": \"2018-06-11T01:39:32.449Z\", \"bidSize\": 957745, \"bidPrice\": 6732.5, \"askPrice\": 6733, \"askSize\": 257247}, {\"timestamp\": \"2018-06-11T01:39:32.475Z\", \"bidSize\": 997745, \"bidPrice\": 6732.5, \"askPrice\": 6733, \"askSize\": 257247}, {\"timestamp\": \"2018-06-11T01:39:32.485Z\", \"bidSize\": 997901, \"bidPrice\": 6732.5, \"askPrice\": 6733, \"askSize\": 257247}, {\"timestamp\": \"2018-06-11T01:39:32.500Z\", \"bidSize\": 1097901, \"bidPrice\": 6732.5, \"askPrice\": 6733, \"askSize\": 257247}, {\"timestamp\": \"2018-06-11T01:39:32.511Z\", \"bidSize\": 1118191, \"bidPrice\": 6732.5, \"askPrice\": 6733, \"askSize\": 257247}, {\"timestamp\": \"2018-06-11T01:39:32.532Z\", \"bidSize\": 1124191, \"bidPrice\": 6732.5, \"askPrice\": 6733, \"askSize\": 257247}, {\"timestamp\": \"2018-06-11T01:39:32.538Z\", \"bidSize\": 1127846, \"bidPrice\": 6732.5, \"askPrice\": 6733, \"askSize\": 257247}, {\"timestamp\": \"2018-06-11T01:39:32.559Z\", \"bidSize\": 1167846, \"bidPrice\": 6732.5, \"askPrice\": 6733, \"askSize\": 257247}, {\"timestamp\": \"2018-06-11T01:39:32.563Z\", \"bidSize\": 1168046, \"bidPrice\": 6732.5, \"askPrice\": 6733, \"askSize\": 257247}, {\"timestamp\": \"2018-06-11T01:39:32.566Z\", \"bidSize\": 1170188, \"bidPrice\": 6732.5, \"askPrice\": 6733, \"askSize\": 257247}, {\"timestamp\": \"2018-06-11T01:39:32.697Z\", \"bidSize\": 1220188, \"bidPrice\": 6732.5, \"askPrice\": 6733, \"askSize\": 257247}, {\"timestamp\": \"2018-06-11T01:39:32.703Z\", \"bidSize\": 1228374, \"bidPrice\": 6732.5, \"askPrice\": 6733, \"askSize\": 257247}, {\"timestamp\": \"2018-06-11T01:39:32.705Z\", \"bidSize\": 1228373, \"bidPrice\": 6732.5, \"askPrice\": 6733, \"askSize\": 257247}, {\"timestamp\": \"2018-06-11T01:39:32.713Z\", \"bidSize\": 1228522, \"bidPrice\": 6732.5, \"askPrice\": 6733, \"askSize\": 257247}, {\"timestamp\": \"2018-06-11T01:39:32.715Z\", \"bidSize\": 1231522, \"bidPrice\": 6732.5, \"askPrice\": 6733, \"askSize\": 257247}, {\"timestamp\": \"2018-06-11T01:39:32.723Z\", \"bidSize\": 1281522, \"bidPrice\": 6732.5, \"askPrice\": 6733, \"askSize\": 257247}, {\"timestamp\": \"2018-06-11T01:39:32.727Z\", \"bidSize\": 1284331, \"bidPrice\": 6732.5, \"askPrice\": 6733, \"askSize\": 257247}, {\"timestamp\": \"2018-06-11T01:39:32.734Z\", \"bidSize\": 1284832, \"bidPrice\": 6732.5, \"askPrice\": 6733, \"askSize\": 257247}, {\"timestamp\": \"2018-06-11T01:39:32.738Z\", \"bidSize\": 1334832, \"bidPrice\": 6732.5, \"askPrice\": 6733, \"askSize\": 257247}, {\"timestamp\": \"2018-06-11T01:39:32.741Z\", \"bidSize\": 1334842, \"bidPrice\": 6732.5, \"askPrice\": 6733, \"askSize\": 257247}, {\"timestamp\": \"2018-06-11T01:39:32.745Z\", \"bidSize\": 1534842, \"bidPrice\": 6732.5, \"askPrice\": 6733, \"askSize\": 257247}, {\"timestamp\": \"2018-06-11T01:39:32.766Z\", \"bidSize\": 1573878, \"bidPrice\": 6732.5, \"askPrice\": 6733, \"askSize\": 257247}, {\"timestamp\": \"2018-06-11T01:39:32.772Z\", \"bidSize\": 1574278, \"bidPrice\": 6732.5, \"askPrice\": 6733, \"askSize\": 257247}, {\"timestamp\": \"2018-06-11T01:39:32.781Z\", \"bidSize\": 1594278, \"bidPrice\": 6732.5, \"askPrice\": 6733, \"askSize\": 257247}, {\"timestamp\": \"2018-06-11T01:39:32.783Z\", \"bidSize\": 1602278, \"bidPrice\": 6732.5, \"askPrice\": 6733, \"askSize\": 257247}, {\"timestamp\": \"2018-06-11T01:39:32.790Z\", \"bidSize\": 1617278, \"bidPrice\": 6732.5, \"askPrice\": 6733, \"askSize\": 257247}, {\"timestamp\": \"2018-06-11T01:39:32.819Z\", \"bidSize\": 1617279, \"bidPrice\": 6732.5, \"askPrice\": 6733, \"askSize\": 257247}, {\"timestamp\": \"2018-06-11T01:39:32.865Z\", \"bidSize\": 1620279, \"bidPrice\": 6732.5, \"askPrice\": 6733, \"askSize\": 257247}, {\"timestamp\": \"2018-06-11T01:39:32.885Z\", \"bidSize\": 1670279, \"bidPrice\": 6732.5, \"askPrice\": 6733, \"askSize\": 257247}, {\"timestamp\": \"2018-06-11T01:39:32.929Z\", \"bidSize\": 1670279, \"bidPrice\": 6732.5, \"askPrice\": 6733, \"askSize\": 263247}, {\"timestamp\": \"2018-06-11T01:39:32.974Z\", \"bidSize\": 1720279, \"bidPrice\": 6732.5, \"askPrice\": 6733, \"askSize\": 263247}], \"symbol\": \"XBTUSD\", \"timestamp\": \"2018-06-11 01:39:33.205359Z\"}", "XBTUSD"], [1528681174701, "{\"table\": \"orderBookL2\", \"action\": \"update\", \"data\": [{\"id\": 8799326900, \"side\": \"Buy\", \"size\": 185113}], \"symbol\": \"XBTUSD\", \"timestamp\": \"2018-06-11 01:39:34.695025Z\"}", "XBTUSD"], [1528681177269, "{\"table\": \"orderBookL2\", \"action\": \"update\", \"data\": [{\"id\": 8799327300, \"side\": \"Buy\", \"size\": 38372}, {\"id\": 8799327400, \"side\": \"Buy\", \"size\": 30762}], \"symbol\": \"XBTUSD\", \"timestamp\": \"2018-06-11 01:39:37.263108Z\"}", "XBTUSD"], [1528681179839, "{\"table\": \"orderBookL2\", \"action\": \"update\", \"data\": [{\"id\": 8799275900, \"side\": \"Sell\", \"size\": 25825}, {\"id\": 8799276100, \"side\": \"Sell\", \"size\": 17850}, {\"id\": 8799276300, \"side\": \"Sell\", \"size\": 59742}, {\"id\": 8799276500, \"side\": \"Sell\", \"size\": 49900}, {\"id\": 8799276700, \"side\": \"Sell\", \"size\": 15800}, {\"id\": 8799326900, \"side\": \"Buy\", \"size\": 164293}, {\"id\": 8799327100, \"side\": \"Buy\", \"size\": 37708}, {\"id\": 8799327300, \"side\": \"Buy\", \"size\": 26801}, {\"id\": 8799327500, \"side\": \"Buy\", \"size\": 40357}], \"symbol\": \"XBTUSD\", \"timestamp\": \"2018-06-11 01:39:39.833648Z\"}", "XBTUSD"], [1528681182887, "{\"table\": \"orderBookL2\", \"action\": \"update\", \"data\": [{\"id\": 8799326300, \"side\": \"Sell\", \"size\": 8547}], \"symbol\": \"XBTUSD\", \"timestamp\": \"2018-06-11 01:39:42.885124Z\"}", "XBTUSD"], [1528681187827, "{\"table\": \"orderBookL2\", \"action\": \"delete\", \"data\": [{\"id\": 8793267000, \"side\": \"Sell\"}], \"symbol\": \"XBTUSD\", \"timestamp\": \"2018-06-11 01:39:47.821387Z\"}", "XBTUSD"], [1528681191235, "{\"table\": \"orderBookL2\", \"action\": \"update\", \"data\": [{\"id\": 8799330000, \"side\": \"Buy\", \"size\": 242618}], \"symbol\": \"XBTUSD\", \"timestamp\": \"2018-06-11 01:39:51.229569Z\"}", "XBTUSD"], [1528681194496, "{\"table\": \"orderBookL2\", \"action\": \"update\", \"data\": [{\"id\": 8799320600, \"side\": \"Sell\", \"size\": 98204}], \"symbol\": \"XBTUSD\", \"timestamp\": \"2018-06-11 01:39:54.490315Z\"}", "XBTUSD"], [1528681198716, "{\"table\": \"quote\", \"action\": \"insert\", \"data\": [{\"timestamp\": \"2018-06-11T01:39:55.925Z\", \"bidSize\": 2194437, \"bidPrice\": 6732.5, \"askPrice\": 6733, \"askSize\": 162477}, {\"timestamp\": \"2018-06-11T01:39:55.928Z\", \"bidSize\": 2193081, \"bidPrice\": 6732.5, \"askPrice\": 6733, \"askSize\": 162477}, {\"timestamp\": \"2018-06-11T01:39:55.930Z\", \"bidSize\": 2188410, \"bidPrice\": 6732.5, \"askPrice\": 6733, \"askSize\": 162477}, {\"timestamp\": \"2018-06-11T01:39:55.933Z\", \"bidSize\": 2138410, \"bidPrice\": 6732.5, \"askPrice\": 6733, \"askSize\": 162477}, {\"timestamp\": \"2018-06-11T01:39:55.935Z\", \"bidSize\": 2098410, \"bidPrice\": 6732.5, \"askPrice\": 6733, \"askSize\": 162477}, {\"timestamp\": \"2018-06-11T01:39:55.940Z\", \"bidSize\": 2048410, \"bidPrice\": 6732.5, \"askPrice\": 6733, \"askSize\": 162477}, {\"timestamp\": \"2018-06-11T01:39:55.943Z\", \"bidSize\": 2048410, \"bidPrice\": 6732.5, \"askPrice\": 6733, \"askSize\": 82477}, {\"timestamp\": \"2018-06-11T01:39:55.964Z\", \"bidSize\": 2008410, \"bidPrice\": 6732.5, \"askPrice\": 6733, \"askSize\": 82477}, {\"timestamp\": \"2018-06-11T01:39:56.247Z\", \"bidSize\": 2000224, \"bidPrice\": 6732.5, \"askPrice\": 6733, \"askSize\": 82477}, {\"timestamp\": \"2018-06-11T01:39:56.266Z\", \"bidSize\": 2000224, \"bidPrice\": 6732.5, \"askPrice\": 6733, \"askSize\": 117806}, {\"timestamp\": \"2018-06-11T01:39:56.278Z\", \"bidSize\": 1960224, \"bidPrice\": 6732.5, \"askPrice\": 6733, \"askSize\": 117806}, {\"timestamp\": \"2018-06-11T01:39:56.287Z\", \"bidSize\": 1960224, \"bidPrice\": 6732.5, \"askPrice\": 6733, \"askSize\": 150806}, {\"timestamp\": \"2018-06-11T01:39:56.298Z\", \"bidSize\": 1960224, \"bidPrice\": 6732.5, \"askPrice\": 6733, \"askSize\": 150808}, {\"timestamp\": \"2018-06-11T01:39:56.317Z\", \"bidSize\": 1960224, \"bidPrice\": 6732.5, \"askPrice\": 6733, \"askSize\": 147497}, {\"timestamp\": \"2018-06-11T01:39:56.328Z\", \"bidSize\": 1910224, \"bidPrice\": 6732.5, \"askPrice\": 6733, \"askSize\": 147497}, {\"timestamp\": \"2018-06-11T01:39:56.481Z\", \"bidSize\": 1910224, \"bidPrice\": 6732.5, \"askPrice\": 6733, \"askSize\": 147498}, {\"timestamp\": \"2018-06-11T01:39:56.810Z\", \"bidSize\": 1960224, \"bidPrice\": 6732.5, \"askPrice\": 6733, \"askSize\": 147498}, {\"timestamp\": \"2018-06-11T01:39:56.817Z\", \"bidSize\": 1961580, \"bidPrice\": 6732.5, \"askPrice\": 6733, \"askSize\": 147498}, {\"timestamp\": \"2018-06-11T01:39:56.824Z\", \"bidSize\": 2011580, \"bidPrice\": 6732.5, \"askPrice\": 6733, \"askSize\": 147498}, {\"timestamp\": \"2018-06-11T01:39:56.831Z\", \"bidSize\": 2011580, \"bidPrice\": 6732.5, \"askPrice\": 6733, \"askSize\": 112169}, {\"timestamp\": \"2018-06-11T01:39:56.835Z\", \"bidSize\": 2051580, \"bidPrice\": 6732.5, \"askPrice\": 6733, \"askSize\": 112169}, {\"timestamp\": \"2018-06-11T01:39:56.842Z\", \"bidSize\": 2091580, \"bidPrice\": 6732.5, \"askPrice\": 6733, \"askSize\": 112169}, {\"timestamp\": \"2018-06-11T01:39:56.857Z\", \"bidSize\": 2131580, \"bidPrice\": 6732.5, \"askPrice\": 6733, \"askSize\": 112169}, {\"timestamp\": \"2018-06-11T01:39:56.864Z\", \"bidSize\": 2136251, \"bidPrice\": 6732.5, \"askPrice\": 6733, \"askSize\": 112169}, {\"timestamp\": \"2018-06-11T01:39:56.871Z\", \"bidSize\": 2136252, \"bidPrice\": 6732.5, \"askPrice\": 6733, \"askSize\": 112169}, {\"timestamp\": \"2018-06-11T01:39:56.939Z\", \"bidSize\": 2135985, \"bidPrice\": 6732.5, \"askPrice\": 6733, \"askSize\": 112169}, {\"timestamp\": \"2018-06-11T01:39:57.004Z\", \"bidSize\": 2185985, \"bidPrice\": 6732.5, \"askPrice\": 6733, \"askSize\": 112169}], \"symbol\": \"XBTUSD\", \"timestamp\": \"2018-06-11 01:39:58.711477Z\"}", "XBTUSD"], [1528681199800, "{\"table\": \"orderBookL2\", \"action\": \"update\", \"data\": [{\"id\": 8799325900, \"side\": \"Sell\", \"size\": 25902}, {\"id\": 8799327500, \"side\": \"Buy\", \"size\": 23500}], \"symbol\": \"XBTUSD\", \"timestamp\": \"2018-06-11 01:39:59.794599Z\"}", "XBTUSD"], [1528681204565, "{\"table\": \"orderBookL2\", \"action\": \"update\", \"data\": [{\"id\": 8799327050, \"side\": \"Buy\", \"size\": 113442}, {\"id\": 8799327150, \"side\": \"Buy\", \"size\": 72796}], \"symbol\": \"XBTUSD\", \"timestamp\": \"2018-06-11 01:40:04.561128Z\"}", "XBTUSD"], [1528681205456, "{\"table\": \"orderBookL2\", \"action\": \"update\", \"data\": [{\"id\": 8799326250, \"side\": \"Sell\", \"size\": 150796}, {\"id\": 8799327850, \"side\": \"Buy\", \"size\": 173295}], \"symbol\": \"XBTUSD\", \"timestamp\": \"2018-06-11 01:40:05.452263Z\"}", "XBTUSD"], [1528681208296, "{\"table\": \"orderBookL2\", \"action\": \"update\", \"data\": [{\"id\": 8799332200, \"side\": \"Buy\", \"size\": 36513}], \"symbol\": \"XBTUSD\", \"timestamp\": \"2018-06-11 01:40:08.291272Z\"}", "XBTUSD"], [1528681212530, "{\"table\": \"orderBookL2\", \"action\": \"update\", \"data\": [{\"id\": 8799326750, \"side\": \"Buy\", \"size\": 1588510}], \"symbol\": \"XBTUSD\", \"timestamp\": \"2018-06-11 01:40:12.521355Z\"}", "XBTUSD"], [1528681214081, "{\"table\": \"orderBookL2\", \"action\": \"update\", \"data\": [{\"id\": 8799326750, \"side\": \"Buy\", \"size\": 1520670}], \"symbol\": \"XBTUSD\", \"timestamp\": \"2018-06-11 01:40:14.078207Z\"}", "XBTUSD"], [1528681216356, "{\"table\": \"orderBookL2\", \"action\": \"update\", \"data\": [{\"id\": 8799319700, \"side\": \"Sell\", \"size\": 16786}], \"symbol\": \"XBTUSD\", \"timestamp\": \"2018-06-11 01:40:16.344346Z\"}", "XBTUSD"], [1528681218618, "{\"table\": \"orderBookL2\", \"action\": \"update\", \"data\": [{\"id\": 8799327400, \"side\": \"Buy\", \"size\": 132658}, {\"id\": 8799327650, \"side\": \"Buy\", \"size\": 19475}], \"symbol\": \"XBTUSD\", \"timestamp\": \"2018-06-11 01:40:18.614585Z\"}", "XBTUSD"], [1528681222580, "{\"table\": \"orderBookL2\", \"action\": \"update\", \"data\": [{\"id\": 8799326700, \"side\": \"Sell\", \"size\": 446030}], \"symbol\": \"XBTUSD\", \"timestamp\": \"2018-06-11 01:40:22.577919Z\"}", "XBTUSD"], [1528681224246, "{\"table\": \"orderBookL2\", \"action\": \"update\", \"data\": [{\"id\": 8799325500, \"side\": \"Sell\", \"size\": 131705}, {\"id\": 8799325700, \"side\": \"Sell\", \"size\": 115887}], \"symbol\": \"XBTUSD\", \"timestamp\": \"2018-06-11 01:40:24.243848Z\"}", "XBTUSD"], [1528681227974, "{\"table\": \"orderBookL2\", \"action\": \"update\", \"data\": [{\"id\": 8799326250, \"side\": \"Sell\", \"size\": 47840}, {\"id\": 8799326400, \"side\": \"Sell\", \"size\": 39166}, {\"id\": 8799327050, \"side\": \"Buy\", \"size\": 112965}, {\"id\": 8799327100, \"side\": \"Buy\", \"size\": 38739}], \"symbol\": \"XBTUSD\", \"timestamp\": \"2018-06-11 01:40:27.968903Z\"}", "XBTUSD"], [1528681232091, "{\"table\": \"orderBookL2\", \"action\": \"update\", \"data\": [{\"id\": 8799325750, \"side\": \"Sell\", \"size\": 33083}, {\"id\": 8799325900, \"side\": \"Sell\", \"size\": 26752}, {\"id\": 8799327050, \"side\": \"Buy\", \"size\": 114424}, {\"id\": 8799327100, \"side\": \"Buy\", \"size\": 44739}], \"symbol\": \"XBTUSD\", \"timestamp\": \"2018-06-11 01:40:32.088425Z\"}", "XBTUSD"], [1528681236043, "{\"table\": \"orderBookL2\", \"action\": \"update\", \"data\": [{\"id\": 8799325450, \"side\": \"Sell\", \"size\": 243865}], \"symbol\": \"XBTUSD\", \"timestamp\": \"2018-06-11 01:40:36.038021Z\"}", "XBTUSD"], [1528681239671, "{\"table\": \"trade\", \"action\": \"insert\", \"data\": [{\"timestamp\": \"2018-06-11T01:40:39.616Z\", \"side\": \"Buy\", \"size\": 10000, \"price\": 6733, \"tickDirection\": \"ZeroPlusTick\", \"trdMatchID\": \"05de2b56-3cd8-72be-ba37-5d6d84819396\", \"grossValue\": 148520000, \"homeNotional\": 1.4852, \"foreignNotional\": 10000}], \"symbol\": \"XBTUSD\", \"timestamp\": \"2018-06-11 01:40:39.662777Z\"}", "XBTUSD"], [1528681243802, "{\"table\": \"orderBookL2\", \"action\": \"update\", \"data\": [{\"id\": 8799298050, \"side\": \"Sell\", \"size\": 1200}, {\"id\": 8799310150, \"side\": \"Sell\", \"size\": 3041}, {\"id\": 8799318900, \"side\": \"Sell\", \"size\": 78161}, {\"id\": 8799324300, \"side\": \"Sell\", \"size\": 385505}, {\"id\": 8799333250, \"side\": \"Buy\", \"size\": 1850}, {\"id\": 8799334050, \"side\": \"Buy\", \"size\": 76580}, {\"id\": 8799342800, \"side\": \"Buy\", \"size\": 16218}, {\"id\": 8799354900, \"side\": \"Buy\", \"size\": 48134}, {\"id\": 8799370400, \"side\": \"Buy\", \"size\": 153600}], \"symbol\": \"XBTUSD\", \"timestamp\": \"2018-06-11 01:40:43.799837Z\"}", "XBTUSD"], [1528681247913, "{\"table\": \"orderBookL2\", \"action\": \"update\", \"data\": [{\"id\": 8799325950, \"side\": \"Sell\", \"size\": 17755}, {\"id\": 8799326100, \"side\": \"Sell\", \"size\": 20651}], \"symbol\": \"XBTUSD\", \"timestamp\": \"2018-06-11 01:40:47.909554Z\"}", "XBTUSD"], [1528681250541, "{\"table\": \"orderBookL2\", \"action\": \"update\", \"data\": [{\"id\": 8799327000, \"side\": \"Buy\", \"size\": 75334}, {\"id\": 8799327050, \"side\": \"Buy\", \"size\": 101051}], \"symbol\": \"XBTUSD\", \"timestamp\": \"2018-06-11 01:40:50.538655Z\"}", "XBTUSD"], [1528681253840, "{\"table\": \"orderBookL2\", \"action\": \"update\", \"data\": [{\"id\": 8799326750, \"side\": \"Buy\", \"size\": 1792903}], \"symbol\": \"XBTUSD\", \"timestamp\": \"2018-06-11 01:40:53.834026Z\"}", "XBTUSD"], [1528681257153, "{\"table\": \"orderBookL2\", \"action\": \"update\", \"data\": [{\"id\": 8799326700, \"side\": \"Sell\", \"size\": 703715}], \"symbol\": \"XBTUSD\", \"timestamp\": \"2018-06-11 01:40:57.150636Z\"}", "XBTUSD"], [1528681260073, "{\"table\": \"trade\", \"action\": \"insert\", \"data\": [{\"timestamp\": \"2018-06-11T01:41:00.040Z\", \"side\": \"Buy\", \"size\": 70000, \"price\": 6733, \"tickDirection\": \"PlusTick\", \"trdMatchID\": \"acc8bea1-c1d8-87c4-6db9-9ce698fbd8c4\", \"grossValue\": 1039640000, \"homeNotional\": 10.3964, \"foreignNotional\": 70000}], \"symbol\": \"XBTUSD\", \"timestamp\": \"2018-06-11 01:41:00.067963Z\"}", "XBTUSD"], [1528681264916, "{\"table\": \"orderBookL2\", \"action\": \"update\", \"data\": [{\"id\": 8799326100, \"side\": \"Sell\", \"size\": 25499}, {\"id\": 8799326200, \"side\": \"Sell\", \"size\": 24823}], \"symbol\": \"XBTUSD\", \"timestamp\": \"2018-06-11 01:41:04.913559Z\"}", "XBTUSD"], [1528681266459, "{\"table\": \"orderBookL2\", \"action\": \"update\", \"data\": [{\"id\": 8799327500, \"side\": \"Buy\", \"size\": 34550}, {\"id\": 8799377500, \"side\": \"Buy\", \"size\": 5025}], \"symbol\": \"XBTUSD\", \"timestamp\": \"2018-06-11 01:41:06.452875Z\"}", "XBTUSD"], [1528681269604, "{\"table\": \"orderBookL2\", \"action\": \"delete\", \"data\": [{\"id\": 8799932700, \"side\": \"Buy\"}], \"symbol\": \"XBTUSD\", \"timestamp\": \"2018-06-11 01:41:09.601935Z\"}", "XBTUSD"], [1528681274379, "{\"table\": \"orderBookL2\", \"action\": \"update\", \"data\": [{\"id\": 8799326400, \"side\": \"Sell\", \"size\": 31366}, {\"id\": 8799328000, \"side\": \"Buy\", \"size\": 220480}], \"symbol\": \"XBTUSD\", \"timestamp\": \"2018-06-11 01:41:14.374238Z\"}", "XBTUSD"], [1528681277843, "{\"table\": \"orderBookL2\", \"action\": \"update\", \"data\": [{\"id\": 8799326600, \"side\": \"Sell\", \"size\": 59180}], \"symbol\": \"XBTUSD\", \"timestamp\": \"2018-06-11 01:41:17.837956Z\"}", "XBTUSD"], [1528681281719, "{\"table\": \"orderBookL2\", \"action\": \"update\", \"data\": [{\"id\": 8799325800, \"side\": \"Sell\", \"size\": 62527}, {\"id\": 8799326100, \"side\": \"Sell\", \"size\": 7701}], \"symbol\": \"XBTUSD\", \"timestamp\": \"2018-06-11 01:41:21.714003Z\"}", "XBTUSD"], [1528681286328, "{\"table\": \"orderBookL2\", \"action\": \"update\", \"data\": [{\"id\": 8799326700, \"side\": \"Sell\", \"size\": 733916}], \"symbol\": \"XBTUSD\", \"timestamp\": \"2018-06-11 01:41:26.324561Z\"}", "XBTUSD"], [1528681289586, "{\"table\": \"orderBookL2\", \"action\": \"update\", \"data\": [{\"id\": 8793266900, \"side\": \"Sell\", \"size\": 406}], \"symbol\": \"XBTUSD\", \"timestamp\": \"2018-06-11 01:41:29.583183Z\"}", "XBTUSD"], [1528681293115, "{\"table\": \"quote\", \"action\": \"insert\", \"data\": [{\"timestamp\": \"2018-06-11T01:41:32.363Z\", \"bidSize\": 1719634, \"bidPrice\": 6732.5, \"askPrice\": 6733, \"askSize\": 87677}], \"symbol\": \"XBTUSD\", \"timestamp\": \"2018-06-11 01:41:33.110037Z\"}", "XBTUSD"], [1528681296354, "{\"table\": \"orderBookL2\", \"action\": \"update\", \"data\": [{\"id\": 8799326500, \"side\": \"Sell\", \"size\": 341325}], \"symbol\": \"XBTUSD\", \"timestamp\": \"2018-06-11 01:41:36.349434Z\"}", "XBTUSD"], [1528681299287, "{\"table\": \"orderBookL2\", \"action\": \"update\", \"data\": [{\"id\": 8799326050, \"side\": \"Sell\", \"size\": 46072}, {\"id\": 8799326400, \"side\": \"Sell\", \"size\": 70386}, {\"id\": 8799326900, \"side\": \"Buy\", \"size\": 163306}, {\"id\": 8799327000, \"side\": \"Buy\", \"size\": 138899}], \"symbol\": \"XBTUSD\", \"timestamp\": \"2018-06-11 01:41:39.284446Z\"}", "XBTUSD"], [1528681300267, "{\"table\": \"orderBookL2\", \"action\": \"update\", \"data\": [{\"id\": 8799326800, \"side\": \"Buy\", \"size\": 58781}], \"symbol\": \"XBTUSD\", \"timestamp\": \"2018-06-11 01:41:40.263307Z\"}", "XBTUSD"], [1528681301234, "{\"table\": \"orderBookL2\", \"action\": \"update\", \"data\": [{\"id\": 8799327700, \"side\": \"Buy\", \"size\": 63894}, {\"id\": 8799327800, \"side\": \"Buy\", \"size\": 350426}], \"symbol\": \"XBTUSD\", \"timestamp\": \"2018-06-11 01:41:41.229310Z\"}", "XBTUSD"], [1528681302420, "{\"table\": \"trade\", \"action\": \"insert\", \"data\": [{\"timestamp\": \"2018-06-11T01:41:42.285Z\", \"side\": \"Sell\", \"size\": 200, \"price\": 6733, \"tickDirection\": \"MinusTick\", \"trdMatchID\": \"09416c79-4ed8-5cc1-3cfe-3a532816dd2f\", \"grossValue\": 2970400, \"homeNotional\": 0.029704, \"foreignNotional\": 200}], \"symbol\": \"XBTUSD\", \"timestamp\": \"2018-06-11 01:41:42.416983Z\"}", "XBTUSD"], [1528681303198, "{\"table\": \"orderBookL2\", \"action\": \"update\", \"data\": [{\"id\": 8799326650, \"side\": \"Buy\", \"size\": 87569}, {\"id\": 8799326700, \"side\": \"Buy\", \"size\": 1804463}], \"symbol\": \"XBTUSD\", \"timestamp\": \"2018-06-11 01:41:43.194863Z\"}", "XBTUSD"], [1528681303999, "{\"table\": \"orderBookL2\", \"action\": \"insert\", \"data\": [{\"id\": 8799326600, \"side\": \"Buy\", \"size\": 5000, \"price\": 6734}], \"symbol\": \"XBTUSD\", \"timestamp\": \"2018-06-11 01:41:43.992886Z\"}", "XBTUSD"], [1528681304581, "{\"table\": \"orderBookL2\", \"action\": \"update\", \"data\": [{\"id\": 8799326600, \"side\": \"Buy\", \"size\": 445689}, {\"id\": 8799326650, \"side\": \"Buy\", \"size\": 738806}], \"symbol\": \"XBTUSD\", \"timestamp\": \"2018-06-11 01:41:44.578233Z\"}", "XBTUSD"], [1528681305216, "{\"table\": \"orderBookL2\", \"action\": \"update\", \"data\": [{\"id\": 8799326250, \"side\": \"Buy\", \"size\": 683116}, {\"id\": 8799326650, \"side\": \"Buy\", \"size\": 481581}], \"symbol\": \"XBTUSD\", \"timestamp\": \"2018-06-11 01:41:45.213412Z\"}", "XBTUSD"], [1528681309123, "{\"table\": \"orderBookL2\", \"action\": \"update\", \"data\": [{\"id\": 8799323100, \"side\": \"Sell\", \"size\": 6464}, {\"id\": 8799327300, \"side\": \"Buy\", \"size\": 189739}], \"symbol\": \"XBTUSD\", \"timestamp\": \"2018-06-11 01:41:49.120838Z\"}", "XBTUSD"], [1528681309287, "{\"table\": \"orderBookL2\", \"action\": \"update\", \"data\": [{\"id\": 8799326050, \"side\": \"Sell\", \"size\": 39472}, {\"id\": 8799327650, \"side\": \"Buy\", \"size\": 30400}], \"symbol\": \"XBTUSD\", \"timestamp\": \"2018-06-11 01:41:49.283109Z\"}", "XBTUSD"], [1528681309750, "{\"table\": \"orderBookL2\", \"action\": \"update\", \"data\": [{\"id\": 8799326150, \"side\": \"Buy\", \"size\": 97500}, {\"id\": 8799326200, \"side\": \"Buy\", \"size\": 104311}], \"symbol\": \"XBTUSD\", \"timestamp\": \"2018-06-11 01:41:49.746712Z\"}", "XBTUSD"], [1528681310067, "{\"table\": \"orderBookL2\", \"action\": \"update\", \"data\": [{\"id\": 8799326750, \"side\": \"Buy\", \"size\": 568525}], \"symbol\": \"XBTUSD\", \"timestamp\": \"2018-06-11 01:41:50.062503Z\"}", "XBTUSD"], [1528681311027, "{\"table\": \"orderBookL2\", \"action\": \"update\", \"data\": [{\"id\": 8799325150, \"side\": \"Sell\", \"size\": 2012}], \"symbol\": \"XBTUSD\", \"timestamp\": \"2018-06-11 01:41:51.023986Z\"}", "XBTUSD"], [1528681313878, "{\"table\": \"orderBookL2\", \"action\": \"update\", \"data\": [{\"id\": 8799327500, \"side\": \"Buy\", \"size\": 39800}, {\"id\": 8799327600, \"side\": \"Buy\", \"size\": 279101}], \"symbol\": \"XBTUSD\", \"timestamp\": \"2018-06-11 01:41:53.875983Z\"}", "XBTUSD"], [1528681314072, "{\"table\": \"orderBookL2\", \"action\": \"update\", \"data\": [{\"id\": 8799325850, \"side\": \"Buy\", \"size\": 1249798}, {\"id\": 8799326250, \"side\": \"Buy\", \"size\": 308531}], \"symbol\": \"XBTUSD\", \"timestamp\": \"2018-06-11 01:41:54.069408Z\"}", "XBTUSD"], [1528681314304, "{\"table\": \"orderBookL2\", \"action\": \"update\", \"data\": [{\"id\": 8799325850, \"side\": \"Buy\", \"size\": 1386113}], \"symbol\": \"XBTUSD\", \"timestamp\": \"2018-06-11 01:41:54.302352Z\"}", "XBTUSD"], [1528681314581, "{\"table\": \"orderBookL2\", \"action\": \"update\", \"data\": [{\"id\": 8799324850, \"side\": \"Sell\", \"size\": 31965}, {\"id\": 8799325700, \"side\": \"Sell\", \"size\": 113000}], \"symbol\": \"XBTUSD\", \"timestamp\": \"2018-06-11 01:41:54.576795Z\"}", "XBTUSD"], [1528681315106, "{\"table\": \"orderBookL2\", \"action\": \"update\", \"data\": [{\"id\": 8799275100, \"side\": \"Sell\", \"size\": 49920}, {\"id\": 8799275300, \"side\": \"Sell\", \"size\": 71047}, {\"id\": 8799275500, \"side\": \"Sell\", \"size\": 230515}, {\"id\": 8799275700, \"side\": \"Sell\", \"size\": 27800}, {\"id\": 8799275800, \"side\": \"Sell\", \"size\": 48120}, {\"id\": 8799326300, \"side\": \"Buy\", \"size\": 139860}, {\"id\": 8799326500, \"side\": \"Buy\", \"size\": 31619}, {\"id\": 8799326700, \"side\": \"Buy\", \"size\": 94824}], \"symbol\": \"XBTUSD\", \"timestamp\": \"2018-06-11 01:41:55.104280Z\"}", "XBTUSD"], [1528681317628, "{\"table\": \"orderBookL2\", \"action\": \"update\", \"data\": [{\"id\": 8799344450, \"side\": \"Buy\", \"size\": 79974}, {\"id\": 8799344950, \"side\": \"Buy\", \"size\": 30590}], \"symbol\": \"XBTUSD\", \"timestamp\": \"2018-06-11 01:41:57.625275Z\"}", "XBTUSD"], [1528681317919, "{\"table\": \"orderBookL2\", \"action\": \"update\", \"data\": [{\"id\": 8799315800, \"side\": \"Sell\", \"size\": 88898}, {\"id\": 8799315900, \"side\": \"Sell\", \"size\": 804450}, {\"id\": 8799317200, \"side\": \"Sell\", \"size\": 111306}, {\"id\": 8799317300, \"side\": \"Sell\", \"size\": 2093}, {\"id\": 8799318600, \"side\": \"Sell\", \"size\": 45520}, {\"id\": 8799318700, \"side\": \"Sell\", \"size\": 59025}, {\"id\": 8799328700, \"side\": \"Buy\", \"size\": 64324}, {\"id\": 8799328800, \"side\": \"Buy\", \"size\": 148118}, {\"id\": 8799330100, \"side\": \"Buy\", \"size\": 44790}, {\"id\": 8799330200, \"side\": \"Buy\", \"size\": 8139}, {\"id\": 8799331500, \"side\": \"Buy\", \"size\": 161906}, {\"id\": 8799331600, \"side\": \"Buy\", \"size\": 120146}], \"symbol\": \"XBTUSD\", \"timestamp\": \"2018-06-11 01:41:57.915610Z\"}", "XBTUSD"], [1528681319301, "{\"table\": \"orderBookL2\", \"action\": \"update\", \"data\": [{\"id\": 8799325800, \"side\": \"Sell\", \"size\": 40145}], \"symbol\": \"XBTUSD\", \"timestamp\": \"2018-06-11 01:41:59.298746Z\"}", "XBTUSD"], [1528681322301, "{\"table\": \"trade\", \"action\": \"insert\", \"data\": [{\"timestamp\": \"2018-06-11T01:42:01.440Z\", \"side\": \"Buy\", \"size\": 1000, \"price\": 6742, \"tickDirection\": \"ZeroPlusTick\", \"trdMatchID\": \"b7152dec-84eb-c9bc-36b7-ab038f45a21b\", \"grossValue\": 14832000, \"homeNotional\": 0.14832, \"foreignNotional\": 1000}], \"symbol\": \"XBTUSD\", \"timestamp\": \"2018-06-11 01:42:02.296623Z\"}", "XBTUSD"], [1528681324785, "{\"table\": \"orderBookL2\", \"action\": \"update\", \"data\": [{\"id\": 8799325100, \"side\": \"Sell\", \"size\": 24171}, {\"id\": 8799325550, \"side\": \"Sell\", \"size\": 71809}], \"symbol\": \"XBTUSD\", \"timestamp\": \"2018-06-11 01:42:04.781336Z\"}", "XBTUSD"], [1528681325069, "{\"table\": \"orderBookL2\", \"action\": \"update\", \"data\": [{\"id\": 8799325850, \"side\": \"Buy\", \"size\": 1592584}], \"symbol\": \"XBTUSD\", \"timestamp\": \"2018-06-11 01:42:05.067295Z\"}", "XBTUSD"], [1528681327378, "{\"table\": \"orderBookL2\", \"action\": \"update\", \"data\": [{\"id\": 8799280050, \"side\": \"Sell\", \"size\": 1143}, {\"id\": 8799280150, \"side\": \"Sell\", \"size\": 200}], \"symbol\": \"XBTUSD\", \"timestamp\": \"2018-06-11 01:42:07.372102Z\"}", "XBTUSD"], [1528681329177, "{\"table\": \"orderBookL2\", \"action\": \"update\", \"data\": [{\"id\": 8799325500, \"side\": \"Sell\", \"size\": 167229}, {\"id\": 8799325800, \"side\": \"Sell\", \"size\": 419834}, {\"id\": 8799326350, \"side\": \"Buy\", \"size\": 157297}, {\"id\": 8799326450, \"side\": \"Buy\", \"size\": 14281}], \"symbol\": \"XBTUSD\", \"timestamp\": \"2018-06-11 01:42:09.174645Z\"}", "XBTUSD"], [1528681330053, "{\"table\": \"orderBookL2\", \"action\": \"update\", \"data\": [{\"id\": 8799325850, \"side\": \"Buy\", \"size\": 1567138}], \"symbol\": \"XBTUSD\", \"timestamp\": \"2018-06-11 01:42:10.051160Z\"}", "XBTUSD"], [1528681332037, "{\"table\": \"orderBookL2\", \"action\": \"update\", \"data\": [{\"id\": 8799325850, \"side\": \"Buy\", \"size\": 1673249}], \"symbol\": \"XBTUSD\", \"timestamp\": \"2018-06-11 01:42:12.033728Z\"}", "XBTUSD"], [1528681334650, "{\"table\": \"orderBookL2\", \"action\": \"update\", \"data\": [{\"id\": 8799326650, \"side\": \"Buy\", \"size\": 35695}, {\"id\": 8799326750, \"side\": \"Buy\", \"size\": 402361}], \"symbol\": \"XBTUSD\", \"timestamp\": \"2018-06-11 01:42:14.644756Z\"}", "XBTUSD"], [1528681336927, "{\"table\": \"orderBookL2\", \"action\": \"update\", \"data\": [{\"id\": 8799325600, \"side\": \"Sell\", \"size\": 8209}, {\"id\": 8799325650, \"side\": \"Sell\", \"size\": 124271}], \"symbol\": \"XBTUSD\", \"timestamp\": \"2018-06-11 01:42:16.919653Z\"}", "XBTUSD"], [1528681338956, "{\"table\": \"orderBookL2\", \"action\": \"update\", \"data\": [{\"id\": 8799325700, \"side\": \"Sell\", \"size\": 157095}], \"symbol\": \"XBTUSD\", \"timestamp\": \"2018-06-11 01:42:18.944106Z\"}", "XBTUSD"], [1528681340255, "{\"table\": \"orderBookL2\", \"action\": \"update\", \"data\": [{\"id\": 8799325850, \"side\": \"Buy\", \"size\": 1339615}], \"symbol\": \"XBTUSD\", \"timestamp\": \"2018-06-11 01:42:20.252789Z\"}", "XBTUSD"], [1528681341289, "{\"table\": \"orderBookL2\", \"action\": \"update\", \"data\": [{\"id\": 8799325850, \"side\": \"Buy\", \"size\": 1605696}], \"symbol\": \"XBTUSD\", \"timestamp\": \"2018-06-11 01:42:21.287240Z\"}", "XBTUSD"], [1528681344287, "{\"table\": \"orderBookL2\", \"action\": \"update\", \"data\": [{\"id\": 8799325850, \"side\": \"Buy\", \"size\": 1744562}], \"symbol\": \"XBTUSD\", \"timestamp\": \"2018-06-11 01:42:24.280522Z\"}", "XBTUSD"], [1528681347669, "{\"table\": \"orderBookL2\", \"action\": \"update\", \"data\": [{\"id\": 8799325750, \"side\": \"Sell\", \"size\": 165}], \"symbol\": \"XBTUSD\", \"timestamp\": \"2018-06-11 01:42:27.664764Z\"}", "XBTUSD"], [1528681348403, "{\"table\": \"orderBookL2\", \"action\": \"update\", \"data\": [{\"id\": 8799326100, \"side\": \"Buy\", \"size\": 105763}], \"symbol\": \"XBTUSD\", \"timestamp\": \"2018-06-11 01:42:28.400491Z\"}", "XBTUSD"], [1528681353139, "{\"table\": \"orderBookL2\", \"action\": \"update\", \"data\": [{\"id\": 8799275100, \"side\": \"Sell\", \"size\": 51520}, {\"id\": 8799275300, \"side\": \"Sell\", \"size\": 72647}, {\"id\": 8799275500, \"side\": \"Sell\", \"size\": 232115}, {\"id\": 8799275700, \"side\": \"Sell\", \"size\": 29400}, {\"id\": 8799275800, \"side\": \"Sell\", \"size\": 49720}, {\"id\": 8799326100, \"side\": \"Buy\", \"size\": 95763}, {\"id\": 8799326300, \"side\": \"Buy\", \"size\": 146732}, {\"id\": 8799326500, \"side\": \"Buy\", \"size\": 108193}, {\"id\": 8799326700, \"side\": \"Buy\", \"size\": 46384}, {\"id\": 8799376700, \"side\": \"Buy\", \"size\": 39950}], \"symbol\": \"XBTUSD\", \"timestamp\": \"2018-06-11 01:42:33.130779Z\"}", "XBTUSD"], [1528681353492, "{\"table\": \"trade\", \"action\": \"insert\", \"data\": [{\"timestamp\": \"2018-06-11T01:42:32.868Z\", \"side\": \"Sell\", \"size\": 1, \"price\": 6744, \"tickDirection\": \"MinusTick\", \"trdMatchID\": \"c66d497b-9a7d-01d5-467a-f4325f7c3c9e\", \"grossValue\": 14828, \"homeNotional\": 0.00014828, \"foreignNotional\": 1}], \"symbol\": \"XBTUSD\", \"timestamp\": \"2018-06-11 01:42:33.490293Z\"}", "XBTUSD"], [1528681353983, "{\"table\": \"orderBookL2\", \"action\": \"update\", \"data\": [{\"id\": 8799323800, \"side\": \"Sell\", \"size\": 101063}, {\"id\": 8799324050, \"side\": \"Sell\", \"size\": 66466}, {\"id\": 8799324550, \"side\": \"Sell\", \"size\": 291198}, {\"id\": 8799324800, \"side\": \"Sell\", \"size\": 179518}, {\"id\": 8799326600, \"side\": \"Buy\", \"size\": 120914}, {\"id\": 8799326800, \"side\": \"Buy\", \"size\": 132895}, {\"id\": 8799327350, \"side\": \"Buy\", \"size\": 94770}, {\"id\": 8799327550, \"side\": \"Buy\", \"size\": 54427}], \"symbol\": \"XBTUSD\", \"timestamp\": \"2018-06-11 01:42:33.978283Z\"}", "XBTUSD"], [1528681354696, "{\"table\": \"orderBookL2\", \"action\": \"update\", \"data\": [{\"id\": 8799325600, \"side\": \"Buy\", \"size\": 1368613}, {\"id\": 8799325850, \"side\": \"Buy\", \"size\": 331598}], \"symbol\": \"XBTUSD\", \"timestamp\": \"2018-06-11 01:42:34.693965Z\"}", "XBTUSD"], [1528681355512, "{\"table\": \"orderBookL2\", \"action\": \"update\", \"data\": [{\"id\": 8799324250, \"side\": \"Sell\", \"size\": 50040}], \"symbol\": \"XBTUSD\", \"timestamp\": \"2018-06-11 01:42:35.510407Z\"}", "XBTUSD"], [1528681357143, "{\"table\": \"orderBookL2\", \"action\": \"update\", \"data\": [{\"id\": 8799325950, \"side\": \"Buy\", \"size\": 55055}], \"symbol\": \"XBTUSD\", \"timestamp\": \"2018-06-11 01:42:37.132947Z\"}", "XBTUSD"], [1528681358869, "{\"table\": \"orderBookL2\", \"action\": \"update\", \"data\": [{\"id\": 8799322450, \"side\": \"Sell\", \"size\": 7060}], \"symbol\": \"XBTUSD\", \"timestamp\": \"2018-06-11 01:42:38.866433Z\"}", "XBTUSD"], [1528681361187, "{\"table\": \"orderBookL2\", \"action\": \"update\", \"data\": [{\"id\": 8799325550, \"side\": \"Sell\", \"size\": 430285}], \"symbol\": \"XBTUSD\", \"timestamp\": \"2018-06-11 01:42:41.178282Z\"}", "XBTUSD"], [1528681363266, "{\"table\": \"orderBookL2\", \"action\": \"update\", \"data\": [{\"id\": 8799325450, \"side\": \"Sell\", \"size\": 15795}, {\"id\": 8799325650, \"side\": \"Buy\", \"size\": 27521}], \"symbol\": \"XBTUSD\", \"timestamp\": \"2018-06-11 01:42:43.263720Z\"}", "XBTUSD"], [1528681365866, "{\"table\": \"orderBookL2\", \"action\": \"update\", \"data\": [{\"id\": 8799325550, \"side\": \"Sell\", \"size\": 611753}], \"symbol\": \"XBTUSD\", \"timestamp\": \"2018-06-11 01:42:45.861029Z\"}", "XBTUSD"], [1528681368044, "{\"table\": \"orderBookL2\", \"action\": \"update\", \"data\": [{\"id\": 8799325600, \"side\": \"Buy\", \"size\": 1439511}], \"symbol\": \"XBTUSD\", \"timestamp\": \"2018-06-11 01:42:48.041410Z\"}", "XBTUSD"], [1528681370062, "{\"table\": \"orderBookL2\", \"action\": \"update\", \"data\": [{\"id\": 8799325550, \"side\": \"Sell\", \"size\": 763335}], \"symbol\": \"XBTUSD\", \"timestamp\": \"2018-06-11 01:42:50.058093Z\"}", "XBTUSD"], [1528681372727, "{\"table\": \"orderBookL2\", \"action\": \"update\", \"data\": [{\"id\": 8799325600, \"side\": \"Buy\", \"size\": 657015}], \"symbol\": \"XBTUSD\", \"timestamp\": \"2018-06-11 01:42:52.719982Z\"}", "XBTUSD"], [1528681373460, "{\"table\": \"orderBookL2\", \"action\": \"update\", \"data\": [{\"id\": 8799325600, \"side\": \"Buy\", \"size\": 511127}], \"symbol\": \"XBTUSD\", \"timestamp\": \"2018-06-11 01:42:53.458133Z\"}", "XBTUSD"], [1528681374645, "{\"table\": \"orderBookL2\", \"action\": \"update\", \"data\": [{\"id\": 8799333250, \"side\": \"Buy\", \"size\": 1050}], \"symbol\": \"XBTUSD\", \"timestamp\": \"2018-06-11 01:42:54.643080Z\"}", "XBTUSD"], [1528681378371, "{\"table\": \"orderBookL2\", \"action\": \"update\", \"data\": [{\"id\": 8799326200, \"side\": \"Buy\", \"size\": 22595}], \"symbol\": \"XBTUSD\", \"timestamp\": \"2018-06-11 01:42:58.365917Z\"}", "XBTUSD"], [1528681379107, "{\"table\": \"orderBookL2\", \"action\": \"update\", \"data\": [{\"id\": 8799325600, \"side\": \"Sell\", \"size\": 7446}, {\"id\": 8799325700, \"side\": \"Sell\", \"size\": 47237}], \"symbol\": \"XBTUSD\", \"timestamp\": \"2018-06-11 01:42:59.103812Z\"}", "XBTUSD"], [1528681379425, "{\"table\": \"orderBookL2\", \"action\": \"update\", \"data\": [{\"id\": 8799324500, \"side\": \"Sell\", \"size\": 421058}], \"symbol\": \"XBTUSD\", \"timestamp\": \"2018-06-11 01:42:59.421942Z\"}", "XBTUSD"], [1528681380231, "{\"table\": \"orderBookL2\", \"action\": \"update\", \"data\": [{\"id\": 8799325500, \"side\": \"Sell\", \"size\": 427372}], \"symbol\": \"XBTUSD\", \"timestamp\": \"2018-06-11 01:43:00.224471Z\"}", "XBTUSD"], [1528681384571, "{\"table\": \"orderBookL2\", \"action\": \"update\", \"data\": [{\"id\": 8799325800, \"side\": \"Sell\", \"size\": 410739}, {\"id\": 8799325850, \"side\": \"Sell\", \"size\": 1011505}], \"symbol\": \"XBTUSD\", \"timestamp\": \"2018-06-11 01:43:04.568513Z\"}", "XBTUSD"], [1528681384903, "{\"table\": \"orderBookL2\", \"action\": \"insert\", \"data\": [{\"id\": 8799325950, \"side\": \"Sell\", \"size\": 5000, \"price\": 6740.5}], \"symbol\": \"XBTUSD\", \"timestamp\": \"2018-06-11 01:43:04.900811Z\"}", "XBTUSD"], [1528681385224, "{\"table\": \"orderBookL2\", \"action\": \"update\", \"data\": [{\"id\": 8799325850, \"side\": \"Sell\", \"size\": 1011235}], \"symbol\": \"XBTUSD\", \"timestamp\": \"2018-06-11 01:43:05.220484Z\"}", "XBTUSD"], [1528681385399, "{\"table\": \"orderBookL2\", \"action\": \"update\", \"data\": [{\"id\": 8799325850, \"side\": \"Sell\", \"size\": 1411385}, {\"id\": 8799325900, \"side\": \"Sell\", \"size\": 574260}], \"symbol\": \"XBTUSD\", \"timestamp\": \"2018-06-11 01:43:05.396368Z\"}", "XBTUSD"], [1528681387930, "{\"table\": \"orderBookL2\", \"action\": \"update\", \"data\": [{\"id\": 8798839100, \"side\": \"Sell\", \"size\": 118}], \"symbol\": \"XBTUSD\", \"timestamp\": \"2018-06-11 01:43:07.927895Z\"}", "XBTUSD"], [1528681389036, "{\"table\": \"orderBookL2\", \"action\": \"update\", \"data\": [{\"id\": 8799320100, \"side\": \"Sell\", \"size\": 574925}], \"symbol\": \"XBTUSD\", \"timestamp\": \"2018-06-11 01:43:09.034117Z\"}", "XBTUSD"], [1528681389264, "{\"table\": \"orderBookL2\", \"action\": \"update\", \"data\": [{\"id\": 8799326800, \"side\": \"Buy\", \"size\": 180923}, {\"id\": 8799326950, \"side\": \"Buy\", \"size\": 77377}], \"symbol\": \"XBTUSD\", \"timestamp\": \"2018-06-11 01:43:09.261320Z\"}", "XBTUSD"], [1528681389730, "{\"table\": \"orderBookL2\", \"action\": \"update\", \"data\": [{\"id\": 8799325850, \"side\": \"Sell\", \"size\": 130488}, {\"id\": 8799328400, \"side\": \"Buy\", \"size\": 187965}], \"symbol\": \"XBTUSD\", \"timestamp\": \"2018-06-11 01:43:09.727433Z\"}", "XBTUSD"], [1528681393786, "{\"table\": \"quote\", \"action\": \"insert\", \"data\": [{\"timestamp\": \"2018-06-11T01:43:10.866Z\", \"bidSize\": 735388, \"bidPrice\": 6740, \"askPrice\": 6740.5, \"askSize\": 1556349}, {\"timestamp\": \"2018-06-11T01:43:10.876Z\", \"bidSize\": 735409, \"bidPrice\": 6740, \"askPrice\": 6740.5, \"askSize\": 1556349}, {\"timestamp\": \"2018-06-11T01:43:10.988Z\", \"bidSize\": 733409, \"bidPrice\": 6740, \"askPrice\": 6740.5, \"askSize\": 1556349}, {\"timestamp\": \"2018-06-11T01:43:11.047Z\", \"bidSize\": 783409, \"bidPrice\": 6740, \"askPrice\": 6740.5, \"askSize\": 1556349}, {\"timestamp\": \"2018-06-11T01:43:11.058Z\", \"bidSize\": 777409, \"bidPrice\": 6740, \"askPrice\": 6740.5, \"askSize\": 1556349}, {\"timestamp\": \"2018-06-11T01:43:11.190Z\", \"bidSize\": 771409, \"bidPrice\": 6740, \"askPrice\": 6740.5, \"askSize\": 1556349}, {\"timestamp\": \"2018-06-11T01:43:11.196Z\", \"bidSize\": 765409, \"bidPrice\": 6740, \"askPrice\": 6740.5, \"askSize\": 1556349}, {\"timestamp\": \"2018-06-11T01:43:11.207Z\", \"bidSize\": 765409, \"bidPrice\": 6740, \"askPrice\": 6740.5, \"askSize\": 1556399}, {\"timestamp\": \"2018-06-11T01:43:11.210Z\", \"bidSize\": 759409, \"bidPrice\": 6740, \"askPrice\": 6740.5, \"askSize\": 1556399}, {\"timestamp\": \"2018-06-11T01:43:11.214Z\", \"bidSize\": 753409, \"bidPrice\": 6740, \"askPrice\": 6740.5, \"askSize\": 1556399}, {\"timestamp\": \"2018-06-11T01:43:11.227Z\", \"bidSize\": 763409, \"bidPrice\": 6740, \"askPrice\": 6740.5, \"askSize\": 1556399}, {\"timestamp\": \"2018-06-11T01:43:11.241Z\", \"bidSize\": 763409, \"bidPrice\": 6740, \"askPrice\": 6740.5, \"askSize\": 1456399}, {\"timestamp\": \"2018-06-11T01:43:11.283Z\", \"bidSize\": 758409, \"bidPrice\": 6740, \"askPrice\": 6740.5, \"askSize\": 1456399}, {\"timestamp\": \"2018-06-11T01:43:11.298Z\", \"bidSize\": 758409, \"bidPrice\": 6740, \"askPrice\": 6740.5, \"askSize\": 1456400}, {\"timestamp\": \"2018-06-11T01:43:11.387Z\", \"bidSize\": 758410, \"bidPrice\": 6740, \"askPrice\": 6740.5, \"askSize\": 1456400}, {\"timestamp\": \"2018-06-11T01:43:11.432Z\", \"bidSize\": 758410, \"bidPrice\": 6740, \"askPrice\": 6740.5, \"askSize\": 1456000}, {\"timestamp\": \"2018-06-11T01:43:11.560Z\", \"bidSize\": 760890, \"bidPrice\": 6740, \"askPrice\": 6740.5, \"askSize\": 1456000}, {\"timestamp\": \"2018-06-11T01:43:11.567Z\", \"bidSize\": 760966, \"bidPrice\": 6740, \"askPrice\": 6740.5, \"askSize\": 1456000}, {\"timestamp\": \"2018-06-11T01:43:11.664Z\", \"bidSize\": 760945, \"bidPrice\": 6740, \"askPrice\": 6740.5, \"askSize\": 1456000}, {\"timestamp\": \"2018-06-11T01:43:11.816Z\", \"bidSize\": 760945, \"bidPrice\": 6740, \"askPrice\": 6740.5, \"askSize\": 1466000}, {\"timestamp\": \"2018-06-11T01:43:11.932Z\", \"bidSize\": 750945, \"bidPrice\": 6740, \"askPrice\": 6740.5, \"askSize\": 1466000}, {\"timestamp\": \"2018-06-11T01:43:12.027Z\", \"bidSize\": 750945, \"bidPrice\": 6740, \"askPrice\": 6740.5, \"askSize\": 1459934}], \"symbol\": \"XBTUSD\", \"timestamp\": \"2018-06-11 01:43:13.779791Z\"}", "XBTUSD"], [1528681394428, "{\"table\": \"orderBookL2\", \"action\": \"update\", \"data\": [{\"id\": 8799326100, \"side\": \"Buy\", \"size\": 96869}], \"symbol\": \"XBTUSD\", \"timestamp\": \"2018-06-11 01:43:14.425106Z\"}", "XBTUSD"], [1528681397300, "{\"table\": \"orderBookL2\", \"action\": \"update\", \"data\": [{\"id\": 8799326000, \"side\": \"Buy\", \"size\": 751617}], \"symbol\": \"XBTUSD\", \"timestamp\": \"2018-06-11 01:43:17.292138Z\"}", "XBTUSD"], [1528681398957, "{\"table\": \"orderBookL2\", \"action\": \"update\", \"data\": [{\"id\": 8799325900, \"side\": \"Sell\", \"size\": 176490}, {\"id\": 8799325950, \"side\": \"Sell\", \"size\": 1397618}], \"symbol\": \"XBTUSD\", \"timestamp\": \"2018-06-11 01:43:18.955024Z\"}", "XBTUSD"], [1528681400971, "{\"table\": \"orderBookL2\", \"action\": \"update\", \"data\": [{\"id\": 8799326400, \"side\": \"Buy\", \"size\": 38481}], \"symbol\": \"XBTUSD\", \"timestamp\": \"2018-06-11 01:43:20.969234Z\"}", "XBTUSD"], [1528681402787, "{\"table\": \"orderBookL2\", \"action\": \"update\", \"data\": [{\"id\": 8799326000, \"side\": \"Sell\", \"size\": 257752}], \"symbol\": \"XBTUSD\", \"timestamp\": \"2018-06-11 01:43:22.783611Z\"}", "XBTUSD"], [1528681403552, "{\"table\": \"orderBookL2\", \"action\": \"update\", \"data\": [{\"id\": 8799326050, \"side\": \"Sell\", \"size\": 254138}], \"symbol\": \"XBTUSD\", \"timestamp\": \"2018-06-11 01:43:23.549004Z\"}", "XBTUSD"], [1528681404295, "{\"table\": \"orderBookL2\", \"action\": \"update\", \"data\": [{\"id\": 8799326150, \"side\": \"Sell\", \"size\": 881336}], \"symbol\": \"XBTUSD\", \"timestamp\": \"2018-06-11 01:43:24.292717Z\"}", "XBTUSD"], [1528681405029, "{\"table\": \"orderBookL2\", \"action\": \"update\", \"data\": [{\"id\": 8799326150, \"side\": \"Sell\", \"size\": 1220280}], \"symbol\": \"XBTUSD\", \"timestamp\": \"2018-06-11 01:43:25.024283Z\"}", "XBTUSD"], [1528681405820, "{\"table\": \"orderBookL2\", \"action\": \"update\", \"data\": [{\"id\": 8799326150, \"side\": \"Sell\", \"size\": 1609840}, {\"id\": 8799328250, \"side\": \"Buy\", \"size\": 341400}], \"symbol\": \"XBTUSD\", \"timestamp\": \"2018-06-11 01:43:25.818187Z\"}", "XBTUSD"], [1528681406979, "{\"table\": \"orderBookL2\", \"action\": \"update\", \"data\": [{\"id\": 8799325550, \"side\": \"Sell\", \"size\": 260790}, {\"id\": 8799325700, \"side\": \"Sell\", \"size\": 28579}, {\"id\": 8799326400, \"side\": \"Buy\", \"size\": 44481}, {\"id\": 8799326450, \"side\": \"Buy\", \"size\": 15617}], \"symbol\": \"XBTUSD\", \"timestamp\": \"2018-06-11 01:43:26.977205Z\"}", "XBTUSD"], [1528681408015, "{\"table\": \"orderBookL2\", \"action\": \"insert\", \"data\": [{\"id\": 8799376250, \"side\": \"Buy\", \"size\": 32800, \"price\": 6237.5}], \"symbol\": \"XBTUSD\", \"timestamp\": \"2018-06-11 01:43:28.012883Z\"}", "XBTUSD"], [1528681408780, "{\"table\": \"orderBookL2\", \"action\": \"update\", \"data\": [{\"id\": 8799324050, \"side\": \"Sell\", \"size\": 67016}, {\"id\": 8799324300, \"side\": \"Sell\", \"size\": 197264}, {\"id\": 8799326650, \"side\": \"Buy\", \"size\": 37424}, {\"id\": 8799326750, \"side\": \"Buy\", \"size\": 122902}], \"symbol\": \"XBTUSD\", \"timestamp\": \"2018-06-11 01:43:28.778175Z\"}", "XBTUSD"], [1528681409531, "{\"table\": \"orderBookL2\", \"action\": \"update\", \"data\": [{\"id\": 8799326900, \"side\": \"Buy\", \"size\": 73680}], \"symbol\": \"XBTUSD\", \"timestamp\": \"2018-06-11 01:43:29.528857Z\"}", "XBTUSD"], [1528681413569, "{\"table\": \"orderBookL2\", \"action\": \"delete\", \"data\": [{\"id\": 8799341650, \"side\": \"Buy\"}], \"symbol\": \"XBTUSD\", \"timestamp\": \"2018-06-11 01:43:33.565028Z\"}", "XBTUSD"], [1528681413870, "{\"table\": \"orderBookL2\", \"action\": \"update\", \"data\": [{\"id\": 8799325650, \"side\": \"Sell\", \"size\": 28850}, {\"id\": 8799325700, \"side\": \"Sell\", \"size\": 6710}], \"symbol\": \"XBTUSD\", \"timestamp\": \"2018-06-11 01:43:33.867951Z\"}", "XBTUSD"], [1528681414911, "{\"table\": \"orderBookL2\", \"action\": \"delete\", \"data\": [{\"id\": 8799317350, \"side\": \"Sell\"}], \"symbol\": \"XBTUSD\", \"timestamp\": \"2018-06-11 01:43:34.908586Z\"}", "XBTUSD"], [1528681418776, "{\"table\": \"orderBookL2\", \"action\": \"update\", \"data\": [{\"id\": 8799336200, \"side\": \"Buy\", \"size\": 64850}, {\"id\": 8799336300, \"side\": \"Buy\", \"size\": 25828}], \"symbol\": \"XBTUSD\", \"timestamp\": \"2018-06-11 01:43:38.771846Z\"}", "XBTUSD"], [1528681418989, "{\"table\": \"orderBookL2\", \"action\": \"update\", \"data\": [{\"id\": 8799309500, \"side\": \"Sell\", \"size\": 302795}, {\"id\": 8799316000, \"side\": \"Sell\", \"size\": 1536031}], \"symbol\": \"XBTUSD\", \"timestamp\": \"2018-06-11 01:43:38.987028Z\"}", "XBTUSD"], [1528681421409, "{\"table\": \"trade\", \"action\": \"insert\", \"data\": [{\"timestamp\": \"2018-06-11T01:43:41.044Z\", \"side\": \"Sell\", \"size\": 5000, \"price\": 6737, \"tickDirection\": \"ZeroMinusTick\", \"trdMatchID\": \"f64472a5-3d0d-042a-01e4-f8d8f2896b95\", \"grossValue\": 74215000, \"homeNotional\": 0.74215, \"foreignNotional\": 5000}], \"symbol\": \"XBTUSD\", \"timestamp\": \"2018-06-11 01:43:41.406227Z\"}", "XBTUSD"], [1528681423866, "{\"table\": \"orderBookL2\", \"action\": \"update\", \"data\": [{\"id\": 8799327850, \"side\": \"Buy\", \"size\": 321687}, {\"id\": 8799328750, \"side\": \"Buy\", \"size\": 65700}], \"symbol\": \"XBTUSD\", \"timestamp\": \"2018-06-11 01:43:43.861618Z\"}", "XBTUSD"], [1528681424139, "{\"table\": \"orderBookL2\", \"action\": \"update\", \"data\": [{\"id\": 8799328500, \"side\": \"Buy\", \"size\": 394660}, {\"id\": 8799332500, \"side\": \"Buy\", \"size\": 361461}], \"symbol\": \"XBTUSD\", \"timestamp\": \"2018-06-11 01:43:44.136300Z\"}", "XBTUSD"], [1528681424643, "{\"table\": \"orderBookL2\", \"action\": \"update\", \"data\": [{\"id\": 8799326350, \"side\": \"Sell\", \"size\": 83701}], \"symbol\": \"XBTUSD\", \"timestamp\": \"2018-06-11 01:43:44.638658Z\"}", "XBTUSD"], [1528681426431, "{\"table\": \"orderBookL2\", \"action\": \"update\", \"data\": [{\"id\": 8799275500, \"side\": \"Sell\", \"size\": 202715}], \"symbol\": \"XBTUSD\", \"timestamp\": \"2018-06-11 01:43:46.428374Z\"}", "XBTUSD"], [1528681428871, "{\"table\": \"orderBookL2\", \"action\": \"update\", \"data\": [{\"id\": 8799295600, \"side\": \"Sell\", \"size\": 147470}, {\"id\": 8799299200, \"side\": \"Sell\", \"size\": 79527}, {\"id\": 8799315550, \"side\": \"Sell\", \"size\": 41674}, {\"id\": 8799324450, \"side\": \"Sell\", \"size\": 59462}, {\"id\": 8799325050, \"side\": \"Sell\", \"size\": 6706}, {\"id\": 8799336000, \"side\": \"Buy\", \"size\": 73541}, {\"id\": 8799336400, \"side\": \"Buy\", \"size\": 45028}, {\"id\": 8799345000, \"side\": \"Buy\", \"size\": 1064048}, {\"id\": 8799359950, \"side\": \"Buy\", \"size\": 6890}, {\"id\": 8799362300, \"side\": \"Buy\", \"size\": 31960}], \"symbol\": \"XBTUSD\", \"timestamp\": \"2018-06-11 01:43:48.867473Z\"}", "XBTUSD"], [1528681429163, "{\"table\": \"orderBookL2\", \"action\": \"update\", \"data\": [{\"id\": 8799326350, \"side\": \"Sell\", \"size\": 1600588}], \"symbol\": \"XBTUSD\", \"timestamp\": \"2018-06-11 01:43:49.160938Z\"}", "XBTUSD"], [1528681431356, "{\"table\": \"orderBookL2\", \"action\": \"update\", \"data\": [{\"id\": 8799326500, \"side\": \"Buy\", \"size\": 179443}], \"symbol\": \"XBTUSD\", \"timestamp\": \"2018-06-11 01:43:51.352387Z\"}", "XBTUSD"], [1528681433802, "{\"table\": \"orderBookL2\", \"action\": \"update\", \"data\": [{\"id\": 8799326300, \"side\": \"Sell\", \"size\": 746673}, {\"id\": 8799326350, \"side\": \"Sell\", \"size\": 827674}], \"symbol\": \"XBTUSD\", \"timestamp\": \"2018-06-11 01:43:53.797380Z\"}", "XBTUSD"], [1528681434069, "{\"table\": \"orderBookL2\", \"action\": \"update\", \"data\": [{\"id\": 8799326350, \"side\": \"Sell\", \"size\": 353278}, {\"id\": 8799328500, \"side\": \"Buy\", \"size\": 94660}], \"symbol\": \"XBTUSD\", \"timestamp\": \"2018-06-11 01:43:54.066331Z\"}", "XBTUSD"], [1528681434424, "{\"table\": \"orderBookL2\", \"action\": \"update\", \"data\": [{\"id\": 8799326350, \"side\": \"Sell\", \"size\": 206152}, {\"id\": 8799326400, \"side\": \"Sell\", \"size\": 218030}], \"symbol\": \"XBTUSD\", \"timestamp\": \"2018-06-11 01:43:54.421684Z\"}", "XBTUSD"], [1528681436261, "{\"table\": \"orderBookL2\", \"action\": \"update\", \"data\": [{\"id\": 8799319600, \"side\": \"Sell\", \"size\": 135240}, {\"id\": 8799331900, \"side\": \"Buy\", \"size\": 38559}], \"symbol\": \"XBTUSD\", \"timestamp\": \"2018-06-11 01:43:56.257813Z\"}", "XBTUSD"], [1528681438400, "{\"table\": \"orderBookL2\", \"action\": \"update\", \"data\": [{\"id\": 8799325750, \"side\": \"Sell\", \"size\": 18000}, {\"id\": 8799325850, \"side\": \"Sell\", \"size\": 30328}], \"symbol\": \"XBTUSD\", \"timestamp\": \"2018-06-11 01:43:58.394553Z\"}", "XBTUSD"], [1528681443051, "{\"table\": \"orderBookL2\", \"action\": \"update\", \"data\": [{\"id\": 8799326400, \"side\": \"Sell\", \"size\": 185665}, {\"id\": 8799326600, \"side\": \"Buy\", \"size\": 65077}], \"symbol\": \"XBTUSD\", \"timestamp\": \"2018-06-11 01:44:03.040136Z\"}", "XBTUSD"], [1528681444206, "{\"table\": \"orderBookL2\", \"action\": \"update\", \"data\": [{\"id\": 8799326500, \"side\": \"Buy\", \"size\": 98325}], \"symbol\": \"XBTUSD\", \"timestamp\": \"2018-06-11 01:44:04.203689Z\"}", "XBTUSD"], [1528681448853, "{\"table\": \"orderBookL2\", \"action\": \"update\", \"data\": [{\"id\": 8799324200, \"side\": \"Sell\", \"size\": 91704}], \"symbol\": \"XBTUSD\", \"timestamp\": \"2018-06-11 01:44:08.848701Z\"}", "XBTUSD"], [1528681449970, "{\"table\": \"orderBookL2\", \"action\": \"update\", \"data\": [{\"id\": 8799326800, \"side\": \"Buy\", \"size\": 54484}], \"symbol\": \"XBTUSD\", \"timestamp\": \"2018-06-11 01:44:09.965008Z\"}", "XBTUSD"], [1528681454076, "{\"table\": \"orderBookL2\", \"action\": \"delete\", \"data\": [{\"id\": 8799312350, \"side\": \"Sell\"}], \"symbol\": \"XBTUSD\", \"timestamp\": \"2018-06-11 01:44:14.072602Z\"}", "XBTUSD"], [1528681455886, "{\"table\": \"orderBookL2\", \"action\": \"insert\", \"data\": [{\"id\": 8798765300, \"side\": \"Sell\", \"size\": 97, \"price\": 12347}], \"symbol\": \"XBTUSD\", \"timestamp\": \"2018-06-11 01:44:15.882109Z\"}", "XBTUSD"], [1528681458856, "{\"table\": \"orderBookL2\", \"action\": \"update\", \"data\": [{\"id\": 8799326500, \"side\": \"Buy\", \"size\": 914715}], \"symbol\": \"XBTUSD\", \"timestamp\": \"2018-06-11 01:44:18.853581Z\"}", "XBTUSD"], [1528681461635, "{\"table\": \"orderBookL2\", \"action\": \"update\", \"data\": [{\"id\": 8799326500, \"side\": \"Buy\", \"size\": 836347}], \"symbol\": \"XBTUSD\", \"timestamp\": \"2018-06-11 01:44:21.628693Z\"}", "XBTUSD"], [1528681464272, "{\"table\": \"orderBookL2\", \"action\": \"update\", \"data\": [{\"id\": 8799326600, \"side\": \"Buy\", \"size\": 45077}, {\"id\": 8799326700, \"side\": \"Buy\", \"size\": 152404}], \"symbol\": \"XBTUSD\", \"timestamp\": \"2018-06-11 01:44:24.269966Z\"}", "XBTUSD"], [1528681465394, "{\"table\": \"orderBookL2\", \"action\": \"update\", \"data\": [{\"id\": 8799326450, \"side\": \"Sell\", \"size\": 659504}], \"symbol\": \"XBTUSD\", \"timestamp\": \"2018-06-11 01:44:25.392144Z\"}", "XBTUSD"], [1528681467977, "{\"table\": \"orderBookL2\", \"action\": \"delete\", \"data\": [{\"id\": 8798768500, \"side\": \"Sell\"}], \"symbol\": \"XBTUSD\", \"timestamp\": \"2018-06-11 01:44:27.970163Z\"}", "XBTUSD"], [1528681471207, "{\"table\": \"orderBookL2\", \"action\": \"update\", \"data\": [{\"id\": 8799327700, \"side\": \"Buy\", \"size\": 63361}], \"symbol\": \"XBTUSD\", \"timestamp\": \"2018-06-11 01:44:31.199372Z\"}", "XBTUSD"], [1528681472998, "{\"table\": \"orderBookL2\", \"action\": \"update\", \"data\": [{\"id\": 8799326050, \"side\": \"Sell\", \"size\": 193}, {\"id\": 8799326500, \"side\": \"Sell\", \"size\": 2487067}], \"symbol\": \"XBTUSD\", \"timestamp\": \"2018-06-11 01:44:32.995646Z\"}", "XBTUSD"], [1528681476288, "{\"table\": \"orderBookL2\", \"action\": \"update\", \"data\": [{\"id\": 8799327300, \"side\": \"Buy\", \"size\": 61471}, {\"id\": 8799327350, \"side\": \"Buy\", \"size\": 93866}], \"symbol\": \"XBTUSD\", \"timestamp\": \"2018-06-11 01:44:36.284393Z\"}", "XBTUSD"], [1528681479084, "{\"table\": \"orderBookL2\", \"action\": \"update\", \"data\": [{\"id\": 8799326700, \"side\": \"Buy\", \"size\": 127110}, {\"id\": 8799326900, \"side\": \"Buy\", \"size\": 262971}, {\"id\": 8799376900, \"side\": \"Buy\", \"size\": 37400}], \"symbol\": \"XBTUSD\", \"timestamp\": \"2018-06-11 01:44:39.079699Z\"}", "XBTUSD"], [1528681481380, "{\"table\": \"orderBookL2\", \"action\": \"update\", \"data\": [{\"id\": 8799319100, \"side\": \"Sell\", \"size\": 24993}], \"symbol\": \"XBTUSD\", \"timestamp\": \"2018-06-11 01:44:41.372765Z\"}", "XBTUSD"], [1528681484614, "{\"table\": \"orderBookL2\", \"action\": \"update\", \"data\": [{\"id\": 8799319300, \"side\": \"Sell\", \"size\": 57001}], \"symbol\": \"XBTUSD\", \"timestamp\": \"2018-06-11 01:44:44.610468Z\"}", "XBTUSD"], [1528681487148, "{\"table\": \"orderBookL2\", \"action\": \"update\", \"data\": [{\"id\": 8799326500, \"side\": \"Sell\", \"size\": 2535950}], \"symbol\": \"XBTUSD\", \"timestamp\": \"2018-06-11 01:44:47.146338Z\"}", "XBTUSD"], [1528681490366, "{\"table\": \"orderBookL2\", \"action\": \"update\", \"data\": [{\"id\": 8799327450, \"side\": \"Buy\", \"size\": 94617}, {\"id\": 8799327550, \"side\": \"Buy\", \"size\": 137753}], \"symbol\": \"XBTUSD\", \"timestamp\": \"2018-06-11 01:44:50.362594Z\"}", "XBTUSD"], [1528681494051, "{\"table\": \"orderBookL2\", \"action\": \"update\", \"data\": [{\"id\": 8799327550, \"side\": \"Buy\", \"size\": 142753}, {\"id\": 8799327650, \"side\": \"Buy\", \"size\": 720}], \"symbol\": \"XBTUSD\", \"timestamp\": \"2018-06-11 01:44:54.042593Z\"}", "XBTUSD"], [1528681495504, "{\"table\": \"orderBookL2\", \"action\": \"update\", \"data\": [{\"id\": 8799326500, \"side\": \"Sell\", \"size\": 2447615}], \"symbol\": \"XBTUSD\", \"timestamp\": \"2018-06-11 01:44:55.500571Z\"}", "XBTUSD"], [1528681499443, "{\"table\": \"orderBookL2\", \"action\": \"update\", \"data\": [{\"id\": 8799326700, \"side\": \"Buy\", \"size\": 2603}], \"symbol\": \"XBTUSD\", \"timestamp\": \"2018-06-11 01:44:59.440094Z\"}", "XBTUSD"], [1528681503227, "{\"table\": \"orderBookL2\", \"action\": \"update\", \"data\": [{\"id\": 8799326500, \"side\": \"Sell\", \"size\": 2209912}], \"symbol\": \"XBTUSD\", \"timestamp\": \"2018-06-11 01:45:03.224266Z\"}", "XBTUSD"], [1528681503676, "{\"table\": \"orderBookL2\", \"action\": \"update\", \"data\": [{\"id\": 8799276300, \"side\": \"Sell\", \"size\": 43942}, {\"id\": 8799276500, \"side\": \"Sell\", \"size\": 34100}, {\"id\": 8799326300, \"side\": \"Sell\", \"size\": 25650}, {\"id\": 8799326500, \"side\": \"Sell\", \"size\": 2460147}, {\"id\": 8799326550, \"side\": \"Buy\", \"size\": 362617}, {\"id\": 8799326700, \"side\": \"Buy\", \"size\": 2603}], \"symbol\": \"XBTUSD\", \"timestamp\": \"2018-06-11 01:45:03.673469Z\"}", "XBTUSD"], [1528681505829, "{\"table\": \"orderBookL2\", \"action\": \"update\", \"data\": [{\"id\": 8799326550, \"side\": \"Buy\", \"size\": 276272}], \"symbol\": \"XBTUSD\", \"timestamp\": \"2018-06-11 01:45:05.824504Z\"}", "XBTUSD"], [1528681508308, "{\"table\": \"orderBookL2\", \"action\": \"update\", \"data\": [{\"id\": 8799326300, \"side\": \"Sell\", \"size\": 67650}], \"symbol\": \"XBTUSD\", \"timestamp\": \"2018-06-11 01:45:08.301864Z\"}", "XBTUSD"], [1528681512579, "{\"table\": \"orderBookL2\", \"action\": \"insert\", \"data\": [{\"id\": 8799274550, \"side\": \"Sell\", \"size\": 14650, \"price\": 7254.5}, {\"id\": 8799303950, \"side\": \"Sell\", \"size\": 22114, \"price\": 6960.5}], \"symbol\": \"XBTUSD\", \"timestamp\": \"2018-06-11 01:45:12.576791Z\"}", "XBTUSD"], [1528681515225, "{\"table\": \"orderBookL2\", \"action\": \"update\", \"data\": [{\"id\": 8799326500, \"side\": \"Sell\", \"size\": 2397570}], \"symbol\": \"XBTUSD\", \"timestamp\": \"2018-06-11 01:45:15.222927Z\"}", "XBTUSD"], [1528681517488, "{\"table\": \"orderBookL2\", \"action\": \"update\", \"data\": [{\"id\": 8799326500, \"side\": \"Sell\", \"size\": 1779228}], \"symbol\": \"XBTUSD\", \"timestamp\": \"2018-06-11 01:45:17.484548Z\"}", "XBTUSD"], [1528681519585, "{\"table\": \"orderBookL2\", \"action\": \"update\", \"data\": [{\"id\": 8799332600, \"side\": \"Buy\", \"size\": 33398}], \"symbol\": \"XBTUSD\", \"timestamp\": \"2018-06-11 01:45:19.579164Z\"}", "XBTUSD"], [1528681523064, "{\"table\": \"orderBookL2\", \"action\": \"update\", \"data\": [{\"id\": 8799326300, \"side\": \"Sell\", \"size\": 27250}], \"symbol\": \"XBTUSD\", \"timestamp\": \"2018-06-11 01:45:23.060076Z\"}", "XBTUSD"], [1528681527245, "{\"table\": \"orderBookL2\", \"action\": \"update\", \"data\": [{\"id\": 8799326500, \"side\": \"Sell\", \"size\": 2204500}], \"symbol\": \"XBTUSD\", \"timestamp\": \"2018-06-11 01:45:27.231587Z\"}", "XBTUSD"], [1528681527854, "{\"table\": \"orderBookL2\", \"action\": \"update\", \"data\": [{\"id\": 8799326550, \"side\": \"Sell\", \"size\": 1293600}], \"symbol\": \"XBTUSD\", \"timestamp\": \"2018-06-11 01:45:27.851932Z\"}", "XBTUSD"], [1528681528068, "{\"table\": \"orderBookL2\", \"action\": \"update\", \"data\": [{\"id\": 8799326600, \"side\": \"Sell\", \"size\": 845187}, {\"id\": 8799328700, \"side\": \"Buy\", \"size\": 170243}], \"symbol\": \"XBTUSD\", \"timestamp\": \"2018-06-11 01:45:28.064848Z\"}", "XBTUSD"], [1528681528774, "{\"table\": \"orderBookL2\", \"action\": \"update\", \"data\": [{\"id\": 8799326150, \"side\": \"Sell\", \"size\": 833}, {\"id\": 8799326250, \"side\": \"Sell\", \"size\": 11000}], \"symbol\": \"XBTUSD\", \"timestamp\": \"2018-06-11 01:45:28.770873Z\"}", "XBTUSD"], [1528681530439, "{\"table\": \"orderBookL2\", \"action\": \"update\", \"data\": [{\"id\": 8799326700, \"side\": \"Buy\", \"size\": 16822}, {\"id\": 8799328800, \"side\": \"Buy\", \"size\": 130203}], \"symbol\": \"XBTUSD\", \"timestamp\": \"2018-06-11 01:45:30.434811Z\"}", "XBTUSD"], [1528681533477, "{\"table\": \"orderBookL2\", \"action\": \"update\", \"data\": [{\"id\": 8799326750, \"side\": \"Buy\", \"size\": 120463}], \"symbol\": \"XBTUSD\", \"timestamp\": \"2018-06-11 01:45:33.469926Z\"}", "XBTUSD"], [1528681537055, "{\"table\": \"orderBookL2\", \"action\": \"update\", \"data\": [{\"id\": 8799326600, \"side\": \"Sell\", \"size\": 1716580}], \"symbol\": \"XBTUSD\", \"timestamp\": \"2018-06-11 01:45:37.049554Z\"}", "XBTUSD"], [1528681539350, "{\"table\": \"orderBookL2\", \"action\": \"update\", \"data\": [{\"id\": 8799324900, \"side\": \"Sell\", \"size\": 197893}, {\"id\": 8799325000, \"side\": \"Sell\", \"size\": 265154}], \"symbol\": \"XBTUSD\", \"timestamp\": \"2018-06-11 01:45:39.346250Z\"}", "XBTUSD"], [1528681543801, "{\"table\": \"orderBookL2\", \"action\": \"update\", \"data\": [{\"id\": 8799316000, \"side\": \"Sell\", \"size\": 934677}, {\"id\": 8799316100, \"side\": \"Sell\", \"size\": 133386}, {\"id\": 8799317400, \"side\": \"Sell\", \"size\": 131172}, {\"id\": 8799317500, \"side\": \"Sell\", \"size\": 1355740}, {\"id\": 8799318800, \"side\": \"Sell\", \"size\": 60001}, {\"id\": 8799318900, \"side\": \"Sell\", \"size\": 78291}, {\"id\": 8799328900, \"side\": \"Buy\", \"size\": 201859}, {\"id\": 8799329000, \"side\": \"Buy\", \"size\": 477720}, {\"id\": 8799330300, \"side\": \"Buy\", \"size\": 67023}, {\"id\": 8799330400, \"side\": \"Buy\", \"size\": 5609}, {\"id\": 8799331700, \"side\": \"Buy\", \"size\": 128663}, {\"id\": 8799331800, \"side\": \"Buy\", \"size\": 172743}], \"symbol\": \"XBTUSD\", \"timestamp\": \"2018-06-11 01:45:43.795950Z\"}", "XBTUSD"], [1528681544323, "{\"table\": \"orderBookL2\", \"action\": \"update\", \"data\": [{\"id\": 8799326650, \"side\": \"Sell\", \"size\": 854469}], \"symbol\": \"XBTUSD\", \"timestamp\": \"2018-06-11 01:45:44.316770Z\"}", "XBTUSD"], [1528681544950, "{\"table\": \"orderBookL2\", \"action\": \"update\", \"data\": [{\"id\": 8799326600, \"side\": \"Sell\", \"size\": 656268}, {\"id\": 8799326900, \"side\": \"Buy\", \"size\": 239836}], \"symbol\": \"XBTUSD\", \"timestamp\": \"2018-06-11 01:45:44.947307Z\"}", "XBTUSD"], [1528681547611, "{\"table\": \"orderBookL2\", \"action\": \"update\", \"data\": [{\"id\": 8799320800, \"side\": \"Sell\", \"size\": 230061}], \"symbol\": \"XBTUSD\", \"timestamp\": \"2018-06-11 01:45:47.606876Z\"}", "XBTUSD"], [1528681550213, "{\"table\": \"orderBookL2\", \"action\": \"update\", \"data\": [{\"id\": 8799326500, \"side\": \"Sell\", \"size\": 683019}, {\"id\": 8799326550, \"side\": \"Sell\", \"size\": 136595}, {\"id\": 8799326950, \"side\": \"Buy\", \"size\": 59836}, {\"id\": 8799327000, \"side\": \"Buy\", \"size\": 161972}], \"symbol\": \"XBTUSD\", \"timestamp\": \"2018-06-11 01:45:50.207614Z\"}", "XBTUSD"], [1528681552881, "{\"table\": \"orderBookL2\", \"action\": \"update\", \"data\": [{\"id\": 8799326650, \"side\": \"Sell\", \"size\": 1344481}], \"symbol\": \"XBTUSD\", \"timestamp\": \"2018-06-11 01:45:52.878762Z\"}", "XBTUSD"], [1528681553696, "{\"table\": \"orderBookL2\", \"action\": \"update\", \"data\": [{\"id\": 8799326400, \"side\": \"Sell\", \"size\": 177579}, {\"id\": 8799326650, \"side\": \"Sell\", \"size\": 880067}], \"symbol\": \"XBTUSD\", \"timestamp\": \"2018-06-11 01:45:53.693756Z\"}", "XBTUSD"], [1528681556409, "{\"table\": \"orderBookL2\", \"action\": \"update\", \"data\": [{\"id\": 8799326650, \"side\": \"Sell\", \"size\": 238526}, {\"id\": 8799326700, \"side\": \"Sell\", \"size\": 1655889}], \"symbol\": \"XBTUSD\", \"timestamp\": \"2018-06-11 01:45:56.401404Z\"}", "XBTUSD"], [1528681557833, "{\"table\": \"orderBookL2\", \"action\": \"update\", \"data\": [{\"id\": 8799326750, \"side\": \"Buy\", \"size\": 96534}], \"symbol\": \"XBTUSD\", \"timestamp\": \"2018-06-11 01:45:57.828969Z\"}", "XBTUSD"], [1528681563359, "{\"table\": \"orderBookL2\", \"action\": \"update\", \"data\": [{\"id\": 8799326750, \"side\": \"Buy\", \"size\": 128357}], \"symbol\": \"XBTUSD\", \"timestamp\": \"2018-06-11 01:46:03.344400Z\"}", "XBTUSD"], [1528681564568, "{\"table\": \"orderBookL2\", \"action\": \"update\", \"data\": [{\"id\": 8799326700, \"side\": \"Sell\", \"size\": 1703945}], \"symbol\": \"XBTUSD\", \"timestamp\": \"2018-06-11 01:46:04.563333Z\"}", "XBTUSD"], [1528681567903, "{\"table\": \"orderBookL2\", \"action\": \"update\", \"data\": [{\"id\": 8799326800, \"side\": \"Buy\", \"size\": 171757}, {\"id\": 8799326850, \"side\": \"Buy\", \"size\": 62708}], \"symbol\": \"XBTUSD\", \"timestamp\": \"2018-06-11 01:46:07.900229Z\"}", "XBTUSD"], [1528681571313, "{\"table\": \"orderBookL2\", \"action\": \"update\", \"data\": [{\"id\": 8799326750, \"side\": \"Buy\", \"size\": 224868}], \"symbol\": \"XBTUSD\", \"timestamp\": \"2018-06-11 01:46:11.307954Z\"}", "XBTUSD"], [1528681574207, "{\"table\": \"quote\", \"action\": \"insert\", \"data\": [{\"timestamp\": \"2018-06-11T01:46:13.341Z\", \"bidSize\": 346589, \"bidPrice\": 6732.5, \"askPrice\": 6733, \"askSize\": 1622508}, {\"timestamp\": \"2018-06-11T01:46:13.430Z\", \"bidSize\": 356589, \"bidPrice\": 6732.5, \"askPrice\": 6733, \"askSize\": 1622508}, {\"timestamp\": \"2018-06-11T01:46:13.798Z\", \"bidSize\": 356738, \"bidPrice\": 6732.5, \"askPrice\": 6733, \"askSize\": 1622508}, {\"timestamp\": \"2018-06-11T01:46:13.872Z\", \"bidSize\": 357238, \"bidPrice\": 6732.5, \"askPrice\": 6733, \"askSize\": 1622508}, {\"timestamp\": \"2018-06-11T01:46:13.878Z\", \"bidSize\": 357239, \"bidPrice\": 6732.5, \"askPrice\": 6733, \"askSize\": 1622508}, {\"timestamp\": \"2018-06-11T01:46:13.881Z\", \"bidSize\": 357231, \"bidPrice\": 6732.5, \"askPrice\": 6733, \"askSize\": 1622508}, {\"timestamp\": \"2018-06-11T01:46:13.917Z\", \"bidSize\": 357232, \"bidPrice\": 6732.5, \"askPrice\": 6733, \"askSize\": 1622508}, {\"timestamp\": \"2018-06-11T01:46:13.940Z\", \"bidSize\": 357232, \"bidPrice\": 6732.5, \"askPrice\": 6733, \"askSize\": 1622509}], \"symbol\": \"XBTUSD\", \"timestamp\": \"2018-06-11 01:46:14.199261Z\"}", "XBTUSD"], [1528681578103, "{\"table\": \"orderBookL2\", \"action\": \"update\", \"data\": [{\"id\": 8799327250, \"side\": \"Buy\", \"size\": 61890}], \"symbol\": \"XBTUSD\", \"timestamp\": \"2018-06-11 01:46:18.101203Z\"}", "XBTUSD"], [1528681581701, "{\"table\": \"orderBookL2\", \"action\": \"update\", \"data\": [{\"id\": 8799326750, \"side\": \"Buy\", \"size\": 608108}], \"symbol\": \"XBTUSD\", \"timestamp\": \"2018-06-11 01:46:21.698457Z\"}", "XBTUSD"], [1528681584298, "{\"table\": \"orderBookL2\", \"action\": \"update\", \"data\": [{\"id\": 8799326750, \"side\": \"Buy\", \"size\": 952234}, {\"id\": 8799326850, \"side\": \"Buy\", \"size\": 19564}], \"symbol\": \"XBTUSD\", \"timestamp\": \"2018-06-11 01:46:24.296057Z\"}", "XBTUSD"], [1528681587240, "{\"table\": \"orderBookL2\", \"action\": \"update\", \"data\": [{\"id\": 8799326750, \"side\": \"Buy\", \"size\": 983408}], \"symbol\": \"XBTUSD\", \"timestamp\": \"2018-06-11 01:46:27.231098Z\"}", "XBTUSD"], [1528681591224, "{\"table\": \"orderBookL2\", \"action\": \"update\", \"data\": [{\"id\": 8799325550, \"side\": \"Sell\", \"size\": 253400}], \"symbol\": \"XBTUSD\", \"timestamp\": \"2018-06-11 01:46:31.219332Z\"}", "XBTUSD"], [1528681594568, "{\"table\": \"orderBookL2\", \"action\": \"insert\", \"data\": [{\"id\": 8793225000, \"side\": \"Sell\", \"size\": 40000, \"price\": 67750}], \"symbol\": \"XBTUSD\", \"timestamp\": \"2018-06-11 01:46:34.565146Z\"}", "XBTUSD"], [1528681598705, "{\"table\": \"orderBookL2\", \"action\": \"update\", \"data\": [{\"id\": 8799326750, \"side\": \"Buy\", \"size\": 1227355}, {\"id\": 8799326800, \"side\": \"Buy\", \"size\": 243322}], \"symbol\": \"XBTUSD\", \"timestamp\": \"2018-06-11 01:46:38.700429Z\"}", "XBTUSD"], [1528681600199, "{\"table\": \"orderBookL2\", \"action\": \"update\", \"data\": [{\"id\": 8799326750, \"side\": \"Buy\", \"size\": 1083127}], \"symbol\": \"XBTUSD\", \"timestamp\": \"2018-06-11 01:46:40.186448Z\"}", "XBTUSD"], [1528681603395, "{\"table\": \"orderBookL2\", \"action\": \"update\", \"data\": [{\"id\": 8799326750, \"side\": \"Buy\", \"size\": 1015073}], \"symbol\": \"XBTUSD\", \"timestamp\": \"2018-06-11 01:46:43.386669Z\"}", "XBTUSD"], [1528681607523, "{\"table\": \"orderBookL2\", \"action\": \"update\", \"data\": [{\"id\": 8799326750, \"side\": \"Buy\", \"size\": 433254}, {\"id\": 8799326850, \"side\": \"Buy\", \"size\": 7536}], \"symbol\": \"XBTUSD\", \"timestamp\": \"2018-06-11 01:46:47.516538Z\"}", "XBTUSD"], [1528681609040, "{\"table\": \"orderBookL2\", \"action\": \"delete\", \"data\": [{\"id\": 8799377300, \"side\": \"Buy\"}], \"symbol\": \"XBTUSD\", \"timestamp\": \"2018-06-11 01:46:49.035445Z\"}", "XBTUSD"], [1528681612750, "{\"table\": \"orderBookL2\", \"action\": \"update\", \"data\": [{\"id\": 8799326100, \"side\": \"Sell\", \"size\": 25081}, {\"id\": 8799326300, \"side\": \"Sell\", \"size\": 101986}, {\"id\": 8799327300, \"side\": \"Buy\", \"size\": 43687}, {\"id\": 8799327350, \"side\": \"Buy\", \"size\": 104300}], \"symbol\": \"XBTUSD\", \"timestamp\": \"2018-06-11 01:46:52.747533Z\"}", "XBTUSD"], [1528681615780, "{\"table\": \"orderBookL2\", \"action\": \"update\", \"data\": [{\"id\": 8799326200, \"side\": \"Sell\", \"size\": 3257}], \"symbol\": \"XBTUSD\", \"timestamp\": \"2018-06-11 01:46:55.774412Z\"}", "XBTUSD"], [1528681617687, "{\"table\": \"orderBookL2\", \"action\": \"update\", \"data\": [{\"id\": 8799326700, \"side\": \"Sell\", \"size\": 1663312}], \"symbol\": \"XBTUSD\", \"timestamp\": \"2018-06-11 01:46:57.682308Z\"}", "XBTUSD"], [1528681622500, "{\"table\": \"orderBookL2\", \"action\": \"update\", \"data\": [{\"id\": 8799320500, \"side\": \"Sell\", \"size\": 43117}, {\"id\": 8799329150, \"side\": \"Buy\", \"size\": 57349}, {\"id\": 8799330800, \"side\": \"Buy\", \"size\": 9274}], \"symbol\": \"XBTUSD\", \"timestamp\": \"2018-06-11 01:47:02.495690Z\"}", "XBTUSD"], [1528681625034, "{\"table\": \"orderBookL2\", \"action\": \"update\", \"data\": [{\"id\": 8799326100, \"side\": \"Sell\", \"size\": 29081}, {\"id\": 8799326450, \"side\": \"Sell\", \"size\": 32257}], \"symbol\": \"XBTUSD\", \"timestamp\": \"2018-06-11 01:47:05.032131Z\"}", "XBTUSD"], [1528681625929, "{\"table\": \"orderBookL2\", \"action\": \"delete\", \"data\": [{\"id\": 8799370900, \"side\": \"Buy\"}], \"symbol\": \"XBTUSD\", \"timestamp\": \"2018-06-11 01:47:05.926856Z\"}", "XBTUSD"], [1528681628667, "{\"table\": \"orderBookL2\", \"action\": \"update\", \"data\": [{\"id\": 8799335300, \"side\": \"Buy\", \"size\": 92354}], \"symbol\": \"XBTUSD\", \"timestamp\": \"2018-06-11 01:47:08.663109Z\"}", "XBTUSD"], [1528681630289, "{\"table\": \"orderBookL2\", \"action\": \"update\", \"data\": [{\"id\": 8799327100, \"side\": \"Buy\", \"size\": 17209}], \"symbol\": \"XBTUSD\", \"timestamp\": \"2018-06-11 01:47:10.286868Z\"}", "XBTUSD"], [1528681632551, "{\"table\": \"orderBookL2\", \"action\": \"update\", \"data\": [{\"id\": 8799326900, \"side\": \"Buy\", \"size\": 231803}], \"symbol\": \"XBTUSD\", \"timestamp\": \"2018-06-11 01:47:12.547289Z\"}", "XBTUSD"], [1528681636309, "{\"table\": \"orderBookL2\", \"action\": \"delete\", \"data\": [{\"id\": 8798936300, \"side\": \"Sell\"}], \"symbol\": \"XBTUSD\", \"timestamp\": \"2018-06-11 01:47:16.304113Z\"}", "XBTUSD"], [1528681639123, "{\"table\": \"orderBookL2\", \"action\": \"insert\", \"data\": [{\"id\": 8798751300, \"side\": \"Sell\", \"size\": 87, \"price\": 12487}], \"symbol\": \"XBTUSD\", \"timestamp\": \"2018-06-11 01:47:19.120377Z\"}", "XBTUSD"], [1528681643817, "{\"table\": \"orderBookL2\", \"action\": \"update\", \"data\": [{\"id\": 8799326350, \"side\": \"Sell\", \"size\": 8544}, {\"id\": 8799327850, \"side\": \"Buy\", \"size\": 70000}], \"symbol\": \"XBTUSD\", \"timestamp\": \"2018-06-11 01:47:23.812791Z\"}", "XBTUSD"], [1528681645202, "{\"table\": \"orderBookL2\", \"action\": \"update\", \"data\": [{\"id\": 8799325900, \"side\": \"Sell\", \"size\": 12982}, {\"id\": 8799325950, \"side\": \"Sell\", \"size\": 48123}, {\"id\": 8799326200, \"side\": \"Sell\", \"size\": 14181}, {\"id\": 8799326300, \"side\": \"Sell\", \"size\": 10186}, {\"id\": 8799326450, \"side\": \"Sell\", \"size\": 20237}, {\"id\": 8799326550, \"side\": \"Sell\", \"size\": 36163}], \"symbol\": \"XBTUSD\", \"timestamp\": \"2018-06-11 01:47:25.197310Z\"}", "XBTUSD"], [1528681648364, "{\"table\": \"orderBookL2\", \"action\": \"update\", \"data\": [{\"id\": 8799318950, \"side\": \"Sell\", \"size\": 55028}], \"symbol\": \"XBTUSD\", \"timestamp\": \"2018-06-11 01:47:28.358182Z\"}", "XBTUSD"], [1528681651424, "{\"table\": \"orderBookL2\", \"action\": \"delete\", \"data\": [{\"id\": 8799377100, \"side\": \"Buy\"}], \"symbol\": \"XBTUSD\", \"timestamp\": \"2018-06-11 01:47:31.420434Z\"}", "XBTUSD"], [1528681653036, "{\"table\": \"orderBookL2\", \"action\": \"update\", \"data\": [{\"id\": 8799327300, \"side\": \"Buy\", \"size\": 120156}], \"symbol\": \"XBTUSD\", \"timestamp\": \"2018-06-11 01:47:33.034078Z\"}", "XBTUSD"], [1528681656452, "{\"table\": \"orderBookL2\", \"action\": \"update\", \"data\": [{\"id\": 8799326200, \"side\": \"Sell\", \"size\": 17644}], \"symbol\": \"XBTUSD\", \"timestamp\": \"2018-06-11 01:47:36.449141Z\"}", "XBTUSD"], [1528681659194, "{\"table\": \"orderBookL2\", \"action\": \"update\", \"data\": [{\"id\": 8799324900, \"side\": \"Sell\", \"size\": 192893}], \"symbol\": \"XBTUSD\", \"timestamp\": \"2018-06-11 01:47:39.191520Z\"}", "XBTUSD"], [1528681661509, "{\"table\": \"orderBookL2\", \"action\": \"update\", \"data\": [{\"id\": 8799326200, \"side\": \"Sell\", \"size\": 31658}], \"symbol\": \"XBTUSD\", \"timestamp\": \"2018-06-11 01:47:41.501043Z\"}", "XBTUSD"], [1528681664236, "{\"table\": \"orderBookL2\", \"action\": \"update\", \"data\": [{\"id\": 8799325850, \"side\": \"Sell\", \"size\": 23286}, {\"id\": 8799326250, \"side\": \"Sell\", \"size\": 16112}, {\"id\": 8799326750, \"side\": \"Buy\", \"size\": 1916195}, {\"id\": 8799326850, \"side\": \"Buy\", \"size\": 24207}], \"symbol\": \"XBTUSD\", \"timestamp\": \"2018-06-11 01:47:44.232439Z\"}", "XBTUSD"], [1528681668774, "{\"table\": \"quote\", \"action\": \"insert\", \"data\": [{\"timestamp\": \"2018-06-11T01:47:46.002Z\", \"bidSize\": 1974790, \"bidPrice\": 6732.5, \"askPrice\": 6733, \"askSize\": 141009}, {\"timestamp\": \"2018-06-11T01:47:46.004Z\", \"bidSize\": 1978790, \"bidPrice\": 6732.5, \"askPrice\": 6733, \"askSize\": 141009}, {\"timestamp\": \"2018-06-11T01:47:46.032Z\", \"bidSize\": 1978590, \"bidPrice\": 6732.5, \"askPrice\": 6733, \"askSize\": 141009}, {\"timestamp\": \"2018-06-11T01:47:46.183Z\", \"bidSize\": 1980590, \"bidPrice\": 6732.5, \"askPrice\": 6733, \"askSize\": 141009}, {\"timestamp\": \"2018-06-11T01:47:46.239Z\", \"bidSize\": 1980590, \"bidPrice\": 6732.5, \"askPrice\": 6733, \"askSize\": 130509}], \"symbol\": \"XBTUSD\", \"timestamp\": \"2018-06-11 01:47:48.770307Z\"}", "XBTUSD"], [1528681669100, "{\"table\": \"orderBookL2\", \"action\": \"update\", \"data\": [{\"id\": 8799328150, \"side\": \"Buy\", \"size\": 79350}], \"symbol\": \"XBTUSD\", \"timestamp\": \"2018-06-11 01:47:49.098318Z\"}", "XBTUSD"], [1528681669884, "{\"table\": \"orderBookL2\", \"action\": \"insert\", \"data\": [{\"id\": 8798755900, \"side\": \"Sell\", \"size\": 91, \"price\": 12441}], \"symbol\": \"XBTUSD\", \"timestamp\": \"2018-06-11 01:47:49.882016Z\"}", "XBTUSD"], [1528681673489, "{\"table\": \"orderBookL2\", \"action\": \"update\", \"data\": [{\"id\": 8799324200, \"side\": \"Sell\", \"size\": 71254}], \"symbol\": \"XBTUSD\", \"timestamp\": \"2018-06-11 01:47:53.484229Z\"}", "XBTUSD"], [1528681673870, "{\"table\": \"orderBookL2\", \"action\": \"update\", \"data\": [{\"id\": 8799327600, \"side\": \"Buy\", \"size\": 78573}, {\"id\": 8799327750, \"side\": \"Buy\", \"size\": 222670}, {\"id\": 8799328350, \"side\": \"Buy\", \"size\": 61853}, {\"id\": 8799328500, \"side\": \"Buy\", \"size\": 65264}], \"symbol\": \"XBTUSD\", \"timestamp\": \"2018-06-11 01:47:53.867793Z\"}", "XBTUSD"], [1528681674067, "{\"table\": \"orderBookL2\", \"action\": \"update\", \"data\": [{\"id\": 8799325800, \"side\": \"Sell\", \"size\": 27276}], \"symbol\": \"XBTUSD\", \"timestamp\": \"2018-06-11 01:47:54.064554Z\"}", "XBTUSD"], [1528681674334, "{\"table\": \"orderBookL2\", \"action\": \"update\", \"data\": [{\"id\": 8799326750, \"side\": \"Buy\", \"size\": 295832}], \"symbol\": \"XBTUSD\", \"timestamp\": \"2018-06-11 01:47:54.329688Z\"}", "XBTUSD"], [1528681675964, "{\"table\": \"orderBookL2\", \"action\": \"update\", \"data\": [{\"id\": 8799326600, \"side\": \"Buy\", \"size\": 1352492}], \"symbol\": \"XBTUSD\", \"timestamp\": \"2018-06-11 01:47:55.957702Z\"}", "XBTUSD"], [1528681677414, "{\"table\": \"orderBookL2\", \"action\": \"update\", \"data\": [{\"id\": 8799326800, \"side\": \"Buy\", \"size\": 53382}, {\"id\": 8799326850, \"side\": \"Buy\", \"size\": 18514}], \"symbol\": \"XBTUSD\", \"timestamp\": \"2018-06-11 01:47:57.410331Z\"}", "XBTUSD"], [1528681679804, "{\"table\": \"orderBookL2\", \"action\": \"update\", \"data\": [{\"id\": 8799326950, \"side\": \"Buy\", \"size\": 60993}, {\"id\": 8799327100, \"side\": \"Buy\", \"size\": 114003}], \"symbol\": \"XBTUSD\", \"timestamp\": \"2018-06-11 01:47:59.798187Z\"}", "XBTUSD"], [1528681683336, "{\"table\": \"orderBookL2\", \"action\": \"update\", \"data\": [{\"id\": 8799326500, \"side\": \"Sell\", \"size\": 13705}], \"symbol\": \"XBTUSD\", \"timestamp\": \"2018-06-11 01:48:03.334252Z\"}", "XBTUSD"], [1528681683494, "{\"table\": \"orderBookL2\", \"action\": \"update\", \"data\": [{\"id\": 8799326550, \"side\": \"Buy\", \"size\": 1205642}], \"symbol\": \"XBTUSD\", \"timestamp\": \"2018-06-11 01:48:03.491846Z\"}", "XBTUSD"], [1528681684303, "{\"table\": \"orderBookL2\", \"action\": \"update\", \"data\": [{\"id\": 8799326650, \"side\": \"Buy\", \"size\": 136615}], \"symbol\": \"XBTUSD\", \"timestamp\": \"2018-06-11 01:48:04.300462Z\"}", "XBTUSD"], [1528681686437, "{\"table\": \"orderBookL2\", \"action\": \"update\", \"data\": [{\"id\": 8799326500, \"side\": \"Buy\", \"size\": 1841497}, {\"id\": 8799326550, \"side\": \"Buy\", \"size\": 563777}], \"symbol\": \"XBTUSD\", \"timestamp\": \"2018-06-11 01:48:06.432149Z\"}", "XBTUSD"], [1528681689014, "{\"table\": \"orderBookL2\", \"action\": \"update\", \"data\": [{\"id\": 8799326600, \"side\": \"Buy\", \"size\": 159344}], \"symbol\": \"XBTUSD\", \"timestamp\": \"2018-06-11 01:48:09.009323Z\"}", "XBTUSD"], [1528681689197, "{\"table\": \"orderBookL2\", \"action\": \"update\", \"data\": [{\"id\": 8799325650, \"side\": \"Sell\", \"size\": 19925}, {\"id\": 8799327250, \"side\": \"Buy\", \"size\": 7942}], \"symbol\": \"XBTUSD\", \"timestamp\": \"2018-06-11 01:48:09.194658Z\"}", "XBTUSD"], [1528681689515, "{\"table\": \"orderBookL2\", \"action\": \"update\", \"data\": [{\"id\": 8799326250, \"side\": \"Sell\", \"size\": 6528}], \"symbol\": \"XBTUSD\", \"timestamp\": \"2018-06-11 01:48:09.512478Z\"}", "XBTUSD"], [1528681690239, "{\"table\": \"orderBookL2\", \"action\": \"update\", \"data\": [{\"id\": 8799326400, \"side\": \"Buy\", \"size\": 1248386}, {\"id\": 8799326450, \"side\": \"Buy\", \"size\": 750229}], \"symbol\": \"XBTUSD\", \"timestamp\": \"2018-06-11 01:48:10.236114Z\"}", "XBTUSD"], [1528681691116, "{\"table\": \"orderBookL2\", \"action\": \"update\", \"data\": [{\"id\": 8799326400, \"side\": \"Buy\", \"size\": 1797483}], \"symbol\": \"XBTUSD\", \"timestamp\": \"2018-06-11 01:48:11.112443Z\"}", "XBTUSD"], [1528681692249, "{\"table\": \"orderBookL2\", \"action\": \"update\", \"data\": [{\"id\": 8799326350, \"side\": \"Buy\", \"size\": 1101563}, {\"id\": 8799326400, \"side\": \"Buy\", \"size\": 840171}], \"symbol\": \"XBTUSD\", \"timestamp\": \"2018-06-11 01:48:12.245065Z\"}", "XBTUSD"], [1528681692978, "{\"table\": \"orderBookL2\", \"action\": \"update\", \"data\": [{\"id\": 8799324550, \"side\": \"Sell\", \"size\": 65451}, {\"id\": 8799324700, \"side\": \"Sell\", \"size\": 176369}, {\"id\": 8799327300, \"side\": \"Buy\", \"size\": 41623}, {\"id\": 8799327550, \"side\": \"Buy\", \"size\": 65202}, {\"id\": 8799328050, \"side\": \"Buy\", \"size\": 12220}, {\"id\": 8799328200, \"side\": \"Buy\", \"size\": 8140}], \"symbol\": \"XBTUSD\", \"timestamp\": \"2018-06-11 01:48:12.975484Z\"}", "XBTUSD"], [1528681693755, "{\"table\": \"orderBookL2\", \"action\": \"update\", \"data\": [{\"id\": 8799325550, \"side\": \"Sell\", \"size\": 260450}, {\"id\": 8799325600, \"side\": \"Sell\", \"size\": 500616}, {\"id\": 8799326300, \"side\": \"Buy\", \"size\": 1397067}, {\"id\": 8799326400, \"side\": \"Buy\", \"size\": 233419}], \"symbol\": \"XBTUSD\", \"timestamp\": \"2018-06-11 01:48:13.750185Z\"}", "XBTUSD"], [1528681694642, "{\"table\": \"orderBookL2\", \"action\": \"update\", \"data\": [{\"id\": 8799326250, \"side\": \"Sell\", \"size\": 29500}], \"symbol\": \"XBTUSD\", \"timestamp\": \"2018-06-11 01:48:14.636239Z\"}", "XBTUSD"], [1528681695488, "{\"table\": \"orderBookL2\", \"action\": \"update\", \"data\": [{\"id\": 8799326050, \"side\": \"Sell\", \"size\": 32392}], \"symbol\": \"XBTUSD\", \"timestamp\": \"2018-06-11 01:48:15.486201Z\"}", "XBTUSD"], [1528681698240, "{\"table\": \"orderBookL2\", \"action\": \"update\", \"data\": [{\"id\": 8799326750, \"side\": \"Buy\", \"size\": 126636}, {\"id\": 8799326900, \"side\": \"Buy\", \"size\": 234520}], \"symbol\": \"XBTUSD\", \"timestamp\": \"2018-06-11 01:48:18.235176Z\"}", "XBTUSD"], [1528681700604, "{\"table\": \"orderBookL2\", \"action\": \"update\", \"data\": [{\"id\": 8799326700, \"side\": \"Buy\", \"size\": 26943}, {\"id\": 8799326850, \"side\": \"Buy\", \"size\": 63533}], \"symbol\": \"XBTUSD\", \"timestamp\": \"2018-06-11 01:48:20.600169Z\"}", "XBTUSD"], [1528681704194, "{\"table\": \"orderBookL2\", \"action\": \"update\", \"data\": [{\"id\": 8799326050, \"side\": \"Sell\", \"size\": 348944}, {\"id\": 8799327600, \"side\": \"Buy\", \"size\": 374090}], \"symbol\": \"XBTUSD\", \"timestamp\": \"2018-06-11 01:48:24.188741Z\"}", "XBTUSD"], [1528681707172, "{\"table\": \"orderBookL2\", \"action\": \"update\", \"data\": [{\"id\": 8799326300, \"side\": \"Buy\", \"size\": 1488010}], \"symbol\": \"XBTUSD\", \"timestamp\": \"2018-06-11 01:48:27.168693Z\"}", "XBTUSD"], [1528681709769, "{\"table\": \"orderBookL2\", \"action\": \"update\", \"data\": [{\"id\": 8799275000, \"side\": \"Sell\", \"size\": 295536}, {\"id\": 8799304150, \"side\": \"Sell\", \"size\": 8000}, {\"id\": 8799305900, \"side\": \"Sell\", \"size\": 29791}, {\"id\": 8799320900, \"side\": \"Sell\", \"size\": 17722}, {\"id\": 8799321550, \"side\": \"Sell\", \"size\": 52087}, {\"id\": 8799336450, \"side\": \"Buy\", \"size\": 35977}, {\"id\": 8799346200, \"side\": \"Buy\", \"size\": 136597}, {\"id\": 8799362400, \"side\": \"Buy\", \"size\": 23597}], \"symbol\": \"XBTUSD\", \"timestamp\": \"2018-06-11 01:48:29.762744Z\"}", "XBTUSD"], [1528681713708, "{\"table\": \"orderBookL2\", \"action\": \"update\", \"data\": [{\"id\": 8799326700, \"side\": \"Buy\", \"size\": 35390}, {\"id\": 8799326800, \"side\": \"Buy\", \"size\": 36945}], \"symbol\": \"XBTUSD\", \"timestamp\": \"2018-06-11 01:48:33.703160Z\"}", "XBTUSD"], [1528681717577, "{\"table\": \"orderBookL2\", \"action\": \"delete\", \"data\": [{\"id\": 8799274450, \"side\": \"Sell\"}], \"symbol\": \"XBTUSD\", \"timestamp\": \"2018-06-11 01:48:37.573329Z\"}", "XBTUSD"], [1528681721253, "{\"table\": \"orderBookL2\", \"action\": \"update\", \"data\": [{\"id\": 8799311800, \"side\": \"Sell\", \"size\": 102605}, {\"id\": 8799312550, \"side\": \"Sell\", \"size\": 6300}], \"symbol\": \"XBTUSD\", \"timestamp\": \"2018-06-11 01:48:41.249372Z\"}", "XBTUSD"], [1528681724891, "{\"table\": \"orderBookL2\", \"action\": \"update\", \"data\": [{\"id\": 8799322800, \"side\": \"Sell\", \"size\": 142153}, {\"id\": 8799323200, \"side\": \"Sell\", \"size\": 112465}, {\"id\": 8799323300, \"side\": \"Sell\", \"size\": 200437}, {\"id\": 8799323550, \"side\": \"Sell\", \"size\": 13984}, {\"id\": 8799323850, \"side\": \"Sell\", \"size\": 4450}, {\"id\": 8799324050, \"side\": \"Sell\", \"size\": 58884}], \"symbol\": \"XBTUSD\", \"timestamp\": \"2018-06-11 01:48:44.885059Z\"}", "XBTUSD"], [1528681728534, "{\"table\": \"orderBookL2\", \"action\": \"update\", \"data\": [{\"id\": 8799326200, \"side\": \"Sell\", \"size\": 341440}, {\"id\": 8799326400, \"side\": \"Buy\", \"size\": 122236}], \"symbol\": \"XBTUSD\", \"timestamp\": \"2018-06-11 01:48:48.529025Z\"}", "XBTUSD"], [1528681731531, "{\"table\": \"orderBookL2\", \"action\": \"update\", \"data\": [{\"id\": 8799326300, \"side\": \"Buy\", \"size\": 1302578}, {\"id\": 8799326350, \"side\": \"Buy\", \"size\": 201075}, {\"id\": 8799326400, \"side\": \"Buy\", \"size\": 123630}], \"symbol\": \"XBTUSD\", \"timestamp\": \"2018-06-11 01:48:51.526887Z\"}", "XBTUSD"], [1528681735344, "{\"table\": \"orderBookL2\", \"action\": \"update\", \"data\": [{\"id\": 8799325650, \"side\": \"Sell\", \"size\": 28381}, {\"id\": 8799325750, \"side\": \"Sell\", \"size\": 20506}, {\"id\": 8799326550, \"side\": \"Buy\", \"size\": 69339}, {\"id\": 8799326650, \"side\": \"Buy\", \"size\": 16676}], \"symbol\": \"XBTUSD\", \"timestamp\": \"2018-06-11 01:48:55.340634Z\"}", "XBTUSD"], [1528681738315, "{\"table\": \"orderBookL2\", \"action\": \"update\", \"data\": [{\"id\": 8799325700, \"side\": \"Sell\", \"size\": 15090}], \"symbol\": \"XBTUSD\", \"timestamp\": \"2018-06-11 01:48:58.311244Z\"}", "XBTUSD"], [1528681743377, "{\"table\": \"orderBookL2\", \"action\": \"update\", \"data\": [{\"id\": 8799325900, \"side\": \"Sell\", \"size\": 159312}, {\"id\": 8799328100, \"side\": \"Buy\", \"size\": 123836}], \"symbol\": \"XBTUSD\", \"timestamp\": \"2018-06-11 01:49:03.373903Z\"}", "XBTUSD"], [1528681744568, "{\"table\": \"orderBookL2\", \"action\": \"update\", \"data\": [{\"id\": 8799326000, \"side\": \"Sell\", \"size\": 422535}, {\"id\": 8799326100, \"side\": \"Sell\", \"size\": 9100}], \"symbol\": \"XBTUSD\", \"timestamp\": \"2018-06-11 01:49:04.563421Z\"}", "XBTUSD"], [1528681747792, "{\"table\": \"orderBookL2\", \"action\": \"update\", \"data\": [{\"id\": 8799326300, \"side\": \"Buy\", \"size\": 1548748}], \"symbol\": \"XBTUSD\", \"timestamp\": \"2018-06-11 01:49:07.786698Z\"}", "XBTUSD"], [1528681751618, "{\"table\": \"orderBookL2\", \"action\": \"update\", \"data\": [{\"id\": 8799325500, \"side\": \"Sell\", \"size\": 300308}], \"symbol\": \"XBTUSD\", \"timestamp\": \"2018-06-11 01:49:11.612634Z\"}", "XBTUSD"], [1528681754202, "{\"table\": \"trade\", \"action\": \"insert\", \"data\": [{\"timestamp\": \"2018-06-11T01:49:12.898Z\", \"side\": \"Buy\", \"size\": 6050, \"price\": 6737.5, \"tickDirection\": \"ZeroPlusTick\", \"trdMatchID\": \"fa138b0f-4ea4-da92-dcb1-2ee4e0e9b4c9\", \"grossValue\": 89794100, \"homeNotional\": 0.897941, \"foreignNotional\": 6050}], \"symbol\": \"XBTUSD\", \"timestamp\": \"2018-06-11 01:49:14.199191Z\"}", "XBTUSD"], [1528681755610, "{\"table\": \"orderBookL2\", \"action\": \"update\", \"data\": [{\"id\": 8799326800, \"side\": \"Buy\", \"size\": 102849}, {\"id\": 8799326900, \"side\": \"Buy\", \"size\": 231358}], \"symbol\": \"XBTUSD\", \"timestamp\": \"2018-06-11 01:49:15.604523Z\"}", "XBTUSD"], [1528681758371, "{\"table\": \"orderBookL2\", \"action\": \"delete\", \"data\": [{\"id\": 8798923500, \"side\": \"Sell\"}], \"symbol\": \"XBTUSD\", \"timestamp\": \"2018-06-11 01:49:18.367848Z\"}", "XBTUSD"], [1528681761699, "{\"table\": \"orderBookL2\", \"action\": \"update\", \"data\": [{\"id\": 8799319450, \"side\": \"Sell\", \"size\": 53897}], \"symbol\": \"XBTUSD\", \"timestamp\": \"2018-06-11 01:49:21.697052Z\"}", "XBTUSD"], [1528681764635, "{\"table\": \"orderBookL2\", \"action\": \"insert\", \"data\": [{\"id\": 8799932600, \"side\": \"Buy\", \"size\": 3, \"price\": 674}], \"symbol\": \"XBTUSD\", \"timestamp\": \"2018-06-11 01:49:24.629155Z\"}", "XBTUSD"], [1528681768894, "{\"table\": \"orderBookL2\", \"action\": \"update\", \"data\": [{\"id\": 8799325350, \"side\": \"Sell\", \"size\": 69800}], \"symbol\": \"XBTUSD\", \"timestamp\": \"2018-06-11 01:49:28.890364Z\"}", "XBTUSD"], [1528681771633, "{\"table\": \"orderBookL2\", \"action\": \"update\", \"data\": [{\"id\": 8799323000, \"side\": \"Sell\", \"size\": 187904}], \"symbol\": \"XBTUSD\", \"timestamp\": \"2018-06-11 01:49:31.627240Z\"}", "XBTUSD"], [1528681772950, "{\"table\": \"orderBookL2\", \"action\": \"delete\", \"data\": [{\"id\": 8793262400, \"side\": \"Sell\"}], \"symbol\": \"XBTUSD\", \"timestamp\": \"2018-06-11 01:49:32.948330Z\"}", "XBTUSD"], [1528681776273, "{\"table\": \"orderBookL2\", \"action\": \"update\", \"data\": [{\"id\": 8799326500, \"side\": \"Buy\", \"size\": 63940}, {\"id\": 8799326650, \"side\": \"Buy\", \"size\": 19086}], \"symbol\": \"XBTUSD\", \"timestamp\": \"2018-06-11 01:49:36.263107Z\"}", "XBTUSD"], [1528681778921, "{\"table\": \"orderBookL2\", \"action\": \"update\", \"data\": [{\"id\": 8799326300, \"side\": \"Buy\", \"size\": 2509591}, {\"id\": 8799326350, \"side\": \"Buy\", \"size\": 234302}], \"symbol\": \"XBTUSD\", \"timestamp\": \"2018-06-11 01:49:38.918623Z\"}", "XBTUSD"], [1528681781329, "{\"table\": \"orderBookL2\", \"action\": \"update\", \"data\": [{\"id\": 8799326250, \"side\": \"Sell\", \"size\": 20696}], \"symbol\": \"XBTUSD\", \"timestamp\": \"2018-06-11 01:49:41.323862Z\"}", "XBTUSD"], [1528681783846, "{\"table\": \"orderBookL2\", \"action\": \"update\", \"data\": [{\"id\": 8799326300, \"side\": \"Buy\", \"size\": 2495610}], \"symbol\": \"XBTUSD\", \"timestamp\": \"2018-06-11 01:49:43.842552Z\"}", "XBTUSD"], [1528681784055, "{\"table\": \"orderBookL2\", \"action\": \"update\", \"data\": [{\"id\": 8799326300, \"side\": \"Buy\", \"size\": 2036211}], \"symbol\": \"XBTUSD\", \"timestamp\": \"2018-06-11 01:49:44.053037Z\"}", "XBTUSD"], [1528681784626, "{\"table\": \"orderBookL2\", \"action\": \"update\", \"data\": [{\"id\": 8799325900, \"side\": \"Sell\", \"size\": 14112}], \"symbol\": \"XBTUSD\", \"timestamp\": \"2018-06-11 01:49:44.624085Z\"}", "XBTUSD"], [1528681787859, "{\"table\": \"trade\", \"action\": \"insert\", \"data\": [{\"timestamp\": \"2018-06-11T01:49:46.395Z\", \"side\": \"Sell\", \"size\": 30000, \"price\": 6737.5, \"tickDirection\": \"MinusTick\", \"trdMatchID\": \"1c25d2f1-4545-4cb9-c18d-95485625a4fd\", \"grossValue\": 445260000, \"homeNotional\": 4.4526, \"foreignNotional\": 30000}], \"symbol\": \"XBTUSD\", \"timestamp\": \"2018-06-11 01:49:47.855257Z\"}", "XBTUSD"], [1528681789175, "{\"table\": \"trade\", \"action\": \"insert\", \"data\": [{\"timestamp\": \"2018-06-11T01:49:47.678Z\", \"side\": \"Buy\", \"size\": 15729, \"price\": 6738.5, \"tickDirection\": \"ZeroPlusTick\", \"trdMatchID\": \"c63b8981-96f9-b0ab-4a13-42b4ad87eb6f\", \"grossValue\": 233418360, \"homeNotional\": 2.3341836, \"foreignNotional\": 15729}, {\"timestamp\": \"2018-06-11T01:49:47.678Z\", \"side\": \"Buy\", \"size\": 45, \"price\": 6738.5, \"tickDirection\": \"ZeroPlusTick\", \"trdMatchID\": \"5cb9127d-033a-84ab-d925-b1dfbf3959b0\", \"grossValue\": 667800, \"homeNotional\": 0.006678, \"foreignNotional\": 45}, {\"timestamp\": \"2018-06-11T01:49:47.678Z\", \"side\": \"Buy\", \"size\": 30, \"price\": 6738.5, \"tickDirection\": \"ZeroPlusTick\", \"trdMatchID\": \"1550b0e2-6cd4-aa5d-beff-9a8ab71900ae\", \"grossValue\": 445200, \"homeNotional\": 0.004452, \"foreignNotional\": 30}, {\"timestamp\": \"2018-06-11T01:49:47.678Z\", \"side\": \"Buy\", \"size\": 25, \"price\": 6738.5, \"tickDirection\": \"ZeroPlusTick\", \"trdMatchID\": \"6e592fac-700d-6e71-90eb-3fc7b000d368\", \"grossValue\": 371000, \"homeNotional\": 0.00371, \"foreignNotional\": 25}, {\"timestamp\": \"2018-06-11T01:49:47.678Z\", \"side\": \"Buy\", \"size\": 500, \"price\": 6739, \"tickDirection\": \"PlusTick\", \"trdMatchID\": \"b397f01e-205a-92eb-aa13-55d0e1b9bfc7\", \"grossValue\": 7419500, \"homeNotional\": 0.074195, \"foreignNotional\": 500}, {\"timestamp\": \"2018-06-11T01:49:47.678Z\", \"side\": \"Buy\", \"size\": 3600, \"price\": 6739, \"tickDirection\": \"ZeroPlusTick\", \"trdMatchID\": \"b6a1dcd2-ed7f-e9ac-7af4-837242e54509\", \"grossValue\": 53420400, \"homeNotional\": 0.534204, \"foreignNotional\": 3600}, {\"timestamp\": \"2018-06-11T01:49:47.678Z\", \"side\": \"Buy\", \"size\": 71, \"price\": 6739, \"tickDirection\": \"ZeroPlusTick\", \"trdMatchID\": \"c5f3e6dd-874a-9068-2477-3c60b8279873\", \"grossValue\": 1053569, \"homeNotional\": 0.01053569, \"foreignNotional\": 71}], \"symbol\": \"XBTUSD\", \"timestamp\": \"2018-06-11 01:49:49.171287Z\"}", "XBTUSD"], [1528681789368, "{\"table\": \"orderBookL2\", \"action\": \"update\", \"data\": [{\"id\": 8799326300, \"side\": \"Buy\", \"size\": 897666}], \"symbol\": \"XBTUSD\", \"timestamp\": \"2018-06-11 01:49:49.365085Z\"}", "XBTUSD"], [1528681789714, "{\"table\": \"orderBookL2\", \"action\": \"update\", \"data\": [{\"id\": 8799326250, \"side\": \"Buy\", \"size\": 1224729}], \"symbol\": \"XBTUSD\", \"timestamp\": \"2018-06-11 01:49:49.712185Z\"}", "XBTUSD"], [1528681790502, "{\"table\": \"orderBookL2\", \"action\": \"update\", \"data\": [{\"id\": 8799326100, \"side\": \"Buy\", \"size\": 1707691}, {\"id\": 8799326250, \"side\": \"Buy\", \"size\": 757153}], \"symbol\": \"XBTUSD\", \"timestamp\": \"2018-06-11 01:49:50.500243Z\"}", "XBTUSD"], [1528681791307, "{\"table\": \"orderBookL2\", \"action\": \"update\", \"data\": [{\"id\": 8799326100, \"side\": \"Buy\", \"size\": 1879381}], \"symbol\": \"XBTUSD\", \"timestamp\": \"2018-06-11 01:49:51.305006Z\"}", "XBTUSD"], [1528681791978, "{\"table\": \"orderBookL2\", \"action\": \"update\", \"data\": [{\"id\": 8799326100, \"side\": \"Buy\", \"size\": 1189900}], \"symbol\": \"XBTUSD\", \"timestamp\": \"2018-06-11 01:49:51.974657Z\"}", "XBTUSD"], [1528681792737, "{\"table\": \"orderBookL2\", \"action\": \"update\", \"data\": [{\"id\": 8799326150, \"side\": \"Buy\", \"size\": 127003}], \"symbol\": \"XBTUSD\", \"timestamp\": \"2018-06-11 01:49:52.733710Z\"}", "XBTUSD"], [1528681793402, "{\"table\": \"orderBookL2\", \"action\": \"update\", \"data\": [{\"id\": 8793260400, \"side\": \"Sell\", \"size\": 204}], \"symbol\": \"XBTUSD\", \"timestamp\": \"2018-06-11 01:49:53.399820Z\"}", "XBTUSD"], [1528681794244, "{\"table\": \"orderBookL2\", \"action\": \"update\", \"data\": [{\"id\": 8799324650, \"side\": \"Sell\", \"size\": 49859}, {\"id\": 8799325050, \"side\": \"Sell\", \"size\": 6750}, {\"id\": 8799326650, \"side\": \"Buy\", \"size\": 56856}, {\"id\": 8799327050, \"side\": \"Buy\", \"size\": 138143}], \"symbol\": \"XBTUSD\", \"timestamp\": \"2018-06-11 01:49:54.241704Z\"}", "XBTUSD"], [1528681796295, "{\"table\": \"orderBookL2\", \"action\": \"update\", \"data\": [{\"id\": 8799324200, \"side\": \"Sell\", \"size\": 52995}, {\"id\": 8799324250, \"side\": \"Sell\", \"size\": 51190}], \"symbol\": \"XBTUSD\", \"timestamp\": \"2018-06-11 01:49:56.291263Z\"}", "XBTUSD"], [1528681798788, "{\"table\": \"orderBookL2\", \"action\": \"update\", \"data\": [{\"id\": 8799305950, \"side\": \"Sell\", \"size\": 8500}], \"symbol\": \"XBTUSD\", \"timestamp\": \"2018-06-11 01:49:58.784975Z\"}", "XBTUSD"], [1528681799587, "{\"table\": \"orderBookL2\", \"action\": \"update\", \"data\": [{\"id\": 8799325550, \"side\": \"Sell\", \"size\": 121793}, {\"id\": 8799327150, \"side\": \"Buy\", \"size\": 172863}], \"symbol\": \"XBTUSD\", \"timestamp\": \"2018-06-11 01:49:59.583391Z\"}", "XBTUSD"], [1528681804857, "{\"table\": \"orderBookL2\", \"action\": \"update\", \"data\": [{\"id\": 8799325250, \"side\": \"Sell\", \"size\": 3785}], \"symbol\": \"XBTUSD\", \"timestamp\": \"2018-06-11 01:50:04.852629Z\"}", "XBTUSD"], [1528681805260, "{\"table\": \"orderBookL2\", \"action\": \"update\", \"data\": [{\"id\": 8799325450, \"side\": \"Sell\", \"size\": 128545}, {\"id\": 8799325550, \"side\": \"Sell\", \"size\": 46576}], \"symbol\": \"XBTUSD\", \"timestamp\": \"2018-06-11 01:50:05.258165Z\"}", "XBTUSD"], [1528681806975, "{\"table\": \"orderBookL2\", \"action\": \"update\", \"data\": [{\"id\": 8799318950, \"side\": \"Sell\", \"size\": 44131}], \"symbol\": \"XBTUSD\", \"timestamp\": \"2018-06-11 01:50:06.971707Z\"}", "XBTUSD"], [1528681808718, "{\"table\": \"orderBookL2\", \"action\": \"update\", \"data\": [{\"id\": 8799325500, \"side\": \"Sell\", \"size\": 265101}], \"symbol\": \"XBTUSD\", \"timestamp\": \"2018-06-11 01:50:08.711471Z\"}", "XBTUSD"], [1528681810615, "{\"table\": \"orderBookL2\", \"action\": \"insert\", \"data\": [{\"id\": 8796594450, \"side\": \"Sell\", \"size\": 625, \"price\": 34055.5}], \"symbol\": \"XBTUSD\", \"timestamp\": \"2018-06-11 01:50:10.608437Z\"}", "XBTUSD"], [1528681812790, "{\"table\": \"orderBookL2\", \"action\": \"update\", \"data\": [{\"id\": 8799325600, \"side\": \"Sell\", \"size\": 2101869}], \"symbol\": \"XBTUSD\", \"timestamp\": \"2018-06-11 01:50:12.785935Z\"}", "XBTUSD"], [1528681813650, "{\"table\": \"orderBookL2\", \"action\": \"update\", \"data\": [{\"id\": 8799325750, \"side\": \"Buy\", \"size\": 55557}, {\"id\": 8799325900, \"side\": \"Buy\", \"size\": 31311}], \"symbol\": \"XBTUSD\", \"timestamp\": \"2018-06-11 01:50:13.643612Z\"}", "XBTUSD"], [1528681816429, "{\"table\": \"orderBookL2\", \"action\": \"update\", \"data\": [{\"id\": 8799324550, \"side\": \"Sell\", \"size\": 3698}, {\"id\": 8799325050, \"side\": \"Sell\", \"size\": 21346}], \"symbol\": \"XBTUSD\", \"timestamp\": \"2018-06-11 01:50:16.426983Z\"}", "XBTUSD"], [1528681818899, "{\"table\": \"trade\", \"action\": \"insert\", \"data\": [{\"timestamp\": \"2018-06-11T01:50:18.399Z\", \"side\": \"Sell\", \"size\": 140, \"price\": 6743.5, \"tickDirection\": \"ZeroMinusTick\", \"trdMatchID\": \"d38a009f-a13f-d583-710e-0e3cca7a1ccc\", \"grossValue\": 2076060, \"homeNotional\": 0.0207606, \"foreignNotional\": 140}], \"symbol\": \"XBTUSD\", \"timestamp\": \"2018-06-11 01:50:18.891916Z\"}", "XBTUSD"], [1528681823261, "{\"table\": \"orderBookL2\", \"action\": \"delete\", \"data\": [{\"id\": 8799344050, \"side\": \"Buy\"}], \"symbol\": \"XBTUSD\", \"timestamp\": \"2018-06-11 01:50:23.257064Z\"}", "XBTUSD"], [1528681824386, "{\"table\": \"orderBookL2\", \"action\": \"delete\", \"data\": [{\"id\": 8798736900, \"side\": \"Sell\"}], \"symbol\": \"XBTUSD\", \"timestamp\": \"2018-06-11 01:50:24.373399Z\"}", "XBTUSD"], [1528681828796, "{\"table\": \"quote\", \"action\": \"insert\", \"data\": [{\"timestamp\": \"2018-06-11T01:50:25.902Z\", \"bidSize\": 255367, \"bidPrice\": 6743.5, \"askPrice\": 6744, \"askSize\": 2374418}, {\"timestamp\": \"2018-06-11T01:50:25.920Z\", \"bidSize\": 252431, \"bidPrice\": 6743.5, \"askPrice\": 6744, \"askSize\": 2374418}, {\"timestamp\": \"2018-06-11T01:50:25.982Z\", \"bidSize\": 247055, \"bidPrice\": 6743.5, \"askPrice\": 6744, \"askSize\": 2374418}, {\"timestamp\": \"2018-06-11T01:50:25.988Z\", \"bidSize\": 250055, \"bidPrice\": 6743.5, \"askPrice\": 6744, \"askSize\": 2374418}, {\"timestamp\": \"2018-06-11T01:50:25.994Z\", \"bidSize\": 245343, \"bidPrice\": 6743.5, \"askPrice\": 6744, \"askSize\": 2374418}, {\"timestamp\": \"2018-06-11T01:50:26.026Z\", \"bidSize\": 248994, \"bidPrice\": 6743.5, \"askPrice\": 6744, \"askSize\": 2374418}, {\"timestamp\": \"2018-06-11T01:50:26.036Z\", \"bidSize\": 248994, \"bidPrice\": 6743.5, \"askPrice\": 6744, \"askSize\": 2374168}, {\"timestamp\": \"2018-06-11T01:50:26.059Z\", \"bidSize\": 248794, \"bidPrice\": 6743.5, \"askPrice\": 6744, \"askSize\": 2374168}, {\"timestamp\": \"2018-06-11T01:50:26.113Z\", \"bidSize\": 248794, \"bidPrice\": 6743.5, \"askPrice\": 6744, \"askSize\": 2404168}, {\"timestamp\": \"2018-06-11T01:50:26.116Z\", \"bidSize\": 246094, \"bidPrice\": 6743.5, \"askPrice\": 6744, \"askSize\": 2404168}, {\"timestamp\": \"2018-06-11T01:50:26.212Z\", \"bidSize\": 240094, \"bidPrice\": 6743.5, \"askPrice\": 6744, \"askSize\": 2404168}, {\"timestamp\": \"2018-06-11T01:50:26.394Z\", \"bidSize\": 240094, \"bidPrice\": 6743.5, \"askPrice\": 6744, \"askSize\": 2401168}, {\"timestamp\": \"2018-06-11T01:50:26.458Z\", \"bidSize\": 240094, \"bidPrice\": 6743.5, \"askPrice\": 6744, \"askSize\": 2401169}, {\"timestamp\": \"2018-06-11T01:50:26.468Z\", \"bidSize\": 290094, \"bidPrice\": 6743.5, \"askPrice\": 6744, \"askSize\": 2401169}, {\"timestamp\": \"2018-06-11T01:50:26.509Z\", \"bidSize\": 290094, \"bidPrice\": 6743.5, \"askPrice\": 6744, \"askSize\": 2303779}, {\"timestamp\": \"2018-06-11T01:50:26.513Z\", \"bidSize\": 290094, \"bidPrice\": 6743.5, \"askPrice\": 6744, \"askSize\": 2311538}, {\"timestamp\": \"2018-06-11T01:50:26.611Z\", \"bidSize\": 290094, \"bidPrice\": 6743.5, \"askPrice\": 6744, \"askSize\": 2011538}, {\"timestamp\": \"2018-06-11T01:50:26.626Z\", \"bidSize\": 290094, \"bidPrice\": 6743.5, \"askPrice\": 6744, \"askSize\": 2311538}, {\"timestamp\": \"2018-06-11T01:50:26.685Z\", \"bidSize\": 290094, \"bidPrice\": 6743.5, \"askPrice\": 6744, \"askSize\": 2410300}, {\"timestamp\": \"2018-06-11T01:50:26.690Z\", \"bidSize\": 290094, \"bidPrice\": 6743.5, \"askPrice\": 6744, \"askSize\": 2300300}, {\"timestamp\": \"2018-06-11T01:50:26.705Z\", \"bidSize\": 290094, \"bidPrice\": 6743.5, \"askPrice\": 6744, \"askSize\": 2410300}, {\"timestamp\": \"2018-06-11T01:50:26.748Z\", \"bidSize\": 335094, \"bidPrice\": 6743.5, \"askPrice\": 6744, \"askSize\": 2410300}, {\"timestamp\": \"2018-06-11T01:50:26.754Z\", \"bidSize\": 335094, \"bidPrice\": 6743.5, \"askPrice\": 6744, \"askSize\": 2380300}, {\"timestamp\": \"2018-06-11T01:50:26.769Z\", \"bidSize\": 335095, \"bidPrice\": 6743.5, \"askPrice\": 6744, \"askSize\": 2380300}, {\"timestamp\": \"2018-06-11T01:50:26.777Z\", \"bidSize\": 335095, \"bidPrice\": 6743.5, \"askPrice\": 6744, \"askSize\": 2410300}, {\"timestamp\": \"2018-06-11T01:50:26.780Z\", \"bidSize\": 325095, \"bidPrice\": 6743.5, \"askPrice\": 6744, \"askSize\": 2410300}, {\"timestamp\": \"2018-06-11T01:50:26.854Z\", \"bidSize\": 325095, \"bidPrice\": 6743.5, \"askPrice\": 6744, \"askSize\": 2460300}, {\"timestamp\": \"2018-06-11T01:50:27.038Z\", \"bidSize\": 325095, \"bidPrice\": 6743.5, \"askPrice\": 6744, \"askSize\": 2378428}], \"symbol\": \"XBTUSD\", \"timestamp\": \"2018-06-11 01:50:28.786188Z\"}", "XBTUSD"], [1528681829035, "{\"table\": \"orderBookL2\", \"action\": \"update\", \"data\": [{\"id\": 8799325500, \"side\": \"Sell\", \"size\": 286631}, {\"id\": 8799325700, \"side\": \"Buy\", \"size\": 156786}], \"symbol\": \"XBTUSD\", \"timestamp\": \"2018-06-11 01:50:29.032798Z\"}", "XBTUSD"], [1528681832061, "{\"table\": \"orderBookL2\", \"action\": \"update\", \"data\": [{\"id\": 8799325100, \"side\": \"Sell\", \"size\": 40593}, {\"id\": 8799325400, \"side\": \"Sell\", \"size\": 51502}], \"symbol\": \"XBTUSD\", \"timestamp\": \"2018-06-11 01:50:32.057727Z\"}", "XBTUSD"], [1528681834556, "{\"table\": \"orderBookL2\", \"action\": \"update\", \"data\": [{\"id\": 8799325900, \"side\": \"Buy\", \"size\": 26485}, {\"id\": 8799326000, \"side\": \"Buy\", \"size\": 15693}], \"symbol\": \"XBTUSD\", \"timestamp\": \"2018-06-11 01:50:34.554012Z\"}", "XBTUSD"], [1528681838800, "{\"table\": \"orderBookL2\", \"action\": \"update\", \"data\": [{\"id\": 8799326100, \"side\": \"Buy\", \"size\": 103187}, {\"id\": 8799328700, \"side\": \"Buy\", \"size\": 16035}], \"symbol\": \"XBTUSD\", \"timestamp\": \"2018-06-11 01:50:38.793307Z\"}", "XBTUSD"], [1528681839668, "{\"table\": \"orderBookL2\", \"action\": \"update\", \"data\": [{\"id\": 8799325450, \"side\": \"Sell\", \"size\": 117565}, {\"id\": 8799325500, \"side\": \"Sell\", \"size\": 286231}, {\"id\": 8799325900, \"side\": \"Buy\", \"size\": 1984}, {\"id\": 8799325950, \"side\": \"Buy\", \"size\": 48230}], \"symbol\": \"XBTUSD\", \"timestamp\": \"2018-06-11 01:50:39.660776Z\"}", "XBTUSD"], [1528681843837, "{\"table\": \"orderBookL2\", \"action\": \"update\", \"data\": [{\"id\": 8799275300, \"side\": \"Sell\", \"size\": 43247}, {\"id\": 8799325300, \"side\": \"Sell\", \"size\": 247575}, {\"id\": 8799325500, \"side\": \"Sell\", \"size\": 294531}], \"symbol\": \"XBTUSD\", \"timestamp\": \"2018-06-11 01:50:43.834187Z\"}", "XBTUSD"], [1528681844697, "{\"table\": \"orderBookL2\", \"action\": \"update\", \"data\": [{\"id\": 8799314600, \"side\": \"Sell\", \"size\": 36257}, {\"id\": 8799316600, \"side\": \"Sell\", \"size\": 59743}, {\"id\": 8799317600, \"side\": \"Sell\", \"size\": 64846}, {\"id\": 8799319600, \"side\": \"Sell\", \"size\": 131140}, {\"id\": 8799320600, \"side\": \"Sell\", \"size\": 89530}, {\"id\": 8799322600, \"side\": \"Sell\", \"size\": 569240}, {\"id\": 8799323600, \"side\": \"Sell\", \"size\": 268666}, {\"id\": 8799325600, \"side\": \"Sell\", \"size\": 1420996}], \"symbol\": \"XBTUSD\", \"timestamp\": \"2018-06-11 01:50:44.694296Z\"}", "XBTUSD"], [1528681850280, "{\"table\": \"orderBookL2\", \"action\": \"update\", \"data\": [{\"id\": 8799325150, \"side\": \"Sell\", \"size\": 12779}, {\"id\": 8799325350, \"side\": \"Sell\", \"size\": 57770}, {\"id\": 8799326050, \"side\": \"Buy\", \"size\": 150826}, {\"id\": 8799326100, \"side\": \"Buy\", \"size\": 108747}], \"symbol\": \"XBTUSD\", \"timestamp\": \"2018-06-11 01:50:50.274656Z\"}", "XBTUSD"], [1528681850600, "{\"table\": \"orderBookL2\", \"action\": \"update\", \"data\": [{\"id\": 8799325700, \"side\": \"Sell\", \"size\": 210329}], \"symbol\": \"XBTUSD\", \"timestamp\": \"2018-06-11 01:50:50.596817Z\"}", "XBTUSD"], [1528681851500, "{\"table\": \"orderBookL2\", \"action\": \"update\", \"data\": [{\"id\": 8799325650, \"side\": \"Sell\", \"size\": 896235}, {\"id\": 8799325700, \"side\": \"Sell\", \"size\": 1675416}], \"symbol\": \"XBTUSD\", \"timestamp\": \"2018-06-11 01:50:51.497319Z\"}", "XBTUSD"], [1528681853812, "{\"table\": \"orderBookL2\", \"action\": \"update\", \"data\": [{\"id\": 8799325600, \"side\": \"Sell\", \"size\": 495045}], \"symbol\": \"XBTUSD\", \"timestamp\": \"2018-06-11 01:50:53.809121Z\"}", "XBTUSD"], [1528681854096, "{\"table\": \"orderBookL2\", \"action\": \"insert\", \"data\": [{\"id\": 8799325750, \"side\": \"Sell\", \"size\": 3000, \"price\": 6742.5}], \"symbol\": \"XBTUSD\", \"timestamp\": \"2018-06-11 01:50:54.093591Z\"}", "XBTUSD"], [1528681854915, "{\"table\": \"orderBookL2\", \"action\": \"update\", \"data\": [{\"id\": 8799325700, \"side\": \"Sell\", \"size\": 1237388}, {\"id\": 8799325750, \"side\": \"Sell\", \"size\": 1279022}], \"symbol\": \"XBTUSD\", \"timestamp\": \"2018-06-11 01:50:54.911066Z\"}", "XBTUSD"], [1528681857437, "{\"table\": \"orderBookL2\", \"action\": \"update\", \"data\": [{\"id\": 8799325650, \"side\": \"Sell\", \"size\": 207168}], \"symbol\": \"XBTUSD\", \"timestamp\": \"2018-06-11 01:50:57.431262Z\"}", "XBTUSD"], [1528681858944, "{\"table\": \"orderBookL2\", \"action\": \"update\", \"data\": [{\"id\": 8799325750, \"side\": \"Sell\", \"size\": 1821426}], \"symbol\": \"XBTUSD\", \"timestamp\": \"2018-06-11 01:50:58.941982Z\"}", "XBTUSD"], [1528681862290, "{\"table\": \"orderBookL2\", \"action\": \"update\", \"data\": [{\"id\": 8799325100, \"side\": \"Sell\", \"size\": 108377}, {\"id\": 8799325550, \"side\": \"Sell\", \"size\": 24220}, {\"id\": 8799325950, \"side\": \"Buy\", \"size\": 68866}, {\"id\": 8799326350, \"side\": \"Buy\", \"size\": 64774}], \"symbol\": \"XBTUSD\", \"timestamp\": \"2018-06-11 01:51:02.288122Z\"}", "XBTUSD"], [1528681864656, "{\"table\": \"orderBookL2\", \"action\": \"update\", \"data\": [{\"id\": 8799326500, \"side\": \"Buy\", \"size\": 106297}, {\"id\": 8799326850, \"side\": \"Buy\", \"size\": 8392}], \"symbol\": \"XBTUSD\", \"timestamp\": \"2018-06-11 01:51:04.652632Z\"}", "XBTUSD"], [1528681864958, "{\"table\": \"orderBookL2\", \"action\": \"update\", \"data\": [{\"id\": 8799326050, \"side\": \"Buy\", \"size\": 55986}, {\"id\": 8799326100, \"side\": \"Buy\", \"size\": 122642}], \"symbol\": \"XBTUSD\", \"timestamp\": \"2018-06-11 01:51:04.953662Z\"}", "XBTUSD"], [1528681867078, "{\"table\": \"orderBookL2\", \"action\": \"update\", \"data\": [{\"id\": 8799325800, \"side\": \"Buy\", \"size\": 520967}], \"symbol\": \"XBTUSD\", \"timestamp\": \"2018-06-11 01:51:07.073981Z\"}", "XBTUSD"], [1528681871306, "{\"table\": \"orderBookL2\", \"action\": \"update\", \"data\": [{\"id\": 8799320100, \"side\": \"Sell\", \"size\": 127079}], \"symbol\": \"XBTUSD\", \"timestamp\": \"2018-06-11 01:51:11.301329Z\"}", "XBTUSD"], [1528681874291, "{\"table\": \"orderBookL2\", \"action\": \"update\", \"data\": [{\"id\": 8799325750, \"side\": \"Sell\", \"size\": 1363528}], \"symbol\": \"XBTUSD\", \"timestamp\": \"2018-06-11 01:51:14.286830Z\"}", "XBTUSD"], [1528681877310, "{\"table\": \"orderBookL2\", \"action\": \"update\", \"data\": [{\"id\": 8799325750, \"side\": \"Sell\", \"size\": 1098657}], \"symbol\": \"XBTUSD\", \"timestamp\": \"2018-06-11 01:51:17.307786Z\"}", "XBTUSD"], [1528681880397, "{\"table\": \"orderBookL2\", \"action\": \"update\", \"data\": [{\"id\": 8799325900, \"side\": \"Buy\", \"size\": 109391}, {\"id\": 8799325950, \"side\": \"Buy\", \"size\": 48845}], \"symbol\": \"XBTUSD\", \"timestamp\": \"2018-06-11 01:51:20.392878Z\"}", "XBTUSD"], [1528681882868, "{\"table\": \"orderBookL2\", \"action\": \"update\", \"data\": [{\"id\": 8799325750, \"side\": \"Sell\", \"size\": 750498}, {\"id\": 8799327500, \"side\": \"Buy\", \"size\": 472045}], \"symbol\": \"XBTUSD\", \"timestamp\": \"2018-06-11 01:51:22.865136Z\"}", "XBTUSD"], [1528681886433, "{\"table\": \"orderBookL2\", \"action\": \"update\", \"data\": [{\"id\": 8799324550, \"side\": \"Sell\", \"size\": 22760}], \"symbol\": \"XBTUSD\", \"timestamp\": \"2018-06-11 01:51:26.429369Z\"}", "XBTUSD"], [1528681888867, "{\"table\": \"orderBookL2\", \"action\": \"update\", \"data\": [{\"id\": 8799325800, \"side\": \"Buy\", \"size\": 1547805}], \"symbol\": \"XBTUSD\", \"timestamp\": \"2018-06-11 01:51:28.864650Z\"}", "XBTUSD"], [1528681893603, "{\"table\": \"orderBookL2\", \"action\": \"insert\", \"data\": [{\"id\": 8799932600, \"side\": \"Buy\", \"size\": 3, \"price\": 674}], \"symbol\": \"XBTUSD\", \"timestamp\": \"2018-06-11 01:51:33.596706Z\"}", "XBTUSD"], [1528681894837, "{\"table\": \"orderBookL2\", \"action\": \"update\", \"data\": [{\"id\": 8799325750, \"side\": \"Sell\", \"size\": 1462215}], \"symbol\": \"XBTUSD\", \"timestamp\": \"2018-06-11 01:51:34.835299Z\"}", "XBTUSD"], [1528681896475, "{\"table\": \"orderBookL2\", \"action\": \"update\", \"data\": [{\"id\": 8799325700, \"side\": \"Sell\", \"size\": 171320}, {\"id\": 8799325900, \"side\": \"Buy\", \"size\": 59838}], \"symbol\": \"XBTUSD\", \"timestamp\": \"2018-06-11 01:51:36.469541Z\"}", "XBTUSD"], [1528681898909, "{\"table\": \"orderBookL2\", \"action\": \"update\", \"data\": [{\"id\": 8799326500, \"side\": \"Buy\", \"size\": 138009}, {\"id\": 8799326600, \"side\": \"Buy\", \"size\": 6090}], \"symbol\": \"XBTUSD\", \"timestamp\": \"2018-06-11 01:51:38.905071Z\"}", "XBTUSD"], [1528681900387, "{\"table\": \"orderBookL2\", \"action\": \"update\", \"data\": [{\"id\": 8799324550, \"side\": \"Sell\", \"size\": 22760}], \"symbol\": \"XBTUSD\", \"timestamp\": \"2018-06-11 01:51:40.382724Z\"}", "XBTUSD"], [1528681903775, "{\"table\": \"orderBookL2\", \"action\": \"update\", \"data\": [{\"id\": 8799325700, \"side\": \"Sell\", \"size\": 186080}], \"symbol\": \"XBTUSD\", \"timestamp\": \"2018-06-11 01:51:43.766607Z\"}", "XBTUSD"], [1528681909016, "{\"table\": \"trade\", \"action\": \"insert\", \"data\": [{\"timestamp\": \"2018-06-11T01:51:46.940Z\", \"side\": \"Sell\", \"size\": 3000, \"price\": 6742, \"tickDirection\": \"MinusTick\", \"trdMatchID\": \"ff635c39-1539-db90-07b0-2ebaddfb948e\", \"grossValue\": 44496000, \"homeNotional\": 0.44496, \"foreignNotional\": 3000}], \"symbol\": \"XBTUSD\", \"timestamp\": \"2018-06-11 01:51:49.006025Z\"}", "XBTUSD"], [1528681909929, "{\"table\": \"orderBookL2\", \"action\": \"update\", \"data\": [{\"id\": 8799325800, \"side\": \"Buy\", \"size\": 1975986}, {\"id\": 8799325850, \"side\": \"Buy\", \"size\": 77749}], \"symbol\": \"XBTUSD\", \"timestamp\": \"2018-06-11 01:51:49.924508Z\"}", "XBTUSD"], [1528681911562, "{\"table\": \"orderBookL2\", \"action\": \"update\", \"data\": [{\"id\": 8799324950, \"side\": \"Sell\", \"size\": 40511}, {\"id\": 8799325000, \"side\": \"Sell\", \"size\": 218189}], \"symbol\": \"XBTUSD\", \"timestamp\": \"2018-06-11 01:51:51.557470Z\"}", "XBTUSD"], [1528681912292, "{\"table\": \"orderBookL2\", \"action\": \"update\", \"data\": [{\"id\": 8799325750, \"side\": \"Buy\", \"size\": 2170051}], \"symbol\": \"XBTUSD\", \"timestamp\": \"2018-06-11 01:51:52.290305Z\"}", "XBTUSD"], [1528681914470, "{\"table\": \"orderBookL2\", \"action\": \"update\", \"data\": [{\"id\": 8799327300, \"side\": \"Buy\", \"size\": 329099}], \"symbol\": \"XBTUSD\", \"timestamp\": \"2018-06-11 01:51:54.464701Z\"}", "XBTUSD"], [1528681916613, "{\"table\": \"orderBookL2\", \"action\": \"update\", \"data\": [{\"id\": 8799308250, \"side\": \"Sell\", \"size\": 2250}], \"symbol\": \"XBTUSD\", \"timestamp\": \"2018-06-11 01:51:56.609234Z\"}", "XBTUSD"], [1528681919989, "{\"table\": \"orderBookL2\", \"action\": \"update\", \"data\": [{\"id\": 8799323650, \"side\": \"Sell\", \"size\": 11153}], \"symbol\": \"XBTUSD\", \"timestamp\": \"2018-06-11 01:51:59.985203Z\"}", "XBTUSD"], [1528681924712, "{\"table\": \"orderBookL2\", \"action\": \"update\", \"data\": [{\"id\": 8799325750, \"side\": \"Buy\", \"size\": 2150879}], \"symbol\": \"XBTUSD\", \"timestamp\": \"2018-06-11 01:52:04.707838Z\"}", "XBTUSD"], [1528681926150, "{\"table\": \"orderBookL2\", \"action\": \"update\", \"data\": [{\"id\": 8799324450, \"side\": \"Sell\", \"size\": 14060}], \"symbol\": \"XBTUSD\", \"timestamp\": \"2018-06-11 01:52:06.142932Z\"}", "XBTUSD"], [1528681928998, "{\"table\": \"orderBookL2\", \"action\": \"update\", \"data\": [{\"id\": 8799325700, \"side\": \"Sell\", \"size\": 70976}], \"symbol\": \"XBTUSD\", \"timestamp\": \"2018-06-11 01:52:08.994224Z\"}", "XBTUSD"], [1528681930002, "{\"table\": \"orderBookL2\", \"action\": \"insert\", \"data\": [{\"id\": 8798775900, \"side\": \"Sell\", \"size\": 91, \"price\": 12241}], \"symbol\": \"XBTUSD\", \"timestamp\": \"2018-06-11 01:52:09.991407Z\"}", "XBTUSD"], [1528681932019, "{\"table\": \"orderBookL2\", \"action\": \"delete\", \"data\": [{\"id\": 8799325700, \"side\": \"Sell\"}], \"symbol\": \"XBTUSD\", \"timestamp\": \"2018-06-11 01:52:12.012895Z\"}", "XBTUSD"], [1528681932758, "{\"table\": \"orderBookL2\", \"action\": \"update\", \"data\": [{\"id\": 8799325700, \"side\": \"Buy\", \"size\": 1534473}], \"symbol\": \"XBTUSD\", \"timestamp\": \"2018-06-11 01:52:12.755541Z\"}", "XBTUSD"], [1528681934348, "{\"table\": \"orderBookL2\", \"action\": \"update\", \"data\": [{\"id\": 8799325700, \"side\": \"Buy\", \"size\": 2174804}], \"symbol\": \"XBTUSD\", \"timestamp\": \"2018-06-11 01:52:14.344359Z\"}", "XBTUSD"], [1528681935212, "{\"table\": \"quote\", \"action\": \"insert\", \"data\": [{\"timestamp\": \"2018-06-11T01:52:14.144Z\", \"bidSize\": 1925723, \"bidPrice\": 6743, \"askPrice\": 6743.5, \"askSize\": 23086}, {\"timestamp\": \"2018-06-11T01:52:14.165Z\", \"bidSize\": 1921723, \"bidPrice\": 6743, \"askPrice\": 6743.5, \"askSize\": 23086}, {\"timestamp\": \"2018-06-11T01:52:14.233Z\", \"bidSize\": 1927523, \"bidPrice\": 6743, \"askPrice\": 6743.5, \"askSize\": 23086}, {\"timestamp\": \"2018-06-11T01:52:14.236Z\", \"bidSize\": 1927524, \"bidPrice\": 6743, \"askPrice\": 6743.5, \"askSize\": 23086}, {\"timestamp\": \"2018-06-11T01:52:14.240Z\", \"bidSize\": 1933524, \"bidPrice\": 6743, \"askPrice\": 6743.5, \"askSize\": 23086}, {\"timestamp\": \"2018-06-11T01:52:14.265Z\", \"bidSize\": 2233524, \"bidPrice\": 6743, \"askPrice\": 6743.5, \"askSize\": 23086}, {\"timestamp\": \"2018-06-11T01:52:14.286Z\", \"bidSize\": 2233525, \"bidPrice\": 6743, \"askPrice\": 6743.5, \"askSize\": 23086}, {\"timestamp\": \"2018-06-11T01:52:14.308Z\", \"bidSize\": 2233525, \"bidPrice\": 6743, \"askPrice\": 6743.5, \"askSize\": 3086}, {\"timestamp\": \"2018-06-11T01:52:14.328Z\", \"bidSize\": 2174804, \"bidPrice\": 6743, \"askPrice\": 6743.5, \"askSize\": 3086}, {\"timestamp\": \"2018-06-11T01:52:14.332Z\", \"bidSize\": 2104804, \"bidPrice\": 6743, \"askPrice\": 6743.5, \"askSize\": 3086}, {\"timestamp\": \"2018-06-11T01:52:14.347Z\", \"bidSize\": 55635, \"bidPrice\": 6743.5, \"askPrice\": 6744, \"askSize\": 97145}, {\"timestamp\": \"2018-06-11T01:52:14.386Z\", \"bidSize\": 75635, \"bidPrice\": 6743.5, \"askPrice\": 6744, \"askSize\": 97145}, {\"timestamp\": \"2018-06-11T01:52:14.390Z\", \"bidSize\": 134849, \"bidPrice\": 6743.5, \"askPrice\": 6744, \"askSize\": 97145}, {\"timestamp\": \"2018-06-11T01:52:14.393Z\", \"bidSize\": 204849, \"bidPrice\": 6743.5, \"askPrice\": 6744, \"askSize\": 97145}, {\"timestamp\": \"2018-06-11T01:52:14.426Z\", \"bidSize\": 209849, \"bidPrice\": 6743.5, \"askPrice\": 6744, \"askSize\": 97145}, {\"timestamp\": \"2018-06-11T01:52:14.433Z\", \"bidSize\": 216349, \"bidPrice\": 6743.5, \"askPrice\": 6744, \"askSize\": 97145}, {\"timestamp\": \"2018-06-11T01:52:14.498Z\", \"bidSize\": 221349, \"bidPrice\": 6743.5, \"askPrice\": 6744, \"askSize\": 97145}, {\"timestamp\": \"2018-06-11T01:52:14.506Z\", \"bidSize\": 221359, \"bidPrice\": 6743.5, \"askPrice\": 6744, \"askSize\": 97145}, {\"timestamp\": \"2018-06-11T01:52:14.508Z\", \"bidSize\": 291359, \"bidPrice\": 6743.5, \"askPrice\": 6744, \"askSize\": 97145}, {\"timestamp\": \"2018-06-11T01:52:14.513Z\", \"bidSize\": 306261, \"bidPrice\": 6743.5, \"askPrice\": 6744, \"askSize\": 97145}, {\"timestamp\": \"2018-06-11T01:52:14.515Z\", \"bidSize\": 309261, \"bidPrice\": 6743.5, \"askPrice\": 6744, \"askSize\": 97145}, {\"timestamp\": \"2018-06-11T01:52:14.521Z\", \"bidSize\": 309261, \"bidPrice\": 6743.5, \"askPrice\": 6744, \"askSize\": 97170}, {\"timestamp\": \"2018-06-11T01:52:14.531Z\", \"bidSize\": 379261, \"bidPrice\": 6743.5, \"askPrice\": 6744, \"askSize\": 97170}, {\"timestamp\": \"2018-06-11T01:52:14.533Z\", \"bidSize\": 479261, \"bidPrice\": 6743.5, \"askPrice\": 6744, \"askSize\": 97170}, {\"timestamp\": \"2018-06-11T01:52:14.536Z\", \"bidSize\": 549261, \"bidPrice\": 6743.5, \"askPrice\": 6744, \"askSize\": 97170}, {\"timestamp\": \"2018-06-11T01:52:14.559Z\", \"bidSize\": 549761, \"bidPrice\": 6743.5, \"askPrice\": 6744, \"askSize\": 97170}, {\"timestamp\": \"2018-06-11T01:52:14.569Z\", \"bidSize\": 549961, \"bidPrice\": 6743.5, \"askPrice\": 6744, \"askSize\": 97170}, {\"timestamp\": \"2018-06-11T01:52:14.573Z\", \"bidSize\": 562792, \"bidPrice\": 6743.5, \"askPrice\": 6744, \"askSize\": 97170}, {\"timestamp\": \"2018-06-11T01:52:14.598Z\", \"bidSize\": 722790, \"bidPrice\": 6743.5, \"askPrice\": 6744, \"askSize\": 97170}, {\"timestamp\": \"2018-06-11T01:52:14.610Z\", \"bidSize\": 726216, \"bidPrice\": 6743.5, \"askPrice\": 6744, \"askSize\": 97170}, {\"timestamp\": \"2018-06-11T01:52:14.634Z\", \"bidSize\": 737446, \"bidPrice\": 6743.5, \"askPrice\": 6744, \"askSize\": 97170}, {\"timestamp\": \"2018-06-11T01:52:14.657Z\", \"bidSize\": 757843, \"bidPrice\": 6743.5, \"askPrice\": 6744, \"askSize\": 97170}, {\"timestamp\": \"2018-06-11T01:52:14.680Z\", \"bidSize\": 785650, \"bidPrice\": 6743.5, \"askPrice\": 6744, \"askSize\": 97170}, {\"timestamp\": \"2018-06-11T01:52:14.703Z\", \"bidSize\": 805978, \"bidPrice\": 6743.5, \"askPrice\": 6744, \"askSize\": 97170}, {\"timestamp\": \"2018-06-11T01:52:14.726Z\", \"bidSize\": 814164, \"bidPrice\": 6743.5, \"askPrice\": 6744, \"askSize\": 97170}, {\"timestamp\": \"2018-06-11T01:52:14.729Z\", \"bidSize\": 824303, \"bidPrice\": 6743.5, \"askPrice\": 6744, \"askSize\": 97170}, {\"timestamp\": \"2018-06-11T01:52:14.757Z\", \"bidSize\": 844303, \"bidPrice\": 6743.5, \"askPrice\": 6744, \"askSize\": 97170}, {\"timestamp\": \"2018-06-11T01:52:14.781Z\", \"bidSize\": 847303, \"bidPrice\": 6743.5, \"askPrice\": 6744, \"askSize\": 97170}, {\"timestamp\": \"2018-06-11T01:52:14.794Z\", \"bidSize\": 847304, \"bidPrice\": 6743.5, \"askPrice\": 6744, \"askSize\": 97170}, {\"timestamp\": \"2018-06-11T01:52:14.796Z\", \"bidSize\": 862304, \"bidPrice\": 6743.5, \"askPrice\": 6744, \"askSize\": 97170}, {\"timestamp\": \"2018-06-11T01:52:14.804Z\", \"bidSize\": 922304, \"bidPrice\": 6743.5, \"askPrice\": 6744, \"askSize\": 97170}, {\"timestamp\": \"2018-06-11T01:52:14.809Z\", \"bidSize\": 924460, \"bidPrice\": 6743.5, \"askPrice\": 6744, \"askSize\": 97170}, {\"timestamp\": \"2018-06-11T01:52:14.812Z\", \"bidSize\": 924609, \"bidPrice\": 6743.5, \"askPrice\": 6744, \"askSize\": 97170}, {\"timestamp\": \"2018-06-11T01:52:14.815Z\", \"bidSize\": 925109, \"bidPrice\": 6743.5, \"askPrice\": 6744, \"askSize\": 97170}, {\"timestamp\": \"2018-06-11T01:52:14.819Z\", \"bidSize\": 925134, \"bidPrice\": 6743.5, \"askPrice\": 6744, \"askSize\": 97170}, {\"timestamp\": \"2018-06-11T01:52:14.823Z\", \"bidSize\": 941827, \"bidPrice\": 6743.5, \"askPrice\": 6744, \"askSize\": 97170}, {\"timestamp\": \"2018-06-11T01:52:14.831Z\", \"bidSize\": 943973, \"bidPrice\": 6743.5, \"askPrice\": 6744, \"askSize\": 97170}, {\"timestamp\": \"2018-06-11T01:52:14.854Z\", \"bidSize\": 949973, \"bidPrice\": 6743.5, \"askPrice\": 6744, \"askSize\": 97170}, {\"timestamp\": \"2018-06-11T01:52:14.857Z\", \"bidSize\": 955973, \"bidPrice\": 6743.5, \"askPrice\": 6744, \"askSize\": 97170}, {\"timestamp\": \"2018-06-11T01:52:14.862Z\", \"bidSize\": 1005973, \"bidPrice\": 6743.5, \"askPrice\": 6744, \"askSize\": 97170}, {\"timestamp\": \"2018-06-11T01:52:14.866Z\", \"bidSize\": 1055973, \"bidPrice\": 6743.5, \"askPrice\": 6744, \"askSize\": 97170}, {\"timestamp\": \"2018-06-11T01:52:14.870Z\", \"bidSize\": 1056170, \"bidPrice\": 6743.5, \"askPrice\": 6744, \"askSize\": 97170}, {\"timestamp\": \"2018-06-11T01:52:14.874Z\", \"bidSize\": 1056570, \"bidPrice\": 6743.5, \"askPrice\": 6744, \"askSize\": 97170}, {\"timestamp\": \"2018-06-11T01:52:14.879Z\", \"bidSize\": 1060232, \"bidPrice\": 6743.5, \"askPrice\": 6744, \"askSize\": 97170}, {\"timestamp\": \"2018-06-11T01:52:14.902Z\", \"bidSize\": 1061232, \"bidPrice\": 6743.5, \"askPrice\": 6744, \"askSize\": 97170}, {\"timestamp\": \"2018-06-11T01:52:14.906Z\", \"bidSize\": 1061293, \"bidPrice\": 6743.5, \"askPrice\": 6744, \"askSize\": 97170}, {\"timestamp\": \"2018-06-11T01:52:14.909Z\", \"bidSize\": 1171293, \"bidPrice\": 6743.5, \"askPrice\": 6744, \"askSize\": 97170}, {\"timestamp\": \"2018-06-11T01:52:14.912Z\", \"bidSize\": 1371293, \"bidPrice\": 6743.5, \"askPrice\": 6744, \"askSize\": 97170}, {\"timestamp\": \"2018-06-11T01:52:14.937Z\", \"bidSize\": 1371970, \"bidPrice\": 6743.5, \"askPrice\": 6744, \"askSize\": 97170}, {\"timestamp\": \"2018-06-11T01:52:14.946Z\", \"bidSize\": 1378745, \"bidPrice\": 6743.5, \"askPrice\": 6744, \"askSize\": 97170}, {\"timestamp\": \"2018-06-11T01:52:14.952Z\", \"bidSize\": 1384745, \"bidPrice\": 6743.5, \"askPrice\": 6744, \"askSize\": 97170}, {\"timestamp\": \"2018-06-11T01:52:14.984Z\", \"bidSize\": 1390745, \"bidPrice\": 6743.5, \"askPrice\": 6744, \"askSize\": 97170}, {\"timestamp\": \"2018-06-11T01:52:14.990Z\", \"bidSize\": 1390939, \"bidPrice\": 6743.5, \"askPrice\": 6744, \"askSize\": 97170}, {\"timestamp\": \"2018-06-11T01:52:15.012Z\", \"bidSize\": 1389839, \"bidPrice\": 6743.5, \"askPrice\": 6744, \"askSize\": 97170}, {\"timestamp\": \"2018-06-11T01:52:15.023Z\", \"bidSize\": 1389839, \"bidPrice\": 6743.5, \"askPrice\": 6744, \"askSize\": 117170}], \"symbol\": \"XBTUSD\", \"timestamp\": \"2018-06-11 01:52:15.203248Z\"}", "XBTUSD"], [1528681935919, "{\"table\": \"orderBookL2\", \"action\": \"update\", \"data\": [{\"id\": 8799325650, \"side\": \"Buy\", \"size\": 1847739}], \"symbol\": \"XBTUSD\", \"timestamp\": \"2018-06-11 01:52:15.916826Z\"}", "XBTUSD"], [1528681937922, "{\"table\": \"orderBookL2\", \"action\": \"update\", \"data\": [{\"id\": 8799325650, \"side\": \"Buy\", \"size\": 2054296}], \"symbol\": \"XBTUSD\", \"timestamp\": \"2018-06-11 01:52:17.919659Z\"}", "XBTUSD"], [1528681940860, "{\"table\": \"orderBookL2\", \"action\": \"update\", \"data\": [{\"id\": 8799324100, \"side\": \"Sell\", \"size\": 9602}], \"symbol\": \"XBTUSD\", \"timestamp\": \"2018-06-11 01:52:20.854812Z\"}", "XBTUSD"], [1528681942313, "{\"table\": \"orderBookL2\", \"action\": \"update\", \"data\": [{\"id\": 8799325600, \"side\": \"Buy\", \"size\": 1620961}], \"symbol\": \"XBTUSD\", \"timestamp\": \"2018-06-11 01:52:22.310248Z\"}", "XBTUSD"], [1528681943284, "{\"table\": \"orderBookL2\", \"action\": \"update\", \"data\": [{\"id\": 8799326100, \"side\": \"Buy\", \"size\": 101565}], \"symbol\": \"XBTUSD\", \"timestamp\": \"2018-06-11 01:52:23.281631Z\"}", "XBTUSD"], [1528681947717, "{\"table\": \"orderBookL2\", \"action\": \"update\", \"data\": [{\"id\": 8799325600, \"side\": \"Buy\", \"size\": 2341719}], \"symbol\": \"XBTUSD\", \"timestamp\": \"2018-06-11 01:52:27.713755Z\"}", "XBTUSD"], [1528681949581, "{\"table\": \"orderBookL2\", \"action\": \"update\", \"data\": [{\"id\": 8799320000, \"side\": \"Sell\", \"size\": 1778991}], \"symbol\": \"XBTUSD\", \"timestamp\": \"2018-06-11 01:52:29.574906Z\"}", "XBTUSD"], [1528681953629, "{\"table\": \"orderBookL2\", \"action\": \"update\", \"data\": [{\"id\": 8799326000, \"side\": \"Buy\", \"size\": 53041}, {\"id\": 8799326050, \"side\": \"Buy\", \"size\": 39568}], \"symbol\": \"XBTUSD\", \"timestamp\": \"2018-06-11 01:52:33.624393Z\"}", "XBTUSD"], [1528681957706, "{\"table\": \"orderBookL2\", \"action\": \"update\", \"data\": [{\"id\": 8799319100, \"side\": \"Sell\", \"size\": 7205}, {\"id\": 8799328000, \"side\": \"Buy\", \"size\": 156917}, {\"id\": 8799329650, \"side\": \"Buy\", \"size\": 6071}], \"symbol\": \"XBTUSD\", \"timestamp\": \"2018-06-11 01:52:37.703651Z\"}", "XBTUSD"], [1528681961235, "{\"table\": \"orderBookL2\", \"action\": \"update\", \"data\": [{\"id\": 8799325650, \"side\": \"Buy\", \"size\": 279607}], \"symbol\": \"XBTUSD\", \"timestamp\": \"2018-06-11 01:52:41.230686Z\"}", "XBTUSD"], [1528681964578, "{\"table\": \"orderBookL2\", \"action\": \"update\", \"data\": [{\"id\": 8799324950, \"side\": \"Sell\", \"size\": 16098}, {\"id\": 8799326450, \"side\": \"Buy\", \"size\": 600}], \"symbol\": \"XBTUSD\", \"timestamp\": \"2018-06-11 01:52:44.574617Z\"}", "XBTUSD"], [1528681968953, "{\"table\": \"orderBookL2\", \"action\": \"update\", \"data\": [{\"id\": 8799324750, \"side\": \"Sell\", \"size\": 10241}, {\"id\": 8799324800, \"side\": \"Sell\", \"size\": 203326}, {\"id\": 8799325700, \"side\": \"Buy\", \"size\": 221909}, {\"id\": 8799325800, \"side\": \"Buy\", \"size\": 210590}], \"symbol\": \"XBTUSD\", \"timestamp\": \"2018-06-11 01:52:48.949488Z\"}", "XBTUSD"], [1528681969136, "{\"table\": \"orderBookL2\", \"action\": \"update\", \"data\": [{\"id\": 8799325500, \"side\": \"Sell\", \"size\": 207027}], \"symbol\": \"XBTUSD\", \"timestamp\": \"2018-06-11 01:52:49.134227Z\"}", "XBTUSD"], [1528681969633, "{\"table\": \"orderBookL2\", \"action\": \"update\", \"data\": [{\"id\": 8799325550, \"side\": \"Buy\", \"size\": 2229961}], \"symbol\": \"XBTUSD\", \"timestamp\": \"2018-06-11 01:52:49.631168Z\"}", "XBTUSD"], [1528681972212, "{\"table\": \"orderBookL2\", \"action\": \"update\", \"data\": [{\"id\": 8799323300, \"side\": \"Sell\", \"size\": 267218}], \"symbol\": \"XBTUSD\", \"timestamp\": \"2018-06-11 01:52:52.207569Z\"}", "XBTUSD"], [1528681973946, "{\"table\": \"orderBookL2\", \"action\": \"update\", \"data\": [{\"id\": 8799325500, \"side\": \"Buy\", \"size\": 896325}, {\"id\": 8799325550, \"side\": \"Buy\", \"size\": 1856320}], \"symbol\": \"XBTUSD\", \"timestamp\": \"2018-06-11 01:52:53.944034Z\"}", "XBTUSD"], [1528681974297, "{\"table\": \"orderBookL2\", \"action\": \"update\", \"data\": [{\"id\": 8799326050, \"side\": \"Buy\", \"size\": 840}], \"symbol\": \"XBTUSD\", \"timestamp\": \"2018-06-11 01:52:54.294119Z\"}", "XBTUSD"], [1528681975290, "{\"table\": \"orderBookL2\", \"action\": \"update\", \"data\": [{\"id\": 8799325500, \"side\": \"Buy\", \"size\": 2145283}], \"symbol\": \"XBTUSD\", \"timestamp\": \"2018-06-11 01:52:55.282085Z\"}", "XBTUSD"], [1528681977180, "{\"table\": \"orderBookL2\", \"action\": \"update\", \"data\": [{\"id\": 8799324500, \"side\": \"Sell\", \"size\": 370455}], \"symbol\": \"XBTUSD\", \"timestamp\": \"2018-06-11 01:52:57.175288Z\"}", "XBTUSD"], [1528681979795, "{\"table\": \"orderBookL2\", \"action\": \"update\", \"data\": [{\"id\": 8799325500, \"side\": \"Buy\", \"size\": 2161203}], \"symbol\": \"XBTUSD\", \"timestamp\": \"2018-06-11 01:52:59.790820Z\"}", "XBTUSD"], [1528681984569, "{\"table\": \"orderBookL2\", \"action\": \"update\", \"data\": [{\"id\": 8799324800, \"side\": \"Sell\", \"size\": 114318}, {\"id\": 8799326300, \"side\": \"Buy\", \"size\": 67545}], \"symbol\": \"XBTUSD\", \"timestamp\": \"2018-06-11 01:53:04.563283Z\"}", "XBTUSD"], [1528681984952, "{\"table\": \"orderBookL2\", \"action\": \"update\", \"data\": [{\"id\": 8799325500, \"side\": \"Buy\", \"size\": 1885355}], \"symbol\": \"XBTUSD\", \"timestamp\": \"2018-06-11 01:53:04.948290Z\"}", "XBTUSD"], [1528681985866, "{\"table\": \"orderBookL2\", \"action\": \"update\", \"data\": [{\"id\": 8799325450, \"side\": \"Buy\", \"size\": 1411393}], \"symbol\": \"XBTUSD\", \"timestamp\": \"2018-06-11 01:53:05.864242Z\"}", "XBTUSD"], [1528681986935, "{\"table\": \"orderBookL2\", \"action\": \"update\", \"data\": [{\"id\": 8799325500, \"side\": \"Buy\", \"size\": 737423}], \"symbol\": \"XBTUSD\", \"timestamp\": \"2018-06-11 01:53:06.924145Z\"}", "XBTUSD"], [1528681988083, "{\"table\": \"orderBookL2\", \"action\": \"update\", \"data\": [{\"id\": 8799324100, \"side\": \"Sell\", \"size\": 13861}], \"symbol\": \"XBTUSD\", \"timestamp\": \"2018-06-11 01:53:08.080592Z\"}", "XBTUSD"], [1528681988785, "{\"table\": \"orderBookL2\", \"action\": \"update\", \"data\": [{\"id\": 8799324900, \"side\": \"Sell\", \"size\": 317258}, {\"id\": 8799327100, \"side\": \"Buy\", \"size\": 120242}], \"symbol\": \"XBTUSD\", \"timestamp\": \"2018-06-11 01:53:08.780195Z\"}", "XBTUSD"], [1528681989537, "{\"table\": \"orderBookL2\", \"action\": \"update\", \"data\": [{\"id\": 8799325400, \"side\": \"Buy\", \"size\": 1137454}, {\"id\": 8799325450, \"side\": \"Buy\", \"size\": 916448}], \"symbol\": \"XBTUSD\", \"timestamp\": \"2018-06-11 01:53:09.535377Z\"}", "XBTUSD"], [1528681990266, "{\"table\": \"orderBookL2\", \"action\": \"update\", \"data\": [{\"id\": 8799325350, \"side\": \"Buy\", \"size\": 78094}], \"symbol\": \"XBTUSD\", \"timestamp\": \"2018-06-11 01:53:10.263372Z\"}", "XBTUSD"], [1528681991045, "{\"table\": \"orderBookL2\", \"action\": \"update\", \"data\": [{\"id\": 8799320700, \"side\": \"Sell\", \"size\": 12165}, {\"id\": 8799323400, \"side\": \"Sell\", \"size\": 68650}], \"symbol\": \"XBTUSD\", \"timestamp\": \"2018-06-11 01:53:11.042664Z\"}", "XBTUSD"], [1528681992144, "{\"table\": \"orderBookL2\", \"action\": \"insert\", \"data\": [{\"id\": 8798889500, \"side\": \"Sell\", \"size\": 55, \"price\": 11105}], \"symbol\": \"XBTUSD\", \"timestamp\": \"2018-06-11 01:53:12.140824Z\"}", "XBTUSD"], [1528681993526, "{\"table\": \"orderBookL2\", \"action\": \"update\", \"data\": [{\"id\": 8799325200, \"side\": \"Sell\", \"size\": 9184}, {\"id\": 8799325400, \"side\": \"Buy\", \"size\": 693848}], \"symbol\": \"XBTUSD\", \"timestamp\": \"2018-06-11 01:53:13.519415Z\"}", "XBTUSD"], [1528681995385, "{\"table\": \"orderBookL2\", \"action\": \"update\", \"data\": [{\"id\": 8799325000, \"side\": \"Sell\", \"size\": 215142}], \"symbol\": \"XBTUSD\", \"timestamp\": \"2018-06-11 01:53:15.379832Z\"}", "XBTUSD"], [1528681996126, "{\"table\": \"orderBookL2\", \"action\": \"update\", \"data\": [{\"id\": 8799324700, \"side\": \"Sell\", \"size\": 229247}, {\"id\": 8799324800, \"side\": \"Sell\", \"size\": 421173}, {\"id\": 8799325350, \"side\": \"Buy\", \"size\": 837437}, {\"id\": 8799325450, \"side\": \"Buy\", \"size\": 249928}], \"symbol\": \"XBTUSD\", \"timestamp\": \"2018-06-11 01:53:16.123474Z\"}", "XBTUSD"], [1528681996934, "{\"table\": \"orderBookL2\", \"action\": \"update\", \"data\": [{\"id\": 8799325250, \"side\": \"Buy\", \"size\": 1254826}, {\"id\": 8799325300, \"side\": \"Buy\", \"size\": 1145284}], \"symbol\": \"XBTUSD\", \"timestamp\": \"2018-06-11 01:53:16.931333Z\"}", "XBTUSD"], [1528681997895, "{\"table\": \"orderBookL2\", \"action\": \"update\", \"data\": [{\"id\": 8799325300, \"side\": \"Buy\", \"size\": 531561}, {\"id\": 8799325350, \"side\": \"Buy\", \"size\": 252455}], \"symbol\": \"XBTUSD\", \"timestamp\": \"2018-06-11 01:53:17.885960Z\"}", "XBTUSD"], [1528681998664, "{\"table\": \"orderBookL2\", \"action\": \"update\", \"data\": [{\"id\": 8799325300, \"side\": \"Buy\", \"size\": 532213}], \"symbol\": \"XBTUSD\", \"timestamp\": \"2018-06-11 01:53:18.662241Z\"}", "XBTUSD"], [1528681999342, "{\"table\": \"orderBookL2\", \"action\": \"update\", \"data\": [{\"id\": 8799325300, \"side\": \"Buy\", \"size\": 379975}], \"symbol\": \"XBTUSD\", \"timestamp\": \"2018-06-11 01:53:19.340362Z\"}", "XBTUSD"], [1528682000059, "{\"table\": \"orderBookL2\", \"action\": \"update\", \"data\": [{\"id\": 8799325150, \"side\": \"Buy\", \"size\": 467512}], \"symbol\": \"XBTUSD\", \"timestamp\": \"2018-06-11 01:53:20.056313Z\"}", "XBTUSD"], [1528682000675, "{\"table\": \"orderBookL2\", \"action\": \"update\", \"data\": [{\"id\": 8799325200, \"side\": \"Buy\", \"size\": 629277}], \"symbol\": \"XBTUSD\", \"timestamp\": \"2018-06-11 01:53:20.673170Z\"}", "XBTUSD"], [1528682001354, "{\"table\": \"orderBookL2\", \"action\": \"update\", \"data\": [{\"id\": 8799325100, \"side\": \"Buy\", \"size\": 823418}, {\"id\": 8799325150, \"side\": \"Buy\", \"size\": 1281887}], \"symbol\": \"XBTUSD\", \"timestamp\": \"2018-06-11 01:53:21.349769Z\"}", "XBTUSD"], [1528682001986, "{\"table\": \"orderBookL2\", \"action\": \"update\", \"data\": [{\"id\": 8799324800, \"side\": \"Sell\", \"size\": 104701}], \"symbol\": \"XBTUSD\", \"timestamp\": \"2018-06-11 01:53:21.983415Z\"}", "XBTUSD"], [1528682002651, "{\"table\": \"orderBookL2\", \"action\": \"update\", \"data\": [{\"id\": 8799325100, \"side\": \"Buy\", \"size\": 802758}], \"symbol\": \"XBTUSD\", \"timestamp\": \"2018-06-11 01:53:22.646099Z\"}", "XBTUSD"], [1528682003471, "{\"table\": \"orderBookL2\", \"action\": \"update\", \"data\": [{\"id\": 8799324700, \"side\": \"Sell\", \"size\": 230500}, {\"id\": 8799324800, \"side\": \"Sell\", \"size\": 93701}], \"symbol\": \"XBTUSD\", \"timestamp\": \"2018-06-11 01:53:23.467476Z\"}", "XBTUSD"], [1528682004160, "{\"table\": \"orderBookL2\", \"action\": \"update\", \"data\": [{\"id\": 8799325050, \"side\": \"Buy\", \"size\": 1997097}], \"symbol\": \"XBTUSD\", \"timestamp\": \"2018-06-11 01:53:24.158297Z\"}", "XBTUSD"], [1528682005545, "{\"table\": \"orderBookL2\", \"action\": \"update\", \"data\": [{\"id\": 8799324700, \"side\": \"Sell\", \"size\": 234587}], \"symbol\": \"XBTUSD\", \"timestamp\": \"2018-06-11 01:53:25.540030Z\"}", "XBTUSD"], [1528682007724, "{\"table\": \"orderBookL2\", \"action\": \"update\", \"data\": [{\"id\": 8799325050, \"side\": \"Buy\", \"size\": 1924070}], \"symbol\": \"XBTUSD\", \"timestamp\": \"2018-06-11 01:53:27.719464Z\"}", "XBTUSD"], [1528682009580, "{\"table\": \"orderBookL2\", \"action\": \"update\", \"data\": [{\"id\": 8799324050, \"side\": \"Sell\", \"size\": 65227}], \"symbol\": \"XBTUSD\", \"timestamp\": \"2018-06-11 01:53:29.573269Z\"}", "XBTUSD"], [1528682011895, "{\"table\": \"orderBookL2\", \"action\": \"update\", \"data\": [{\"id\": 8799327100, \"side\": \"Buy\", \"size\": 40786}], \"symbol\": \"XBTUSD\", \"timestamp\": \"2018-06-11 01:53:31.888634Z\"}", "XBTUSD"], [1528682014523, "{\"table\": \"orderBookL2\", \"action\": \"update\", \"data\": [{\"id\": 8793249900, \"side\": \"Sell\", \"size\": 204}], \"symbol\": \"XBTUSD\", \"timestamp\": \"2018-06-11 01:53:34.518566Z\"}", "XBTUSD"], [1528682017819, "{\"table\": \"orderBookL2\", \"action\": \"update\", \"data\": [{\"id\": 8799324900, \"side\": \"Sell\", \"size\": 217966}, {\"id\": 8799325100, \"side\": \"Buy\", \"size\": 63515}], \"symbol\": \"XBTUSD\", \"timestamp\": \"2018-06-11 01:53:37.816637Z\"}", "XBTUSD"], [1528682019512, "{\"table\": \"orderBookL2\", \"action\": \"update\", \"data\": [{\"id\": 8799324900, \"side\": \"Sell\", \"size\": 223866}, {\"id\": 8799325100, \"side\": \"Buy\", \"size\": 62720}], \"symbol\": \"XBTUSD\", \"timestamp\": \"2018-06-11 01:53:39.510045Z\"}", "XBTUSD"], [1528682021610, "{\"table\": \"orderBookL2\", \"action\": \"update\", \"data\": [{\"id\": 8799324900, \"side\": \"Sell\", \"size\": 240066}], \"symbol\": \"XBTUSD\", \"timestamp\": \"2018-06-11 01:53:41.604621Z\"}", "XBTUSD"], [1528682024279, "{\"table\": \"orderBookL2\", \"action\": \"update\", \"data\": [{\"id\": 8799323600, \"side\": \"Sell\", \"size\": 225965}, {\"id\": 8799324700, \"side\": \"Sell\", \"size\": 227369}, {\"id\": 8799325500, \"side\": \"Buy\", \"size\": 156725}, {\"id\": 8799327600, \"side\": \"Buy\", \"size\": 264858}], \"symbol\": \"XBTUSD\", \"timestamp\": \"2018-06-11 01:53:44.274534Z\"}", "XBTUSD"], [1528682026444, "{\"table\": \"orderBookL2\", \"action\": \"update\", \"data\": [{\"id\": 8799325050, \"side\": \"Buy\", \"size\": 326145}], \"symbol\": \"XBTUSD\", \"timestamp\": \"2018-06-11 01:53:46.442320Z\"}", "XBTUSD"], [1528682029052, "{\"table\": \"orderBookL2\", \"action\": \"update\", \"data\": [{\"id\": 8799280100, \"side\": \"Sell\", \"size\": 20243}, {\"id\": 8799280150, \"side\": \"Sell\", \"size\": 200}], \"symbol\": \"XBTUSD\", \"timestamp\": \"2018-06-11 01:53:49.048190Z\"}", "XBTUSD"], [1528682029411, "{\"table\": \"orderBookL2\", \"action\": \"update\", \"data\": [{\"id\": 8799325450, \"side\": \"Buy\", \"size\": 13536}], \"symbol\": \"XBTUSD\", \"timestamp\": \"2018-06-11 01:53:49.409328Z\"}", "XBTUSD"], [1528682029922, "{\"table\": \"orderBookL2\", \"action\": \"update\", \"data\": [{\"id\": 8799325100, \"side\": \"Sell\", \"size\": 994115}], \"symbol\": \"XBTUSD\", \"timestamp\": \"2018-06-11 01:53:49.917560Z\"}", "XBTUSD"], [1528682030761, "{\"table\": \"orderBookL2\", \"action\": \"update\", \"data\": [{\"id\": 8799325100, \"side\": \"Sell\", \"size\": 738632}], \"symbol\": \"XBTUSD\", \"timestamp\": \"2018-06-11 01:53:50.758670Z\"}", "XBTUSD"], [1528682031529, "{\"table\": \"orderBookL2\", \"action\": \"update\", \"data\": [{\"id\": 8799326000, \"side\": \"Buy\", \"size\": 79170}, {\"id\": 8799326200, \"side\": \"Buy\", \"size\": 27843}], \"symbol\": \"XBTUSD\", \"timestamp\": \"2018-06-11 01:53:51.526025Z\"}", "XBTUSD"], [1528682032352, "{\"table\": \"orderBookL2\", \"action\": \"update\", \"data\": [{\"id\": 8799329950, \"side\": \"Buy\", \"size\": 155267}, {\"id\": 8799331600, \"side\": \"Buy\", \"size\": 114404}], \"symbol\": \"XBTUSD\", \"timestamp\": \"2018-06-11 01:53:52.349448Z\"}", "XBTUSD"], [1528682033256, "{\"table\": \"orderBookL2\", \"action\": \"update\", \"data\": [{\"id\": 8799323250, \"side\": \"Sell\", \"size\": 138043}], \"symbol\": \"XBTUSD\", \"timestamp\": \"2018-06-11 01:53:53.253382Z\"}", "XBTUSD"], [1528682034035, "{\"table\": \"orderBookL2\", \"action\": \"update\", \"data\": [{\"id\": 8799325200, \"side\": \"Sell\", \"size\": 1859384}], \"symbol\": \"XBTUSD\", \"timestamp\": \"2018-06-11 01:53:54.032457Z\"}", "XBTUSD"], [1528682034897, "{\"table\": \"orderBookL2\", \"action\": \"update\", \"data\": [{\"id\": 8799325200, \"side\": \"Sell\", \"size\": 1617203}, {\"id\": 8799325300, \"side\": \"Sell\", \"size\": 196498}], \"symbol\": \"XBTUSD\", \"timestamp\": \"2018-06-11 01:53:54.893363Z\"}", "XBTUSD"], [1528682037163, "{\"table\": \"orderBookL2\", \"action\": \"update\", \"data\": [{\"id\": 8799325200, \"side\": \"Sell\", \"size\": 950799}, {\"id\": 8799325250, \"side\": \"Sell\", \"size\": 1032890}], \"symbol\": \"XBTUSD\", \"timestamp\": \"2018-06-11 01:53:57.159347Z\"}", "XBTUSD"], [1528682038946, "{\"table\": \"orderBookL2\", \"action\": \"update\", \"data\": [{\"id\": 8799325300, \"side\": \"Sell\", \"size\": 1233521}], \"symbol\": \"XBTUSD\", \"timestamp\": \"2018-06-11 01:53:58.941142Z\"}", "XBTUSD"], [1528682039172, "{\"table\": \"orderBookL2\", \"action\": \"update\", \"data\": [{\"id\": 8799323650, \"side\": \"Sell\", \"size\": 67774}], \"symbol\": \"XBTUSD\", \"timestamp\": \"2018-06-11 01:53:59.169895Z\"}", "XBTUSD"], [1528682039512, "{\"table\": \"orderBookL2\", \"action\": \"update\", \"data\": [{\"id\": 8799325300, \"side\": \"Sell\", \"size\": 1762941}, {\"id\": 8799325350, \"side\": \"Sell\", \"size\": 542878}], \"symbol\": \"XBTUSD\", \"timestamp\": \"2018-06-11 01:53:59.507818Z\"}", "XBTUSD"], [1528682042113, "{\"table\": \"orderBookL2\", \"action\": \"update\", \"data\": [{\"id\": 8799325350, \"side\": \"Sell\", \"size\": 1514210}], \"symbol\": \"XBTUSD\", \"timestamp\": \"2018-06-11 01:54:02.107329Z\"}", "XBTUSD"], [1528682045098, "{\"table\": \"orderBookL2\", \"action\": \"update\", \"data\": [{\"id\": 8799325300, \"side\": \"Sell\", \"size\": 849884}, {\"id\": 8799327550, \"side\": \"Buy\", \"size\": 249000}], \"symbol\": \"XBTUSD\", \"timestamp\": \"2018-06-11 01:54:05.094052Z\"}", "XBTUSD"], [1528682045474, "{\"table\": \"orderBookL2\", \"action\": \"update\", \"data\": [{\"id\": 8799325450, \"side\": \"Sell\", \"size\": 166276}], \"symbol\": \"XBTUSD\", \"timestamp\": \"2018-06-11 01:54:05.471937Z\"}", "XBTUSD"], [1528682045827, "{\"table\": \"orderBookL2\", \"action\": \"update\", \"data\": [{\"id\": 8799325450, \"side\": \"Sell\", \"size\": 723110}], \"symbol\": \"XBTUSD\", \"timestamp\": \"2018-06-11 01:54:05.825084Z\"}", "XBTUSD"], [1528682046325, "{\"table\": \"orderBookL2\", \"action\": \"update\", \"data\": [{\"id\": 8799325400, \"side\": \"Sell\", \"size\": 203663}], \"symbol\": \"XBTUSD\", \"timestamp\": \"2018-06-11 01:54:06.323315Z\"}", "XBTUSD"], [1528682047086, "{\"table\": \"orderBookL2\", \"action\": \"update\", \"data\": [{\"id\": 8799325500, \"side\": \"Buy\", \"size\": 201734}], \"symbol\": \"XBTUSD\", \"timestamp\": \"2018-06-11 01:54:07.083953Z\"}", "XBTUSD"], [1528682048951, "{\"table\": \"orderBookL2\", \"action\": \"update\", \"data\": [{\"id\": 8799335050, \"side\": \"Buy\", \"size\": 10092}, {\"id\": 8799335500, \"side\": \"Buy\", \"size\": 58209}], \"symbol\": \"XBTUSD\", \"timestamp\": \"2018-06-11 01:54:08.946805Z\"}", "XBTUSD"], [1528682051493, "{\"table\": \"orderBookL2\", \"action\": \"update\", \"data\": [{\"id\": 8799325500, \"side\": \"Sell\", \"size\": 420296}], \"symbol\": \"XBTUSD\", \"timestamp\": \"2018-06-11 01:54:11.488966Z\"}", "XBTUSD"], [1528682054057, "{\"table\": \"orderBookL2\", \"action\": \"update\", \"data\": [{\"id\": 8799325450, \"side\": \"Sell\", \"size\": 1035956}], \"symbol\": \"XBTUSD\", \"timestamp\": \"2018-06-11 01:54:14.051875Z\"}", "XBTUSD"], [1528682054344, "{\"table\": \"orderBookL2\", \"action\": \"update\", \"data\": [{\"id\": 8799325400, \"side\": \"Sell\", \"size\": 242895}, {\"id\": 8799325450, \"side\": \"Sell\", \"size\": 871651}, {\"id\": 8799325850, \"side\": \"Buy\", \"size\": 8888}, {\"id\": 8799326300, \"side\": \"Buy\", \"size\": 14231}], \"symbol\": \"XBTUSD\", \"timestamp\": \"2018-06-11 01:54:14.340158Z\"}", "XBTUSD"], [1528682054763, "{\"table\": \"orderBookL2\", \"action\": \"update\", \"data\": [{\"id\": 8799325500, \"side\": \"Sell\", \"size\": 1052689}, {\"id\": 8799325550, \"side\": \"Sell\", \"size\": 1245271}], \"symbol\": \"XBTUSD\", \"timestamp\": \"2018-06-11 01:54:14.760923Z\"}", "XBTUSD"], [1528682055656, "{\"table\": \"orderBookL2\", \"action\": \"update\", \"data\": [{\"id\": 8799325500, \"side\": \"Sell\", \"size\": 830198}], \"symbol\": \"XBTUSD\", \"timestamp\": \"2018-06-11 01:54:15.652756Z\"}", "XBTUSD"], [1528682057866, "{\"table\": \"orderBookL2\", \"action\": \"update\", \"data\": [{\"id\": 8799325550, \"side\": \"Sell\", \"size\": 2116252}], \"symbol\": \"XBTUSD\", \"timestamp\": \"2018-06-11 01:54:17.859432Z\"}", "XBTUSD"], [1528682059875, "{\"table\": \"orderBookL2\", \"action\": \"update\", \"data\": [{\"id\": 8799325050, \"side\": \"Sell\", \"size\": 18212}, {\"id\": 8799325300, \"side\": \"Sell\", \"size\": 60900}, {\"id\": 8799326050, \"side\": \"Buy\", \"size\": 22567}, {\"id\": 8799326100, \"side\": \"Buy\", \"size\": 14044}], \"symbol\": \"XBTUSD\", \"timestamp\": \"2018-06-11 01:54:19.872927Z\"}", "XBTUSD"], [1528682062889, "{\"table\": \"orderBookL2\", \"action\": \"update\", \"data\": [{\"id\": 8799325600, \"side\": \"Buy\", \"size\": 270375}], \"symbol\": \"XBTUSD\", \"timestamp\": \"2018-06-11 01:54:22.887280Z\"}", "XBTUSD"], [1528682065273, "{\"table\": \"orderBookL2\", \"action\": \"delete\", \"data\": [{\"id\": 8798900800, \"side\": \"Sell\"}], \"symbol\": \"XBTUSD\", \"timestamp\": \"2018-06-11 01:54:25.267094Z\"}", "XBTUSD"], [1528682067881, "{\"table\": \"orderBookL2\", \"action\": \"update\", \"data\": [{\"id\": 8799325600, \"side\": \"Buy\", \"size\": 293541}], \"symbol\": \"XBTUSD\", \"timestamp\": \"2018-06-11 01:54:27.870722Z\"}", "XBTUSD"], [1528682073078, "{\"table\": \"orderBookL2\", \"action\": \"update\", \"data\": [{\"id\": 8799326700, \"side\": \"Buy\", \"size\": 7083}, {\"id\": 8799326800, \"side\": \"Buy\", \"size\": 62860}], \"symbol\": \"XBTUSD\", \"timestamp\": \"2018-06-11 01:54:33.068951Z\"}", "XBTUSD"], [1528682073863, "{\"table\": \"orderBookL2\", \"action\": \"update\", \"data\": [{\"id\": 8799325600, \"side\": \"Buy\", \"size\": 48655}], \"symbol\": \"XBTUSD\", \"timestamp\": \"2018-06-11 01:54:33.860204Z\"}", "XBTUSD"], [1528682077673, "{\"table\": \"orderBookL2\", \"action\": \"update\", \"data\": [{\"id\": 8799325150, \"side\": \"Sell\", \"size\": 2738}, {\"id\": 8799325450, \"side\": \"Sell\", \"size\": 112493}, {\"id\": 8799325750, \"side\": \"Buy\", \"size\": 82078}, {\"id\": 8799326100, \"side\": \"Buy\", \"size\": 21744}], \"symbol\": \"XBTUSD\", \"timestamp\": \"2018-06-11 01:54:37.668879Z\"}", "XBTUSD"], [1528682080236, "{\"table\": \"orderBookL2\", \"action\": \"delete\", \"data\": [{\"id\": 8793251900, \"side\": \"Sell\"}], \"symbol\": \"XBTUSD\", \"timestamp\": \"2018-06-11 01:54:40.231221Z\"}", "XBTUSD"], [1528682083747, "{\"table\": \"orderBookL2\", \"action\": \"update\", \"data\": [{\"id\": 8799325600, \"side\": \"Sell\", \"size\": 173175}], \"symbol\": \"XBTUSD\", \"timestamp\": \"2018-06-11 01:54:43.743338Z\"}", "XBTUSD"], [1528682084619, "{\"table\": \"orderBookL2\", \"action\": \"update\", \"data\": [{\"id\": 8799325650, \"side\": \"Buy\", \"size\": 26460}], \"symbol\": \"XBTUSD\", \"timestamp\": \"2018-06-11 01:54:44.617454Z\"}", "XBTUSD"], [1528682086439, "{\"table\": \"orderBookL2\", \"action\": \"update\", \"data\": [{\"id\": 8799325650, \"side\": \"Buy\", \"size\": 19069}], \"symbol\": \"XBTUSD\", \"timestamp\": \"2018-06-11 01:54:46.435934Z\"}", "XBTUSD"], [1528682088667, "{\"table\": \"orderBookL2\", \"action\": \"update\", \"data\": [{\"id\": 8799325600, \"side\": \"Sell\", \"size\": 1578541}, {\"id\": 8799325650, \"side\": \"Sell\", \"size\": 822672}], \"symbol\": \"XBTUSD\", \"timestamp\": \"2018-06-11 01:54:48.664344Z\"}", "XBTUSD"], [1528682089603, "{\"table\": \"orderBookL2\", \"action\": \"update\", \"data\": [{\"id\": 8799323750, \"side\": \"Sell\", \"size\": 70685}, {\"id\": 8799325550, \"side\": \"Sell\", \"size\": 299490}, {\"id\": 8799325600, \"side\": \"Sell\", \"size\": 1068573}, {\"id\": 8799325650, \"side\": \"Sell\", \"size\": 1577305}], \"symbol\": \"XBTUSD\", \"timestamp\": \"2018-06-11 01:54:49.600326Z\"}", "XBTUSD"], [1528682092652, "{\"table\": \"orderBookL2\", \"action\": \"delete\", \"data\": [{\"id\": 8799932600, \"side\": \"Buy\"}], \"symbol\": \"XBTUSD\", \"timestamp\": \"2018-06-11 01:54:52.647678Z\"}", "XBTUSD"], [1528682094231, "{\"table\": \"orderBookL2\", \"action\": \"update\", \"data\": [{\"id\": 8799325650, \"side\": \"Sell\", \"size\": 2268419}], \"symbol\": \"XBTUSD\", \"timestamp\": \"2018-06-11 01:54:54.224954Z\"}", "XBTUSD"], [1528682096231, "{\"table\": \"orderBookL2\", \"action\": \"update\", \"data\": [{\"id\": 8799325650, \"side\": \"Sell\", \"size\": 2004530}, {\"id\": 8799325700, \"side\": \"Sell\", \"size\": 375939}], \"symbol\": \"XBTUSD\", \"timestamp\": \"2018-06-11 01:54:56.228671Z\"}", "XBTUSD"], [1528682096934, "{\"table\": \"orderBookL2\", \"action\": \"update\", \"data\": [{\"id\": 8799325700, \"side\": \"Sell\", \"size\": 1475429}], \"symbol\": \"XBTUSD\", \"timestamp\": \"2018-06-11 01:54:56.931503Z\"}", "XBTUSD"], [1528682098128, "{\"table\": \"orderBookL2\", \"action\": \"update\", \"data\": [{\"id\": 8799327500, \"side\": \"Buy\", \"size\": 205590}, {\"id\": 8799328500, \"side\": \"Buy\", \"size\": 118010}, {\"id\": 8799329500, \"side\": \"Buy\", \"size\": 59928}], \"symbol\": \"XBTUSD\", \"timestamp\": \"2018-06-11 01:54:58.123264Z\"}", "XBTUSD"], [1528682102403, "{\"table\": \"orderBookL2\", \"action\": \"update\", \"data\": [{\"id\": 8799325700, \"side\": \"Sell\", \"size\": 2184524}], \"symbol\": \"XBTUSD\", \"timestamp\": \"2018-06-11 01:55:02.398384Z\"}", "XBTUSD"], [1528682103823, "{\"table\": \"orderBookL2\", \"action\": \"update\", \"data\": [{\"id\": 8799325700, \"side\": \"Sell\", \"size\": 2360105}, {\"id\": 8799327950, \"side\": \"Buy\", \"size\": 371749}], \"symbol\": \"XBTUSD\", \"timestamp\": \"2018-06-11 01:55:03.820849Z\"}", "XBTUSD"], [1528682105444, "{\"table\": \"orderBookL2\", \"action\": \"update\", \"data\": [{\"id\": 8799318550, \"side\": \"Sell\", \"size\": 6140}], \"symbol\": \"XBTUSD\", \"timestamp\": \"2018-06-11 01:55:05.438452Z\"}", "XBTUSD"], [1528682107526, "{\"table\": \"orderBookL2\", \"action\": \"update\", \"data\": [{\"id\": 8799318900, \"side\": \"Sell\", \"size\": 76791}], \"symbol\": \"XBTUSD\", \"timestamp\": \"2018-06-11 01:55:07.519466Z\"}", "XBTUSD"], [1528682109675, "{\"table\": \"orderBookL2\", \"action\": \"update\", \"data\": [{\"id\": 8799325900, \"side\": \"Buy\", \"size\": 157391}], \"symbol\": \"XBTUSD\", \"timestamp\": \"2018-06-11 01:55:09.668073Z\"}", "XBTUSD"], [1528682112546, "{\"table\": \"orderBookL2\", \"action\": \"update\", \"data\": [{\"id\": 8799326550, \"side\": \"Buy\", \"size\": 70035}, {\"id\": 8799326600, \"side\": \"Buy\", \"size\": 16855}], \"symbol\": \"XBTUSD\", \"timestamp\": \"2018-06-11 01:55:12.540326Z\"}", "XBTUSD"], [1528682113397, "{\"table\": \"orderBookL2\", \"action\": \"update\", \"data\": [{\"id\": 8799325700, \"side\": \"Sell\", \"size\": 1264424}, {\"id\": 8799325800, \"side\": \"Sell\", \"size\": 1180304}], \"symbol\": \"XBTUSD\", \"timestamp\": \"2018-06-11 01:55:13.393667Z\"}", "XBTUSD"], [1528682114158, "{\"table\": \"orderBookL2\", \"action\": \"update\", \"data\": [{\"id\": 8799327100, \"side\": \"Buy\", \"size\": 10600}, {\"id\": 8799327250, \"side\": \"Buy\", \"size\": 10550}], \"symbol\": \"XBTUSD\", \"timestamp\": \"2018-06-11 01:55:14.155616Z\"}", "XBTUSD"], [1528682114825, "{\"table\": \"orderBookL2\", \"action\": \"update\", \"data\": [{\"id\": 8799325800, \"side\": \"Sell\", \"size\": 1644781}, {\"id\": 8799325850, \"side\": \"Sell\", \"size\": 916954}], \"symbol\": \"XBTUSD\", \"timestamp\": \"2018-06-11 01:55:14.821225Z\"}", "XBTUSD"], [1528682117666, "{\"table\": \"orderBookL2\", \"action\": \"update\", \"data\": [{\"id\": 8799320650, \"side\": \"Sell\", \"size\": 14894}], \"symbol\": \"XBTUSD\", \"timestamp\": \"2018-06-11 01:55:17.660495Z\"}", "XBTUSD"], [1528682119158, "{\"table\": \"orderBookL2\", \"action\": \"update\", \"data\": [{\"id\": 8799325850, \"side\": \"Sell\", \"size\": 1477011}], \"symbol\": \"XBTUSD\", \"timestamp\": \"2018-06-11 01:55:19.154702Z\"}", "XBTUSD"], [1528682119406, "{\"table\": \"orderBookL2\", \"action\": \"update\", \"data\": [{\"id\": 8799324350, \"side\": \"Sell\", \"size\": 17849}], \"symbol\": \"XBTUSD\", \"timestamp\": \"2018-06-11 01:55:19.402541Z\"}", "XBTUSD"], [1528682119617, "{\"table\": \"orderBookL2\", \"action\": \"update\", \"data\": [{\"id\": 8799325850, \"side\": \"Sell\", \"size\": 853169}], \"symbol\": \"XBTUSD\", \"timestamp\": \"2018-06-11 01:55:19.613473Z\"}", "XBTUSD"], [1528682121862, "{\"table\": \"orderBookL2\", \"action\": \"update\", \"data\": [{\"id\": 8799326050, \"side\": \"Buy\", \"size\": 9490}], \"symbol\": \"XBTUSD\", \"timestamp\": \"2018-06-11 01:55:21.857953Z\"}", "XBTUSD"], [1528682122813, "{\"table\": \"orderBookL2\", \"action\": \"update\", \"data\": [{\"id\": 8799325900, \"side\": \"Sell\", \"size\": 2118861}], \"symbol\": \"XBTUSD\", \"timestamp\": \"2018-06-11 01:55:22.810818Z\"}", "XBTUSD"], [1528682124629, "{\"table\": \"orderBookL2\", \"action\": \"update\", \"data\": [{\"id\": 8799326600, \"side\": \"Buy\", \"size\": 7738}, {\"id\": 8799326850, \"side\": \"Buy\", \"size\": 31394}], \"symbol\": \"XBTUSD\", \"timestamp\": \"2018-06-11 01:55:24.626478Z\"}", "XBTUSD"], [1528682128163, "{\"table\": \"orderBookL2\", \"action\": \"update\", \"data\": [{\"id\": 8799323250, \"side\": \"Sell\", \"size\": 111111}, {\"id\": 8799323650, \"side\": \"Sell\", \"size\": 53062}, {\"id\": 8799323800, \"side\": \"Sell\", \"size\": 96294}, {\"id\": 8799324150, \"side\": \"Sell\", \"size\": 53726}], \"symbol\": \"XBTUSD\", \"timestamp\": \"2018-06-11 01:55:28.157695Z\"}", "XBTUSD"], [1528682129053, "{\"table\": \"orderBookL2\", \"action\": \"update\", \"data\": [{\"id\": 8799325900, \"side\": \"Sell\", \"size\": 2234797}, {\"id\": 8799327800, \"side\": \"Buy\", \"size\": 553}], \"symbol\": \"XBTUSD\", \"timestamp\": \"2018-06-11 01:55:29.049858Z\"}", "XBTUSD"], [1528682132689, "{\"table\": \"orderBookL2\", \"action\": \"update\", \"data\": [{\"id\": 8799325900, \"side\": \"Sell\", \"size\": 1996982}, {\"id\": 8799328300, \"side\": \"Buy\", \"size\": 119386}], \"symbol\": \"XBTUSD\", \"timestamp\": \"2018-06-11 01:55:32.683705Z\"}", "XBTUSD"], [1528682134441, "{\"table\": \"orderBookL2\", \"action\": \"update\", \"data\": [{\"id\": 8799326500, \"side\": \"Buy\", \"size\": 42279}], \"symbol\": \"XBTUSD\", \"timestamp\": \"2018-06-11 01:55:34.437406Z\"}", "XBTUSD"], [1528682138659, "{\"table\": \"orderBookL2\", \"action\": \"update\", \"data\": [{\"id\": 8799487500, \"side\": \"Buy\", \"size\": 120110}], \"symbol\": \"XBTUSD\", \"timestamp\": \"2018-06-11 01:55:38.654780Z\"}", "XBTUSD"], [1528682139568, "{\"table\": \"orderBookL2\", \"action\": \"update\", \"data\": [{\"id\": 8799326900, \"side\": \"Buy\", \"size\": 56091}], \"symbol\": \"XBTUSD\", \"timestamp\": \"2018-06-11 01:55:39.563103Z\"}", "XBTUSD"], [1528682143767, "{\"table\": \"orderBookL2\", \"action\": \"update\", \"data\": [{\"id\": 8799324300, \"side\": \"Sell\", \"size\": 210445}], \"symbol\": \"XBTUSD\", \"timestamp\": \"2018-06-11 01:55:43.762799Z\"}", "XBTUSD"], [1528682144594, "{\"table\": \"orderBookL2\", \"action\": \"update\", \"data\": [{\"id\": 8799325900, \"side\": \"Sell\", \"size\": 1566106}], \"symbol\": \"XBTUSD\", \"timestamp\": \"2018-06-11 01:55:44.591472Z\"}", "XBTUSD"], [1528682146404, "{\"table\": \"orderBookL2\", \"action\": \"update\", \"data\": [{\"id\": 8799325900, \"side\": \"Sell\", \"size\": 1059336}], \"symbol\": \"XBTUSD\", \"timestamp\": \"2018-06-11 01:55:46.401242Z\"}", "XBTUSD"], [1528682149137, "{\"table\": \"orderBookL2\", \"action\": \"update\", \"data\": [{\"id\": 8799325000, \"side\": \"Sell\", \"size\": 163669}, {\"id\": 8799325900, \"side\": \"Sell\", \"size\": 498353}], \"symbol\": \"XBTUSD\", \"timestamp\": \"2018-06-11 01:55:49.134605Z\"}", "XBTUSD"], [1528682151352, "{\"table\": \"orderBookL2\", \"action\": \"update\", \"data\": [{\"id\": 8799324850, \"side\": \"Sell\", \"size\": 13464}], \"symbol\": \"XBTUSD\", \"timestamp\": \"2018-06-11 01:55:51.348640Z\"}", "XBTUSD"], [1528682153298, "{\"table\": \"orderBookL2\", \"action\": \"delete\", \"data\": [{\"id\": 8799326000, \"side\": \"Buy\"}], \"symbol\": \"XBTUSD\", \"timestamp\": \"2018-06-11 01:55:53.292698Z\"}", "XBTUSD"], [1528682153969, "{\"table\": \"orderBookL2\", \"action\": \"update\", \"data\": [{\"id\": 8799325950, \"side\": \"Sell\", \"size\": 1104827}, {\"id\": 8799326000, \"side\": \"Sell\", \"size\": 1341868}], \"symbol\": \"XBTUSD\", \"timestamp\": \"2018-06-11 01:55:53.966607Z\"}", "XBTUSD"], [1528682156350, "{\"table\": \"orderBookL2\", \"action\": \"update\", \"data\": [{\"id\": 8799326050, \"side\": \"Buy\", \"size\": 80114}], \"symbol\": \"XBTUSD\", \"timestamp\": \"2018-06-11 01:55:56.346435Z\"}", "XBTUSD"], [1528682157771, "{\"table\": \"trade\", \"action\": \"insert\", \"data\": [{\"timestamp\": \"2018-06-11T01:55:57.360Z\", \"side\": \"Sell\", \"size\": 1, \"price\": 6739, \"tickDirection\": \"ZeroMinusTick\", \"trdMatchID\": \"a633360a-9e89-d49e-8f43-b66a7c5c3e7e\", \"grossValue\": 14839, \"homeNotional\": 0.00014839, \"foreignNotional\": 1}], \"symbol\": \"XBTUSD\", \"timestamp\": \"2018-06-11 01:55:57.768996Z\"}", "XBTUSD"], [1528682158202, "{\"table\": \"orderBookL2\", \"action\": \"update\", \"data\": [{\"id\": 8799326050, \"side\": \"Sell\", \"size\": 3097652}], \"symbol\": \"XBTUSD\", \"timestamp\": \"2018-06-11 01:55:58.199773Z\"}", "XBTUSD"], [1528682159076, "{\"table\": \"orderBookL2\", \"action\": \"update\", \"data\": [{\"id\": 8799326050, \"side\": \"Sell\", \"size\": 2252615}, {\"id\": 8799326100, \"side\": \"Sell\", \"size\": 1086880}], \"symbol\": \"XBTUSD\", \"timestamp\": \"2018-06-11 01:55:59.074177Z\"}", "XBTUSD"], [1528682159851, "{\"table\": \"orderBookL2\", \"action\": \"update\", \"data\": [{\"id\": 8799326000, \"side\": \"Sell\", \"size\": 294147}, {\"id\": 8799326050, \"side\": \"Sell\", \"size\": 2207835}], \"symbol\": \"XBTUSD\", \"timestamp\": \"2018-06-11 01:55:59.848365Z\"}", "XBTUSD"], [1528682163547, "{\"table\": \"orderBookL2\", \"action\": \"update\", \"data\": [{\"id\": 8799326150, \"side\": \"Sell\", \"size\": 1081042}, {\"id\": 8799326200, \"side\": \"Sell\", \"size\": 590419}], \"symbol\": \"XBTUSD\", \"timestamp\": \"2018-06-11 01:56:03.543175Z\"}", "XBTUSD"], [1528682163765, "{\"table\": \"quote\", \"action\": \"insert\", \"data\": [{\"timestamp\": \"2018-06-11T01:56:01.657Z\", \"bidSize\": 53229, \"bidPrice\": 6737.5, \"askPrice\": 6738, \"askSize\": 504248}, {\"timestamp\": \"2018-06-11T01:56:01.691Z\", \"bidSize\": 53229, \"bidPrice\": 6737.5, \"askPrice\": 6738, \"askSize\": 510248}, {\"timestamp\": \"2018-06-11T01:56:01.768Z\", \"bidSize\": 53229, \"bidPrice\": 6737.5, \"askPrice\": 6738, \"askSize\": 516312}, {\"timestamp\": \"2018-06-11T01:56:01.768Z\", \"bidSize\": 53229, \"bidPrice\": 6737.5, \"askPrice\": 6738, \"askSize\": 522376}, {\"timestamp\": \"2018-06-11T01:56:01.816Z\", \"bidSize\": 53229, \"bidPrice\": 6737.5, \"askPrice\": 6738, \"askSize\": 562376}, {\"timestamp\": \"2018-06-11T01:56:01.837Z\", \"bidSize\": 53229, \"bidPrice\": 6737.5, \"askPrice\": 6738, \"askSize\": 565355}, {\"timestamp\": \"2018-06-11T01:56:01.869Z\", \"bidSize\": 53229, \"bidPrice\": 6737.5, \"askPrice\": 6738, \"askSize\": 573355}, {\"timestamp\": \"2018-06-11T01:56:01.869Z\", \"bidSize\": 53229, \"bidPrice\": 6737.5, \"askPrice\": 6738, \"askSize\": 581355}, {\"timestamp\": \"2018-06-11T01:56:01.869Z\", \"bidSize\": 53229, \"bidPrice\": 6737.5, \"askPrice\": 6738, \"askSize\": 587419}, {\"timestamp\": \"2018-06-11T01:56:01.889Z\", \"bidSize\": 53229, \"bidPrice\": 6737.5, \"askPrice\": 6738, \"askSize\": 590419}, {\"timestamp\": \"2018-06-11T01:56:01.896Z\", \"bidSize\": 53229, \"bidPrice\": 6737.5, \"askPrice\": 6738, \"askSize\": 595419}, {\"timestamp\": \"2018-06-11T01:56:01.933Z\", \"bidSize\": 53229, \"bidPrice\": 6737.5, \"askPrice\": 6738, \"askSize\": 620949}, {\"timestamp\": \"2018-06-11T01:56:01.965Z\", \"bidSize\": 53229, \"bidPrice\": 6737.5, \"askPrice\": 6738, \"askSize\": 625949}, {\"timestamp\": \"2018-06-11T01:56:01.972Z\", \"bidSize\": 53229, \"bidPrice\": 6737.5, \"askPrice\": 6738, \"askSize\": 632013}, {\"timestamp\": \"2018-06-11T01:56:01.995Z\", \"bidSize\": 53229, \"bidPrice\": 6737.5, \"askPrice\": 6738, \"askSize\": 625949}, {\"timestamp\": \"2018-06-11T01:56:01.999Z\", \"bidSize\": 53229, \"bidPrice\": 6737.5, \"askPrice\": 6738, \"askSize\": 785947}, {\"timestamp\": \"2018-06-11T01:56:02.009Z\", \"bidSize\": 53229, \"bidPrice\": 6737.5, \"askPrice\": 6738, \"askSize\": 855947}, {\"timestamp\": \"2018-06-11T01:56:02.033Z\", \"bidSize\": 53229, \"bidPrice\": 6737.5, \"askPrice\": 6738, \"askSize\": 925947}, {\"timestamp\": \"2018-06-11T01:56:02.062Z\", \"bidSize\": 53229, \"bidPrice\": 6737.5, \"askPrice\": 6738, \"askSize\": 995947}, {\"timestamp\": \"2018-06-11T01:56:02.066Z\", \"bidSize\": 53229, \"bidPrice\": 6737.5, \"askPrice\": 6738, \"askSize\": 1051045}, {\"timestamp\": \"2018-06-11T01:56:02.091Z\", \"bidSize\": 53229, \"bidPrice\": 6737.5, \"askPrice\": 6738, \"askSize\": 1051245}, {\"timestamp\": \"2018-06-11T01:56:02.095Z\", \"bidSize\": 53229, \"bidPrice\": 6737.5, \"askPrice\": 6738, \"askSize\": 1151245}, {\"timestamp\": \"2018-06-11T01:56:02.098Z\", \"bidSize\": 53229, \"bidPrice\": 6737.5, \"askPrice\": 6738, \"askSize\": 1179066}, {\"timestamp\": \"2018-06-11T01:56:02.134Z\", \"bidSize\": 53229, \"bidPrice\": 6737.5, \"askPrice\": 6738, \"askSize\": 1181213}, {\"timestamp\": \"2018-06-11T01:56:02.160Z\", \"bidSize\": 53229, \"bidPrice\": 6737.5, \"askPrice\": 6738, \"askSize\": 1194051}, {\"timestamp\": \"2018-06-11T01:56:02.189Z\", \"bidSize\": 53229, \"bidPrice\": 6737.5, \"askPrice\": 6738, \"askSize\": 1194061}, {\"timestamp\": \"2018-06-11T01:56:02.202Z\", \"bidSize\": 21, \"bidPrice\": 6737.5, \"askPrice\": 6738, \"askSize\": 1194061}, {\"timestamp\": \"2018-06-11T01:56:02.216Z\", \"bidSize\": 21, \"bidPrice\": 6737.5, \"askPrice\": 6738, \"askSize\": 1202038}, {\"timestamp\": \"2018-06-11T01:56:02.218Z\", \"bidSize\": 21, \"bidPrice\": 6737.5, \"askPrice\": 6738, \"askSize\": 1222446}, {\"timestamp\": \"2018-06-11T01:56:02.249Z\", \"bidSize\": 21, \"bidPrice\": 6737.5, \"askPrice\": 6738, \"askSize\": 1222946}, {\"timestamp\": \"2018-06-11T01:56:02.256Z\", \"bidSize\": 21, \"bidPrice\": 6737.5, \"askPrice\": 6738, \"askSize\": 1233091}, {\"timestamp\": \"2018-06-11T01:56:02.281Z\", \"bidSize\": 21, \"bidPrice\": 6737.5, \"askPrice\": 6738, \"askSize\": 1253091}, {\"timestamp\": \"2018-06-11T01:56:02.292Z\", \"bidSize\": 30437, \"bidPrice\": 6737, \"askPrice\": 6738, \"askSize\": 1253091}, {\"timestamp\": \"2018-06-11T01:56:02.318Z\", \"bidSize\": 6740, \"bidPrice\": 6737.5, \"askPrice\": 6738, \"askSize\": 1253091}, {\"timestamp\": \"2018-06-11T01:56:02.350Z\", \"bidSize\": 6740, \"bidPrice\": 6737.5, \"askPrice\": 6738, \"askSize\": 1259091}, {\"timestamp\": \"2018-06-11T01:56:02.352Z\", \"bidSize\": 6740, \"bidPrice\": 6737.5, \"askPrice\": 6738, \"askSize\": 1265091}, {\"timestamp\": \"2018-06-11T01:56:02.366Z\", \"bidSize\": 6740, \"bidPrice\": 6737.5, \"askPrice\": 6738, \"askSize\": 1271091}, {\"timestamp\": \"2018-06-11T01:56:02.371Z\", \"bidSize\": 6740, \"bidPrice\": 6737.5, \"askPrice\": 6738, \"askSize\": 1277091}, {\"timestamp\": \"2018-06-11T01:56:02.379Z\", \"bidSize\": 6740, \"bidPrice\": 6737.5, \"askPrice\": 6738, \"askSize\": 1276491}, {\"timestamp\": \"2018-06-11T01:56:02.446Z\", \"bidSize\": 6740, \"bidPrice\": 6737.5, \"askPrice\": 6738, \"askSize\": 1277491}, {\"timestamp\": \"2018-06-11T01:56:02.448Z\", \"bidSize\": 6790, \"bidPrice\": 6737.5, \"askPrice\": 6738, \"askSize\": 1277491}, {\"timestamp\": \"2018-06-11T01:56:02.454Z\", \"bidSize\": 6790, \"bidPrice\": 6737.5, \"askPrice\": 6738, \"askSize\": 1278491}], \"symbol\": \"XBTUSD\", \"timestamp\": \"2018-06-11 01:56:03.753578Z\"}", "XBTUSD"], [1528682164141, "{\"table\": \"orderBookL2\", \"action\": \"update\", \"data\": [{\"id\": 8799326100, \"side\": \"Sell\", \"size\": 364247}, {\"id\": 8799326200, \"side\": \"Sell\", \"size\": 1334760}, {\"id\": 8799327100, \"side\": \"Buy\", \"size\": 19393}, {\"id\": 8799327250, \"side\": \"Buy\", \"size\": 71471}, {\"id\": 8799327650, \"side\": \"Buy\", \"size\": 766}, {\"id\": 8799327800, \"side\": \"Buy\", \"size\": 21182}, {\"id\": 8799328200, \"side\": \"Buy\", \"size\": 1077}, {\"id\": 8799328350, \"side\": \"Buy\", \"size\": 125571}], \"symbol\": \"XBTUSD\", \"timestamp\": \"2018-06-11 01:56:04.138217Z\"}", "XBTUSD"], [1528682165204, "{\"table\": \"orderBookL2\", \"action\": \"update\", \"data\": [{\"id\": 8799326200, \"side\": \"Sell\", \"size\": 1372131}], \"symbol\": \"XBTUSD\", \"timestamp\": \"2018-06-11 01:56:05.201458Z\"}", "XBTUSD"], [1528682166082, "{\"table\": \"orderBookL2\", \"action\": \"update\", \"data\": [{\"id\": 8799326200, \"side\": \"Sell\", \"size\": 1525457}], \"symbol\": \"XBTUSD\", \"timestamp\": \"2018-06-11 01:56:06.079981Z\"}", "XBTUSD"], [1528682166849, "{\"table\": \"orderBookL2\", \"action\": \"update\", \"data\": [{\"id\": 8799319450, \"side\": \"Sell\", \"size\": 42478}], \"symbol\": \"XBTUSD\", \"timestamp\": \"2018-06-11 01:56:06.846252Z\"}", "XBTUSD"], [1528682167594, "{\"table\": \"orderBookL2\", \"action\": \"update\", \"data\": [{\"id\": 8799326350, \"side\": \"Sell\", \"size\": 1226782}], \"symbol\": \"XBTUSD\", \"timestamp\": \"2018-06-11 01:56:07.591291Z\"}", "XBTUSD"], [1528682168463, "{\"table\": \"orderBookL2\", \"action\": \"update\", \"data\": [{\"id\": 8799326400, \"side\": \"Buy\", \"size\": 304162}], \"symbol\": \"XBTUSD\", \"timestamp\": \"2018-06-11 01:56:08.461134Z\"}", "XBTUSD"], [1528682169404, "{\"table\": \"orderBookL2\", \"action\": \"update\", \"data\": [{\"id\": 8799326200, \"side\": \"Sell\", \"size\": 890085}, {\"id\": 8799326350, \"side\": \"Sell\", \"size\": 1355387}], \"symbol\": \"XBTUSD\", \"timestamp\": \"2018-06-11 01:56:09.401796Z\"}", "XBTUSD"], [1528682170917, "{\"table\": \"orderBookL2\", \"action\": \"update\", \"data\": [{\"id\": 8799326450, \"side\": \"Buy\", \"size\": 84573}], \"symbol\": \"XBTUSD\", \"timestamp\": \"2018-06-11 01:56:10.915049Z\"}", "XBTUSD"], [1528682172817, "{\"table\": \"orderBookL2\", \"action\": \"update\", \"data\": [{\"id\": 8799327000, \"side\": \"Buy\", \"size\": 122339}], \"symbol\": \"XBTUSD\", \"timestamp\": \"2018-06-11 01:56:12.815125Z\"}", "XBTUSD"], [1528682174421, "{\"table\": \"orderBookL2\", \"action\": \"update\", \"data\": [{\"id\": 8799327050, \"side\": \"Buy\", \"size\": 189055}, {\"id\": 8799328000, \"side\": \"Buy\", \"size\": 1013430}], \"symbol\": \"XBTUSD\", \"timestamp\": \"2018-06-11 01:56:14.415809Z\"}", "XBTUSD"], [1528682176196, "{\"table\": \"orderBookL2\", \"action\": \"update\", \"data\": [{\"id\": 8799326350, \"side\": \"Sell\", \"size\": 1839838}], \"symbol\": \"XBTUSD\", \"timestamp\": \"2018-06-11 01:56:16.189835Z\"}", "XBTUSD"], [1528682179286, "{\"table\": \"orderBookL2\", \"action\": \"update\", \"data\": [{\"id\": 8799323500, \"side\": \"Sell\", \"size\": 108626}, {\"id\": 8799323650, \"side\": \"Sell\", \"size\": 51623}, {\"id\": 8799328000, \"side\": \"Buy\", \"size\": 1018318}, {\"id\": 8799328150, \"side\": \"Buy\", \"size\": 116549}], \"symbol\": \"XBTUSD\", \"timestamp\": \"2018-06-11 01:56:19.281772Z\"}", "XBTUSD"], [1528682183513, "{\"table\": \"orderBookL2\", \"action\": \"update\", \"data\": [{\"id\": 8799327550, \"side\": \"Buy\", \"size\": 331953}, {\"id\": 8799327650, \"side\": \"Buy\", \"size\": 766}], \"symbol\": \"XBTUSD\", \"timestamp\": \"2018-06-11 01:56:23.508795Z\"}", "XBTUSD"], [1528682186302, "{\"table\": \"orderBookL2\", \"action\": \"update\", \"data\": [{\"id\": 8799320450, \"side\": \"Sell\", \"size\": 64610}, {\"id\": 8799329150, \"side\": \"Buy\", \"size\": 52213}, {\"id\": 8799330800, \"side\": \"Buy\", \"size\": 9174}], \"symbol\": \"XBTUSD\", \"timestamp\": \"2018-06-11 01:56:26.299710Z\"}", "XBTUSD"], [1528682188810, "{\"table\": \"orderBookL2\", \"action\": \"insert\", \"data\": [{\"id\": 8799270350, \"side\": \"Sell\", \"size\": 316760, \"price\": 7296.5}], \"symbol\": \"XBTUSD\", \"timestamp\": \"2018-06-11 01:56:28.807484Z\"}", "XBTUSD"], [1528682192462, "{\"table\": \"orderBookL2\", \"action\": \"update\", \"data\": [{\"id\": 8799327100, \"side\": \"Buy\", \"size\": 29067}, {\"id\": 8799327250, \"side\": \"Buy\", \"size\": 48586}], \"symbol\": \"XBTUSD\", \"timestamp\": \"2018-06-11 01:56:32.459119Z\"}", "XBTUSD"], [1528682194849, "{\"table\": \"orderBookL2\", \"action\": \"update\", \"data\": [{\"id\": 8799326400, \"side\": \"Buy\", \"size\": 31908}], \"symbol\": \"XBTUSD\", \"timestamp\": \"2018-06-11 01:56:34.847223Z\"}", "XBTUSD"], [1528682198767, "{\"table\": \"quote\", \"action\": \"insert\", \"data\": [{\"timestamp\": \"2018-06-11T01:56:35.925Z\", \"bidSize\": 32110, \"bidPrice\": 6736, \"askPrice\": 6736.5, \"askSize\": 2086615}, {\"timestamp\": \"2018-06-11T01:56:35.965Z\", \"bidSize\": 32110, \"bidPrice\": 6736, \"askPrice\": 6736.5, \"askSize\": 2086515}, {\"timestamp\": \"2018-06-11T01:56:35.987Z\", \"bidSize\": 12110, \"bidPrice\": 6736, \"askPrice\": 6736.5, \"askSize\": 2086515}, {\"timestamp\": \"2018-06-11T01:56:36.099Z\", \"bidSize\": 12110, \"bidPrice\": 6736, \"askPrice\": 6736.5, \"askSize\": 2105215}, {\"timestamp\": \"2018-06-11T01:56:36.122Z\", \"bidSize\": 11610, \"bidPrice\": 6736, \"askPrice\": 6736.5, \"askSize\": 2105215}, {\"timestamp\": \"2018-06-11T01:56:36.187Z\", \"bidSize\": 10660, \"bidPrice\": 6736, \"askPrice\": 6736.5, \"askSize\": 2105215}, {\"timestamp\": \"2018-06-11T01:56:36.376Z\", \"bidSize\": 10685, \"bidPrice\": 6736, \"askPrice\": 6736.5, \"askSize\": 2105215}, {\"timestamp\": \"2018-06-11T01:56:36.431Z\", \"bidSize\": 10685, \"bidPrice\": 6736, \"askPrice\": 6736.5, \"askSize\": 2086515}, {\"timestamp\": \"2018-06-11T01:56:36.555Z\", \"bidSize\": 10711, \"bidPrice\": 6736, \"askPrice\": 6736.5, \"askSize\": 2086515}, {\"timestamp\": \"2018-06-11T01:56:36.810Z\", \"bidSize\": 6711, \"bidPrice\": 6736, \"askPrice\": 6736.5, \"askSize\": 2086515}, {\"timestamp\": \"2018-06-11T01:56:36.825Z\", \"bidSize\": 5253, \"bidPrice\": 6736, \"askPrice\": 6736.5, \"askSize\": 2086515}, {\"timestamp\": \"2018-06-11T01:56:36.834Z\", \"bidSize\": 5253, \"bidPrice\": 6736, \"askPrice\": 6736.5, \"askSize\": 1786515}, {\"timestamp\": \"2018-06-11T01:56:36.848Z\", \"bidSize\": 5253, \"bidPrice\": 6736, \"askPrice\": 6736.5, \"askSize\": 2086515}, {\"timestamp\": \"2018-06-11T01:56:36.876Z\", \"bidSize\": 5253, \"bidPrice\": 6736, \"askPrice\": 6736.5, \"askSize\": 1986729}, {\"timestamp\": \"2018-06-11T01:56:36.954Z\", \"bidSize\": 5253, \"bidPrice\": 6736, \"askPrice\": 6736.5, \"askSize\": 1956729}, {\"timestamp\": \"2018-06-11T01:56:36.973Z\", \"bidSize\": 5253, \"bidPrice\": 6736, \"askPrice\": 6736.5, \"askSize\": 1986729}, {\"timestamp\": \"2018-06-11T01:56:36.994Z\", \"bidSize\": 5253, \"bidPrice\": 6736, \"askPrice\": 6736.5, \"askSize\": 2079889}, {\"timestamp\": \"2018-06-11T01:56:37.033Z\", \"bidSize\": 9071, \"bidPrice\": 6736, \"askPrice\": 6736.5, \"askSize\": 2079889}], \"symbol\": \"XBTUSD\", \"timestamp\": \"2018-06-11 01:56:38.762900Z\"}", "XBTUSD"], [1528682198987, "{\"table\": \"orderBookL2\", \"action\": \"update\", \"data\": [{\"id\": 8799326350, \"side\": \"Sell\", \"size\": 1474924}, {\"id\": 8799326400, \"side\": \"Sell\", \"size\": 1042438}], \"symbol\": \"XBTUSD\", \"timestamp\": \"2018-06-11 01:56:38.984746Z\"}", "XBTUSD"], [1528682200061, "{\"table\": \"orderBookL2\", \"action\": \"update\", \"data\": [{\"id\": 8799319400, \"side\": \"Sell\", \"size\": 108561}], \"symbol\": \"XBTUSD\", \"timestamp\": \"2018-06-11 01:56:40.057680Z\"}", "XBTUSD"], [1528682201368, "{\"table\": \"orderBookL2\", \"action\": \"update\", \"data\": [{\"id\": 8799326400, \"side\": \"Sell\", \"size\": 1941389}, {\"id\": 8799326450, \"side\": \"Sell\", \"size\": 19032}], \"symbol\": \"XBTUSD\", \"timestamp\": \"2018-06-11 01:56:41.366170Z\"}", "XBTUSD"], [1528682201967, "{\"table\": \"orderBookL2\", \"action\": \"update\", \"data\": [{\"id\": 8799326950, \"side\": \"Buy\", \"size\": 75358}], \"symbol\": \"XBTUSD\", \"timestamp\": \"2018-06-11 01:56:41.965156Z\"}", "XBTUSD"], [1528682203215, "{\"table\": \"orderBookL2\", \"action\": \"update\", \"data\": [{\"id\": 8799327350, \"side\": \"Buy\", \"size\": 98576}], \"symbol\": \"XBTUSD\", \"timestamp\": \"2018-06-11 01:56:43.212395Z\"}", "XBTUSD"], [1528682206367, "{\"table\": \"orderBookL2\", \"action\": \"update\", \"data\": [{\"id\": 8799326550, \"side\": \"Buy\", \"size\": 2321}], \"symbol\": \"XBTUSD\", \"timestamp\": \"2018-06-11 01:56:46.364180Z\"}", "XBTUSD"], [1528682209371, "{\"table\": \"orderBookL2\", \"action\": \"delete\", \"data\": [{\"id\": 8798763000, \"side\": \"Sell\"}], \"symbol\": \"XBTUSD\", \"timestamp\": \"2018-06-11 01:56:49.368519Z\"}", "XBTUSD"], [1528682212653, "{\"table\": \"orderBookL2\", \"action\": \"update\", \"data\": [{\"id\": 8799326450, \"side\": \"Sell\", \"size\": 1989222}], \"symbol\": \"XBTUSD\", \"timestamp\": \"2018-06-11 01:56:52.649132Z\"}", "XBTUSD"], [1528682216338, "{\"table\": \"orderBookL2\", \"action\": \"update\", \"data\": [{\"id\": 8799326550, \"side\": \"Buy\", \"size\": 3288}], \"symbol\": \"XBTUSD\", \"timestamp\": \"2018-06-11 01:56:56.335522Z\"}", "XBTUSD"], [1528682219388, "{\"table\": \"orderBookL2\", \"action\": \"update\", \"data\": [{\"id\": 8799325350, \"side\": \"Sell\", \"size\": 69387}, {\"id\": 8799325650, \"side\": \"Sell\", \"size\": 13551}], \"symbol\": \"XBTUSD\", \"timestamp\": \"2018-06-11 01:56:59.383772Z\"}", "XBTUSD"], [1528682222427, "{\"table\": \"orderBookL2\", \"action\": \"update\", \"data\": [{\"id\": 8799327000, \"side\": \"Buy\", \"size\": 97046}, {\"id\": 8799327700, \"side\": \"Buy\", \"size\": 47656}], \"symbol\": \"XBTUSD\", \"timestamp\": \"2018-06-11 01:57:02.418063Z\"}", "XBTUSD"], [1528682224857, "{\"table\": \"orderBookL2\", \"action\": \"update\", \"data\": [{\"id\": 8799325000, \"side\": \"Sell\", \"size\": 233230}, {\"id\": 8799325650, \"side\": \"Sell\", \"size\": 25000}], \"symbol\": \"XBTUSD\", \"timestamp\": \"2018-06-11 01:57:04.851847Z\"}", "XBTUSD"], [1528682227950, "{\"table\": \"orderBookL2\", \"action\": \"insert\", \"data\": [{\"id\": 8799366150, \"side\": \"Buy\", \"size\": 24449, \"price\": 6338.5}], \"symbol\": \"XBTUSD\", \"timestamp\": \"2018-06-11 01:57:07.945661Z\"}", "XBTUSD"], [1528682231268, "{\"table\": \"orderBookL2\", \"action\": \"update\", \"data\": [{\"id\": 8799325400, \"side\": \"Sell\", \"size\": 72464}, {\"id\": 8799326050, \"side\": \"Sell\", \"size\": 1108}], \"symbol\": \"XBTUSD\", \"timestamp\": \"2018-06-11 01:57:11.257889Z\"}", "XBTUSD"], [1528682233999, "{\"table\": \"orderBookL2\", \"action\": \"update\", \"data\": [{\"id\": 8799295000, \"side\": \"Sell\", \"size\": 5940128}], \"symbol\": \"XBTUSD\", \"timestamp\": \"2018-06-11 01:57:13.993516Z\"}", "XBTUSD"], [1528682237551, "{\"table\": \"orderBookL2\", \"action\": \"update\", \"data\": [{\"id\": 8799327350, \"side\": \"Buy\", \"size\": 61643}], \"symbol\": \"XBTUSD\", \"timestamp\": \"2018-06-11 01:57:17.546119Z\"}", "XBTUSD"], [1528682239225, "{\"table\": \"orderBookL2\", \"action\": \"update\", \"data\": [{\"id\": 8799324750, \"side\": \"Sell\", \"size\": 1421}, {\"id\": 8799324850, \"side\": \"Sell\", \"size\": 13464}, {\"id\": 8799325250, \"side\": \"Sell\", \"size\": 1685}, {\"id\": 8799325400, \"side\": \"Sell\", \"size\": 72464}], \"symbol\": \"XBTUSD\", \"timestamp\": \"2018-06-11 01:57:19.220462Z\"}", "XBTUSD"], [1528682242409, "{\"table\": \"orderBookL2\", \"action\": \"update\", \"data\": [{\"id\": 8799336450, \"side\": \"Buy\", \"size\": 12644}, {\"id\": 8799336500, \"side\": \"Buy\", \"size\": 246481}], \"symbol\": \"XBTUSD\", \"timestamp\": \"2018-06-11 01:57:22.406966Z\"}", "XBTUSD"], [1528682244522, "{\"table\": \"orderBookL2\", \"action\": \"update\", \"data\": [{\"id\": 8799326500, \"side\": \"Buy\", \"size\": 842446}], \"symbol\": \"XBTUSD\", \"timestamp\": \"2018-06-11 01:57:24.520040Z\"}", "XBTUSD"], [1528682248852, "{\"table\": \"orderBookL2\", \"action\": \"update\", \"data\": [{\"id\": 8799320250, \"side\": \"Sell\", \"size\": 2000}, {\"id\": 8799332400, \"side\": \"Buy\", \"size\": 89498}], \"symbol\": \"XBTUSD\", \"timestamp\": \"2018-06-11 01:57:28.847087Z\"}", "XBTUSD"], [1528682249328, "{\"table\": \"orderBookL2\", \"action\": \"update\", \"data\": [{\"id\": 8799326500, \"side\": \"Buy\", \"size\": 873838}], \"symbol\": \"XBTUSD\", \"timestamp\": \"2018-06-11 01:57:29.325290Z\"}", "XBTUSD"], [1528682254315, "{\"table\": \"orderBookL2\", \"action\": \"update\", \"data\": [{\"id\": 8799932600, \"side\": \"Buy\", \"size\": 7}], \"symbol\": \"XBTUSD\", \"timestamp\": \"2018-06-11 01:57:34.311792Z\"}", "XBTUSD"], [1528682256286, "{\"table\": \"orderBookL2\", \"action\": \"update\", \"data\": [{\"id\": 8799326450, \"side\": \"Sell\", \"size\": 223922}], \"symbol\": \"XBTUSD\", \"timestamp\": \"2018-06-11 01:57:36.283989Z\"}", "XBTUSD"], [1528682257980, "{\"table\": \"orderBookL2\", \"action\": \"update\", \"data\": [{\"id\": 8799326750, \"side\": \"Buy\", \"size\": 209694}, {\"id\": 8799326800, \"side\": \"Buy\", \"size\": 47771}], \"symbol\": \"XBTUSD\", \"timestamp\": \"2018-06-11 01:57:37.977675Z\"}", "XBTUSD"], [1528682261311, "{\"table\": \"orderBookL2\", \"action\": \"update\", \"data\": [{\"id\": 8799325700, \"side\": \"Sell\", \"size\": 32889}, {\"id\": 8799325800, \"side\": \"Sell\", \"size\": 5390}], \"symbol\": \"XBTUSD\", \"timestamp\": \"2018-06-11 01:57:41.306613Z\"}", "XBTUSD"], [1528682263791, "{\"table\": \"orderBookL2\", \"action\": \"update\", \"data\": [{\"id\": 8799326500, \"side\": \"Buy\", \"size\": 701097}], \"symbol\": \"XBTUSD\", \"timestamp\": \"2018-06-11 01:57:43.788815Z\"}", "XBTUSD"], [1528682264094, "{\"table\": \"orderBookL2\", \"action\": \"update\", \"data\": [{\"id\": 8799326100, \"side\": \"Sell\", \"size\": 5635}, {\"id\": 8799326950, \"side\": \"Buy\", \"size\": 79083}], \"symbol\": \"XBTUSD\", \"timestamp\": \"2018-06-11 01:57:44.091448Z\"}", "XBTUSD"], [1528682266294, "{\"table\": \"orderBookL2\", \"action\": \"update\", \"data\": [{\"id\": 8799326450, \"side\": \"Buy\", \"size\": 2002171}], \"symbol\": \"XBTUSD\", \"timestamp\": \"2018-06-11 01:57:46.286666Z\"}", "XBTUSD"], [1528682267994, "{\"table\": \"orderBookL2\", \"action\": \"update\", \"data\": [{\"id\": 8799326300, \"side\": \"Sell\", \"size\": 6175}, {\"id\": 8799326500, \"side\": \"Buy\", \"size\": 511505}], \"symbol\": \"XBTUSD\", \"timestamp\": \"2018-06-11 01:57:47.990329Z\"}", "XBTUSD"], [1528682269427, "{\"table\": \"orderBookL2\", \"action\": \"update\", \"data\": [{\"id\": 8799275700, \"side\": \"Sell\", \"size\": 25400}, {\"id\": 8799275900, \"side\": \"Sell\", \"size\": 35425}, {\"id\": 8799276100, \"side\": \"Sell\", \"size\": 27450}, {\"id\": 8799276300, \"side\": \"Sell\", \"size\": 69342}, {\"id\": 8799276400, \"side\": \"Sell\", \"size\": 29264}, {\"id\": 8799326700, \"side\": \"Buy\", \"size\": 106944}, {\"id\": 8799326900, \"side\": \"Buy\", \"size\": 35211}, {\"id\": 8799327100, \"side\": \"Buy\", \"size\": 398894}, {\"id\": 8799327300, \"side\": \"Buy\", \"size\": 324334}], \"symbol\": \"XBTUSD\", \"timestamp\": \"2018-06-11 01:57:49.423500Z\"}", "XBTUSD"], [1528682273847, "{\"table\": \"orderBookL2\", \"action\": \"update\", \"data\": [{\"id\": 8799323500, \"side\": \"Sell\", \"size\": 107654}], \"symbol\": \"XBTUSD\", \"timestamp\": \"2018-06-11 01:57:53.840904Z\"}", "XBTUSD"], [1528682274579, "{\"table\": \"orderBookL2\", \"action\": \"update\", \"data\": [{\"id\": 8799325950, \"side\": \"Sell\", \"size\": 63608}], \"symbol\": \"XBTUSD\", \"timestamp\": \"2018-06-11 01:57:54.575344Z\"}", "XBTUSD"], [1528682278332, "{\"table\": \"orderBookL2\", \"action\": \"update\", \"data\": [{\"id\": 8799325750, \"side\": \"Sell\", \"size\": 4282}, {\"id\": 8799325800, \"side\": \"Sell\", \"size\": 20390}], \"symbol\": \"XBTUSD\", \"timestamp\": \"2018-06-11 01:57:58.328642Z\"}", "XBTUSD"], [1528682278943, "{\"table\": \"orderBookL2\", \"action\": \"update\", \"data\": [{\"id\": 8799326700, \"side\": \"Buy\", \"size\": 84784}], \"symbol\": \"XBTUSD\", \"timestamp\": \"2018-06-11 01:57:58.941303Z\"}", "XBTUSD"], [1528682279652, "{\"table\": \"orderBookL2\", \"action\": \"update\", \"data\": [{\"id\": 8799326400, \"side\": \"Buy\", \"size\": 1993450}], \"symbol\": \"XBTUSD\", \"timestamp\": \"2018-06-11 01:57:59.648176Z\"}", "XBTUSD"], [1528682283345, "{\"table\": \"orderBookL2\", \"action\": \"update\", \"data\": [{\"id\": 8799325950, \"side\": \"Sell\", \"size\": 89608}, {\"id\": 8799326350, \"side\": \"Sell\", \"size\": 254681}, {\"id\": 8799327000, \"side\": \"Buy\", \"size\": 96915}, {\"id\": 8799327600, \"side\": \"Buy\", \"size\": 15365}], \"symbol\": \"XBTUSD\", \"timestamp\": \"2018-06-11 01:58:03.341446Z\"}", "XBTUSD"], [1528682283558, "{\"table\": \"orderBookL2\", \"action\": \"update\", \"data\": [{\"id\": 8799325650, \"side\": \"Sell\", \"size\": 45200}], \"symbol\": \"XBTUSD\", \"timestamp\": \"2018-06-11 01:58:03.555560Z\"}", "XBTUSD"], [1528682284602, "{\"table\": \"orderBookL2\", \"action\": \"update\", \"data\": [{\"id\": 8799326150, \"side\": \"Sell\", \"size\": 243807}], \"symbol\": \"XBTUSD\", \"timestamp\": \"2018-06-11 01:58:04.599244Z\"}", "XBTUSD"], [1528682286406, "{\"table\": \"orderBookL2\", \"action\": \"update\", \"data\": [{\"id\": 8799325150, \"side\": \"Sell\", \"size\": 40600}], \"symbol\": \"XBTUSD\", \"timestamp\": \"2018-06-11 01:58:06.396280Z\"}", "XBTUSD"], [1528682288560, "{\"table\": \"orderBookL2\", \"action\": \"update\", \"data\": [{\"id\": 8799275500, \"side\": \"Sell\", \"size\": 224405}, {\"id\": 8799275700, \"side\": \"Sell\", \"size\": 21600}, {\"id\": 8799275900, \"side\": \"Sell\", \"size\": 31625}, {\"id\": 8799276100, \"side\": \"Sell\", \"size\": 23650}, {\"id\": 8799276350, \"side\": \"Sell\", \"size\": 22235}, {\"id\": 8799326700, \"side\": \"Buy\", \"size\": 79164}, {\"id\": 8799326900, \"side\": \"Buy\", \"size\": 64888}, {\"id\": 8799327100, \"side\": \"Buy\", \"size\": 50394}], \"symbol\": \"XBTUSD\", \"timestamp\": \"2018-06-11 01:58:08.556984Z\"}", "XBTUSD"], [1528682290061, "{\"table\": \"orderBookL2\", \"action\": \"update\", \"data\": [{\"id\": 8799932600, \"side\": \"Buy\", \"size\": 4}], \"symbol\": \"XBTUSD\", \"timestamp\": \"2018-06-11 01:58:10.057293Z\"}", "XBTUSD"], [1528682292830, "{\"table\": \"orderBookL2\", \"action\": \"update\", \"data\": [{\"id\": 8799326100, \"side\": \"Sell\", \"size\": 23672}], \"symbol\": \"XBTUSD\", \"timestamp\": \"2018-06-11 01:58:12.827782Z\"}", "XBTUSD"], [1528682295008, "{\"table\": \"orderBookL2\", \"action\": \"update\", \"data\": [{\"id\": 8799326350, \"side\": \"Sell\", \"size\": 22093}], \"symbol\": \"XBTUSD\", \"timestamp\": \"2018-06-11 01:58:15.004011Z\"}", "XBTUSD"], [1528682299312, "{\"table\": \"orderBookL2\", \"action\": \"update\", \"data\": [{\"id\": 8799318900, \"side\": \"Sell\", \"size\": 77841}], \"symbol\": \"XBTUSD\", \"timestamp\": \"2018-06-11 01:58:19.307654Z\"}", "XBTUSD"], [1528682299570, "{\"table\": \"orderBookL2\", \"action\": \"update\", \"data\": [{\"id\": 8799325700, \"side\": \"Sell\", \"size\": 23792}], \"symbol\": \"XBTUSD\", \"timestamp\": \"2018-06-11 01:58:19.567710Z\"}", "XBTUSD"], [1528682299874, "{\"table\": \"orderBookL2\", \"action\": \"update\", \"data\": [{\"id\": 8799326350, \"side\": \"Buy\", \"size\": 1443216}], \"symbol\": \"XBTUSD\", \"timestamp\": \"2018-06-11 01:58:19.870969Z\"}", "XBTUSD"], [1528682302756, "{\"table\": \"orderBookL2\", \"action\": \"update\", \"data\": [{\"id\": 8799325400, \"side\": \"Sell\", \"size\": 33046}, {\"id\": 8799325650, \"side\": \"Sell\", \"size\": 2258}, {\"id\": 8799326400, \"side\": \"Buy\", \"size\": 773962}, {\"id\": 8